Workbook

Sheet Start
A2: The STR Ledger
A4: Year-Over-Year Comparison
A5: Did this year actually go better — or did it just feel that way?
A6: =IF('Portfolio Roll-up'!B7=0,"📊 Set your years on Settings, then enter PY + CY data to see your verdict.",IF(('Portfolio Roll-up'!B11-'Portfolio Roll-up'!B7)/'Portfolio Roll-up'!B7>=0,"✅ Revenue YoY = "&TEXT(('Portfolio Roll-up'!B11-'Portfolio Roll-up'!B7)/'Portfolio Roll-up'!B7,"+0.0%")&" — CY pacing ahead of PY.","⚠ Revenue YoY = "&TEXT(('Portfolio Roll-up'!B11-'Portfolio Roll-up'!B7)/'Portfolio Roll-up'!B7,"+0.0%")&" — CY pacing behind PY; review Top Movers."))
A7: FIN-005 · v2.3 · BLANK
A10: WHAT THIS DOES
A11: Side-by-side prior-year vs current-year P&L for up to three properties. Per-property 24-col matrix (12 PY months / 12 CY months) with $ delta + % delta. Portfolio rollup surfaces revenue YoY %, NOI YoY %, and the top-3 favorable + top-3 unfavorable category movers — the variance-analysis conversation a CPA would charge $300/hr to walk you through.
A18: REVENUE YoY % | D18: NOI YoY % | G18: TOP MOVER (+) | J18: TOP PROBLEM (−)
A19: =IFERROR(('Portfolio Roll-up'!B11-'Portfolio Roll-up'!B7)/'Portfolio Roll-up'!B7,0) | D19: =IFERROR(('Portfolio Roll-up'!B19-'Portfolio Roll-up'!B15)/ABS('Portfolio Roll-up'!B15),0) | G19: =IFERROR('Top Movers'!B6 & " / " & 'Top Movers'!C6, "—") | J19: =IFERROR('Top Movers'!B14 & " / " & 'Top Movers'!C14, "—")
A21: portfolio gross | D21: net operating income | G21: =IFERROR(TEXT('Top Movers'!F6,"$#,##0"),"") | J21: =IFERROR(TEXT('Top Movers'!F14,"$#,##0"),"")
A25: =HYPERLINK("#'Per Property'!A1", "→ OPEN PER-PROPERTY COMPARISON")
A30: =HYPERLINK("#'Portfolio Roll-up'!A1", "Portfolio Roll-up") | D30: =HYPERLINK("#'Top Movers'!A1", "Top Movers") | G30: =HYPERLINK("#'Settings'!A1", "Settings") | J30: =HYPERLINK("#'Portfolio Roll-up'!A1", "📄 Print Pack")
A33: 📅 YEAR-END RITUAL: paste prior-year totals from your P&L tracker into the PY columns, current-year YTD into CY, and let the deltas tell the story. Bump Settings B5/B7 each January.
A35: 💡 Upgrade to the Full version at thestrledger.com/upgrade — multi-property, depreciation, multi-LLC support.
A38: Questions? hello@thestrledger.com
A39: FIN-005 · v2.3 · Free updates forever

Sheet Per Property
A2: =HYPERLINK("#'Start'!A1", "← BACK") | D2: PER PROPERTY | J2: =HYPERLINK("#'Portfolio Roll-up'!A1", "NEXT →")
A4: Each property: 12 PY months (Jan..Dec) + 12 CY months + Total PY / Total CY / $ Δ / % Δ. Year labels driven by Settings B5 + B7.
A6: PROPERTY 1: SMOKIES RIDGE CABIN
B7: ="PRIOR YEAR ("&Settings!$B$7&")" | O7: ="CURRENT YEAR ("&Settings!$B$5&")" | AB7: DELTA
A8: Category | B8: Jan | C8: Feb | D8: Mar | E8: Apr | F8: May | G8: Jun | H8: Jul | I8: Aug | J8: Sep | K8: Oct | L8: Nov | M8: Dec | N8: Total PY | O8: Jan | P8: Feb | Q8: Mar | R8: Apr | S8: May | T8: Jun | U8: Jul | V8: Aug | W8: Sep | X8: Oct | Y8: Nov | Z8: Dec | AA8: Total CY | AB8: $ Δ | AC8: % Δ
A9: REVENUE
A10: Rents + cleaning fees collected | N10: =SUM(B10:M10) | AA10: =SUM(O10:Z10) | AB10: =AA10-N10 | AC10: =IFERROR((AA10-N10)/N10,0)
A11: Total revenue | B11: =SUM(B10:B10) | C11: =SUM(C10:C10) | D11: =SUM(D10:D10) | E11: =SUM(E10:E10) | F11: =SUM(F10:F10) | G11: =SUM(G10:G10) | H11: =SUM(H10:H10) | I11: =SUM(I10:I10) | ... AB11: =SUM(AB10:AB10) | AC11: =IFERROR((AA11-N11)/N11,0)
A13: EXPENSES
A14: Cleaning + maintenance | N14: =SUM(B14:M14) | AA14: =SUM(O14:Z14) | AB14: =AA14-N14 | AC14: =IFERROR((AA14-N14)/N14,0)
A15: Insurance | N15: =SUM(B15:M15) | AA15: =SUM(O15:Z15) | AB15: =AA15-N15 | AC15: =IFERROR((AA15-N15)/N15,0)
A16: Mortgage interest | N16: =SUM(B16:M16) | AA16: =SUM(O16:Z16) | AB16: =AA16-N16 | AC16: =IFERROR((AA16-N16)/N16,0)
A17: Repairs | N17: =SUM(B17:M17) | AA17: =SUM(O17:Z17) | AB17: =AA17-N17 | AC17: =IFERROR((AA17-N17)/N17,0)
A18: Utilities | N18: =SUM(B18:M18) | AA18: =SUM(O18:Z18) | AB18: =AA18-N18 | AC18: =IFERROR((AA18-N18)/N18,0)
A19: Management fees | N19: =SUM(B19:M19) | AA19: =SUM(O19:Z19) | AB19: =AA19-N19 | AC19: =IFERROR((AA19-N19)/N19,0)
A20: Supplies | N20: =SUM(B20:M20) | AA20: =SUM(O20:Z20) | AB20: =AA20-N20 | AC20: =IFERROR((AA20-N20)/N20,0)
A21: Other | N21: =SUM(B21:M21) | AA21: =SUM(O21:Z21) | AB21: =AA21-N21 | AC21: =IFERROR((AA21-N21)/N21,0)
A22: Total expenses | B22: =SUM(B14:B21) | C22: =SUM(C14:C21) | D22: =SUM(D14:D21) | E22: =SUM(E14:E21) | F22: =SUM(F14:F21) | G22: =SUM(G14:G21) | H22: =SUM(H14:H21) | I22: =SUM(I14:I21) | ... AB22: =SUM(AB14:AB21) | AC22: =IFERROR((AA22-N22)/N22,0)
A24: NET INCOME | B24: =B11-B22 | C24: =C11-C22 | D24: =D11-D22 | E24: =E11-E22 | F24: =F11-F22 | G24: =G11-G22 | H24: =H11-H22 | I24: =I11-I22 | ... AA24: =AA11-AA22 | AB24: =AA24-N24 | AC24: =IFERROR((AA24-N24)/ABS(N24),0)
A27: PROPERTY 2: LAKEHOUSE RETREAT
B28: ="PRIOR YEAR ("&Settings!$B$7&")" | O28: ="CURRENT YEAR ("&Settings!$B$5&")" | AB28: DELTA
A29: Category | B29: Jan | C29: Feb | D29: Mar | E29: Apr | F29: May | G29: Jun | H29: Jul | I29: Aug | J29: Sep | K29: Oct | L29: Nov | M29: Dec | N29: Total PY | O29: Jan | P29: Feb | Q29: Mar | R29: Apr | S29: May | T29: Jun | U29: Jul | V29: Aug | W29: Sep | X29: Oct | Y29: Nov | Z29: Dec | AA29: Total CY | AB29: $ Δ | AC29: % Δ
A30: REVENUE
A31: Rents + cleaning fees collected | N31: =SUM(B31:M31) | AA31: =SUM(O31:Z31) | AB31: =AA31-N31 | AC31: =IFERROR((AA31-N31)/N31,0)
A32: Total revenue | B32: =SUM(B31:B31) | C32: =SUM(C31:C31) | D32: =SUM(D31:D31) | E32: =SUM(E31:E31) | F32: =SUM(F31:F31) | G32: =SUM(G31:G31) | H32: =SUM(H31:H31) | I32: =SUM(I31:I31) | ... AB32: =SUM(AB31:AB31) | AC32: =IFERROR((AA32-N32)/N32,0)
A34: EXPENSES
A35: Cleaning + maintenance | N35: =SUM(B35:M35) | AA35: =SUM(O35:Z35) | AB35: =AA35-N35 | AC35: =IFERROR((AA35-N35)/N35,0)
A36: Insurance | N36: =SUM(B36:M36) | AA36: =SUM(O36:Z36) | AB36: =AA36-N36 | AC36: =IFERROR((AA36-N36)/N36,0)
A37: Mortgage interest | N37: =SUM(B37:M37) | AA37: =SUM(O37:Z37) | AB37: =AA37-N37 | AC37: =IFERROR((AA37-N37)/N37,0)
A38: Repairs | N38: =SUM(B38:M38) | AA38: =SUM(O38:Z38) | AB38: =AA38-N38 | AC38: =IFERROR((AA38-N38)/N38,0)
A39: Utilities | N39: =SUM(B39:M39) | AA39: =SUM(O39:Z39) | AB39: =AA39-N39 | AC39: =IFERROR((AA39-N39)/N39,0)
A40: Management fees | N40: =SUM(B40:M40) | AA40: =SUM(O40:Z40) | AB40: =AA40-N40 | AC40: =IFERROR((AA40-N40)/N40,0)
A41: Supplies | N41: =SUM(B41:M41) | AA41: =SUM(O41:Z41) | AB41: =AA41-N41 | AC41: =IFERROR((AA41-N41)/N41,0)
A42: Other | N42: =SUM(B42:M42) | AA42: =SUM(O42:Z42) | AB42: =AA42-N42 | AC42: =IFERROR((AA42-N42)/N42,0)
A43: Total expenses | B43: =SUM(B35:B42) | C43: =SUM(C35:C42) | D43: =SUM(D35:D42) | E43: =SUM(E35:E42) | F43: =SUM(F35:F42) | G43: =SUM(G35:G42) | H43: =SUM(H35:H42) | I43: =SUM(I35:I42) | ... AB43: =SUM(AB35:AB42) | AC43: =IFERROR((AA43-N43)/N43,0)
A45: NET INCOME | B45: =B32-B43 | C45: =C32-C43 | D45: =D32-D43 | E45: =E32-E43 | F45: =F32-F43 | G45: =G32-G43 | H45: =H32-H43 | I45: =I32-I43 | ... AA45: =AA32-AA43 | AB45: =AA45-N45 | AC45: =IFERROR((AA45-N45)/ABS(N45),0)
A48: PROPERTY 3: COASTAL COTTAGE
B49: ="PRIOR YEAR ("&Settings!$B$7&")" | O49: ="CURRENT YEAR ("&Settings!$B$5&")" | AB49: DELTA
A50: Category | B50: Jan | C50: Feb | D50: Mar | E50: Apr | F50: May | G50: Jun | H50: Jul | I50: Aug | J50: Sep | K50: Oct | L50: Nov | M50: Dec | N50: Total PY | O50: Jan | P50: Feb | Q50: Mar | R50: Apr | S50: May | T50: Jun | U50: Jul | V50: Aug | W50: Sep | X50: Oct | Y50: Nov | Z50: Dec | AA50: Total CY | AB50: $ Δ | AC50: % Δ
A51: REVENUE
...

Sheet Portfolio Roll-up
A2: =HYPERLINK("#'Per Property'!A1", "← BACK") | D2: PORTFOLIO ROLL-UP | J2: =HYPERLINK("#'Top Movers'!A1", "NEXT →")
A4: Portfolio totals — PY vs CY across all properties on the Per Property tab
A5: Metric | B5: ="Prior ("&Settings!$B$7&")" | C5: ="Current ("&Settings!$B$5&")" | D5: $ Δ | E5: % Δ
A6: REVENUE
A7: Portfolio revenue (all properties) | B7: ='Per Property'!N11+'Per Property'!N30+'Per Property'!N49 | C7: ='Per Property'!AA11+'Per Property'!AA30+'Per Property'!AA49 | D7: =C7-B7 | E7: =IFERROR((C7-B7)/B7,0)
A8: Smokies Ridge Cabin | B8: ='Per Property'!N11 | C8: ='Per Property'!AA11 | D8: =C8-B8 | E8: =IFERROR((C8-B8)/B8,0)
A9: Lakehouse Retreat | B9: ='Per Property'!N30 | C9: ='Per Property'!AA30 | D9: =C9-B9 | E9: =IFERROR((C9-B9)/B9,0)
A10: Coastal Cottage | B10: ='Per Property'!N49 | C10: ='Per Property'!AA49 | D10: =C10-B10 | E10: =IFERROR((C10-B10)/B10,0)
A11: Portfolio revenue — CY pacing | B11: =C7
A13: EXPENSES
A14: Portfolio expenses (all properties) | B14: ='Per Property'!N21+'Per Property'!N40+'Per Property'!N59 | C14: ='Per Property'!AA21+'Per Property'!AA40+'Per Property'!AA59 | D14: =C14-B14 | E14: =IFERROR((C14-B14)/B14,0)
A15: NOI — Net operating income (PY) | B15: =B7-B14 | C15: =C7-C14 | D15: =C15-B15 | E15: =IFERROR((C15-B15)/ABS(B15),0)
A16: Smokies Ridge Cabin | B16: ='Per Property'!N11-'Per Property'!N21 | C16: ='Per Property'!AA11-'Per Property'!AA21 | D16: =C16-B16 | E16: =IFERROR((C16-B16)/ABS(B16),0)
A17: Lakehouse Retreat | B17: ='Per Property'!N30-'Per Property'!N40 | C17: ='Per Property'!AA30-'Per Property'!AA40 | D17: =C17-B17 | E17: =IFERROR((C17-B17)/ABS(B17),0)
A18: Coastal Cottage | B18: ='Per Property'!N49-'Per Property'!N59 | C18: ='Per Property'!AA49-'Per Property'!AA59 | D18: =C18-B18 | E18: =IFERROR((C18-B18)/ABS(B18),0)
A19: NOI — CY pacing | B19: =C15
A22: MONTHLY (portfolio)
A23: Month | B23: Jan | C23: Feb | D23: Mar | E23: Apr | F23: May | G23: Jun | H23: Jul | I23: Aug | J23: Sep | K23: Oct | L23: Nov | M23: Dec
A24: ="Revenue PY ("&Settings!$B$7&")" | B24: ='Per Property'!B10+'Per Property'!B29+'Per Property'!B48 | C24: ='Per Property'!C10+'Per Property'!C29+'Per Property'!C48 | D24: ='Per Property'!D10+'Per Property'!D29+'Per Property'!D48 | E24: ='Per Property'!E10+'Per Property'!E29+'Per Property'!E48 | F24: ='Per Property'!F10+'Per Property'!F29+'Per Property'!F48 | G24: ='Per Property'!G10+'Per Property'!G29+'Per Property'!G48 | H24: ='Per Property'!H10+'Per Property'!H29+'Per Property'!H48 | I24: ='Per Property'!I10+'Per Property'!I29+'Per Property'!I48 | ... M24: ='Per Property'!M10+'Per Property'!M29+'Per Property'!M48
A25: ="Revenue CY ("&Settings!$B$5&")" | B25: ='Per Property'!O10+'Per Property'!O29+'Per Property'!O48 | C25: ='Per Property'!P10+'Per Property'!P29+'Per Property'!P48 | D25: ='Per Property'!Q10+'Per Property'!Q29+'Per Property'!Q48 | E25: ='Per Property'!R10+'Per Property'!R29+'Per Property'!R48 | F25: ='Per Property'!S10+'Per Property'!S29+'Per Property'!S48 | G25: ='Per Property'!T10+'Per Property'!T29+'Per Property'!T48 | H25: ='Per Property'!U10+'Per Property'!U29+'Per Property'!U48 | I25: ='Per Property'!V10+'Per Property'!V29+'Per Property'!V48 | ... M25: ='Per Property'!Z10+'Per Property'!Z29+'Per Property'!Z48

Sheet Top Movers
A2: =HYPERLINK("#'Portfolio Roll-up'!A1", "← BACK") | D2: TOP MOVERS | J2: =HYPERLINK("#'Settings'!A1", "NEXT →")
A4: Top-3 favorable + top-3 unfavorable expense moves across all properties. Driven by SMALL/LARGE on the per-property delta column.
A5: ✅ | B5: TOP-3 FAVORABLE (expense decreases)
A6: 1 | B6: =INDEX(A30:A53,MATCH(SMALL(E30:E53,1),E30:E53,0)) | C6: =INDEX(B30:B53,MATCH(SMALL(E30:E53,1),E30:E53,0)) | D6: =INDEX(C30:C53,MATCH(SMALL(E30:E53,1),E30:E53,0)) | E6: =INDEX(D30:D53,MATCH(SMALL(E30:E53,1),E30:E53,0)) | F6: =SMALL(E30:E53,1) | G6: =IFERROR(F6/D6,0) | H6: ↓
A7: 2 | B7: =INDEX(A30:A53,MATCH(SMALL(E30:E53,2),E30:E53,0)) | C7: =INDEX(B30:B53,MATCH(SMALL(E30:E53,2),E30:E53,0)) | D7: =INDEX(C30:C53,MATCH(SMALL(E30:E53,2),E30:E53,0)) | E7: =INDEX(D30:D53,MATCH(SMALL(E30:E53,2),E30:E53,0)) | F7: =SMALL(E30:E53,2) | G7: =IFERROR(F7/D7,0) | H7: ↓
A8: 3 | B8: =INDEX(A30:A53,MATCH(SMALL(E30:E53,3),E30:E53,0)) | C8: =INDEX(B30:B53,MATCH(SMALL(E30:E53,3),E30:E53,0)) | D8: =INDEX(C30:C53,MATCH(SMALL(E30:E53,3),E30:E53,0)) | E8: =INDEX(D30:D53,MATCH(SMALL(E30:E53,3),E30:E53,0)) | F8: =SMALL(E30:E53,3) | G8: =IFERROR(F8/D8,0) | H8: ↓
A12: ⚠ | B12: TOP-3 UNFAVORABLE (expense increases)
A14: 1 | B14: =INDEX(A30:A53,MATCH(LARGE(E30:E53,1),E30:E53,0)) | C14: =INDEX(B30:B53,MATCH(LARGE(E30:E53,1),E30:E53,0)) | D14: =INDEX(C30:C53,MATCH(LARGE(E30:E53,1),E30:E53,0)) | E14: =INDEX(D30:D53,MATCH(LARGE(E30:E53,1),E30:E53,0)) | F14: =LARGE(E30:E53,1) | G14: =IFERROR(F14/D14,0) | H14: ↑
A15: 2 | B15: =INDEX(A30:A53,MATCH(LARGE(E30:E53,2),E30:E53,0)) | C15: =INDEX(B30:B53,MATCH(LARGE(E30:E53,2),E30:E53,0)) | D15: =INDEX(C30:C53,MATCH(LARGE(E30:E53,2),E30:E53,0)) | E15: =INDEX(D30:D53,MATCH(LARGE(E30:E53,2),E30:E53,0)) | F15: =LARGE(E30:E53,2) | G15: =IFERROR(F15/D15,0) | H15: ↑
A16: 3 | B16: =INDEX(A30:A53,MATCH(LARGE(E30:E53,3),E30:E53,0)) | C16: =INDEX(B30:B53,MATCH(LARGE(E30:E53,3),E30:E53,0)) | D16: =INDEX(C30:C53,MATCH(LARGE(E30:E53,3),E30:E53,0)) | E16: =INDEX(D30:D53,MATCH(LARGE(E30:E53,3),E30:E53,0)) | F16: =LARGE(E30:E53,3) | G16: =IFERROR(F16/D16,0) | H16: ↑
A18: ℹ Movers ranked across categories × properties (24 rows). Ties broken arbitrarily by Excel — if two rows show identical deltas, MATCH returns the first.
A30: Cleaning + maintenance | B30: Smokies Ridge Cabin | C30: ='Per Property'!N13 | D30: ='Per Property'!AA13 | E30: =D30-C30
A31: Insurance | B31: Smokies Ridge Cabin | C31: ='Per Property'!N14 | D31: ='Per Property'!AA14 | E31: =D31-C31
A32: Mortgage interest | B32: Smokies Ridge Cabin | C32: ='Per Property'!N15 | D32: ='Per Property'!AA15 | E32: =D32-C32
A33: Repairs | B33: Smokies Ridge Cabin | C33: ='Per Property'!N16 | D33: ='Per Property'!AA16 | E33: =D33-C33
A34: Utilities | B34: Smokies Ridge Cabin | C34: ='Per Property'!N17 | D34: ='Per Property'!AA17 | E34: =D34-C34
A35: Management fees | B35: Smokies Ridge Cabin | C35: ='Per Property'!N18 | D35: ='Per Property'!AA18 | E35: =D35-C35
A36: Supplies | B36: Smokies Ridge Cabin | C36: ='Per Property'!N19 | D36: ='Per Property'!AA19 | E36: =D36-C36
A37: Other | B37: Smokies Ridge Cabin | C37: ='Per Property'!N20 | D37: ='Per Property'!AA20 | E37: =D37-C37
A38: Cleaning + maintenance | B38: Lakehouse Retreat | C38: ='Per Property'!N32 | D38: ='Per Property'!AA32 | E38: =D38-C38
A39: Insurance | B39: Lakehouse Retreat | C39: ='Per Property'!N33 | D39: ='Per Property'!AA33 | E39: =D39-C39
A40: Mortgage interest | B40: Lakehouse Retreat | C40: ='Per Property'!N34 | D40: ='Per Property'!AA34 | E40: =D40-C40
A41: Repairs | B41: Lakehouse Retreat | C41: ='Per Property'!N35 | D41: ='Per Property'!AA35 | E41: =D41-C41
A42: Utilities | B42: Lakehouse Retreat | C42: ='Per Property'!N36 | D42: ='Per Property'!AA36 | E42: =D42-C42
A43: Management fees | B43: Lakehouse Retreat | C43: ='Per Property'!N37 | D43: ='Per Property'!AA37 | E43: =D43-C43
A44: Supplies | B44: Lakehouse Retreat | C44: ='Per Property'!N38 | D44: ='Per Property'!AA38 | E44: =D44-C44
A45: Other | B45: Lakehouse Retreat | C45: ='Per Property'!N39 | D45: ='Per Property'!AA39 | E45: =D45-C45
A46: Cleaning + maintenance | B46: Coastal Cottage | C46: ='Per Property'!N51 | D46: ='Per Property'!AA51 | E46: =D46-C46
A47: Insurance | B47: Coastal Cottage | C47: ='Per Property'!N52 | D47: ='Per Property'!AA52 | E47: =D47-C47
A48: Mortgage interest | B48: Coastal Cottage | C48: ='Per Property'!N53 | D48: ='Per Property'!AA53 | E48: =D48-C48
A49: Repairs | B49: Coastal Cottage | C49: ='Per Property'!N54 | D49: ='Per Property'!AA54 | E49: =D49-C49
A50: Utilities | B50: Coastal Cottage | C50: ='Per Property'!N55 | D50: ='Per Property'!AA55 | E50: =D50-C50
A51: Management fees | B51: Coastal Cottage | C51: ='Per Property'!N56 | D51: ='Per Property'!AA56 | E51: =D51-C51
A52: Supplies | B52: Coastal Cottage | C52: ='Per Property'!N57 | D52: ='Per Property'!AA57 | E52: =D52-C52
A53: Other | B53: Coastal Cottage | C53: ='Per Property'!N58 | D53: ='Per Property'!AA58 | E53: =D53-C53

Sheet Settings
A2: =HYPERLINK("#'Top Movers'!A1", "← BACK") | D2: SETTINGS
A4: Current year drives every CY label · Prior year drives every PY label · property list shown for reference
A5: Current year: | B5: 2026
A6: Bump this each January. Drives every CY column header, the Start verdict cell, and every $Δ + %Δ on the Per Property tab.
A7: Prior year: | B7: 2025
A8: Usually current_year - 1. Drives every PY column header on Per Property and the PY series in the portfolio charts.
A9: Property 1: | B9: Smokies Ridge Cabin
A10: Property 2: | B10: Lakehouse Retreat
A11: Property 3: | B11: Coastal Cottage
A12: Property 4:
A13: Property 5:
A14: Property 6:
A15: Property 7:
A16: Property 8:
A17: Property 9:
A18: Property 10:
A19: Up to 10 property names — the Per Property tab uses the first 3. Edit Per Property section banners directly to swap properties.
