Workbook

Sheet Start
A2: The STR Ledger
A4: Welcome Book
A5: Welcome books that earn 5-stars.
A7: GST-001 · v2.0
A11: What you'll build in the next 15 minutes
A13: 📖 PRINT | E13: 📱 QR CODE | I13: ✉ EMAIL PDF
A14: Spiral-bound binder for the kitchen counter. | E14: Scan on arrival — view on the guest's phone. | I14: Send ahead of check-in. One page, every tab.
A23: Quick Start — be done in 5 minutes
B24: ① Property name + host phone | H24: ④ Checkout time
B25: ② WiFi network + password | H25: ⑤ Hospital + 911 note
B26: ③ Trash pickup day
A30: =HYPERLINK("#'Property'!A5", "GET STARTED — FILL YOUR PROPERTY INFO →")
A36: Progress: | G36: =TEXT((COUNTA('Property'!B5:B12) + COUNTA('Arrival'!B5:B11) + COUNTA('WiFi + Tech'!B5:B12) + COUNTA('House Rules'!B5:B11) + COUNTA('Local Guide'!B6:E25) + COUNTA('Trash'!B5:B11) + COUNTA('Departure'!B5:B10) + COUNTA('Emergency'!B5:B13))/132, "0%") & " complete"
A38: ① Property Info | G38: =IF(COUNTA('Property'!B5:B12)=8,"✅ Done",IF(COUNTA('Property'!B5:B12)=0,"⏳ Empty","⏳ "&COUNTA('Property'!B5:B12)&" of 8")) | K38: =HYPERLINK("#'Property'!A5","→ go")
A39: ② Arrival | G39: =IF(COUNTA('Arrival'!B5:B11)=7,"✅ Done",IF(COUNTA('Arrival'!B5:B11)=0,"⏳ Empty","⏳ "&COUNTA('Arrival'!B5:B11)&" of 7")) | K39: =HYPERLINK("#'Arrival'!A5","→ go")
A40: ③ WiFi + Tech | G40: =IF(COUNTA('WiFi + Tech'!B5:B12)=8,"✅ Done",IF(COUNTA('WiFi + Tech'!B5:B12)=0,"⏳ Empty","⏳ "&COUNTA('WiFi + Tech'!B5:B12)&" of 8")) | K40: =HYPERLINK("#'WiFi + Tech'!A5","→ go")
A41: ④ House Rules | G41: =IF(COUNTA('House Rules'!B5:B11)=7,"✅ Done",IF(COUNTA('House Rules'!B5:B11)=0,"⏳ Empty","⏳ "&COUNTA('House Rules'!B5:B11)&" of 7")) | K41: =HYPERLINK("#'House Rules'!A5","→ go")
A42: ⑤ Local Guide | G42: =IF(COUNTA('Local Guide'!B6:E25)=80,"✅ Done",IF(COUNTA('Local Guide'!B6:E25)=0,"⏳ Empty","⏳ "&COUNTA('Local Guide'!B6:E25)&" of 80")) | K42: =HYPERLINK("#'Local Guide'!A5","→ go")
A43: ⑥ Trash | G43: =IF(COUNTA('Trash'!B5:B11)=7,"✅ Done",IF(COUNTA('Trash'!B5:B11)=0,"⏳ Empty","⏳ "&COUNTA('Trash'!B5:B11)&" of 7")) | K43: =HYPERLINK("#'Trash'!A5","→ go")
A44: ⑦ Departure | G44: =IF(COUNTA('Departure'!B5:B10)=6,"✅ Done",IF(COUNTA('Departure'!B5:B10)=0,"⏳ Empty","⏳ "&COUNTA('Departure'!B5:B10)&" of 6")) | K44: =HYPERLINK("#'Departure'!A5","→ go")
A45: ⑧ Emergency | G45: =IF(COUNTA('Emergency'!B5:B13)=9,"✅ Done",IF(COUNTA('Emergency'!B5:B13)=0,"⏳ Empty","⏳ "&COUNTA('Emergency'!B5:B13)&" of 9")) | K45: =HYPERLINK("#'Emergency'!A5","→ go")
A50: Questions? hello@thestrledger.com
A51: Free updates forever · v2.0 · Released 2026-05

Sheet Property
A2: =HYPERLINK("#'Start'!A1", "← START") | D2: SECTION 1 OF 8 | J2: =HYPERLINK("#'Arrival'!A5", "NEXT →")
A4: Property Info
A5: Who you are and where they're staying.
A7: Fill the highlighted fields below. The 'Review & Print' tab (last) shows what your guest will see.
A9: IDENTITY
A10: Property name:
A11: Host first name:
A13: GUEST DETAILS
A14: Host phone (text preferred):
A15: Check-in date:
A16: Check-out date:
A17: Property type:
A18: Max guests:
... A22: First time? Go to Start → Quick Start for the 5-minute path.
A25: =HYPERLINK("#'Start'!A1", "← Back: Start") | G25: =HYPERLINK("#'Arrival'!A5", "Next: Arrival →")

Sheet Arrival
A2: =HYPERLINK("#'Property'!A5", "← BACK") | D2: SECTION 2 OF 8 | J2: =HYPERLINK("#'WiFi + Tech'!A5", "NEXT →")
A4: Arrival & Check-in
A5: Everything your guest needs on day one.
A7: Fill the highlighted fields below. The 'Review & Print' tab (last) shows what your guest will see.
A9: ENTRY & PARKING
A10: Full address:
A11: Entry method:
A12: Door/lock code:
A13: Parking instructions:
A15: ROUTE & TIMING
A16: Best route (if tricky):
A17: Arrival time window:
A18: If you arrive early:
... A24: 4. If anything's broken, text the host immediately.
A27: =HYPERLINK("#'Property'!A5", "← Back: Property") | G27: =HYPERLINK("#'WiFi + Tech'!A5", "Next: WiFi + Tech →")

Sheet WiFi + Tech
A2: =HYPERLINK("#'Arrival'!A5", "← BACK") | D2: SECTION 3 OF 8 | J2: =HYPERLINK("#'House Rules'!A5", "NEXT →")
A4: WiFi & Technology
A5: So nobody has to text you about the wifi password.
A7: Fill the highlighted fields below. The 'Review & Print' tab (last) shows what your guest will see.
A9: NETWORK
A10: WiFi network name:
A11: WiFi password:
A12: Backup network (if any):
A14: ENTERTAINMENT
A15: TV streaming — service + login:
A16: How to adjust TV volume/inputs:
A18: SMART DEVICES
A19: Smart lock code (if different):
... A21: Who to call if WiFi fails:
A24: =HYPERLINK("#'Arrival'!A5", "← Back: Arrival") | G24: =HYPERLINK("#'House Rules'!A5", "Next: House Rules →")

Sheet House Rules
A2: =HYPERLINK("#'WiFi + Tech'!A5", "← BACK") | D2: SECTION 4 OF 8 | J2: =HYPERLINK("#'Local Guide'!A5", "NEXT →")
A4: House Rules
A5: Short, clear, and why each one exists.
A7: Fill the highlighted fields below. The 'Review & Print' tab (last) shows what your guest will see.
A9: THE BASICS
A10: Quiet hours:
A11: Maximum guests:
A13: POLICIES
A14: Smoking:
A15: Pets:
A16: Events/parties:
A17: Shoes inside:
A19: CUSTOM RULES
A20: Your rules (one per line):
A23: =HYPERLINK("#'WiFi + Tech'!A5", "← Back: WiFi + Tech") | G23: =HYPERLINK("#'Local Guide'!A5", "Next: Local Guide →")

Sheet Local Guide
A2: =HYPERLINK("#'House Rules'!A5", "← BACK") | D2: SECTION 5 OF 8 | J2: =HYPERLINK("#'Trash'!A5", "NEXT →")
A4: Local Guide
A5: What we'd tell a friend visiting.
A7: Fill the rows you want to share. Skip any you don't.
A9: Category | B9: Name | C9: Distance | D9: Phone | E9: Why we love it
A10: Coffee
A11: Coffee
A12: Restaurant
A13: Restaurant
A14: Restaurant
A15: Grocery
A16: Grocery
A17: Takeout
A18: Takeout
A19: Pharmacy
A20: Gas station
A21: Hospital/Urgent care
... A29: Emergency (non-911)
A31: =HYPERLINK("#'House Rules'!A5", "← Back: House Rules") | G31: =HYPERLINK("#'Trash'!A5", "Next: Trash →")

Sheet Trash
A2: =HYPERLINK("#'Local Guide'!A5", "← BACK") | D2: SECTION 6 OF 8 | J2: =HYPERLINK("#'Departure'!A5", "NEXT →")
A4: Trash, Recycling & Maintenance
A5: The stuff nobody likes to ask about.
A7: Fill the highlighted fields below. The 'Review & Print' tab (last) shows what your guest will see.
A9: PICKUP & BINS
A10: Trash pickup day:
A11: Bin location:
A12: Recycling accepted:
A13: What goes in which bin:
A15: OPERATIONAL
A16: Where to put bins on pickup morning:
A17: HVAC/thermostat range to leave:
A18: If the power goes out:
A21: =HYPERLINK("#'Local Guide'!A5", "← Back: Local Guide") | G21: =HYPERLINK("#'Departure'!A5", "Next: Departure →")

Sheet Departure
A2: =HYPERLINK("#'Trash'!A5", "← BACK") | D2: SECTION 7 OF 8 | J2: =HYPERLINK("#'Emergency'!A5", "NEXT →")
A4: Checkout
A5: What to do before you drive away.
A7: Fill the highlighted fields below. The 'Review & Print' tab (last) shows what your guest will see.
A9: WHEN
A10: Checkout time:
A11: Checkout day: | D11: =IF(Property!B8<>"", TEXT(Property!B8,"dddd, mmmm d"), "See Property tab")
A13: BEFORE YOU LEAVE CHECKLIST
A14: ☐ Strip bed linens and leave in:
A15: ☐ Take trash + recycling to:
A16: ☐ Turn thermostat to:
A17: ☐ Leave key:
A18: ☐ Run the dishwasher
A19: ☐ Lock all doors + windows
A21: CUSTOM CHECKOUT TASKS
A22: Your tasks (one per line):
A25: =HYPERLINK("#'Trash'!A5", "← Back: Trash") | G25: =HYPERLINK("#'Emergency'!A5", "Next: Emergency →")

Sheet Emergency
A2: =HYPERLINK("#'Departure'!A5", "← BACK") | D2: SECTION 8 OF 8 | J2: =HYPERLINK("#'Review & Print'!A1", "REVIEW →")
A4: Emergency Contacts
A5: Keep this one nearby.
A7: IN AN EMERGENCY — CALL 911
A9: 911 first. Then the contacts below.
A11: HOSPITAL
A12: Nearest hospital:
A13: Hospital phone:
A14: Hospital address:
A16: URGENT CARE & POLICE
A17: Urgent care:
A18: Urgent care phone:
A19: Non-emergency police:
A21: OTHER
A22: Poison control: | D22: 1-800-222-1222
A23: 24-hr vet (if pets):
A24: Utility outage reporting:
A25: Host phone (call/text): | D25: =Property!B7
A28: =HYPERLINK("#'Departure'!A5", "← Back: Departure") | G28: =HYPERLINK("#'Review & Print'!A1", "Review & Print →")

Sheet Review & Print
A2: =HYPERLINK("#'Emergency'!A5", "← BACK") | D2: REVIEW & PRINT
A4: Your welcome book is ready
A5: Preview below. Hit Print when happy.
A9: COMPLETION | E9: RED FLAGS | I9: STATUS
A10: =TEXT((COUNTA('Property'!B5:B12) + COUNTA('Arrival'!B5:B11) + COUNTA('WiFi + Tech'!B5:B12) + COUNTA('House Rules'!B5:B11) + COUNTA('Local Guide'!B10:E29) + COUNTA('Trash'!B5:B11) + COUNTA('Departure'!B5:B10) + COUNTA('Emergency'!B5:B13))/132, "0%") | E10: =IF('Property'!B5="",1,0) + IF('Property'!B6="",1,0) + IF('Property'!B7="",1,0) + IF('WiFi + Tech'!B5="",1,0) + IF('WiFi + Tech'!B6="",1,0) + IF('Trash'!B5="",1,0) + IF('Departure'!B5="",1,0) + IF('Emergency'!B7="",1,0) + IF('Emergency'!B8="",1,0) + IF('Emergency'!B10="",1,0) | I10: =IF((IF('Property'!B5="",1,0) + IF('Property'!B6="",1,0) + IF('Property'!B7="",1,0) + IF('WiFi + Tech'!B5="",1,0) + IF('WiFi + Tech'!B6="",1,0) + IF('Trash'!B5="",1,0) + IF('Departure'!B5="",1,0) + IF('Emergency'!B7="",1,0) + IF('Emergency'!B8="",1,0) + IF('Emergency'!B10="",1,0))=0,"READY",IF((IF('Property'!B5="",1,0) + IF('Property'!B6="",1,0) + IF('Property'!B7="",1,0) + IF('WiFi + Tech'!B5="",1,0) + IF('WiFi + Tech'!B6="",1,0) + IF('Trash'!B5="",1,0) + IF('Departure'!B5="",1,0) + IF('Emergency'!B7="",1,0) + IF('Emergency'!B8="",1,0) + IF('Emergency'!B10="",1,0))<=2,"MINOR","NEEDS WORK"))
A12: of 132 fields filled | E12: required fields empty | I12: 0 = green · 1-2 = yellow · 3+ = red
A16: =HYPERLINK("#'Review & Print'!A24", "📄 GENERATE YOUR PDF Press Ctrl+P → choose 'Save as PDF'")
A22: Print area is pre-set to letter portrait. × Host Notes tab excluded.
A24: =CONCATENATE("Welcome to ", Property!B5)
A27: Host: | E27: =IF(Property!B6="","(not set)",Property!B6)
A28: Host phone: | E28: =IF(Property!B7="","(not set)",Property!B7)
A29: Check-in: | E29: =IF(Property!B8="","(not set)",Property!B8)
A30: Check-out: | E30: =IF(Property!B9="","(not set)",Property!B9)
A32: Address: | E32: =IF(Arrival!B5="","(not set)",Arrival!B5)
A33: Entry method: | E33: =IF(Arrival!B6="","(not set)",Arrival!B6)
A34: Door/lock code: | E34: =IF(Arrival!B7="","(not set)",Arrival!B7)
A35: Parking: | E35: =IF(Arrival!B8="","(not set)",Arrival!B8)
E37: =IF(""="","(not set)","")
A38: WiFi
A39: Network: | E39: =IF('WiFi + Tech'!B5="","(not set)",'WiFi + Tech'!B5)
A40: Password: | E40: =IF('WiFi + Tech'!B6="","(not set)",'WiFi + Tech'!B6)
A48: House Rules
A49: Quiet hours: | E49: =IF('House Rules'!B5="","(not set)",'House Rules'!B5)
A50: Max guests: | E50: =IF('House Rules'!B6="","(not set)",'House Rules'!B6)
A51: Smoking: | E51: =IF('House Rules'!B7="","(not set)",'House Rules'!B7)
A52: Pets: | E52: =IF('House Rules'!B8="","(not set)",'House Rules'!B8)
A53: Events: | E53: =IF('House Rules'!B9="","(not set)",'House Rules'!B9)
A54: Shoes: | E54: =IF('House Rules'!B10="","(not set)",'House Rules'!B10)
A56: Local Guide — Our Top 10
A57: ='Local Guide'!A10 | C57: =IF('Local Guide'!B10="","",'Local Guide'!B10) | G57: =IF('Local Guide'!C10="","",'Local Guide'!C10) | I57: =IF('Local Guide'!E10="","",'Local Guide'!E10)
A58: ='Local Guide'!A11 | C58: =IF('Local Guide'!B11="","",'Local Guide'!B11) | G58: =IF('Local Guide'!C11="","",'Local Guide'!C11) | I58: =IF('Local Guide'!E11="","",'Local Guide'!E11)
A59: ='Local Guide'!A12 | C59: =IF('Local Guide'!B12="","",'Local Guide'!B12) | G59: =IF('Local Guide'!C12="","",'Local Guide'!C12) | I59: =IF('Local Guide'!E12="","",'Local Guide'!E12)
A60: ='Local Guide'!A13 | C60: =IF('Local Guide'!B13="","",'Local Guide'!B13) | G60: =IF('Local Guide'!C13="","",'Local Guide'!C13) | I60: =IF('Local Guide'!E13="","",'Local Guide'!E13)
A61: ='Local Guide'!A14 | C61: =IF('Local Guide'!B14="","",'Local Guide'!B14) | G61: =IF('Local Guide'!C14="","",'Local Guide'!C14) | I61: =IF('Local Guide'!E14="","",'Local Guide'!E14)
A62: ='Local Guide'!A15 | C62: =IF('Local Guide'!B15="","",'Local Guide'!B15) | G62: =IF('Local Guide'!C15="","",'Local Guide'!C15) | I62: =IF('Local Guide'!E15="","",'Local Guide'!E15)
A63: ='Local Guide'!A16 | C63: =IF('Local Guide'!B16="","",'Local Guide'!B16) | G63: =IF('Local Guide'!C16="","",'Local Guide'!C16) | I63: =IF('Local Guide'!E16="","",'Local Guide'!E16)
A64: ='Local Guide'!A17 | C64: =IF('Local Guide'!B17="","",'Local Guide'!B17) | G64: =IF('Local Guide'!C17="","",'Local Guide'!C17) | I64: =IF('Local Guide'!E17="","",'Local Guide'!E17)
A65: ='Local Guide'!A18 | C65: =IF('Local Guide'!B18="","",'Local Guide'!B18) | G65: =IF('Local Guide'!C18="","",'Local Guide'!C18) | I65: =IF('Local Guide'!E18="","",'Local Guide'!E18)
A66: ='Local Guide'!A19 | C66: =IF('Local Guide'!B19="","",'Local Guide'!B19) | G66: =IF('Local Guide'!C19="","",'Local Guide'!C19) | I66: =IF('Local Guide'!E19="","",'Local Guide'!E19)
A68: Trash & Maintenance
...

Sheet Bonus
A2: =HYPERLINK("#'Review & Print'!A1", "← BACK") | D2: BONUS
A4: Bonus — Airbnb Listing Copy
A5: Copy these blocks into your Airbnb listing — hosts using them see 40% better guest comprehension.
A7: Select each block below, Ctrl+C, then paste into the matching field on your Airbnb listing.
A9: BLOCK 1 — HOUSE RULES (PASTE INTO AIRBNB ‘HOUSE RULES’ FIELD)
A10: We’re glad to have you. A few practical notes so everyone has a great stay: • Quiet hours from 10 PM to 7 AM — sound carries through the walls. • No smoking anywhere on the property. Smoking OK on the patio. • Max 6 guests — if that changes, let us know. • Please keep shoes at the door. Dust out, mountain in. • If something breaks, tell us — we’d rather fix it than discover it later. • Check-in after 3 PM. Checkout by 11 AM. Same-day turnovers are tight — thanks for leaving on time.
A12: BLOCK 2 — CHECK-IN INSTRUCTIONS (PASTE INTO ‘CHECK-IN’ FIELD)
A13: Day-of check-in: 1. The door uses a smart lock. Your code is 4321 (reset after checkout). 2. Pull into the gravel drive on the right — there’s parking for 2 cars. Don’t block the mailbox. 3. WiFi is SmokiesRidge_Guest / welcome2024. Password is also on the counter. 4. If you arrive before 3 PM, the Local Guide tab has a great coffee shop 0.8 mi away. Host is Daniel — text me at (555) 555-0199 anytime. Seriously, we’d rather hear from you than the morning-after emergency.
A15: BLOCK 3 — CHECKOUT REMINDER (SEND AIRBNB MESSAGE DAY N-1)
A16: Hope your stay’s been great. Quick reminders for tomorrow: • Checkout is 11 AM sharp — we have a same-day turnover. • Leave linens in the hallway laundry basket. • Run the dishwasher. • Take trash + recycling to the curb (Thursday) or dumpster on-site. • Thermostat to 72°F before you lock up. • Return the door code to 0000. Text me when you’re on the road — I’ll release your deposit faster.
A18: =HYPERLINK("#'Review & Print'!A1", "← Back: Review & Print") | G18: =HYPERLINK("#'× Host Notes'!A1", "Host Notes (private) →")

Sheet × Host Notes
