Workbook

Sheet Start
A2: The STR Ledger
A4: House Rules Builder
A5: Specific, defensible rules — not 4 generic bullets.
A7: GST-002 · v2.0
A11: What you'll build in the next 12 minutes
A13: LISTING-READY | E13: PRINTABLE PDF | I13: DEFENSIBLE
A14: Paste straight into Airbnb / VRBO 'House rules' field. | E14: One-page rules sheet for the property binder. | I14: 25-40 specific rules — not 4 generic bullets.
A23: Quick Start — be done in 10 minutes
B24: ① Property name + capacity | H24: ④ Pet policy
B25: ② Quiet hours window | H25: ⑤ Check-out time + fees
B26: ③ Smoking policy
A30: =HYPERLINK("#'§1 Property + Capacity'!A5", "GET STARTED — FILL §1 PROPERTY + CAPACITY →")
A36: Progress: | G36: =TEXT((COUNTA('§1 Property + Capacity'!B8:B13) + COUNTA('§2 Quiet Hours + Parties'!B8:B13) + COUNTA('§3 Smoking + Substances'!B8:B12) + COUNTA('§4 Pets'!B8:B12) + COUNTA('§5 Damage + Liability'!B8:B13) + COUNTA('§6 Check-out + Penalties'!B8:B13))/34, "0%") & " complete"
A38: ① Property + Capacity | G38: =IF(COUNTA('§1 Property + Capacity'!B8:B13)=6,"✅ Done",IF(COUNTA('§1 Property + Capacity'!B8:B13)=0,"⏳ Empty","⏳ "&COUNTA('§1 Property + Capacity'!B8:B13)&" of 6")) | K38: =HYPERLINK("#'§1 Property + Capacity'!A5","→ go")
A39: ② Quiet Hours + Parties | G39: =IF(COUNTA('§2 Quiet Hours + Parties'!B8:B13)=6,"✅ Done",IF(COUNTA('§2 Quiet Hours + Parties'!B8:B13)=0,"⏳ Empty","⏳ "&COUNTA('§2 Quiet Hours + Parties'!B8:B13)&" of 6")) | K39: =HYPERLINK("#'§2 Quiet Hours + Parties'!A5","→ go")
A40: ③ Smoking + Substances | G40: =IF(COUNTA('§3 Smoking + Substances'!B8:B12)=5,"✅ Done",IF(COUNTA('§3 Smoking + Substances'!B8:B12)=0,"⏳ Empty","⏳ "&COUNTA('§3 Smoking + Substances'!B8:B12)&" of 5")) | K40: =HYPERLINK("#'§3 Smoking + Substances'!A5","→ go")
A41: ④ Pets | G41: =IF(COUNTA('§4 Pets'!B8:B12)=5,"✅ Done",IF(COUNTA('§4 Pets'!B8:B12)=0,"⏳ Empty","⏳ "&COUNTA('§4 Pets'!B8:B12)&" of 5")) | K41: =HYPERLINK("#'§4 Pets'!A5","→ go")
A42: ⑤ Damage + Liability | G42: =IF(COUNTA('§5 Damage + Liability'!B8:B13)=6,"✅ Done",IF(COUNTA('§5 Damage + Liability'!B8:B13)=0,"⏳ Empty","⏳ "&COUNTA('§5 Damage + Liability'!B8:B13)&" of 6")) | K42: =HYPERLINK("#'§5 Damage + Liability'!A5","→ go")
A43: ⑥ Check-out + Penalties | G43: =IF(COUNTA('§6 Check-out + Penalties'!B8:B13)=6,"✅ Done",IF(COUNTA('§6 Check-out + Penalties'!B8:B13)=0,"⏳ Empty","⏳ "&COUNTA('§6 Check-out + Penalties'!B8:B13)&" of 6")) | K43: =HYPERLINK("#'§6 Check-out + Penalties'!A5","→ go")
A47: Questions? hello@thestrledger.com
A48: Free updates forever · v2.0 · Released 2026-05

Sheet §1 Property + Capacity
A2: =HYPERLINK("#'Start'!A1", "← START") | D2: SECTION 1 OF 6 | J2: =HYPERLINK("#'§2 Quiet Hours + Parties'!A5", "NEXT →")
A4: §1 Property + Capacity
A5: The basics that frame every other rule.
A6: Fill the highlighted fields below. The 'Launch' tab (last) builds your print-ready rules document.
A7: §1 PROPERTY + CAPACITY
A8: Property name: | B8: Smokies Ridge Cabin
A9: Full address: | B9: 123 Mountain Lane, Gatlinburg, TN 37738
A10: Max overnight guests: | B10: 10
A11: Bedrooms / bathrooms: | B11: 4 BR / 3 BA
A12: Sleeping arrangements: | B12: 1 King, 2 Queens, 2 Twin bunk-beds, 1 Queen sleeper-sofa
A13: Parking instructions: | B13: Gravel drive — fits 3 cars. No street parking after 8 PM.
A15: =HYPERLINK("#'Start'!A1", "← Back: Start") | G15: =HYPERLINK("#'§2 Quiet Hours + Parties'!A5", "Next: §2 Quiet Hours + Parties →")

Sheet §2 Quiet Hours + Parties
A2: =HYPERLINK("#'§1 Property + Capacity'!A5", "← BACK") | D2: SECTION 2 OF 6 | J2: =HYPERLINK("#'§3 Smoking + Substances'!A5", "NEXT →")
A4: §2 Quiet Hours + Parties
A5: Set the noise floor — neighbors are listening.
A6: Fill the highlighted fields below. The 'Launch' tab (last) builds your print-ready rules document.
A7: §2 QUIET HOURS + PARTIES
A8: Quiet hours start (e.g., 10:00 PM): | B8: 10:00 PM
A9: Quiet hours end (e.g., 8:00 AM): | B9: 8:00 AM
A10: Parties / events policy: | B10: No parties or events of any kind
A11: Day visitors / gatherings: | B11: Day visitors OK until 9 PM (max 4 above booked guest count)
A12: Guests of guests rule: | B12: Must be approved in advance via message
A13: Outdoor music after dark: | B13: No outdoor amplified music after sunset
A15: =HYPERLINK("#'§1 Property + Capacity'!A5", "← Back: §1 Property + Capacity") | G15: =HYPERLINK("#'§3 Smoking + Substances'!A5", "Next: §3 Smoking + Substances →")

Sheet §3 Smoking + Substances
A2: =HYPERLINK("#'§2 Quiet Hours + Parties'!A5", "← BACK") | D2: SECTION 3 OF 6 | J2: =HYPERLINK("#'§4 Pets'!A5", "NEXT →")
A4: §3 Smoking + Substances
A5: Smoke smell is the #1 cause of $250+ cleaning claims.
A6: Fill the highlighted fields below. The 'Launch' tab (last) builds your print-ready rules document.
A7: §3 SMOKING + SUBSTANCES
A8: Smoking — inside the home: | B8: No smoking, vaping, or cannabis use anywhere inside
A9: Smoking — outside / designated area: | B9: Smoking permitted only on the gravel turnaround — butts in metal can
A10: Vaping policy: | B10: Outdoor only — same rules as smoking
A11: Cannabis / weed policy: | B11: Outdoor only where state-legal; never inside
A12: Alcohol notes: | B12: Adults only; please drink responsibly. No kegs.
A14: =HYPERLINK("#'§2 Quiet Hours + Parties'!A5", "← Back: §2 Quiet Hours + Parties") | G14: =HYPERLINK("#'§4 Pets'!A5", "Next: §4 Pets →")

Sheet §4 Pets
A2: =HYPERLINK("#'§3 Smoking + Substances'!A5", "← BACK") | D2: SECTION 4 OF 6 | J2: =HYPERLINK("#'§5 Damage + Liability'!A5", "NEXT →")
A4: §4 Pets
A5: Specific pet rules avoid surprise damage and disputes.
A6: Fill the highlighted fields below. The 'Launch' tab (last) builds your print-ready rules document.
A7: §4 PETS
A8: Pets allowed? | B8: Yes — dogs only
A9: Number of pets allowed: | B9: Max 2 dogs
A10: Weight limit per pet: | B10: Each dog under 50 lb
A11: Pet fee: | B11: $50 per pet per stay (non-refundable)
A12: Pet ground rules: | B12: Crate when unattended; no pets on furniture; clean up yard waste daily
A13: Service animals are exempt from pet fees and pet bans by law (ADA/FHA).
A15: =HYPERLINK("#'§3 Smoking + Substances'!A5", "← Back: §3 Smoking + Substances") | G15: =HYPERLINK("#'§5 Damage + Liability'!A5", "Next: §5 Damage + Liability →")

Sheet §5 Damage + Liability
A2: =HYPERLINK("#'§4 Pets'!A5", "← BACK") | D2: SECTION 5 OF 6 | J2: =HYPERLINK("#'§6 Check-out + Penalties'!A5", "NEXT →")
A4: §5 Damage + Liability
A5: The rules that hold up in an AirCover or VRBO claim.
A6: Fill the highlighted fields below. The 'Launch' tab (last) builds your print-ready rules document.
A7: §5 DAMAGE + LIABILITY
A8: Moving furniture: | B8: Please do not move beds or living-room furniture
A9: Pool / hot tub rules: | B9: Hot tub closes at 10 PM; no glass; shower before entering; max 6 adults
A10: Fireplace rules: | B10: Wood-burning fireplace is OFF for guest stays — do not light
A11: Kids / minors policy: | B11: Children must be supervised in loft and on the deck at all times
A12: Maximum occupancy (overnight): | B12: Maximum 10 guests overnight (matches Airbnb listing)
A13: Damage / claim policy: | B13: Damage above $250 will be reported to Airbnb resolution / VRBO claim
A15: =HYPERLINK("#'§4 Pets'!A5", "← Back: §4 Pets") | G15: =HYPERLINK("#'§6 Check-out + Penalties'!A5", "Next: §6 Check-out + Penalties →")

Sheet §6 Check-out + Penalties
A2: =HYPERLINK("#'§5 Damage + Liability'!A5", "← BACK") | D2: SECTION 6 OF 6 | J2: =HYPERLINK("#'Launch'!A1", "LAUNCH →")
A4: §6 Check-out + Penalties
A5: What happens if guests don't follow the rules.
A6: Fill the highlighted fields below. The 'Launch' tab (last) builds your print-ready rules document.
A7: §6 CHECK-OUT + PENALTIES
A8: Check-out time: | B8: 10:00 AM
A9: Late check-out fee: | B9: $50 per hour past 10 AM (must request in advance)
A10: Missing-item fee: | B10: $25 + replacement cost per missing item
A11: Smoking violation fine: | B11: $250 deep-clean fee if smoking detected indoors
A12: Key / lock return: | B12: Smart-lock — no key return needed; do not change the code
A13: Damage deposit policy: | B13: Damage deposit refunded within 7 days of check-out, post-inspection
A15: =HYPERLINK("#'§5 Damage + Liability'!A5", "← Back: §5 Damage + Liability") | G15: =HYPERLINK("#'Launch'!A1", "Next: Launch →")

Sheet Launch
A2: =HYPERLINK("#'§6 Check-out + Penalties'!A5", "← BACK: §6 Check-out + Penalties") | D2: LAUNCH
A4: Your house rules are ready
A5: Build the print-ready doc, then paste into your listing.
A9: COMPLETION | E9: RED FLAGS | I9: STATUS
A10: =TEXT((COUNTA('§1 Property + Capacity'!B8:B13) + COUNTA('§2 Quiet Hours + Parties'!B8:B13) + COUNTA('§3 Smoking + Substances'!B8:B12) + COUNTA('§4 Pets'!B8:B12) + COUNTA('§5 Damage + Liability'!B8:B13) + COUNTA('§6 Check-out + Penalties'!B8:B13))/34, "0%") | E10: =IF('§1 Property + Capacity'!B8="",1,0) + IF('§1 Property + Capacity'!B10="",1,0) + IF('§2 Quiet Hours + Parties'!B8="",1,0) + IF('§2 Quiet Hours + Parties'!B9="",1,0) + IF('§2 Quiet Hours + Parties'!B10="",1,0) + IF('§3 Smoking + Substances'!B8="",1,0) + IF('§4 Pets'!B8="",1,0) + IF('§6 Check-out + Penalties'!B8="",1,0) | I10: =IF((IF('§1 Property + Capacity'!B8="",1,0) + IF('§1 Property + Capacity'!B10="",1,0) + IF('§2 Quiet Hours + Parties'!B8="",1,0) + IF('§2 Quiet Hours + Parties'!B9="",1,0) + IF('§2 Quiet Hours + Parties'!B10="",1,0) + IF('§3 Smoking + Substances'!B8="",1,0) + IF('§4 Pets'!B8="",1,0) + IF('§6 Check-out + Penalties'!B8="",1,0))=0,"READY",IF((IF('§1 Property + Capacity'!B8="",1,0) + IF('§1 Property + Capacity'!B10="",1,0) + IF('§2 Quiet Hours + Parties'!B8="",1,0) + IF('§2 Quiet Hours + Parties'!B9="",1,0) + IF('§2 Quiet Hours + Parties'!B10="",1,0) + IF('§3 Smoking + Substances'!B8="",1,0) + IF('§4 Pets'!B8="",1,0) + IF('§6 Check-out + Penalties'!B8="",1,0))<=2,"MINOR","NEEDS WORK"))
A12: of 34 fields filled | E12: required fields empty | I12: 0 = green · 1-2 = yellow · 3+ = red
A16: =HYPERLINK("#'Rules Output'!A1", "📄 BUILD RULES DOC →")
A22: Opens the Rules Output tab — select all, copy, paste into Airbnb / VRBO 'House rules' field. Or Ctrl+P for the printable PDF.

Sheet Rules Output
A2: =HYPERLINK("#'Launch'!A1", "←") | B2: RULES OUTPUT — copy, print, or paste into your listing
A4: =IF('§1 Property + Capacity'!B8="","House Rules",'§1 Property + Capacity'!B8 & " — House Rules")
A5: =IF('§1 Property + Capacity'!B9="","","Address: " & '§1 Property + Capacity'!B9)
B7: Property + Capacity
A8: =IF(IF('§1 Property + Capacity'!B10="","","Maximum overnight guests: " & '§1 Property + Capacity'!B10)="","","•") | B8: =IF('§1 Property + Capacity'!B10="","","Maximum overnight guests: " & '§1 Property + Capacity'!B10)
A9: =IF(IF('§1 Property + Capacity'!B11="","","Bedrooms / bathrooms: " & '§1 Property + Capacity'!B11)="","","•") | B9: =IF('§1 Property + Capacity'!B11="","","Bedrooms / bathrooms: " & '§1 Property + Capacity'!B11)
A10: =IF(IF('§1 Property + Capacity'!B12="","","Sleeping arrangements: " & '§1 Property + Capacity'!B12)="","","•") | B10: =IF('§1 Property + Capacity'!B12="","","Sleeping arrangements: " & '§1 Property + Capacity'!B12)
A11: =IF(IF('§1 Property + Capacity'!B13="","","Parking: " & '§1 Property + Capacity'!B13)="","","•") | B11: =IF('§1 Property + Capacity'!B13="","","Parking: " & '§1 Property + Capacity'!B13)
B13: Quiet Hours + Parties
A14: =IF(IF(OR('§2 Quiet Hours + Parties'!B8="",'§2 Quiet Hours + Parties'!B9=""),"","Quiet hours: " & '§2 Quiet Hours + Parties'!B8 & " to " & '§2 Quiet Hours + Parties'!B9 & " — sound carries through walls.")="","","•") | B14: =IF(OR('§2 Quiet Hours + Parties'!B8="",'§2 Quiet Hours + Parties'!B9=""),"","Quiet hours: " & '§2 Quiet Hours + Parties'!B8 & " to " & '§2 Quiet Hours + Parties'!B9 & " — sound carries through walls.")
A15: =IF(IF('§2 Quiet Hours + Parties'!B10="","","Parties / events: " & '§2 Quiet Hours + Parties'!B10)="","","•") | B15: =IF('§2 Quiet Hours + Parties'!B10="","","Parties / events: " & '§2 Quiet Hours + Parties'!B10)
A16: =IF(IF('§2 Quiet Hours + Parties'!B11="","","Day visitors / gatherings: " & '§2 Quiet Hours + Parties'!B11)="","","•") | B16: =IF('§2 Quiet Hours + Parties'!B11="","","Day visitors / gatherings: " & '§2 Quiet Hours + Parties'!B11)
A17: =IF(IF('§2 Quiet Hours + Parties'!B12="","","Guests of guests: " & '§2 Quiet Hours + Parties'!B12)="","","•") | B17: =IF('§2 Quiet Hours + Parties'!B12="","","Guests of guests: " & '§2 Quiet Hours + Parties'!B12)
A18: =IF(IF('§2 Quiet Hours + Parties'!B13="","","Outdoor music: " & '§2 Quiet Hours + Parties'!B13)="","","•") | B18: =IF('§2 Quiet Hours + Parties'!B13="","","Outdoor music: " & '§2 Quiet Hours + Parties'!B13)
B20: Smoking + Substances
A21: =IF(IF('§3 Smoking + Substances'!B8="","","Smoking — inside: " & '§3 Smoking + Substances'!B8)="","","•") | B21: =IF('§3 Smoking + Substances'!B8="","","Smoking — inside: " & '§3 Smoking + Substances'!B8)
A22: =IF(IF('§3 Smoking + Substances'!B9="","","Smoking — outside: " & '§3 Smoking + Substances'!B9)="","","•") | B22: =IF('§3 Smoking + Substances'!B9="","","Smoking — outside: " & '§3 Smoking + Substances'!B9)
A23: =IF(IF('§3 Smoking + Substances'!B10="","","Vaping: " & '§3 Smoking + Substances'!B10)="","","•") | B23: =IF('§3 Smoking + Substances'!B10="","","Vaping: " & '§3 Smoking + Substances'!B10)
A24: =IF(IF('§3 Smoking + Substances'!B11="","","Cannabis: " & '§3 Smoking + Substances'!B11)="","","•") | B24: =IF('§3 Smoking + Substances'!B11="","","Cannabis: " & '§3 Smoking + Substances'!B11)
A25: =IF(IF('§3 Smoking + Substances'!B12="","","Alcohol: " & '§3 Smoking + Substances'!B12)="","","•") | B25: =IF('§3 Smoking + Substances'!B12="","","Alcohol: " & '§3 Smoking + Substances'!B12)
B27: Pets
A28: =IF(IF('§4 Pets'!B8="","","Pet policy: " & '§4 Pets'!B8)="","","•") | B28: =IF('§4 Pets'!B8="","","Pet policy: " & '§4 Pets'!B8)
A29: =IF(IF('§4 Pets'!B9="","","Number allowed: " & '§4 Pets'!B9)="","","•") | B29: =IF('§4 Pets'!B9="","","Number allowed: " & '§4 Pets'!B9)
A30: =IF(IF('§4 Pets'!B10="","","Weight limit: " & '§4 Pets'!B10)="","","•") | B30: =IF('§4 Pets'!B10="","","Weight limit: " & '§4 Pets'!B10)
A31: =IF(IF('§4 Pets'!B11="","","Pet fee: " & '§4 Pets'!B11)="","","•") | B31: =IF('§4 Pets'!B11="","","Pet fee: " & '§4 Pets'!B11)
A32: =IF(IF('§4 Pets'!B12="","","Ground rules: " & '§4 Pets'!B12)="","","•") | B32: =IF('§4 Pets'!B12="","","Ground rules: " & '§4 Pets'!B12)
B33: Service animals are exempt from pet fees and pet bans by law (ADA/FHA).
B35: Damage + Liability
A36: =IF(IF('§5 Damage + Liability'!B8="","","Furniture: " & '§5 Damage + Liability'!B8)="","","•") | B36: =IF('§5 Damage + Liability'!B8="","","Furniture: " & '§5 Damage + Liability'!B8)
A37: =IF(IF('§5 Damage + Liability'!B9="","","Pool / hot tub: " & '§5 Damage + Liability'!B9)="","","•") | B37: =IF('§5 Damage + Liability'!B9="","","Pool / hot tub: " & '§5 Damage + Liability'!B9)
A38: =IF(IF('§5 Damage + Liability'!B10="","","Fireplace: " & '§5 Damage + Liability'!B10)="","","•") | B38: =IF('§5 Damage + Liability'!B10="","","Fireplace: " & '§5 Damage + Liability'!B10)
A39: =IF(IF('§5 Damage + Liability'!B11="","","Children: " & '§5 Damage + Liability'!B11)="","","•") | B39: =IF('§5 Damage + Liability'!B11="","","Children: " & '§5 Damage + Liability'!B11)
A40: =IF(IF('§5 Damage + Liability'!B12="","","Maximum occupancy: " & '§5 Damage + Liability'!B12)="","","•") | B40: =IF('§5 Damage + Liability'!B12="","","Maximum occupancy: " & '§5 Damage + Liability'!B12)
A41: =IF(IF('§5 Damage + Liability'!B13="","","Damage policy: " & '§5 Damage + Liability'!B13)="","","•") | B41: =IF('§5 Damage + Liability'!B13="","","Damage policy: " & '§5 Damage + Liability'!B13)
B43: Check-out + Penalties
A44: =IF(IF('§6 Check-out + Penalties'!B8="","","Check-out time: " & '§6 Check-out + Penalties'!B8)="","","•") | B44: =IF('§6 Check-out + Penalties'!B8="","","Check-out time: " & '§6 Check-out + Penalties'!B8)
A45: =IF(IF('§6 Check-out + Penalties'!B9="","","Late check-out fee: " & '§6 Check-out + Penalties'!B9)="","","•") | B45: =IF('§6 Check-out + Penalties'!B9="","","Late check-out fee: " & '§6 Check-out + Penalties'!B9)
A46: =IF(IF('§6 Check-out + Penalties'!B10="","","Missing items: " & '§6 Check-out + Penalties'!B10)="","","•") | B46: =IF('§6 Check-out + Penalties'!B10="","","Missing items: " & '§6 Check-out + Penalties'!B10)
A47: =IF(IF('§6 Check-out + Penalties'!B11="","","Smoking violation: " & '§6 Check-out + Penalties'!B11)="","","•") | B47: =IF('§6 Check-out + Penalties'!B11="","","Smoking violation: " & '§6 Check-out + Penalties'!B11)
A48: =IF(IF('§6 Check-out + Penalties'!B12="","","Keys / lock: " & '§6 Check-out + Penalties'!B12)="","","•") | B48: =IF('§6 Check-out + Penalties'!B12="","","Keys / lock: " & '§6 Check-out + Penalties'!B12)
...
