Workbook

Sheet Start
A2: The STR Ledger
A4: Insurance Claim Log
A5: Storm, fire, theft, water — every claim filed against your STR policy.
A7: LGL-004 · v1.0 · BLANK
A10: OPEN CLAIMS | E10: $ AT RISK | I10: RECOVERY YTD
A11: =COUNTIFS('Claims Log'!P6:P55,"<>Settled",'Claims Log'!P6:P55,"<>Closed",'Claims Log'!P6:P55,"<>Denied",'Claims Log'!P6:P55,"<>",'Claims Log'!A6:A55,"<>") | E11: =SUMIFS('Claims Log'!J6:J55,'Claims Log'!P6:P55,"<>Settled",'Claims Log'!P6:P55,"<>Closed",'Claims Log'!P6:P55,"<>Denied",'Claims Log'!A6:A55,"<>") | I11: =SUMPRODUCT((YEAR('Claims Log'!B6:B55)=Settings!$B$5)*'Claims Log'!K6:K55)
A14: claims still in flight | E14: submitted, not yet recovered | I14: recovered this year
A17: WHAT THIS DOES
A18: Tracks claims filed against your underlying STR insurance carrier (HO-3, DP-3, Proper, Foremost, etc.) — separate from platform claims like Airbnb AirCover. Records every claim from FNOL through settlement, captures recovery $ vs deductible, and surfaces lessons-learned so each claim makes the next one easier.
A23: =HYPERLINK("#'Claims Log'!A6", "→ NEW CLAIM") | G23: =HYPERLINK("#'Active Claim'!A1", "Active Claim Detail")
A28: =HYPERLINK("#'Annual Summary'!A1", "Annual Summary") | G28: =HYPERLINK("#'Settings'!A1", "Settings")
A32: 💡 Need full operations coverage? Add the Operator Bundle at thestrledger.com/operator — turnover + maintenance + claims + insurance.
A35: Questions? hello@thestrledger.com
A36: LGL-004 · v1.0 · BLANK · Free updates forever

Sheet Claims Log
A2: =HYPERLINK("#'Start'!A1", "← BACK") | D2: CLAIMS LOG | J2: =HYPERLINK("#'Active Claim'!A1", "NEXT →")
A4: Master register — every claim filed against the underlying carrier. Net to host (col L) = Recovered − Deductible. Days to close (col O) auto-calculates once you set Date closed.
A5: Claim # | B5: Date of loss | C5: Property | D5: Carrier | E5: Policy # | F5: Type | G5: Loss description | H5: $ Est. damages | I5: Deductible | J5: $ Submitted | K5: $ Recovered | L5: Net to host | M5: Date filed | N5: Date closed | O5: Days to close | P5: Status | Q5: Notes
L6: =IF(K6="","",K6-I6) | O6: =IF(AND(M6<>"",N6<>""),N6-M6,"")
L7: =IF(K7="","",K7-I7) | O7: =IF(AND(M7<>"",N7<>""),N7-M7,"")
L8: =IF(K8="","",K8-I8) | O8: =IF(AND(M8<>"",N8<>""),N8-M8,"")
L9: =IF(K9="","",K9-I9) | O9: =IF(AND(M9<>"",N9<>""),N9-M9,"")
L10: =IF(K10="","",K10-I10) | O10: =IF(AND(M10<>"",N10<>""),N10-M10,"")
L11: =IF(K11="","",K11-I11) | O11: =IF(AND(M11<>"",N11<>""),N11-M11,"")
L12: =IF(K12="","",K12-I12) | O12: =IF(AND(M12<>"",N12<>""),N12-M12,"")
L13: =IF(K13="","",K13-I13) | O13: =IF(AND(M13<>"",N13<>""),N13-M13,"")
L14: =IF(K14="","",K14-I14) | O14: =IF(AND(M14<>"",N14<>""),N14-M14,"")
L15: =IF(K15="","",K15-I15) | O15: =IF(AND(M15<>"",N15<>""),N15-M15,"")
L16: =IF(K16="","",K16-I16) | O16: =IF(AND(M16<>"",N16<>""),N16-M16,"")
L17: =IF(K17="","",K17-I17) | O17: =IF(AND(M17<>"",N17<>""),N17-M17,"")
... L55: =IF(K55="","",K55-I55) | O55: =IF(AND(M55<>"",N55<>""),N55-M55,"")

Sheet Active Claim
A2: =HYPERLINK("#'Claims Log'!A1", "← BACK") | D2: ACTIVE CLAIM DETAIL | J2: =HYPERLINK("#'Annual Summary'!A1", "NEXT →")
A4: Per-claim deep dive — fill from top to bottom. When the claim closes, copy the outcome row up to the Claims Log so the dashboard reflects it. Reuse this tab for the next claim (or duplicate it to keep history).
A6: §1 LOSS DETAILS
B7: Claim #:
B8: Date of loss:
B9: Time of loss:
B10: Property:
B11: Carrier:
B12: Policy #:
B13: Type of loss:
B14: Severity (1-5):
B16: Narrative:
A21: §2 DAMAGE INVENTORY
B22: Item description | G22: Replacement cost | I22: Depreciation | K22: ACV
B33: Total ACV: | K33: =SUM(K23:L32)
A35: §3 EVIDENCE CHECKLIST
C36: Photos of damage (pre-mitigation)
C37: Photos of damage (post-mitigation)
C38: Mitigation invoice (water-extraction, board-up, tarp)
C39: Repair / contractor receipts
C40: Contractor estimate(s) for restoration
C41: Original purchase receipts (damaged items)
C42: Police / fire report (if applicable)
C43: Weather report (if storm event)
C44: Witness statements (cleaner, vendor, neighbor)
C45: Loss-of-rent calculation worksheet
A48: §4 COMMUNICATIONS LOG
B49: Date / time | E49: Channel | G49: Direction | H49: Summary
A61: §5 TIMELINE — FNOL → SETTLEMENT
B62: FNOL filed
B63: Adjuster assigned
B64: Adjuster site visit
B65: Carrier estimate received
B66: Approval / scope agreed
B67: ACV check issued
B68: Repairs completed
B69: Final settlement
A71: §6 OUTCOME + LESSONS LEARNED
B72: $ Submitted:
B73: $ Recovered:
...

Sheet Annual Summary
A2: =HYPERLINK("#'Active Claim'!A1", "← BACK") | D2: ANNUAL SUMMARY | J2: =HYPERLINK("#'Settings'!A1", "NEXT →")
A4: Year-end summary — recovery rate, claim frequency, premium-vs-recovery ratio, and breakdowns by category and property. The active year is set in Settings → cell B5.
B6: Active year: | C6: =Settings!$B$5
A8: TOTALS
B9: Claim count: | C9: =SUMPRODUCT((YEAR('Claims Log'!B6:B55)=Settings!$B$5)*('Claims Log'!A6:A55<>""))
B10: Total $ submitted: | C10: =SUMPRODUCT((YEAR('Claims Log'!B6:B55)=Settings!$B$5)*'Claims Log'!J6:J55)
B11: Total $ recovered: | C11: =SUMPRODUCT((YEAR('Claims Log'!B6:B55)=Settings!$B$5)*'Claims Log'!K6:K55)
B12: Recovery rate: | C12: =IFERROR(C11/C10,0)
B13: Avg days to close: | C13: =IFERROR(AVERAGEIFS('Claims Log'!O6:O55,'Claims Log'!B6:B55,">="&DATE(Settings!$B$5,1,1),'Claims Log'!B6:B55,"<="&DATE(Settings!$B$5,12,31),'Claims Log'!N6:N55,"<>"),0)
B14: Annual premium paid: | C14: =Settings!$B$40
B15: Insurance ROI (recovery ÷ premium): | C15: =IFERROR(C11/C14,0)
A17: BY CLAIM TYPE
B18: Type | C18: $ Submitted | D18: $ Recovered
B19: Wind/Storm | C19: =SUMPRODUCT((YEAR('Claims Log'!B6:B55)=Settings!$B$5)*('Claims Log'!F6:F55=B19)*'Claims Log'!J6:J55) | D19: =SUMPRODUCT((YEAR('Claims Log'!B6:B55)=Settings!$B$5)*('Claims Log'!F6:F55=B19)*'Claims Log'!K6:K55)
B20: Fire | C20: =SUMPRODUCT((YEAR('Claims Log'!B6:B55)=Settings!$B$5)*('Claims Log'!F6:F55=B20)*'Claims Log'!J6:J55) | D20: =SUMPRODUCT((YEAR('Claims Log'!B6:B55)=Settings!$B$5)*('Claims Log'!F6:F55=B20)*'Claims Log'!K6:K55)
B21: Water | C21: =SUMPRODUCT((YEAR('Claims Log'!B6:B55)=Settings!$B$5)*('Claims Log'!F6:F55=B21)*'Claims Log'!J6:J55) | D21: =SUMPRODUCT((YEAR('Claims Log'!B6:B55)=Settings!$B$5)*('Claims Log'!F6:F55=B21)*'Claims Log'!K6:K55)
B22: Theft | C22: =SUMPRODUCT((YEAR('Claims Log'!B6:B55)=Settings!$B$5)*('Claims Log'!F6:F55=B22)*'Claims Log'!J6:J55) | D22: =SUMPRODUCT((YEAR('Claims Log'!B6:B55)=Settings!$B$5)*('Claims Log'!F6:F55=B22)*'Claims Log'!K6:K55)
B23: Liability | C23: =SUMPRODUCT((YEAR('Claims Log'!B6:B55)=Settings!$B$5)*('Claims Log'!F6:F55=B23)*'Claims Log'!J6:J55) | D23: =SUMPRODUCT((YEAR('Claims Log'!B6:B55)=Settings!$B$5)*('Claims Log'!F6:F55=B23)*'Claims Log'!K6:K55)
B24: Vandalism | C24: =SUMPRODUCT((YEAR('Claims Log'!B6:B55)=Settings!$B$5)*('Claims Log'!F6:F55=B24)*'Claims Log'!J6:J55) | D24: =SUMPRODUCT((YEAR('Claims Log'!B6:B55)=Settings!$B$5)*('Claims Log'!F6:F55=B24)*'Claims Log'!K6:K55)
B25: Other | C25: =SUMPRODUCT((YEAR('Claims Log'!B6:B55)=Settings!$B$5)*('Claims Log'!F6:F55=B25)*'Claims Log'!J6:J55) | D25: =SUMPRODUCT((YEAR('Claims Log'!B6:B55)=Settings!$B$5)*('Claims Log'!F6:F55=B25)*'Claims Log'!K6:K55)
A27: BY PROPERTY
B28: Property | C28: $ Submitted | D28: $ Recovered
B29: Smokies Ridge Cabin | C29: =SUMPRODUCT((YEAR('Claims Log'!B6:B55)=Settings!$B$5)*('Claims Log'!C6:C55=B29)*'Claims Log'!J6:J55) | D29: =SUMPRODUCT((YEAR('Claims Log'!B6:B55)=Settings!$B$5)*('Claims Log'!C6:C55=B29)*'Claims Log'!K6:K55)
B30: Creek Side | C30: =SUMPRODUCT((YEAR('Claims Log'!B6:B55)=Settings!$B$5)*('Claims Log'!C6:C55=B30)*'Claims Log'!J6:J55) | D30: =SUMPRODUCT((YEAR('Claims Log'!B6:B55)=Settings!$B$5)*('Claims Log'!C6:C55=B30)*'Claims Log'!K6:K55)
B31: Lakehouse A | C31: =SUMPRODUCT((YEAR('Claims Log'!B6:B55)=Settings!$B$5)*('Claims Log'!C6:C55=B31)*'Claims Log'!J6:J55) | D31: =SUMPRODUCT((YEAR('Claims Log'!B6:B55)=Settings!$B$5)*('Claims Log'!C6:C55=B31)*'Claims Log'!K6:K55)
B32: Lakehouse B | C32: =SUMPRODUCT((YEAR('Claims Log'!B6:B55)=Settings!$B$5)*('Claims Log'!C6:C55=B32)*'Claims Log'!J6:J55) | D32: =SUMPRODUCT((YEAR('Claims Log'!B6:B55)=Settings!$B$5)*('Claims Log'!C6:C55=B32)*'Claims Log'!K6:K55)
B33: Mountain View | C33: =SUMPRODUCT((YEAR('Claims Log'!B6:B55)=Settings!$B$5)*('Claims Log'!C6:C55=B33)*'Claims Log'!J6:J55) | D33: =SUMPRODUCT((YEAR('Claims Log'!B6:B55)=Settings!$B$5)*('Claims Log'!C6:C55=B33)*'Claims Log'!K6:K55)
B34: Downtown Loft | C34: =SUMPRODUCT((YEAR('Claims Log'!B6:B55)=Settings!$B$5)*('Claims Log'!C6:C55=B34)*'Claims Log'!J6:J55) | D34: =SUMPRODUCT((YEAR('Claims Log'!B6:B55)=Settings!$B$5)*('Claims Log'!C6:C55=B34)*'Claims Log'!K6:K55)
B41: =HYPERLINK("#'Claims Log'!A1", "← Back to Claims Log")

Sheet Settings
A2: =HYPERLINK("#'Annual Summary'!A1", "← BACK") | D2: SETTINGS
A4: Edit these lists to match your portfolio + carriers. They drive the dropdowns and the year-scoped formulas on every other tab.
B5: 2026 | D5: ← Active year (drives all annual formulas)
B6: PROPERTIES
B7: Smokies Ridge Cabin
B8: Creek Side
B9: Lakehouse A
B10: Lakehouse B
B11: Mountain View
B12: Downtown Loft
B17: CARRIERS
B18: Foremost Signature
B19: Proper Insurance
B20: Allstate
B21: State Farm
... B39: ANNUAL PREMIUM
D40: ← Total premium paid this year (for ROI calc)
A43: YEAR-END ARCHIVE — fill each January from the Annual Summary
B44: Year | C44: Claims | D44: $ Submitted | E44: $ Recovered
B45: 2026
B46: 2027
B47: 2028
B48: 2029
B49: 2030
B50: 2031
