Workbook

Sheet Start
A2: The STR Ledger
A4: Listing SEO Audit
A5: Score, fix list, re-audit date — your listing diagnosed.
A7: MKT-001 · v1.0 · BLANK
A11: =IF('Listing Inputs'!C7="","(enter listing name on Listing Inputs)",'Listing Inputs'!C7)
A13: OVERALL SCORE
A14: =TEXT('Audit Score'!C2,"0")&" / 100"
A18: =IF('Audit Score'!C2>=90,"PARCHMENT — listing is dialed in",IF('Audit Score'!C2>=80,"GOLD-SOFT — strong listing, polish remaining",IF('Audit Score'!C2>=60,"GOLD — typical listing; clear room to grow","RED — major fixes needed before paid traffic helps")))
A20: TITLE | C20: DESC | E20: PHOTOS | G20: AMEN | I20: TRUST | K20: TOTAL
B21: ='Audit Score'!E5 | D21: ='Audit Score'!E6 | F21: ='Audit Score'!E7 | H21: ='Audit Score'!E8 | J21: ='Audit Score'!E9 | L21: ='Audit Score'!C11
A24: TOP 3 FIXES TO PRIORITIZE
A25: 1. | B25: ='Audit Score'!H20 | F25: ='Audit Score'!I20
A26: 2. | B26: ='Audit Score'!H21 | F26: ='Audit Score'!I21
A27: 3. | B27: ='Audit Score'!H22 | F27: ='Audit Score'!I22
B29: Next re-audit by: | C29: ='Re-audit Tracker'!C7 | E29: Set on the Re-audit Tracker tab. Re-run after material listing changes.
A32: =HYPERLINK("#'Listing Inputs'!A1", "Listing Inputs") | D32: =HYPERLINK("#'Audit Score'!A1", "Audit Score") | G32: =HYPERLINK("#'Comp Compare'!A1", "Comp Compare") | J32: =HYPERLINK("#'Methodology'!A1", "Methodology")
A36: =HYPERLINK("#'Re-audit Tracker'!A1", "→ Re-audit Tracker")
A40: 💡 Auditing your whole portfolio? Get the Marketing Bundle at thestrledger.com — SEO audit + review tracker + referral CRM, $97.
A43: Questions? hello@thestrledger.com
A44: MKT-001 · v1.0 · BLANK · Free updates forever

Sheet Listing Inputs
A2: =HYPERLINK("#'Start'!A1", "← BACK") | D2: LISTING INPUTS | J2: =HYPERLINK("#'Audit Score'!A1", "NEXT →")
A4: Paste your live listing details here. The Audit Score tab reads from these inputs.
A6: LISTING IDENTITY
B7: Listing name: | E7: How you'll reference this listing internally
B8: Listing URL: | E8: airbnb.com/h/... (paste the public link)
A10: TITLE
B11: Title text (paste): | E11: Airbnb caps titles at 50 characters
B12: Title char count: | E12: Should be 35-50 — under is thin, over gets truncated
A14: DESCRIPTION
B15: Description:
B18: Description word count: | E18: Sweet spot: 150-500 words
A20: PHOTOS
B21: Total photo count: | E21: Aim for ≥ 25
B22: Cover photo type: | E22: Dropdown — should be Exterior or hero Living
B23: Bedroom photos count: | E23: ≥ 1 per bedroom
B24: Bathroom photos count: | E24: ≥ 1 per bathroom
B25: Kitchen photos count: | E25: Wide + 1 detail shot
B26: Outdoor photos count: | E26: Porch, deck, yard, view
B27: Photos professional? | E27: Yes/No — paid photographer or pro-grade DSLR
B28: Twilight / sunset photos? | E28: Yes/No — at least 1-2
B29: Sequenced as guest journey? | E29: Yes/No — arrival → living → bedrooms → bath → kitchen → outdoor
A31: AMENITIES
B32: Total amenities listed: | E32: Walk through Airbnb's full list — aim for ≥ 40
B33: Hot tub?
B34: Pool?
B35: Fireplace?
B36: Fast WiFi (≥ 100 Mbps)?
B37: Workspace / desk?
B38: EV charger?
B39: Pet-friendly?
B40: Kid-friendly?
B41: Self check-in?
A43: TRUST SIGNALS
B44: Response rate (%): | E44: Airbnb dashboard shows this
B45: Response time: | E45: Dropdown — <1hr is the sweet spot
B46: Instant Book on? | E46: Yes/No
B47: Superhost? | E47: Yes/No
B48: Total reviews:
B49: Average rating:
B50: Cancellation policy: | E50: Dropdown
...

Sheet Audit Score
A2: =HYPERLINK("#'Listing Inputs'!A1", "← BACK") | D2: AUDIT SCORE | J2: =HYPERLINK("#'Comp Compare'!A1", "NEXT →")
B4: CATEGORY | C4: MAX PTS | D4: EARNED | E4: WEIGHTED
B5: Category A — Title (15% weight) | C5: =E31 | D5: =D31 | E5: =IF(C5=0,0,(D5/C5)*15)
B6: Category B — Description (20% weight) | C6: =E42 | D6: =D42 | E6: =IF(C6=0,0,(D6/C6)*20)
B7: Category C — Photos (30% weight) | C7: =E57 | D7: =D57 | E7: =IF(C7=0,0,(D7/C7)*30)
B8: Category D — Amenities (20% weight) | C8: =E68 | D8: =D68 | E8: =IF(C8=0,0,(D8/C8)*20)
B9: Category E — Trust signals (Airbnb algorithm) (15% weight) | C9: =E78 | D9: =D78 | E9: =IF(C9=0,0,(D9/C9)*15)
B10: TOTAL (max possible 100) | E10: =SUM(E5:E9)
B11: OVERALL SCORE (0-100): | C11: =E10/100*100
H19: TOP 3 LOWEST-SCORING (CRITERION + FIX)
H20: =IFERROR(INDEX(B26:B77,MATCH(LARGE(J26:J77,1),J26:J77,0)),"") | I20: =IFERROR(INDEX(F26:F77,MATCH(LARGE(J26:J77,1),J26:J77,0)),"")
H21: =IFERROR(INDEX(B26:B77,MATCH(LARGE(J26:J77,2),J26:J77,0)),"") | I21: =IFERROR(INDEX(F26:F77,MATCH(LARGE(J26:J77,2),J26:J77,0)),"")
H22: =IFERROR(INDEX(B26:B77,MATCH(LARGE(J26:J77,3),J26:J77,0)),"") | I22: =IFERROR(INDEX(F26:F77,MATCH(LARGE(J26:J77,3),J26:J77,0)),"")
A24: ID | B24: Criterion | C24: Met? | D24: Pts | E24: Max | F24: Specific fix
A25: CATEGORY A — TITLE · 15% WEIGHT
A26: 1 | B26: Title length 35-50 chars (sweet spot) | D26: =IF(C26="Yes",10,IF(C26="Partial",5,IF(C26="No",0,0))) | E26: 10 | F26: Trim to 50 chars max. Cut weak words first: 'beautiful', 'amazing', 'cozy'. | J26: =(E26-D26)*15/10
A27: 2 | B27: Includes city or neighborhood | D27: =IF(C27="Yes",10,IF(C27="Partial",5,IF(C27="No",0,0))) | E27: 10 | F27: Add city or neighborhood near the front of the title. | J27: =(E27-D27)*15/10
A28: 3 | B28: Includes 1-2 highest-value amenities (hot tub / view / walkable) | D28: =IF(C28="Yes",10,IF(C28="Partial",5,IF(C28="No",0,0))) | E28: 10 | F28: Promote your top 1-2 amenities into the title. Hot tub > view > walkable. | J28: =(E28-D28)*15/10
A29: 4 | B29: No ALL CAPS, no emojis, no clickbait | D29: =IF(C29="Yes",10,IF(C29="Partial",5,IF(C29="No",0,0))) | E29: 10 | F29: Strip caps and emojis. Airbnb's algorithm and guests both penalize them. | J29: =(E29-D29)*15/10
A30: 5 | B30: Differentiating phrase or experience hook | D30: =IF(C30="Yes",10,IF(C30="Partial",5,IF(C30="No",0,0))) | E30: 10 | F30: Add a 2-3 word hook: 'sunset deck', 'creekside cabin', 'walk to brewery'. | J30: =(E30-D30)*15/10
B31: Category A subtotal: | D31: =SUM(D26:D30) | E31: =SUM(E26:E30)
A33: CATEGORY B — DESCRIPTION · 20% WEIGHT
A34: 6 | B34: Opens with a hook line (NOT 'Welcome to my home!') | D34: =IF(C34="Yes",10,IF(C34="Partial",5,IF(C34="No",0,0))) | E34: 10 | F34: Replace generic welcome with one sentence that paints a scene or promise. | J34: =(E34-D34)*20/10
A35: 7 | B35: Length between 150-500 words | D35: =IF(C35="Yes",10,IF(C35="Partial",5,IF(C35="No",0,0))) | E35: 10 | F35: Aim for 220-350 words. Less = thin. More = guests skim and miss key info. | J35: =(E35-D35)*20/10
A36: 8 | B36: Lists what makes property unique in first 3 sentences | D36: =IF(C36="Yes",10,IF(C36="Partial",5,IF(C36="No",0,0))) | E36: 10 | F36: Move your unique edge (view, hot tub, location) into the opening 3 sentences. | J36: =(E36-D36)*20/10
A37: 9 | B37: Mentions surrounding area + walkability or drive times | D37: =IF(C37="Yes",10,IF(C37="Partial",5,IF(C37="No",0,0))) | E37: 10 | F37: Add 1-2 lines on nearby attractions with drive minutes ('15 min to Dollywood'). | J37: =(E37-D37)*20/10
A38: 10 | B38: Has dedicated bedrooms section with sleeping config | D38: =IF(C38="Yes",10,IF(C38="Partial",5,IF(C38="No",0,0))) | E38: 10 | F38: Add a 'Sleeping arrangements' block: 'Bedroom 1: King · Bedroom 2: Queen + bunk'. | J38: =(E38-D38)*20/10
A39: 11 | B39: Has dedicated amenities section (formatted, scannable) | D39: =IF(C39="Yes",10,IF(C39="Partial",5,IF(C39="No",0,0))) | E39: 10 | F39: Add a bullet list: 'Hot tub · Fast WiFi · EV charger · Workspace'. | J39: =(E39-D39)*20/10
A40: 12 | B40: Includes house rules (positive framing) | D40: =IF(C40="Yes",10,IF(C40="Partial",5,IF(C40="No",0,0))) | E40: 10 | F40: Reframe rules as guest-friendly: 'Quiet hours after 10pm to keep neighbors happy'. | J40: =(E40-D40)*20/10
A41: 13 | B41: Closes with hospitality / response promise | D41: =IF(C41="Yes",10,IF(C41="Partial",5,IF(C41="No",0,0))) | E41: 10 | F41: End with: 'Message us anytime — we typically reply within an hour.' | J41: =(E41-D41)*20/10
B42: Category B subtotal: | D42: =SUM(D34:D41) | E42: =SUM(E34:E41)
A44: CATEGORY C — PHOTOS · 30% WEIGHT
A45: 14 | B45: At least 25 photos posted | D45: =IF(C45="Yes",10,IF(C45="Partial",5,IF(C45="No",0,0))) | E45: 10 | F45: Add 6+ photos to reach 25. Twilight exterior, kitchen detail, bedroom #2 are common gaps. | J45: =(E45-D45)*30/10
A46: 15 | B46: Cover photo is exterior or hero interior shot | D46: =IF(C46="Yes",10,IF(C46="Partial",5,IF(C46="No",0,0))) | E46: 10 | F46: Swap cover to exterior or hero living shot. Bedroom covers are conversion killers. | J46: =(E46-D46)*30/10
A47: 16 | B47: Bedroom photo for every bedroom | D47: =IF(C47="Yes",10,IF(C47="Partial",5,IF(C47="No",0,0))) | E47: 10 | F47: Add at least one wide-angle shot per bedroom. Show the bed clearly. | J47: =(E47-D47)*30/10
A48: 17 | B48: Bathroom photo for every bathroom | D48: =IF(C48="Yes",10,IF(C48="Partial",5,IF(C48="No",0,0))) | E48: 10 | F48: Add bathroom shots. Highlight cleanliness, towels, walk-in shower if you have one. | J48: =(E48-D48)*30/10
A49: 18 | B49: Kitchen photo (wide + detail) | D49: =IF(C49="Yes",10,IF(C49="Partial",5,IF(C49="No",0,0))) | E49: 10 | F49: Add a wide kitchen shot plus 1 detail (coffee setup, island, range). | J49: =(E49-D49)*30/10
A50: 19 | B50: Living / common space photo | D50: =IF(C50="Yes",10,IF(C50="Partial",5,IF(C50="No",0,0))) | E50: 10 | F50: Show the main hangout space with sofa, lighting, and TV in frame. | J50: =(E50-D50)*30/10
A51: 20 | B51: Outdoor space photo (porch, deck, yard, view) | D51: =IF(C51="Yes",10,IF(C51="Partial",5,IF(C51="No",0,0))) | E51: 10 | F51: Add an outdoor shot. Hot tub at twilight or a deck view drives bookings. | J51: =(E51-D51)*30/10
A52: 21 | B52: Twilight or sunset photo | D52: =IF(C52="Yes",10,IF(C52="Partial",5,IF(C52="No",0,0))) | E52: 10 | F52: Add 1-2 twilight shots. Hire a pro or shoot 30 min after sunset, lights ON. | J52: =(E52-D52)*30/10
...

Sheet Comp Compare
A2: =HYPERLINK("#'Audit Score'!A1", "← BACK") | D2: COMP COMPARE | J2: =HYPERLINK("#'Methodology'!A1", "NEXT →")
A4: Paste 5 competitor listings as you'd score them. The grid surfaces where comps beat you.
B6: Comp → | C6: Mine
A7: ID | B7: Criterion | C7: Mine | D7: Comp 1 | E7: Comp 2 | F7: Comp 3 | G7: Comp 4 | H7: Comp 5
A9: CATEGORY A — TITLE · 15% WEIGHT
A10: 1 | B10: Title length 35-50 chars (sweet spot) | C10: =IFERROR(INDEX('Audit Score'!$C:$C,MATCH(1,'Audit Score'!$A:$A,0)),"")
A11: 2 | B11: Includes city or neighborhood | C11: =IFERROR(INDEX('Audit Score'!$C:$C,MATCH(2,'Audit Score'!$A:$A,0)),"")
A12: 3 | B12: Includes 1-2 highest-value amenities (hot tub / view / walkable) | C12: =IFERROR(INDEX('Audit Score'!$C:$C,MATCH(3,'Audit Score'!$A:$A,0)),"")
A13: 4 | B13: No ALL CAPS, no emojis, no clickbait | C13: =IFERROR(INDEX('Audit Score'!$C:$C,MATCH(4,'Audit Score'!$A:$A,0)),"")
A14: 5 | B14: Differentiating phrase or experience hook | C14: =IFERROR(INDEX('Audit Score'!$C:$C,MATCH(5,'Audit Score'!$A:$A,0)),"")
A15: CATEGORY B — DESCRIPTION · 20% WEIGHT
A16: 6 | B16: Opens with a hook line (NOT 'Welcome to my home!') | C16: =IFERROR(INDEX('Audit Score'!$C:$C,MATCH(6,'Audit Score'!$A:$A,0)),"")
A17: 7 | B17: Length between 150-500 words | C17: =IFERROR(INDEX('Audit Score'!$C:$C,MATCH(7,'Audit Score'!$A:$A,0)),"")
A18: 8 | B18: Lists what makes property unique in first 3 sentences | C18: =IFERROR(INDEX('Audit Score'!$C:$C,MATCH(8,'Audit Score'!$A:$A,0)),"")
A19: 9 | B19: Mentions surrounding area + walkability or drive times | C19: =IFERROR(INDEX('Audit Score'!$C:$C,MATCH(9,'Audit Score'!$A:$A,0)),"")
A20: 10 | B20: Has dedicated bedrooms section with sleeping config | C20: =IFERROR(INDEX('Audit Score'!$C:$C,MATCH(10,'Audit Score'!$A:$A,0)),"")
A21: 11 | B21: Has dedicated amenities section (formatted, scannable) | C21: =IFERROR(INDEX('Audit Score'!$C:$C,MATCH(11,'Audit Score'!$A:$A,0)),"")
A22: 12 | B22: Includes house rules (positive framing) | C22: =IFERROR(INDEX('Audit Score'!$C:$C,MATCH(12,'Audit Score'!$A:$A,0)),"")
A23: 13 | B23: Closes with hospitality / response promise | C23: =IFERROR(INDEX('Audit Score'!$C:$C,MATCH(13,'Audit Score'!$A:$A,0)),"")
A24: CATEGORY C — PHOTOS · 30% WEIGHT
A25: 14 | B25: At least 25 photos posted | C25: =IFERROR(INDEX('Audit Score'!$C:$C,MATCH(14,'Audit Score'!$A:$A,0)),"")
A26: 15 | B26: Cover photo is exterior or hero interior shot | C26: =IFERROR(INDEX('Audit Score'!$C:$C,MATCH(15,'Audit Score'!$A:$A,0)),"")
A27: 16 | B27: Bedroom photo for every bedroom | C27: =IFERROR(INDEX('Audit Score'!$C:$C,MATCH(16,'Audit Score'!$A:$A,0)),"")
A28: 17 | B28: Bathroom photo for every bathroom | C28: =IFERROR(INDEX('Audit Score'!$C:$C,MATCH(17,'Audit Score'!$A:$A,0)),"")
A29: 18 | B29: Kitchen photo (wide + detail) | C29: =IFERROR(INDEX('Audit Score'!$C:$C,MATCH(18,'Audit Score'!$A:$A,0)),"")
A30: 19 | B30: Living / common space photo | C30: =IFERROR(INDEX('Audit Score'!$C:$C,MATCH(19,'Audit Score'!$A:$A,0)),"")
A31: 20 | B31: Outdoor space photo (porch, deck, yard, view) | C31: =IFERROR(INDEX('Audit Score'!$C:$C,MATCH(20,'Audit Score'!$A:$A,0)),"")
A32: 21 | B32: Twilight or sunset photo | C32: =IFERROR(INDEX('Audit Score'!$C:$C,MATCH(21,'Audit Score'!$A:$A,0)),"")
A33: 22 | B33: Professional quality (sharp, well-lit, level horizon) | C33: =IFERROR(INDEX('Audit Score'!$C:$C,MATCH(22,'Audit Score'!$A:$A,0)),"")
A34: 23 | B34: Photos sequenced as guest journey (arrival → living → bedrooms → bath → kitchen → outdoor) | C34: =IFERROR(INDEX('Audit Score'!$C:$C,MATCH(23,'Audit Score'!$A:$A,0)),"")
A35: 24 | B35: Captions on every photo | C35: =IFERROR(INDEX('Audit Score'!$C:$C,MATCH(24,'Audit Score'!$A:$A,0)),"")
A36: 25 | B36: No phone-camera-mirror shots, no clutter visible | C36: =IFERROR(INDEX('Audit Score'!$C:$C,MATCH(25,'Audit Score'!$A:$A,0)),"")
A37: CATEGORY D — AMENITIES · 20% WEIGHT
A38: 26 | B38: At least 40 amenities checked | C38: =IFERROR(INDEX('Audit Score'!$C:$C,MATCH(26,'Audit Score'!$A:$A,0)),"")
A39: 27 | B39: Top-tier amenities listed (hot tub / pool / view / fireplace) | C39: =IFERROR(INDEX('Audit Score'!$C:$C,MATCH(27,'Audit Score'!$A:$A,0)),"")
A40: 28 | B40: Fast WiFi listed with speed (≥ 100 Mbps) | C40: =IFERROR(INDEX('Audit Score'!$C:$C,MATCH(28,'Audit Score'!$A:$A,0)),"")
A41: 29 | B41: Workspace / desk listed | C41: =IFERROR(INDEX('Audit Score'!$C:$C,MATCH(29,'Audit Score'!$A:$A,0)),"")
A42: 30 | B42: Self check-in OR clear arrival instructions | C42: =IFERROR(INDEX('Audit Score'!$C:$C,MATCH(30,'Audit Score'!$A:$A,0)),"")
A43: 31 | B43: Pet policy clearly stated | C43: =IFERROR(INDEX('Audit Score'!$C:$C,MATCH(31,'Audit Score'!$A:$A,0)),"")
A44: 32 | B44: Family-friendly amenities (if family-friendly listing) | C44: =IFERROR(INDEX('Audit Score'!$C:$C,MATCH(32,'Audit Score'!$A:$A,0)),"")
...

Sheet Methodology
A2: =HYPERLINK("#'Comp Compare'!A1", "← BACK") | D2: METHODOLOGY | J2: =HYPERLINK("#'Re-audit Tracker'!A1", "NEXT →")
A4: How we score — published rubric. Public-facing. Last updated 2026-05-01.
A6: ID | B6: Criterion | C6: Weight% | D6: Why it matters | E6: Source | F6: Last verified
A7: CATEGORY A — TITLE · 15% TOTAL · 3.00% PER CRITERION
A8: 1 | B8: Title length 35-50 chars (sweet spot) | C8: 3 | D8: Airbnb truncates titles past 50 chars on mobile search results — your hook gets cut. | E8: Airbnb published | F8: 2026-05-01
A9: 2 | B9: Includes city or neighborhood | C9: 3 | D9: Location keywords match guest search queries directly. ~70% of searches include geo. | E9: Airbnb published | F9: 2026-05-01
A10: 3 | B10: Includes 1-2 highest-value amenities (hot tub / view / walkable) | C10: 3 | D10: Top-tier amenities (hot tub, view) are the #1 booking decision driver. | E10: Hospitable 2024 study | F10: 2026-05-01
A11: 4 | B11: No ALL CAPS, no emojis, no clickbait | C11: 3 | D11: Caps and emojis trigger algorithm-spam heuristics + reduce perceived professionalism. | E11: Host community consensus | F11: 2026-05-01
A12: 5 | B12: Differentiating phrase or experience hook | C12: 3 | D12: Differentiating phrases capture the 'experience' signal Airbnb's algorithm rewards. | E12: AirDNA Marketscore | F12: 2026-05-01
A13: CATEGORY B — DESCRIPTION · 20% TOTAL · 2.50% PER CRITERION
A14: 6 | B14: Opens with a hook line (NOT 'Welcome to my home!') | C14: 2.5 | D14: Generic openings lose the first-3-second skim test. Hook = retention. | E14: Hospitable 2024 study | F14: 2026-05-01
A15: 7 | B15: Length between 150-500 words | C15: 2.5 | D15: <150 words = thin signal. >500 words = guests skim and miss key info. | E15: Host community consensus | F15: 2026-05-01
A16: 8 | B16: Lists what makes property unique in first 3 sentences | C16: 2.5 | D16: Guests decide in 3 sentences. Bury the lead and you lose them. | E16: Conversion best practice | F16: 2026-05-01
A17: 9 | B17: Mentions surrounding area + walkability or drive times | C17: 2.5 | D17: Walkability/drive times answer the silent question every guest has. | E17: Airbnb host blog | F17: 2026-05-01
A18: 10 | B18: Has dedicated bedrooms section with sleeping config | C18: 2.5 | D18: Sleeping config is the #1 question guests message about. | E18: Host community consensus | F18: 2026-05-01
A19: 11 | B19: Has dedicated amenities section (formatted, scannable) | C19: 2.5 | D19: Scannable amenity list reduces messages and improves conversion. | E19: Hospitable 2024 study | F19: 2026-05-01
A20: 12 | B20: Includes house rules (positive framing) | C20: 2.5 | D20: Positive-framed rules signal hospitality. Negative framing kills bookings. | E20: Host community consensus | F20: 2026-05-01
A21: 13 | B21: Closes with hospitality / response promise | C21: 2.5 | D21: Response promise sets expectations and improves message-to-book rate. | E21: Conversion best practice | F21: 2026-05-01
A22: CATEGORY C — PHOTOS · 30% TOTAL · 2.50% PER CRITERION
A23: 14 | B23: At least 25 photos posted | C23: 2.5 | D23: Listings with 25+ photos out-book sub-25 by ~30% on average. | E23: AirDNA 2023 study | F23: 2026-05-01
A24: 15 | B24: Cover photo is exterior or hero interior shot | C24: 2.5 | D24: Cover photo is the click-through trigger. Bedroom covers underperform exterior 2:1. | E24: AirDNA 2023 study | F24: 2026-05-01
A25: 16 | B25: Bedroom photo for every bedroom | C25: 2.5 | D25: Guests filter by bedroom count — they expect to see each one. | E25: Airbnb published | F25: 2026-05-01
A26: 17 | B26: Bathroom photo for every bathroom | C26: 2.5 | D26: Bathroom photos signal cleanliness, the #1 review factor. | E26: Airbnb review data | F26: 2026-05-01
A27: 18 | B27: Kitchen photo (wide + detail) | C27: 2.5 | D27: Kitchen is the second-most-photographed room in winning listings. | E27: AirDNA 2023 study | F27: 2026-05-01
A28: 19 | B28: Living / common space photo | C28: 2.5 | D28: Living photo establishes the 'hangout' value — drives long-stay bookings. | E28: Conversion best practice | F28: 2026-05-01
A29: 20 | B29: Outdoor space photo (porch, deck, yard, view) | C29: 2.5 | D29: Outdoor space signals seasonal value, hot tubs convert highest. | E29: Hospitable 2024 study | F29: 2026-05-01
A30: 21 | B30: Twilight or sunset photo | C30: 2.5 | D30: Twilight photos beat daytime photos on engagement by ~40%. | E30: Hospitable 2024 study | F30: 2026-05-01
A31: 22 | B31: Professional quality (sharp, well-lit, level horizon) | C31: 2.5 | D31: Pro photos pay back in 30-60 days. Highest ROI marketing spend. | E31: STR investor consensus | F31: 2026-05-01
A32: 23 | B32: Photos sequenced as guest journey (arrival → living → bedrooms → bath → kitchen → outdoor) | C32: 2.5 | D32: Guest journey order matches mental model: arrive → live → sleep → eat → outside. | E32: UX best practice | F32: 2026-05-01
A33: 24 | B33: Captions on every photo | C33: 2.5 | D33: Captioned photos rank higher in Airbnb search — accessibility signal. | E33: Airbnb published | F33: 2026-05-01
A34: 25 | B34: No phone-camera-mirror shots, no clutter visible | C34: 2.5 | D34: Mirror-selfies and clutter signal amateur listing → lower trust. | E34: Host community consensus | F34: 2026-05-01
A35: CATEGORY D — AMENITIES · 20% TOTAL · 2.50% PER CRITERION
A36: 26 | B36: At least 40 amenities checked | C36: 2.5 | D36: Amenity count is a direct algorithm completeness signal. | E36: Airbnb published | F36: 2026-05-01
A37: 27 | B37: Top-tier amenities listed (hot tub / pool / view / fireplace) | C37: 2.5 | D37: Top-tier amenities have explicit search filters — must be checked to appear. | E37: Airbnb published | F37: 2026-05-01
A38: 28 | B38: Fast WiFi listed with speed (≥ 100 Mbps) | C38: 2.5 | D38: WiFi speed in description converts remote workers (30%+ weekday demand). | E38: AirDNA workforce data | F38: 2026-05-01
A39: 29 | B39: Workspace / desk listed | C39: 2.5 | D39: Workspace amenity has its own search filter — easy ranking lift. | E39: Airbnb published | F39: 2026-05-01
A40: 30 | B40: Self check-in OR clear arrival instructions | C40: 2.5 | D40: Self check-in unlocks Instant Book guest segments with separate filter. | E40: Airbnb published | F40: 2026-05-01
A41: 31 | B41: Pet policy clearly stated | C41: 2.5 | D41: Pet policy clarity reduces wrong-fit bookings and bad reviews. | E41: Host community consensus | F41: 2026-05-01
A42: 32 | B42: Family-friendly amenities (if family-friendly listing) | C42: 2.5 | D42: Family filters drive 40%+ of weekend bookings in family markets. | E42: AirDNA family data | F42: 2026-05-01
A43: 33 | B43: Accessibility features listed | C43: 2.5 | D43: Accessibility tags expand qualified-buyer pool with no inventory change. | E43: Airbnb published | F43: 2026-05-01
...

Sheet Re-audit Tracker
A2: =HYPERLINK("#'Methodology'!A1", "← BACK") | D2: RE-AUDIT TRACKER
A4: Schedule your next audit and log every prior re-run. Track score progression.
A6: NEXT RE-AUDIT
B7: Re-audit by: | E7: Re-run after pro photos refresh, description rewrite, or pricing/ADR change.
B8: Days until next audit: | C8: =IF(C7="","",C7-TODAY())
A11: AUDIT HISTORY (5 most recent)
B12: Audit date | C12: Score | D12: Δ vs prior | E12: Notes / what changed
D13: =""
D14: =IF(OR(C14="",C13=""),"",C14-C13)
D15: =IF(OR(C15="",C14=""),"",C15-C14)
D16: =IF(OR(C16="",C15=""),"",C16-C15)
D17: =IF(OR(C17="",C16=""),"",C17-C16)
A20: WHEN TO RE-AUDIT
B21: Quarterly minimum. | C21: STR markets shift season-to-season. A Q1 score is stale by Q3.
B22: After every material listing change. | C22: New photos, rewritten description, amenity changes, pricing changes.
B23: After Airbnb algorithm announcements. | C23: Methodology page updates after Airbnb publishes changes — re-run to verify.
A27: Questions? hello@thestrledger.com
A28: MKT-001 · Re-audit Tracker
