Workbook

Sheet Start
A2: The STR Ledger
A4: Utility Usage + Trend
A5: Catch a leak before it costs a month.
A6: =IF(COUNTA('Bills Log'!B6:B505)=0,"📊 Log your first bill to see your verdict.",IF('Trend & Anomalies'!$B$3=0,"✅ No anomalies detected — usage is steady year-over-year.","⚠ "&'Trend & Anomalies'!$B$3&" anomalies detected — see Trend & Anomalies tab."))
A7: OPS-007 · v2.2 · BLANK
A10: WHAT THIS DOES
A11: Track every utility bill (electric, gas, water, internet, trash, propane) per property in a 12-column matrix. The Trend & Anomalies tab compares each month to the prior year and flags any service whose bill jumped >25% — your early warning system for leaks, runaway HVAC, and price hikes you didn't see coming.
A18: HOW TO USE
A19: ① Settings: list your properties + confirm active year.
A20: ② Bills Log: log every utility bill — date, property, service, $, usage, notes.
A21: ③ Property Matrix: per-property 12-month roll-up by service (auto).
A22: ④ Trend & Anomalies: scan the ⚠ flags — anything >25% YoY needs a look.
A23: ⑤ Bump 'Active tax year' on Settings each January so YoY checks stay aligned.
A24: ⑥ Log bills the day they arrive — backfilling kills the trend signal.
A27: =HYPERLINK("#'Bills Log'!A6", "→ LOG A BILL")
A32: YTD UTILITY $ | E32: AVG $/MONTH | I32: ANOMALIES
A33: =SUMIFS('Bills Log'!F:F,'Bills Log'!A:A,">="&DATE(Settings!$B$5,1,1),'Bills Log'!A:A,"<"&DATE(Settings!$B$5+1,1,1)) | E33: =IFERROR(SUMIFS('Bills Log'!F:F,'Bills Log'!A:A,">="&DATE(Settings!$B$5,1,1),'Bills Log'!A:A,"<"&DATE(Settings!$B$5+1,1,1))/12,0) | I33: ='Trend & Anomalies'!$B$3
A35: all properties combined | E35: across all services | I35: YoY jumps >25%
A39: =HYPERLINK("#'Bills Log'!A1", "Bills Log") | D39: =HYPERLINK("#'Property Matrix'!A1", "Property Matrix") | G39: =HYPERLINK("#'Trend & Anomalies'!A1", "⚠ Trend & Anomalies") | J39: =HYPERLINK("#'Settings'!A1", "Settings")
A42: ⚠ ANOMALY = a month's bill jumped >25% vs the same month last year. Common causes: leak, AC/heat running while vacant, rate hike, or a misread meter. Check the Trend & Anomalies tab monthly.
A44: 💡 Upgrade to the Full version at thestrledger.com/upgrade — multi-property, depreciation, multi-LLC support.
A47: Questions? hello@thestrledger.com
A48: OPS-007 · v2.2 · Free updates forever

Sheet Bills Log
A2: =HYPERLINK("#'Start'!A1", "← BACK") | D2: BILLS LOG | J2: =HYPERLINK("#'Property Matrix'!A1", "NEXT →")
A4: One row per utility bill — date, property, service, $, usage
A5: Bill Date | B5: Property | C5: Service | D5: Period Start | E5: Period End | F5: $ Amount | G5: Usage | H5: Units | I5: $/Unit | J5: Notes
I6: =IFERROR(F6/G6,"")
I7: =IFERROR(F7/G7,"")
I8: =IFERROR(F8/G8,"")
I9: =IFERROR(F9/G9,"")
I10: =IFERROR(F10/G10,"")
I11: =IFERROR(F11/G11,"")
I12: =IFERROR(F12/G12,"")
I13: =IFERROR(F13/G13,"")
I14: =IFERROR(F14/G14,"")
I15: =IFERROR(F15/G15,"")
I16: =IFERROR(F16/G16,"")
I17: =IFERROR(F17/G17,"")
... I505: =IFERROR(F505/G505,"")

Sheet Property Matrix
A2: =HYPERLINK("#'Bills Log'!A1", "← BACK") | D2: PROPERTY MATRIX | J2: =HYPERLINK("#'Trend & Anomalies'!A1", "NEXT →")
A4: Per-property 12-month roll-up — auto-rolled from Bills Log
A6: ="Property: "&Settings!$B$7
A7: Service | B7: Jan | C7: Feb | D7: Mar | E7: Apr | F7: May | G7: Jun | H7: Jul | I7: Aug | J7: Sep | K7: Oct | L7: Nov | M7: Dec | N7: Total | O7: Avg
A8: Electric | B8: =SUMIFS('Bills Log'!$F$6:$F$505,'Bills Log'!$A$6:$A$505,">="&DATE(Settings!$B$5,1,1),'Bills Log'!$A$6:$A$505,"<"&DATE(Settings!$B$5,2,1),'Bills Log'!$B$6:$B$505,Settings!$B$7,'Bills Log'!$C$6:$C$505,$A8) | C8: =SUMIFS('Bills Log'!$F$6:$F$505,'Bills Log'!$A$6:$A$505,">="&DATE(Settings!$B$5,2,1),'Bills Log'!$A$6:$A$505,"<"&DATE(Settings!$B$5,3,1),'Bills Log'!$B$6:$B$505,Settings!$B$7,'Bills Log'!$C$6:$C$505,$A8) | D8: =SUMIFS('Bills Log'!$F$6:$F$505,'Bills Log'!$A$6:$A$505,">="&DATE(Settings!$B$5,3,1),'Bills Log'!$A$6:$A$505,"<"&DATE(Settings!$B$5,4,1),'Bills Log'!$B$6:$B$505,Settings!$B$7,'Bills Log'!$C$6:$C$505,$A8) | E8: =SUMIFS('Bills Log'!$F$6:$F$505,'Bills Log'!$A$6:$A$505,">="&DATE(Settings!$B$5,4,1),'Bills Log'!$A$6:$A$505,"<"&DATE(Settings!$B$5,5,1),'Bills Log'!$B$6:$B$505,Settings!$B$7,'Bills Log'!$C$6:$C$505,$A8) | F8: =SUMIFS('Bills Log'!$F$6:$F$505,'Bills Log'!$A$6:$A$505,">="&DATE(Settings!$B$5,5,1),'Bills Log'!$A$6:$A$505,"<"&DATE(Settings!$B$5,6,1),'Bills Log'!$B$6:$B$505,Settings!$B$7,'Bills Log'!$C$6:$C$505,$A8) | G8: =SUMIFS('Bills Log'!$F$6:$F$505,'Bills Log'!$A$6:$A$505,">="&DATE(Settings!$B$5,6,1),'Bills Log'!$A$6:$A$505,"<"&DATE(Settings!$B$5,7,1),'Bills Log'!$B$6:$B$505,Settings!$B$7,'Bills Log'!$C$6:$C$505,$A8) | H8: =SUMIFS('Bills Log'!$F$6:$F$505,'Bills Log'!$A$6:$A$505,">="&DATE(Settings!$B$5,7,1),'Bills Log'!$A$6:$A$505,"<"&DATE(Settings!$B$5,8,1),'Bills Log'!$B$6:$B$505,Settings!$B$7,'Bills Log'!$C$6:$C$505,$A8) | I8: =SUMIFS('Bills Log'!$F$6:$F$505,'Bills Log'!$A$6:$A$505,">="&DATE(Settings!$B$5,8,1),'Bills Log'!$A$6:$A$505,"<"&DATE(Settings!$B$5,9,1),'Bills Log'!$B$6:$B$505,Settings!$B$7,'Bills Log'!$C$6:$C$505,$A8) | J8: =SUMIFS('Bills Log'!$F$6:$F$505,'Bills Log'!$A$6:$A$505,">="&DATE(Settings!$B$5,9,1),'Bills Log'!$A$6:$A$505,"<"&DATE(Settings!$B$5,10,1),'Bills Log'!$B$6:$B$505,Settings!$B$7,'Bills Log'!$C$6:$C$505,$A8) | K8: =SUMIFS('Bills Log'!$F$6:$F$505,'Bills Log'!$A$6:$A$505,">="&DATE(Settings!$B$5,10,1),'Bills Log'!$A$6:$A$505,"<"&DATE(Settings!$B$5,11,1),'Bills Log'!$B$6:$B$505,Settings!$B$7,'Bills Log'!$C$6:$C$505,$A8) | L8: =SUMIFS('Bills Log'!$F$6:$F$505,'Bills Log'!$A$6:$A$505,">="&DATE(Settings!$B$5,11,1),'Bills Log'!$A$6:$A$505,"<"&DATE(Settings!$B$5,12,1),'Bills Log'!$B$6:$B$505,Settings!$B$7,'Bills Log'!$C$6:$C$505,$A8) | M8: =SUMIFS('Bills Log'!$F$6:$F$505,'Bills Log'!$A$6:$A$505,">="&DATE(Settings!$B$5,12,1),'Bills Log'!$A$6:$A$505,"<"&DATE(Settings!$B$5+1,1,1),'Bills Log'!$B$6:$B$505,Settings!$B$7,'Bills Log'!$C$6:$C$505,$A8) | N8: =SUM(B8:M8) | O8: =IFERROR(N8/12,0)
A9: Gas | B9: =SUMIFS('Bills Log'!$F$6:$F$505,'Bills Log'!$A$6:$A$505,">="&DATE(Settings!$B$5,1,1),'Bills Log'!$A$6:$A$505,"<"&DATE(Settings!$B$5,2,1),'Bills Log'!$B$6:$B$505,Settings!$B$7,'Bills Log'!$C$6:$C$505,$A9) | C9: =SUMIFS('Bills Log'!$F$6:$F$505,'Bills Log'!$A$6:$A$505,">="&DATE(Settings!$B$5,2,1),'Bills Log'!$A$6:$A$505,"<"&DATE(Settings!$B$5,3,1),'Bills Log'!$B$6:$B$505,Settings!$B$7,'Bills Log'!$C$6:$C$505,$A9) | D9: =SUMIFS('Bills Log'!$F$6:$F$505,'Bills Log'!$A$6:$A$505,">="&DATE(Settings!$B$5,3,1),'Bills Log'!$A$6:$A$505,"<"&DATE(Settings!$B$5,4,1),'Bills Log'!$B$6:$B$505,Settings!$B$7,'Bills Log'!$C$6:$C$505,$A9) | E9: =SUMIFS('Bills Log'!$F$6:$F$505,'Bills Log'!$A$6:$A$505,">="&DATE(Settings!$B$5,4,1),'Bills Log'!$A$6:$A$505,"<"&DATE(Settings!$B$5,5,1),'Bills Log'!$B$6:$B$505,Settings!$B$7,'Bills Log'!$C$6:$C$505,$A9) | F9: =SUMIFS('Bills Log'!$F$6:$F$505,'Bills Log'!$A$6:$A$505,">="&DATE(Settings!$B$5,5,1),'Bills Log'!$A$6:$A$505,"<"&DATE(Settings!$B$5,6,1),'Bills Log'!$B$6:$B$505,Settings!$B$7,'Bills Log'!$C$6:$C$505,$A9) | G9: =SUMIFS('Bills Log'!$F$6:$F$505,'Bills Log'!$A$6:$A$505,">="&DATE(Settings!$B$5,6,1),'Bills Log'!$A$6:$A$505,"<"&DATE(Settings!$B$5,7,1),'Bills Log'!$B$6:$B$505,Settings!$B$7,'Bills Log'!$C$6:$C$505,$A9) | H9: =SUMIFS('Bills Log'!$F$6:$F$505,'Bills Log'!$A$6:$A$505,">="&DATE(Settings!$B$5,7,1),'Bills Log'!$A$6:$A$505,"<"&DATE(Settings!$B$5,8,1),'Bills Log'!$B$6:$B$505,Settings!$B$7,'Bills Log'!$C$6:$C$505,$A9) | I9: =SUMIFS('Bills Log'!$F$6:$F$505,'Bills Log'!$A$6:$A$505,">="&DATE(Settings!$B$5,8,1),'Bills Log'!$A$6:$A$505,"<"&DATE(Settings!$B$5,9,1),'Bills Log'!$B$6:$B$505,Settings!$B$7,'Bills Log'!$C$6:$C$505,$A9) | J9: =SUMIFS('Bills Log'!$F$6:$F$505,'Bills Log'!$A$6:$A$505,">="&DATE(Settings!$B$5,9,1),'Bills Log'!$A$6:$A$505,"<"&DATE(Settings!$B$5,10,1),'Bills Log'!$B$6:$B$505,Settings!$B$7,'Bills Log'!$C$6:$C$505,$A9) | K9: =SUMIFS('Bills Log'!$F$6:$F$505,'Bills Log'!$A$6:$A$505,">="&DATE(Settings!$B$5,10,1),'Bills Log'!$A$6:$A$505,"<"&DATE(Settings!$B$5,11,1),'Bills Log'!$B$6:$B$505,Settings!$B$7,'Bills Log'!$C$6:$C$505,$A9) | L9: =SUMIFS('Bills Log'!$F$6:$F$505,'Bills Log'!$A$6:$A$505,">="&DATE(Settings!$B$5,11,1),'Bills Log'!$A$6:$A$505,"<"&DATE(Settings!$B$5,12,1),'Bills Log'!$B$6:$B$505,Settings!$B$7,'Bills Log'!$C$6:$C$505,$A9) | M9: =SUMIFS('Bills Log'!$F$6:$F$505,'Bills Log'!$A$6:$A$505,">="&DATE(Settings!$B$5,12,1),'Bills Log'!$A$6:$A$505,"<"&DATE(Settings!$B$5+1,1,1),'Bills Log'!$B$6:$B$505,Settings!$B$7,'Bills Log'!$C$6:$C$505,$A9) | N9: =SUM(B9:M9) | O9: =IFERROR(N9/12,0)
A10: Water | B10: =SUMIFS('Bills Log'!$F$6:$F$505,'Bills Log'!$A$6:$A$505,">="&DATE(Settings!$B$5,1,1),'Bills Log'!$A$6:$A$505,"<"&DATE(Settings!$B$5,2,1),'Bills Log'!$B$6:$B$505,Settings!$B$7,'Bills Log'!$C$6:$C$505,$A10) | C10: =SUMIFS('Bills Log'!$F$6:$F$505,'Bills Log'!$A$6:$A$505,">="&DATE(Settings!$B$5,2,1),'Bills Log'!$A$6:$A$505,"<"&DATE(Settings!$B$5,3,1),'Bills Log'!$B$6:$B$505,Settings!$B$7,'Bills Log'!$C$6:$C$505,$A10) | D10: =SUMIFS('Bills Log'!$F$6:$F$505,'Bills Log'!$A$6:$A$505,">="&DATE(Settings!$B$5,3,1),'Bills Log'!$A$6:$A$505,"<"&DATE(Settings!$B$5,4,1),'Bills Log'!$B$6:$B$505,Settings!$B$7,'Bills Log'!$C$6:$C$505,$A10) | E10: =SUMIFS('Bills Log'!$F$6:$F$505,'Bills Log'!$A$6:$A$505,">="&DATE(Settings!$B$5,4,1),'Bills Log'!$A$6:$A$505,"<"&DATE(Settings!$B$5,5,1),'Bills Log'!$B$6:$B$505,Settings!$B$7,'Bills Log'!$C$6:$C$505,$A10) | F10: =SUMIFS('Bills Log'!$F$6:$F$505,'Bills Log'!$A$6:$A$505,">="&DATE(Settings!$B$5,5,1),'Bills Log'!$A$6:$A$505,"<"&DATE(Settings!$B$5,6,1),'Bills Log'!$B$6:$B$505,Settings!$B$7,'Bills Log'!$C$6:$C$505,$A10) | G10: =SUMIFS('Bills Log'!$F$6:$F$505,'Bills Log'!$A$6:$A$505,">="&DATE(Settings!$B$5,6,1),'Bills Log'!$A$6:$A$505,"<"&DATE(Settings!$B$5,7,1),'Bills Log'!$B$6:$B$505,Settings!$B$7,'Bills Log'!$C$6:$C$505,$A10) | H10: =SUMIFS('Bills Log'!$F$6:$F$505,'Bills Log'!$A$6:$A$505,">="&DATE(Settings!$B$5,7,1),'Bills Log'!$A$6:$A$505,"<"&DATE(Settings!$B$5,8,1),'Bills Log'!$B$6:$B$505,Settings!$B$7,'Bills Log'!$C$6:$C$505,$A10) | I10: =SUMIFS('Bills Log'!$F$6:$F$505,'Bills Log'!$A$6:$A$505,">="&DATE(Settings!$B$5,8,1),'Bills Log'!$A$6:$A$505,"<"&DATE(Settings!$B$5,9,1),'Bills Log'!$B$6:$B$505,Settings!$B$7,'Bills Log'!$C$6:$C$505,$A10) | J10: =SUMIFS('Bills Log'!$F$6:$F$505,'Bills Log'!$A$6:$A$505,">="&DATE(Settings!$B$5,9,1),'Bills Log'!$A$6:$A$505,"<"&DATE(Settings!$B$5,10,1),'Bills Log'!$B$6:$B$505,Settings!$B$7,'Bills Log'!$C$6:$C$505,$A10) | K10: =SUMIFS('Bills Log'!$F$6:$F$505,'Bills Log'!$A$6:$A$505,">="&DATE(Settings!$B$5,10,1),'Bills Log'!$A$6:$A$505,"<"&DATE(Settings!$B$5,11,1),'Bills Log'!$B$6:$B$505,Settings!$B$7,'Bills Log'!$C$6:$C$505,$A10) | L10: =SUMIFS('Bills Log'!$F$6:$F$505,'Bills Log'!$A$6:$A$505,">="&DATE(Settings!$B$5,11,1),'Bills Log'!$A$6:$A$505,"<"&DATE(Settings!$B$5,12,1),'Bills Log'!$B$6:$B$505,Settings!$B$7,'Bills Log'!$C$6:$C$505,$A10) | M10: =SUMIFS('Bills Log'!$F$6:$F$505,'Bills Log'!$A$6:$A$505,">="&DATE(Settings!$B$5,12,1),'Bills Log'!$A$6:$A$505,"<"&DATE(Settings!$B$5+1,1,1),'Bills Log'!$B$6:$B$505,Settings!$B$7,'Bills Log'!$C$6:$C$505,$A10) | N10: =SUM(B10:M10) | O10: =IFERROR(N10/12,0)
A11: Internet | B11: =SUMIFS('Bills Log'!$F$6:$F$505,'Bills Log'!$A$6:$A$505,">="&DATE(Settings!$B$5,1,1),'Bills Log'!$A$6:$A$505,"<"&DATE(Settings!$B$5,2,1),'Bills Log'!$B$6:$B$505,Settings!$B$7,'Bills Log'!$C$6:$C$505,$A11) | C11: =SUMIFS('Bills Log'!$F$6:$F$505,'Bills Log'!$A$6:$A$505,">="&DATE(Settings!$B$5,2,1),'Bills Log'!$A$6:$A$505,"<"&DATE(Settings!$B$5,3,1),'Bills Log'!$B$6:$B$505,Settings!$B$7,'Bills Log'!$C$6:$C$505,$A11) | D11: =SUMIFS('Bills Log'!$F$6:$F$505,'Bills Log'!$A$6:$A$505,">="&DATE(Settings!$B$5,3,1),'Bills Log'!$A$6:$A$505,"<"&DATE(Settings!$B$5,4,1),'Bills Log'!$B$6:$B$505,Settings!$B$7,'Bills Log'!$C$6:$C$505,$A11) | E11: =SUMIFS('Bills Log'!$F$6:$F$505,'Bills Log'!$A$6:$A$505,">="&DATE(Settings!$B$5,4,1),'Bills Log'!$A$6:$A$505,"<"&DATE(Settings!$B$5,5,1),'Bills Log'!$B$6:$B$505,Settings!$B$7,'Bills Log'!$C$6:$C$505,$A11) | F11: =SUMIFS('Bills Log'!$F$6:$F$505,'Bills Log'!$A$6:$A$505,">="&DATE(Settings!$B$5,5,1),'Bills Log'!$A$6:$A$505,"<"&DATE(Settings!$B$5,6,1),'Bills Log'!$B$6:$B$505,Settings!$B$7,'Bills Log'!$C$6:$C$505,$A11) | G11: =SUMIFS('Bills Log'!$F$6:$F$505,'Bills Log'!$A$6:$A$505,">="&DATE(Settings!$B$5,6,1),'Bills Log'!$A$6:$A$505,"<"&DATE(Settings!$B$5,7,1),'Bills Log'!$B$6:$B$505,Settings!$B$7,'Bills Log'!$C$6:$C$505,$A11) | H11: =SUMIFS('Bills Log'!$F$6:$F$505,'Bills Log'!$A$6:$A$505,">="&DATE(Settings!$B$5,7,1),'Bills Log'!$A$6:$A$505,"<"&DATE(Settings!$B$5,8,1),'Bills Log'!$B$6:$B$505,Settings!$B$7,'Bills Log'!$C$6:$C$505,$A11) | I11: =SUMIFS('Bills Log'!$F$6:$F$505,'Bills Log'!$A$6:$A$505,">="&DATE(Settings!$B$5,8,1),'Bills Log'!$A$6:$A$505,"<"&DATE(Settings!$B$5,9,1),'Bills Log'!$B$6:$B$505,Settings!$B$7,'Bills Log'!$C$6:$C$505,$A11) | J11: =SUMIFS('Bills Log'!$F$6:$F$505,'Bills Log'!$A$6:$A$505,">="&DATE(Settings!$B$5,9,1),'Bills Log'!$A$6:$A$505,"<"&DATE(Settings!$B$5,10,1),'Bills Log'!$B$6:$B$505,Settings!$B$7,'Bills Log'!$C$6:$C$505,$A11) | K11: =SUMIFS('Bills Log'!$F$6:$F$505,'Bills Log'!$A$6:$A$505,">="&DATE(Settings!$B$5,10,1),'Bills Log'!$A$6:$A$505,"<"&DATE(Settings!$B$5,11,1),'Bills Log'!$B$6:$B$505,Settings!$B$7,'Bills Log'!$C$6:$C$505,$A11) | L11: =SUMIFS('Bills Log'!$F$6:$F$505,'Bills Log'!$A$6:$A$505,">="&DATE(Settings!$B$5,11,1),'Bills Log'!$A$6:$A$505,"<"&DATE(Settings!$B$5,12,1),'Bills Log'!$B$6:$B$505,Settings!$B$7,'Bills Log'!$C$6:$C$505,$A11) | M11: =SUMIFS('Bills Log'!$F$6:$F$505,'Bills Log'!$A$6:$A$505,">="&DATE(Settings!$B$5,12,1),'Bills Log'!$A$6:$A$505,"<"&DATE(Settings!$B$5+1,1,1),'Bills Log'!$B$6:$B$505,Settings!$B$7,'Bills Log'!$C$6:$C$505,$A11) | N11: =SUM(B11:M11) | O11: =IFERROR(N11/12,0)
A12: Trash | B12: =SUMIFS('Bills Log'!$F$6:$F$505,'Bills Log'!$A$6:$A$505,">="&DATE(Settings!$B$5,1,1),'Bills Log'!$A$6:$A$505,"<"&DATE(Settings!$B$5,2,1),'Bills Log'!$B$6:$B$505,Settings!$B$7,'Bills Log'!$C$6:$C$505,$A12) | C12: =SUMIFS('Bills Log'!$F$6:$F$505,'Bills Log'!$A$6:$A$505,">="&DATE(Settings!$B$5,2,1),'Bills Log'!$A$6:$A$505,"<"&DATE(Settings!$B$5,3,1),'Bills Log'!$B$6:$B$505,Settings!$B$7,'Bills Log'!$C$6:$C$505,$A12) | D12: =SUMIFS('Bills Log'!$F$6:$F$505,'Bills Log'!$A$6:$A$505,">="&DATE(Settings!$B$5,3,1),'Bills Log'!$A$6:$A$505,"<"&DATE(Settings!$B$5,4,1),'Bills Log'!$B$6:$B$505,Settings!$B$7,'Bills Log'!$C$6:$C$505,$A12) | E12: =SUMIFS('Bills Log'!$F$6:$F$505,'Bills Log'!$A$6:$A$505,">="&DATE(Settings!$B$5,4,1),'Bills Log'!$A$6:$A$505,"<"&DATE(Settings!$B$5,5,1),'Bills Log'!$B$6:$B$505,Settings!$B$7,'Bills Log'!$C$6:$C$505,$A12) | F12: =SUMIFS('Bills Log'!$F$6:$F$505,'Bills Log'!$A$6:$A$505,">="&DATE(Settings!$B$5,5,1),'Bills Log'!$A$6:$A$505,"<"&DATE(Settings!$B$5,6,1),'Bills Log'!$B$6:$B$505,Settings!$B$7,'Bills Log'!$C$6:$C$505,$A12) | G12: =SUMIFS('Bills Log'!$F$6:$F$505,'Bills Log'!$A$6:$A$505,">="&DATE(Settings!$B$5,6,1),'Bills Log'!$A$6:$A$505,"<"&DATE(Settings!$B$5,7,1),'Bills Log'!$B$6:$B$505,Settings!$B$7,'Bills Log'!$C$6:$C$505,$A12) | H12: =SUMIFS('Bills Log'!$F$6:$F$505,'Bills Log'!$A$6:$A$505,">="&DATE(Settings!$B$5,7,1),'Bills Log'!$A$6:$A$505,"<"&DATE(Settings!$B$5,8,1),'Bills Log'!$B$6:$B$505,Settings!$B$7,'Bills Log'!$C$6:$C$505,$A12) | I12: =SUMIFS('Bills Log'!$F$6:$F$505,'Bills Log'!$A$6:$A$505,">="&DATE(Settings!$B$5,8,1),'Bills Log'!$A$6:$A$505,"<"&DATE(Settings!$B$5,9,1),'Bills Log'!$B$6:$B$505,Settings!$B$7,'Bills Log'!$C$6:$C$505,$A12) | J12: =SUMIFS('Bills Log'!$F$6:$F$505,'Bills Log'!$A$6:$A$505,">="&DATE(Settings!$B$5,9,1),'Bills Log'!$A$6:$A$505,"<"&DATE(Settings!$B$5,10,1),'Bills Log'!$B$6:$B$505,Settings!$B$7,'Bills Log'!$C$6:$C$505,$A12) | K12: =SUMIFS('Bills Log'!$F$6:$F$505,'Bills Log'!$A$6:$A$505,">="&DATE(Settings!$B$5,10,1),'Bills Log'!$A$6:$A$505,"<"&DATE(Settings!$B$5,11,1),'Bills Log'!$B$6:$B$505,Settings!$B$7,'Bills Log'!$C$6:$C$505,$A12) | L12: =SUMIFS('Bills Log'!$F$6:$F$505,'Bills Log'!$A$6:$A$505,">="&DATE(Settings!$B$5,11,1),'Bills Log'!$A$6:$A$505,"<"&DATE(Settings!$B$5,12,1),'Bills Log'!$B$6:$B$505,Settings!$B$7,'Bills Log'!$C$6:$C$505,$A12) | M12: =SUMIFS('Bills Log'!$F$6:$F$505,'Bills Log'!$A$6:$A$505,">="&DATE(Settings!$B$5,12,1),'Bills Log'!$A$6:$A$505,"<"&DATE(Settings!$B$5+1,1,1),'Bills Log'!$B$6:$B$505,Settings!$B$7,'Bills Log'!$C$6:$C$505,$A12) | N12: =SUM(B12:M12) | O12: =IFERROR(N12/12,0)
A13: Propane | B13: =SUMIFS('Bills Log'!$F$6:$F$505,'Bills Log'!$A$6:$A$505,">="&DATE(Settings!$B$5,1,1),'Bills Log'!$A$6:$A$505,"<"&DATE(Settings!$B$5,2,1),'Bills Log'!$B$6:$B$505,Settings!$B$7,'Bills Log'!$C$6:$C$505,$A13) | C13: =SUMIFS('Bills Log'!$F$6:$F$505,'Bills Log'!$A$6:$A$505,">="&DATE(Settings!$B$5,2,1),'Bills Log'!$A$6:$A$505,"<"&DATE(Settings!$B$5,3,1),'Bills Log'!$B$6:$B$505,Settings!$B$7,'Bills Log'!$C$6:$C$505,$A13) | D13: =SUMIFS('Bills Log'!$F$6:$F$505,'Bills Log'!$A$6:$A$505,">="&DATE(Settings!$B$5,3,1),'Bills Log'!$A$6:$A$505,"<"&DATE(Settings!$B$5,4,1),'Bills Log'!$B$6:$B$505,Settings!$B$7,'Bills Log'!$C$6:$C$505,$A13) | E13: =SUMIFS('Bills Log'!$F$6:$F$505,'Bills Log'!$A$6:$A$505,">="&DATE(Settings!$B$5,4,1),'Bills Log'!$A$6:$A$505,"<"&DATE(Settings!$B$5,5,1),'Bills Log'!$B$6:$B$505,Settings!$B$7,'Bills Log'!$C$6:$C$505,$A13) | F13: =SUMIFS('Bills Log'!$F$6:$F$505,'Bills Log'!$A$6:$A$505,">="&DATE(Settings!$B$5,5,1),'Bills Log'!$A$6:$A$505,"<"&DATE(Settings!$B$5,6,1),'Bills Log'!$B$6:$B$505,Settings!$B$7,'Bills Log'!$C$6:$C$505,$A13) | G13: =SUMIFS('Bills Log'!$F$6:$F$505,'Bills Log'!$A$6:$A$505,">="&DATE(Settings!$B$5,6,1),'Bills Log'!$A$6:$A$505,"<"&DATE(Settings!$B$5,7,1),'Bills Log'!$B$6:$B$505,Settings!$B$7,'Bills Log'!$C$6:$C$505,$A13) | H13: =SUMIFS('Bills Log'!$F$6:$F$505,'Bills Log'!$A$6:$A$505,">="&DATE(Settings!$B$5,7,1),'Bills Log'!$A$6:$A$505,"<"&DATE(Settings!$B$5,8,1),'Bills Log'!$B$6:$B$505,Settings!$B$7,'Bills Log'!$C$6:$C$505,$A13) | I13: =SUMIFS('Bills Log'!$F$6:$F$505,'Bills Log'!$A$6:$A$505,">="&DATE(Settings!$B$5,8,1),'Bills Log'!$A$6:$A$505,"<"&DATE(Settings!$B$5,9,1),'Bills Log'!$B$6:$B$505,Settings!$B$7,'Bills Log'!$C$6:$C$505,$A13) | J13: =SUMIFS('Bills Log'!$F$6:$F$505,'Bills Log'!$A$6:$A$505,">="&DATE(Settings!$B$5,9,1),'Bills Log'!$A$6:$A$505,"<"&DATE(Settings!$B$5,10,1),'Bills Log'!$B$6:$B$505,Settings!$B$7,'Bills Log'!$C$6:$C$505,$A13) | K13: =SUMIFS('Bills Log'!$F$6:$F$505,'Bills Log'!$A$6:$A$505,">="&DATE(Settings!$B$5,10,1),'Bills Log'!$A$6:$A$505,"<"&DATE(Settings!$B$5,11,1),'Bills Log'!$B$6:$B$505,Settings!$B$7,'Bills Log'!$C$6:$C$505,$A13) | L13: =SUMIFS('Bills Log'!$F$6:$F$505,'Bills Log'!$A$6:$A$505,">="&DATE(Settings!$B$5,11,1),'Bills Log'!$A$6:$A$505,"<"&DATE(Settings!$B$5,12,1),'Bills Log'!$B$6:$B$505,Settings!$B$7,'Bills Log'!$C$6:$C$505,$A13) | M13: =SUMIFS('Bills Log'!$F$6:$F$505,'Bills Log'!$A$6:$A$505,">="&DATE(Settings!$B$5,12,1),'Bills Log'!$A$6:$A$505,"<"&DATE(Settings!$B$5+1,1,1),'Bills Log'!$B$6:$B$505,Settings!$B$7,'Bills Log'!$C$6:$C$505,$A13) | N13: =SUM(B13:M13) | O13: =IFERROR(N13/12,0)
A14: TOTAL | B14: =SUM(B8:B13) | C14: =SUM(C8:C13) | D14: =SUM(D8:D13) | E14: =SUM(E8:E13) | F14: =SUM(F8:F13) | G14: =SUM(G8:G13) | H14: =SUM(H8:H13) | I14: =SUM(I8:I13) | ... O14: =SUM(O8:O13)
A28: ="Property: "&Settings!$B$8
A29: Service | B29: Jan | C29: Feb | D29: Mar | E29: Apr | F29: May | G29: Jun | H29: Jul | I29: Aug | J29: Sep | K29: Oct | L29: Nov | M29: Dec | N29: Total | O29: Avg
A30: Electric | B30: =SUMIFS('Bills Log'!$F$6:$F$505,'Bills Log'!$A$6:$A$505,">="&DATE(Settings!$B$5,1,1),'Bills Log'!$A$6:$A$505,"<"&DATE(Settings!$B$5,2,1),'Bills Log'!$B$6:$B$505,Settings!$B$8,'Bills Log'!$C$6:$C$505,$A30) | C30: =SUMIFS('Bills Log'!$F$6:$F$505,'Bills Log'!$A$6:$A$505,">="&DATE(Settings!$B$5,2,1),'Bills Log'!$A$6:$A$505,"<"&DATE(Settings!$B$5,3,1),'Bills Log'!$B$6:$B$505,Settings!$B$8,'Bills Log'!$C$6:$C$505,$A30) | D30: =SUMIFS('Bills Log'!$F$6:$F$505,'Bills Log'!$A$6:$A$505,">="&DATE(Settings!$B$5,3,1),'Bills Log'!$A$6:$A$505,"<"&DATE(Settings!$B$5,4,1),'Bills Log'!$B$6:$B$505,Settings!$B$8,'Bills Log'!$C$6:$C$505,$A30) | E30: =SUMIFS('Bills Log'!$F$6:$F$505,'Bills Log'!$A$6:$A$505,">="&DATE(Settings!$B$5,4,1),'Bills Log'!$A$6:$A$505,"<"&DATE(Settings!$B$5,5,1),'Bills Log'!$B$6:$B$505,Settings!$B$8,'Bills Log'!$C$6:$C$505,$A30) | F30: =SUMIFS('Bills Log'!$F$6:$F$505,'Bills Log'!$A$6:$A$505,">="&DATE(Settings!$B$5,5,1),'Bills Log'!$A$6:$A$505,"<"&DATE(Settings!$B$5,6,1),'Bills Log'!$B$6:$B$505,Settings!$B$8,'Bills Log'!$C$6:$C$505,$A30) | G30: =SUMIFS('Bills Log'!$F$6:$F$505,'Bills Log'!$A$6:$A$505,">="&DATE(Settings!$B$5,6,1),'Bills Log'!$A$6:$A$505,"<"&DATE(Settings!$B$5,7,1),'Bills Log'!$B$6:$B$505,Settings!$B$8,'Bills Log'!$C$6:$C$505,$A30) | H30: =SUMIFS('Bills Log'!$F$6:$F$505,'Bills Log'!$A$6:$A$505,">="&DATE(Settings!$B$5,7,1),'Bills Log'!$A$6:$A$505,"<"&DATE(Settings!$B$5,8,1),'Bills Log'!$B$6:$B$505,Settings!$B$8,'Bills Log'!$C$6:$C$505,$A30) | I30: =SUMIFS('Bills Log'!$F$6:$F$505,'Bills Log'!$A$6:$A$505,">="&DATE(Settings!$B$5,8,1),'Bills Log'!$A$6:$A$505,"<"&DATE(Settings!$B$5,9,1),'Bills Log'!$B$6:$B$505,Settings!$B$8,'Bills Log'!$C$6:$C$505,$A30) | J30: =SUMIFS('Bills Log'!$F$6:$F$505,'Bills Log'!$A$6:$A$505,">="&DATE(Settings!$B$5,9,1),'Bills Log'!$A$6:$A$505,"<"&DATE(Settings!$B$5,10,1),'Bills Log'!$B$6:$B$505,Settings!$B$8,'Bills Log'!$C$6:$C$505,$A30) | K30: =SUMIFS('Bills Log'!$F$6:$F$505,'Bills Log'!$A$6:$A$505,">="&DATE(Settings!$B$5,10,1),'Bills Log'!$A$6:$A$505,"<"&DATE(Settings!$B$5,11,1),'Bills Log'!$B$6:$B$505,Settings!$B$8,'Bills Log'!$C$6:$C$505,$A30) | L30: =SUMIFS('Bills Log'!$F$6:$F$505,'Bills Log'!$A$6:$A$505,">="&DATE(Settings!$B$5,11,1),'Bills Log'!$A$6:$A$505,"<"&DATE(Settings!$B$5,12,1),'Bills Log'!$B$6:$B$505,Settings!$B$8,'Bills Log'!$C$6:$C$505,$A30) | M30: =SUMIFS('Bills Log'!$F$6:$F$505,'Bills Log'!$A$6:$A$505,">="&DATE(Settings!$B$5,12,1),'Bills Log'!$A$6:$A$505,"<"&DATE(Settings!$B$5+1,1,1),'Bills Log'!$B$6:$B$505,Settings!$B$8,'Bills Log'!$C$6:$C$505,$A30) | N30: =SUM(B30:M30) | O30: =IFERROR(N30/12,0)
A31: Gas | B31: =SUMIFS('Bills Log'!$F$6:$F$505,'Bills Log'!$A$6:$A$505,">="&DATE(Settings!$B$5,1,1),'Bills Log'!$A$6:$A$505,"<"&DATE(Settings!$B$5,2,1),'Bills Log'!$B$6:$B$505,Settings!$B$8,'Bills Log'!$C$6:$C$505,$A31) | C31: =SUMIFS('Bills Log'!$F$6:$F$505,'Bills Log'!$A$6:$A$505,">="&DATE(Settings!$B$5,2,1),'Bills Log'!$A$6:$A$505,"<"&DATE(Settings!$B$5,3,1),'Bills Log'!$B$6:$B$505,Settings!$B$8,'Bills Log'!$C$6:$C$505,$A31) | D31: =SUMIFS('Bills Log'!$F$6:$F$505,'Bills Log'!$A$6:$A$505,">="&DATE(Settings!$B$5,3,1),'Bills Log'!$A$6:$A$505,"<"&DATE(Settings!$B$5,4,1),'Bills Log'!$B$6:$B$505,Settings!$B$8,'Bills Log'!$C$6:$C$505,$A31) | E31: =SUMIFS('Bills Log'!$F$6:$F$505,'Bills Log'!$A$6:$A$505,">="&DATE(Settings!$B$5,4,1),'Bills Log'!$A$6:$A$505,"<"&DATE(Settings!$B$5,5,1),'Bills Log'!$B$6:$B$505,Settings!$B$8,'Bills Log'!$C$6:$C$505,$A31) | F31: =SUMIFS('Bills Log'!$F$6:$F$505,'Bills Log'!$A$6:$A$505,">="&DATE(Settings!$B$5,5,1),'Bills Log'!$A$6:$A$505,"<"&DATE(Settings!$B$5,6,1),'Bills Log'!$B$6:$B$505,Settings!$B$8,'Bills Log'!$C$6:$C$505,$A31) | G31: =SUMIFS('Bills Log'!$F$6:$F$505,'Bills Log'!$A$6:$A$505,">="&DATE(Settings!$B$5,6,1),'Bills Log'!$A$6:$A$505,"<"&DATE(Settings!$B$5,7,1),'Bills Log'!$B$6:$B$505,Settings!$B$8,'Bills Log'!$C$6:$C$505,$A31) | H31: =SUMIFS('Bills Log'!$F$6:$F$505,'Bills Log'!$A$6:$A$505,">="&DATE(Settings!$B$5,7,1),'Bills Log'!$A$6:$A$505,"<"&DATE(Settings!$B$5,8,1),'Bills Log'!$B$6:$B$505,Settings!$B$8,'Bills Log'!$C$6:$C$505,$A31) | I31: =SUMIFS('Bills Log'!$F$6:$F$505,'Bills Log'!$A$6:$A$505,">="&DATE(Settings!$B$5,8,1),'Bills Log'!$A$6:$A$505,"<"&DATE(Settings!$B$5,9,1),'Bills Log'!$B$6:$B$505,Settings!$B$8,'Bills Log'!$C$6:$C$505,$A31) | J31: =SUMIFS('Bills Log'!$F$6:$F$505,'Bills Log'!$A$6:$A$505,">="&DATE(Settings!$B$5,9,1),'Bills Log'!$A$6:$A$505,"<"&DATE(Settings!$B$5,10,1),'Bills Log'!$B$6:$B$505,Settings!$B$8,'Bills Log'!$C$6:$C$505,$A31) | K31: =SUMIFS('Bills Log'!$F$6:$F$505,'Bills Log'!$A$6:$A$505,">="&DATE(Settings!$B$5,10,1),'Bills Log'!$A$6:$A$505,"<"&DATE(Settings!$B$5,11,1),'Bills Log'!$B$6:$B$505,Settings!$B$8,'Bills Log'!$C$6:$C$505,$A31) | L31: =SUMIFS('Bills Log'!$F$6:$F$505,'Bills Log'!$A$6:$A$505,">="&DATE(Settings!$B$5,11,1),'Bills Log'!$A$6:$A$505,"<"&DATE(Settings!$B$5,12,1),'Bills Log'!$B$6:$B$505,Settings!$B$8,'Bills Log'!$C$6:$C$505,$A31) | M31: =SUMIFS('Bills Log'!$F$6:$F$505,'Bills Log'!$A$6:$A$505,">="&DATE(Settings!$B$5,12,1),'Bills Log'!$A$6:$A$505,"<"&DATE(Settings!$B$5+1,1,1),'Bills Log'!$B$6:$B$505,Settings!$B$8,'Bills Log'!$C$6:$C$505,$A31) | N31: =SUM(B31:M31) | O31: =IFERROR(N31/12,0)
A32: Water | B32: =SUMIFS('Bills Log'!$F$6:$F$505,'Bills Log'!$A$6:$A$505,">="&DATE(Settings!$B$5,1,1),'Bills Log'!$A$6:$A$505,"<"&DATE(Settings!$B$5,2,1),'Bills Log'!$B$6:$B$505,Settings!$B$8,'Bills Log'!$C$6:$C$505,$A32) | C32: =SUMIFS('Bills Log'!$F$6:$F$505,'Bills Log'!$A$6:$A$505,">="&DATE(Settings!$B$5,2,1),'Bills Log'!$A$6:$A$505,"<"&DATE(Settings!$B$5,3,1),'Bills Log'!$B$6:$B$505,Settings!$B$8,'Bills Log'!$C$6:$C$505,$A32) | D32: =SUMIFS('Bills Log'!$F$6:$F$505,'Bills Log'!$A$6:$A$505,">="&DATE(Settings!$B$5,3,1),'Bills Log'!$A$6:$A$505,"<"&DATE(Settings!$B$5,4,1),'Bills Log'!$B$6:$B$505,Settings!$B$8,'Bills Log'!$C$6:$C$505,$A32) | E32: =SUMIFS('Bills Log'!$F$6:$F$505,'Bills Log'!$A$6:$A$505,">="&DATE(Settings!$B$5,4,1),'Bills Log'!$A$6:$A$505,"<"&DATE(Settings!$B$5,5,1),'Bills Log'!$B$6:$B$505,Settings!$B$8,'Bills Log'!$C$6:$C$505,$A32) | F32: =SUMIFS('Bills Log'!$F$6:$F$505,'Bills Log'!$A$6:$A$505,">="&DATE(Settings!$B$5,5,1),'Bills Log'!$A$6:$A$505,"<"&DATE(Settings!$B$5,6,1),'Bills Log'!$B$6:$B$505,Settings!$B$8,'Bills Log'!$C$6:$C$505,$A32) | G32: =SUMIFS('Bills Log'!$F$6:$F$505,'Bills Log'!$A$6:$A$505,">="&DATE(Settings!$B$5,6,1),'Bills Log'!$A$6:$A$505,"<"&DATE(Settings!$B$5,7,1),'Bills Log'!$B$6:$B$505,Settings!$B$8,'Bills Log'!$C$6:$C$505,$A32) | H32: =SUMIFS('Bills Log'!$F$6:$F$505,'Bills Log'!$A$6:$A$505,">="&DATE(Settings!$B$5,7,1),'Bills Log'!$A$6:$A$505,"<"&DATE(Settings!$B$5,8,1),'Bills Log'!$B$6:$B$505,Settings!$B$8,'Bills Log'!$C$6:$C$505,$A32) | I32: =SUMIFS('Bills Log'!$F$6:$F$505,'Bills Log'!$A$6:$A$505,">="&DATE(Settings!$B$5,8,1),'Bills Log'!$A$6:$A$505,"<"&DATE(Settings!$B$5,9,1),'Bills Log'!$B$6:$B$505,Settings!$B$8,'Bills Log'!$C$6:$C$505,$A32) | J32: =SUMIFS('Bills Log'!$F$6:$F$505,'Bills Log'!$A$6:$A$505,">="&DATE(Settings!$B$5,9,1),'Bills Log'!$A$6:$A$505,"<"&DATE(Settings!$B$5,10,1),'Bills Log'!$B$6:$B$505,Settings!$B$8,'Bills Log'!$C$6:$C$505,$A32) | K32: =SUMIFS('Bills Log'!$F$6:$F$505,'Bills Log'!$A$6:$A$505,">="&DATE(Settings!$B$5,10,1),'Bills Log'!$A$6:$A$505,"<"&DATE(Settings!$B$5,11,1),'Bills Log'!$B$6:$B$505,Settings!$B$8,'Bills Log'!$C$6:$C$505,$A32) | L32: =SUMIFS('Bills Log'!$F$6:$F$505,'Bills Log'!$A$6:$A$505,">="&DATE(Settings!$B$5,11,1),'Bills Log'!$A$6:$A$505,"<"&DATE(Settings!$B$5,12,1),'Bills Log'!$B$6:$B$505,Settings!$B$8,'Bills Log'!$C$6:$C$505,$A32) | M32: =SUMIFS('Bills Log'!$F$6:$F$505,'Bills Log'!$A$6:$A$505,">="&DATE(Settings!$B$5,12,1),'Bills Log'!$A$6:$A$505,"<"&DATE(Settings!$B$5+1,1,1),'Bills Log'!$B$6:$B$505,Settings!$B$8,'Bills Log'!$C$6:$C$505,$A32) | N32: =SUM(B32:M32) | O32: =IFERROR(N32/12,0)
A33: Internet | B33: =SUMIFS('Bills Log'!$F$6:$F$505,'Bills Log'!$A$6:$A$505,">="&DATE(Settings!$B$5,1,1),'Bills Log'!$A$6:$A$505,"<"&DATE(Settings!$B$5,2,1),'Bills Log'!$B$6:$B$505,Settings!$B$8,'Bills Log'!$C$6:$C$505,$A33) | C33: =SUMIFS('Bills Log'!$F$6:$F$505,'Bills Log'!$A$6:$A$505,">="&DATE(Settings!$B$5,2,1),'Bills Log'!$A$6:$A$505,"<"&DATE(Settings!$B$5,3,1),'Bills Log'!$B$6:$B$505,Settings!$B$8,'Bills Log'!$C$6:$C$505,$A33) | D33: =SUMIFS('Bills Log'!$F$6:$F$505,'Bills Log'!$A$6:$A$505,">="&DATE(Settings!$B$5,3,1),'Bills Log'!$A$6:$A$505,"<"&DATE(Settings!$B$5,4,1),'Bills Log'!$B$6:$B$505,Settings!$B$8,'Bills Log'!$C$6:$C$505,$A33) | E33: =SUMIFS('Bills Log'!$F$6:$F$505,'Bills Log'!$A$6:$A$505,">="&DATE(Settings!$B$5,4,1),'Bills Log'!$A$6:$A$505,"<"&DATE(Settings!$B$5,5,1),'Bills Log'!$B$6:$B$505,Settings!$B$8,'Bills Log'!$C$6:$C$505,$A33) | F33: =SUMIFS('Bills Log'!$F$6:$F$505,'Bills Log'!$A$6:$A$505,">="&DATE(Settings!$B$5,5,1),'Bills Log'!$A$6:$A$505,"<"&DATE(Settings!$B$5,6,1),'Bills Log'!$B$6:$B$505,Settings!$B$8,'Bills Log'!$C$6:$C$505,$A33) | G33: =SUMIFS('Bills Log'!$F$6:$F$505,'Bills Log'!$A$6:$A$505,">="&DATE(Settings!$B$5,6,1),'Bills Log'!$A$6:$A$505,"<"&DATE(Settings!$B$5,7,1),'Bills Log'!$B$6:$B$505,Settings!$B$8,'Bills Log'!$C$6:$C$505,$A33) | H33: =SUMIFS('Bills Log'!$F$6:$F$505,'Bills Log'!$A$6:$A$505,">="&DATE(Settings!$B$5,7,1),'Bills Log'!$A$6:$A$505,"<"&DATE(Settings!$B$5,8,1),'Bills Log'!$B$6:$B$505,Settings!$B$8,'Bills Log'!$C$6:$C$505,$A33) | I33: =SUMIFS('Bills Log'!$F$6:$F$505,'Bills Log'!$A$6:$A$505,">="&DATE(Settings!$B$5,8,1),'Bills Log'!$A$6:$A$505,"<"&DATE(Settings!$B$5,9,1),'Bills Log'!$B$6:$B$505,Settings!$B$8,'Bills Log'!$C$6:$C$505,$A33) | J33: =SUMIFS('Bills Log'!$F$6:$F$505,'Bills Log'!$A$6:$A$505,">="&DATE(Settings!$B$5,9,1),'Bills Log'!$A$6:$A$505,"<"&DATE(Settings!$B$5,10,1),'Bills Log'!$B$6:$B$505,Settings!$B$8,'Bills Log'!$C$6:$C$505,$A33) | K33: =SUMIFS('Bills Log'!$F$6:$F$505,'Bills Log'!$A$6:$A$505,">="&DATE(Settings!$B$5,10,1),'Bills Log'!$A$6:$A$505,"<"&DATE(Settings!$B$5,11,1),'Bills Log'!$B$6:$B$505,Settings!$B$8,'Bills Log'!$C$6:$C$505,$A33) | L33: =SUMIFS('Bills Log'!$F$6:$F$505,'Bills Log'!$A$6:$A$505,">="&DATE(Settings!$B$5,11,1),'Bills Log'!$A$6:$A$505,"<"&DATE(Settings!$B$5,12,1),'Bills Log'!$B$6:$B$505,Settings!$B$8,'Bills Log'!$C$6:$C$505,$A33) | M33: =SUMIFS('Bills Log'!$F$6:$F$505,'Bills Log'!$A$6:$A$505,">="&DATE(Settings!$B$5,12,1),'Bills Log'!$A$6:$A$505,"<"&DATE(Settings!$B$5+1,1,1),'Bills Log'!$B$6:$B$505,Settings!$B$8,'Bills Log'!$C$6:$C$505,$A33) | N33: =SUM(B33:M33) | O33: =IFERROR(N33/12,0)
A34: Trash | B34: =SUMIFS('Bills Log'!$F$6:$F$505,'Bills Log'!$A$6:$A$505,">="&DATE(Settings!$B$5,1,1),'Bills Log'!$A$6:$A$505,"<"&DATE(Settings!$B$5,2,1),'Bills Log'!$B$6:$B$505,Settings!$B$8,'Bills Log'!$C$6:$C$505,$A34) | C34: =SUMIFS('Bills Log'!$F$6:$F$505,'Bills Log'!$A$6:$A$505,">="&DATE(Settings!$B$5,2,1),'Bills Log'!$A$6:$A$505,"<"&DATE(Settings!$B$5,3,1),'Bills Log'!$B$6:$B$505,Settings!$B$8,'Bills Log'!$C$6:$C$505,$A34) | D34: =SUMIFS('Bills Log'!$F$6:$F$505,'Bills Log'!$A$6:$A$505,">="&DATE(Settings!$B$5,3,1),'Bills Log'!$A$6:$A$505,"<"&DATE(Settings!$B$5,4,1),'Bills Log'!$B$6:$B$505,Settings!$B$8,'Bills Log'!$C$6:$C$505,$A34) | E34: =SUMIFS('Bills Log'!$F$6:$F$505,'Bills Log'!$A$6:$A$505,">="&DATE(Settings!$B$5,4,1),'Bills Log'!$A$6:$A$505,"<"&DATE(Settings!$B$5,5,1),'Bills Log'!$B$6:$B$505,Settings!$B$8,'Bills Log'!$C$6:$C$505,$A34) | F34: =SUMIFS('Bills Log'!$F$6:$F$505,'Bills Log'!$A$6:$A$505,">="&DATE(Settings!$B$5,5,1),'Bills Log'!$A$6:$A$505,"<"&DATE(Settings!$B$5,6,1),'Bills Log'!$B$6:$B$505,Settings!$B$8,'Bills Log'!$C$6:$C$505,$A34) | G34: =SUMIFS('Bills Log'!$F$6:$F$505,'Bills Log'!$A$6:$A$505,">="&DATE(Settings!$B$5,6,1),'Bills Log'!$A$6:$A$505,"<"&DATE(Settings!$B$5,7,1),'Bills Log'!$B$6:$B$505,Settings!$B$8,'Bills Log'!$C$6:$C$505,$A34) | H34: =SUMIFS('Bills Log'!$F$6:$F$505,'Bills Log'!$A$6:$A$505,">="&DATE(Settings!$B$5,7,1),'Bills Log'!$A$6:$A$505,"<"&DATE(Settings!$B$5,8,1),'Bills Log'!$B$6:$B$505,Settings!$B$8,'Bills Log'!$C$6:$C$505,$A34) | I34: =SUMIFS('Bills Log'!$F$6:$F$505,'Bills Log'!$A$6:$A$505,">="&DATE(Settings!$B$5,8,1),'Bills Log'!$A$6:$A$505,"<"&DATE(Settings!$B$5,9,1),'Bills Log'!$B$6:$B$505,Settings!$B$8,'Bills Log'!$C$6:$C$505,$A34) | J34: =SUMIFS('Bills Log'!$F$6:$F$505,'Bills Log'!$A$6:$A$505,">="&DATE(Settings!$B$5,9,1),'Bills Log'!$A$6:$A$505,"<"&DATE(Settings!$B$5,10,1),'Bills Log'!$B$6:$B$505,Settings!$B$8,'Bills Log'!$C$6:$C$505,$A34) | K34: =SUMIFS('Bills Log'!$F$6:$F$505,'Bills Log'!$A$6:$A$505,">="&DATE(Settings!$B$5,10,1),'Bills Log'!$A$6:$A$505,"<"&DATE(Settings!$B$5,11,1),'Bills Log'!$B$6:$B$505,Settings!$B$8,'Bills Log'!$C$6:$C$505,$A34) | L34: =SUMIFS('Bills Log'!$F$6:$F$505,'Bills Log'!$A$6:$A$505,">="&DATE(Settings!$B$5,11,1),'Bills Log'!$A$6:$A$505,"<"&DATE(Settings!$B$5,12,1),'Bills Log'!$B$6:$B$505,Settings!$B$8,'Bills Log'!$C$6:$C$505,$A34) | M34: =SUMIFS('Bills Log'!$F$6:$F$505,'Bills Log'!$A$6:$A$505,">="&DATE(Settings!$B$5,12,1),'Bills Log'!$A$6:$A$505,"<"&DATE(Settings!$B$5+1,1,1),'Bills Log'!$B$6:$B$505,Settings!$B$8,'Bills Log'!$C$6:$C$505,$A34) | N34: =SUM(B34:M34) | O34: =IFERROR(N34/12,0)
A35: Propane | B35: =SUMIFS('Bills Log'!$F$6:$F$505,'Bills Log'!$A$6:$A$505,">="&DATE(Settings!$B$5,1,1),'Bills Log'!$A$6:$A$505,"<"&DATE(Settings!$B$5,2,1),'Bills Log'!$B$6:$B$505,Settings!$B$8,'Bills Log'!$C$6:$C$505,$A35) | C35: =SUMIFS('Bills Log'!$F$6:$F$505,'Bills Log'!$A$6:$A$505,">="&DATE(Settings!$B$5,2,1),'Bills Log'!$A$6:$A$505,"<"&DATE(Settings!$B$5,3,1),'Bills Log'!$B$6:$B$505,Settings!$B$8,'Bills Log'!$C$6:$C$505,$A35) | D35: =SUMIFS('Bills Log'!$F$6:$F$505,'Bills Log'!$A$6:$A$505,">="&DATE(Settings!$B$5,3,1),'Bills Log'!$A$6:$A$505,"<"&DATE(Settings!$B$5,4,1),'Bills Log'!$B$6:$B$505,Settings!$B$8,'Bills Log'!$C$6:$C$505,$A35) | E35: =SUMIFS('Bills Log'!$F$6:$F$505,'Bills Log'!$A$6:$A$505,">="&DATE(Settings!$B$5,4,1),'Bills Log'!$A$6:$A$505,"<"&DATE(Settings!$B$5,5,1),'Bills Log'!$B$6:$B$505,Settings!$B$8,'Bills Log'!$C$6:$C$505,$A35) | F35: =SUMIFS('Bills Log'!$F$6:$F$505,'Bills Log'!$A$6:$A$505,">="&DATE(Settings!$B$5,5,1),'Bills Log'!$A$6:$A$505,"<"&DATE(Settings!$B$5,6,1),'Bills Log'!$B$6:$B$505,Settings!$B$8,'Bills Log'!$C$6:$C$505,$A35) | G35: =SUMIFS('Bills Log'!$F$6:$F$505,'Bills Log'!$A$6:$A$505,">="&DATE(Settings!$B$5,6,1),'Bills Log'!$A$6:$A$505,"<"&DATE(Settings!$B$5,7,1),'Bills Log'!$B$6:$B$505,Settings!$B$8,'Bills Log'!$C$6:$C$505,$A35) | H35: =SUMIFS('Bills Log'!$F$6:$F$505,'Bills Log'!$A$6:$A$505,">="&DATE(Settings!$B$5,7,1),'Bills Log'!$A$6:$A$505,"<"&DATE(Settings!$B$5,8,1),'Bills Log'!$B$6:$B$505,Settings!$B$8,'Bills Log'!$C$6:$C$505,$A35) | I35: =SUMIFS('Bills Log'!$F$6:$F$505,'Bills Log'!$A$6:$A$505,">="&DATE(Settings!$B$5,8,1),'Bills Log'!$A$6:$A$505,"<"&DATE(Settings!$B$5,9,1),'Bills Log'!$B$6:$B$505,Settings!$B$8,'Bills Log'!$C$6:$C$505,$A35) | J35: =SUMIFS('Bills Log'!$F$6:$F$505,'Bills Log'!$A$6:$A$505,">="&DATE(Settings!$B$5,9,1),'Bills Log'!$A$6:$A$505,"<"&DATE(Settings!$B$5,10,1),'Bills Log'!$B$6:$B$505,Settings!$B$8,'Bills Log'!$C$6:$C$505,$A35) | K35: =SUMIFS('Bills Log'!$F$6:$F$505,'Bills Log'!$A$6:$A$505,">="&DATE(Settings!$B$5,10,1),'Bills Log'!$A$6:$A$505,"<"&DATE(Settings!$B$5,11,1),'Bills Log'!$B$6:$B$505,Settings!$B$8,'Bills Log'!$C$6:$C$505,$A35) | L35: =SUMIFS('Bills Log'!$F$6:$F$505,'Bills Log'!$A$6:$A$505,">="&DATE(Settings!$B$5,11,1),'Bills Log'!$A$6:$A$505,"<"&DATE(Settings!$B$5,12,1),'Bills Log'!$B$6:$B$505,Settings!$B$8,'Bills Log'!$C$6:$C$505,$A35) | M35: =SUMIFS('Bills Log'!$F$6:$F$505,'Bills Log'!$A$6:$A$505,">="&DATE(Settings!$B$5,12,1),'Bills Log'!$A$6:$A$505,"<"&DATE(Settings!$B$5+1,1,1),'Bills Log'!$B$6:$B$505,Settings!$B$8,'Bills Log'!$C$6:$C$505,$A35) | N35: =SUM(B35:M35) | O35: =IFERROR(N35/12,0)
A36: TOTAL | B36: =SUM(B30:B35) | C36: =SUM(C30:C35) | D36: =SUM(D30:D35) | E36: =SUM(E30:E35) | F36: =SUM(F30:F35) | G36: =SUM(G30:G35) | H36: =SUM(H30:H35) | I36: =SUM(I30:I35) | ... O36: =SUM(O30:O35)
A50: ="Property: "&Settings!$B$9
A51: Service | B51: Jan | C51: Feb | D51: Mar | E51: Apr | F51: May | G51: Jun | H51: Jul | I51: Aug | J51: Sep | K51: Oct | L51: Nov | M51: Dec | N51: Total | O51: Avg
A52: Electric | B52: =SUMIFS('Bills Log'!$F$6:$F$505,'Bills Log'!$A$6:$A$505,">="&DATE(Settings!$B$5,1,1),'Bills Log'!$A$6:$A$505,"<"&DATE(Settings!$B$5,2,1),'Bills Log'!$B$6:$B$505,Settings!$B$9,'Bills Log'!$C$6:$C$505,$A52) | C52: =SUMIFS('Bills Log'!$F$6:$F$505,'Bills Log'!$A$6:$A$505,">="&DATE(Settings!$B$5,2,1),'Bills Log'!$A$6:$A$505,"<"&DATE(Settings!$B$5,3,1),'Bills Log'!$B$6:$B$505,Settings!$B$9,'Bills Log'!$C$6:$C$505,$A52) | D52: =SUMIFS('Bills Log'!$F$6:$F$505,'Bills Log'!$A$6:$A$505,">="&DATE(Settings!$B$5,3,1),'Bills Log'!$A$6:$A$505,"<"&DATE(Settings!$B$5,4,1),'Bills Log'!$B$6:$B$505,Settings!$B$9,'Bills Log'!$C$6:$C$505,$A52) | E52: =SUMIFS('Bills Log'!$F$6:$F$505,'Bills Log'!$A$6:$A$505,">="&DATE(Settings!$B$5,4,1),'Bills Log'!$A$6:$A$505,"<"&DATE(Settings!$B$5,5,1),'Bills Log'!$B$6:$B$505,Settings!$B$9,'Bills Log'!$C$6:$C$505,$A52) | F52: =SUMIFS('Bills Log'!$F$6:$F$505,'Bills Log'!$A$6:$A$505,">="&DATE(Settings!$B$5,5,1),'Bills Log'!$A$6:$A$505,"<"&DATE(Settings!$B$5,6,1),'Bills Log'!$B$6:$B$505,Settings!$B$9,'Bills Log'!$C$6:$C$505,$A52) | G52: =SUMIFS('Bills Log'!$F$6:$F$505,'Bills Log'!$A$6:$A$505,">="&DATE(Settings!$B$5,6,1),'Bills Log'!$A$6:$A$505,"<"&DATE(Settings!$B$5,7,1),'Bills Log'!$B$6:$B$505,Settings!$B$9,'Bills Log'!$C$6:$C$505,$A52) | H52: =SUMIFS('Bills Log'!$F$6:$F$505,'Bills Log'!$A$6:$A$505,">="&DATE(Settings!$B$5,7,1),'Bills Log'!$A$6:$A$505,"<"&DATE(Settings!$B$5,8,1),'Bills Log'!$B$6:$B$505,Settings!$B$9,'Bills Log'!$C$6:$C$505,$A52) | I52: =SUMIFS('Bills Log'!$F$6:$F$505,'Bills Log'!$A$6:$A$505,">="&DATE(Settings!$B$5,8,1),'Bills Log'!$A$6:$A$505,"<"&DATE(Settings!$B$5,9,1),'Bills Log'!$B$6:$B$505,Settings!$B$9,'Bills Log'!$C$6:$C$505,$A52) | J52: =SUMIFS('Bills Log'!$F$6:$F$505,'Bills Log'!$A$6:$A$505,">="&DATE(Settings!$B$5,9,1),'Bills Log'!$A$6:$A$505,"<"&DATE(Settings!$B$5,10,1),'Bills Log'!$B$6:$B$505,Settings!$B$9,'Bills Log'!$C$6:$C$505,$A52) | K52: =SUMIFS('Bills Log'!$F$6:$F$505,'Bills Log'!$A$6:$A$505,">="&DATE(Settings!$B$5,10,1),'Bills Log'!$A$6:$A$505,"<"&DATE(Settings!$B$5,11,1),'Bills Log'!$B$6:$B$505,Settings!$B$9,'Bills Log'!$C$6:$C$505,$A52) | L52: =SUMIFS('Bills Log'!$F$6:$F$505,'Bills Log'!$A$6:$A$505,">="&DATE(Settings!$B$5,11,1),'Bills Log'!$A$6:$A$505,"<"&DATE(Settings!$B$5,12,1),'Bills Log'!$B$6:$B$505,Settings!$B$9,'Bills Log'!$C$6:$C$505,$A52) | M52: =SUMIFS('Bills Log'!$F$6:$F$505,'Bills Log'!$A$6:$A$505,">="&DATE(Settings!$B$5,12,1),'Bills Log'!$A$6:$A$505,"<"&DATE(Settings!$B$5+1,1,1),'Bills Log'!$B$6:$B$505,Settings!$B$9,'Bills Log'!$C$6:$C$505,$A52) | N52: =SUM(B52:M52) | O52: =IFERROR(N52/12,0)
A53: Gas | B53: =SUMIFS('Bills Log'!$F$6:$F$505,'Bills Log'!$A$6:$A$505,">="&DATE(Settings!$B$5,1,1),'Bills Log'!$A$6:$A$505,"<"&DATE(Settings!$B$5,2,1),'Bills Log'!$B$6:$B$505,Settings!$B$9,'Bills Log'!$C$6:$C$505,$A53) | C53: =SUMIFS('Bills Log'!$F$6:$F$505,'Bills Log'!$A$6:$A$505,">="&DATE(Settings!$B$5,2,1),'Bills Log'!$A$6:$A$505,"<"&DATE(Settings!$B$5,3,1),'Bills Log'!$B$6:$B$505,Settings!$B$9,'Bills Log'!$C$6:$C$505,$A53) | D53: =SUMIFS('Bills Log'!$F$6:$F$505,'Bills Log'!$A$6:$A$505,">="&DATE(Settings!$B$5,3,1),'Bills Log'!$A$6:$A$505,"<"&DATE(Settings!$B$5,4,1),'Bills Log'!$B$6:$B$505,Settings!$B$9,'Bills Log'!$C$6:$C$505,$A53) | E53: =SUMIFS('Bills Log'!$F$6:$F$505,'Bills Log'!$A$6:$A$505,">="&DATE(Settings!$B$5,4,1),'Bills Log'!$A$6:$A$505,"<"&DATE(Settings!$B$5,5,1),'Bills Log'!$B$6:$B$505,Settings!$B$9,'Bills Log'!$C$6:$C$505,$A53) | F53: =SUMIFS('Bills Log'!$F$6:$F$505,'Bills Log'!$A$6:$A$505,">="&DATE(Settings!$B$5,5,1),'Bills Log'!$A$6:$A$505,"<"&DATE(Settings!$B$5,6,1),'Bills Log'!$B$6:$B$505,Settings!$B$9,'Bills Log'!$C$6:$C$505,$A53) | G53: =SUMIFS('Bills Log'!$F$6:$F$505,'Bills Log'!$A$6:$A$505,">="&DATE(Settings!$B$5,6,1),'Bills Log'!$A$6:$A$505,"<"&DATE(Settings!$B$5,7,1),'Bills Log'!$B$6:$B$505,Settings!$B$9,'Bills Log'!$C$6:$C$505,$A53) | H53: =SUMIFS('Bills Log'!$F$6:$F$505,'Bills Log'!$A$6:$A$505,">="&DATE(Settings!$B$5,7,1),'Bills Log'!$A$6:$A$505,"<"&DATE(Settings!$B$5,8,1),'Bills Log'!$B$6:$B$505,Settings!$B$9,'Bills Log'!$C$6:$C$505,$A53) | I53: =SUMIFS('Bills Log'!$F$6:$F$505,'Bills Log'!$A$6:$A$505,">="&DATE(Settings!$B$5,8,1),'Bills Log'!$A$6:$A$505,"<"&DATE(Settings!$B$5,9,1),'Bills Log'!$B$6:$B$505,Settings!$B$9,'Bills Log'!$C$6:$C$505,$A53) | J53: =SUMIFS('Bills Log'!$F$6:$F$505,'Bills Log'!$A$6:$A$505,">="&DATE(Settings!$B$5,9,1),'Bills Log'!$A$6:$A$505,"<"&DATE(Settings!$B$5,10,1),'Bills Log'!$B$6:$B$505,Settings!$B$9,'Bills Log'!$C$6:$C$505,$A53) | K53: =SUMIFS('Bills Log'!$F$6:$F$505,'Bills Log'!$A$6:$A$505,">="&DATE(Settings!$B$5,10,1),'Bills Log'!$A$6:$A$505,"<"&DATE(Settings!$B$5,11,1),'Bills Log'!$B$6:$B$505,Settings!$B$9,'Bills Log'!$C$6:$C$505,$A53) | L53: =SUMIFS('Bills Log'!$F$6:$F$505,'Bills Log'!$A$6:$A$505,">="&DATE(Settings!$B$5,11,1),'Bills Log'!$A$6:$A$505,"<"&DATE(Settings!$B$5,12,1),'Bills Log'!$B$6:$B$505,Settings!$B$9,'Bills Log'!$C$6:$C$505,$A53) | M53: =SUMIFS('Bills Log'!$F$6:$F$505,'Bills Log'!$A$6:$A$505,">="&DATE(Settings!$B$5,12,1),'Bills Log'!$A$6:$A$505,"<"&DATE(Settings!$B$5+1,1,1),'Bills Log'!$B$6:$B$505,Settings!$B$9,'Bills Log'!$C$6:$C$505,$A53) | N53: =SUM(B53:M53) | O53: =IFERROR(N53/12,0)
A54: Water | B54: =SUMIFS('Bills Log'!$F$6:$F$505,'Bills Log'!$A$6:$A$505,">="&DATE(Settings!$B$5,1,1),'Bills Log'!$A$6:$A$505,"<"&DATE(Settings!$B$5,2,1),'Bills Log'!$B$6:$B$505,Settings!$B$9,'Bills Log'!$C$6:$C$505,$A54) | C54: =SUMIFS('Bills Log'!$F$6:$F$505,'Bills Log'!$A$6:$A$505,">="&DATE(Settings!$B$5,2,1),'Bills Log'!$A$6:$A$505,"<"&DATE(Settings!$B$5,3,1),'Bills Log'!$B$6:$B$505,Settings!$B$9,'Bills Log'!$C$6:$C$505,$A54) | D54: =SUMIFS('Bills Log'!$F$6:$F$505,'Bills Log'!$A$6:$A$505,">="&DATE(Settings!$B$5,3,1),'Bills Log'!$A$6:$A$505,"<"&DATE(Settings!$B$5,4,1),'Bills Log'!$B$6:$B$505,Settings!$B$9,'Bills Log'!$C$6:$C$505,$A54) | E54: =SUMIFS('Bills Log'!$F$6:$F$505,'Bills Log'!$A$6:$A$505,">="&DATE(Settings!$B$5,4,1),'Bills Log'!$A$6:$A$505,"<"&DATE(Settings!$B$5,5,1),'Bills Log'!$B$6:$B$505,Settings!$B$9,'Bills Log'!$C$6:$C$505,$A54) | F54: =SUMIFS('Bills Log'!$F$6:$F$505,'Bills Log'!$A$6:$A$505,">="&DATE(Settings!$B$5,5,1),'Bills Log'!$A$6:$A$505,"<"&DATE(Settings!$B$5,6,1),'Bills Log'!$B$6:$B$505,Settings!$B$9,'Bills Log'!$C$6:$C$505,$A54) | G54: =SUMIFS('Bills Log'!$F$6:$F$505,'Bills Log'!$A$6:$A$505,">="&DATE(Settings!$B$5,6,1),'Bills Log'!$A$6:$A$505,"<"&DATE(Settings!$B$5,7,1),'Bills Log'!$B$6:$B$505,Settings!$B$9,'Bills Log'!$C$6:$C$505,$A54) | H54: =SUMIFS('Bills Log'!$F$6:$F$505,'Bills Log'!$A$6:$A$505,">="&DATE(Settings!$B$5,7,1),'Bills Log'!$A$6:$A$505,"<"&DATE(Settings!$B$5,8,1),'Bills Log'!$B$6:$B$505,Settings!$B$9,'Bills Log'!$C$6:$C$505,$A54) | I54: =SUMIFS('Bills Log'!$F$6:$F$505,'Bills Log'!$A$6:$A$505,">="&DATE(Settings!$B$5,8,1),'Bills Log'!$A$6:$A$505,"<"&DATE(Settings!$B$5,9,1),'Bills Log'!$B$6:$B$505,Settings!$B$9,'Bills Log'!$C$6:$C$505,$A54) | J54: =SUMIFS('Bills Log'!$F$6:$F$505,'Bills Log'!$A$6:$A$505,">="&DATE(Settings!$B$5,9,1),'Bills Log'!$A$6:$A$505,"<"&DATE(Settings!$B$5,10,1),'Bills Log'!$B$6:$B$505,Settings!$B$9,'Bills Log'!$C$6:$C$505,$A54) | K54: =SUMIFS('Bills Log'!$F$6:$F$505,'Bills Log'!$A$6:$A$505,">="&DATE(Settings!$B$5,10,1),'Bills Log'!$A$6:$A$505,"<"&DATE(Settings!$B$5,11,1),'Bills Log'!$B$6:$B$505,Settings!$B$9,'Bills Log'!$C$6:$C$505,$A54) | L54: =SUMIFS('Bills Log'!$F$6:$F$505,'Bills Log'!$A$6:$A$505,">="&DATE(Settings!$B$5,11,1),'Bills Log'!$A$6:$A$505,"<"&DATE(Settings!$B$5,12,1),'Bills Log'!$B$6:$B$505,Settings!$B$9,'Bills Log'!$C$6:$C$505,$A54) | M54: =SUMIFS('Bills Log'!$F$6:$F$505,'Bills Log'!$A$6:$A$505,">="&DATE(Settings!$B$5,12,1),'Bills Log'!$A$6:$A$505,"<"&DATE(Settings!$B$5+1,1,1),'Bills Log'!$B$6:$B$505,Settings!$B$9,'Bills Log'!$C$6:$C$505,$A54) | N54: =SUM(B54:M54) | O54: =IFERROR(N54/12,0)
A55: Internet | B55: =SUMIFS('Bills Log'!$F$6:$F$505,'Bills Log'!$A$6:$A$505,">="&DATE(Settings!$B$5,1,1),'Bills Log'!$A$6:$A$505,"<"&DATE(Settings!$B$5,2,1),'Bills Log'!$B$6:$B$505,Settings!$B$9,'Bills Log'!$C$6:$C$505,$A55) | C55: =SUMIFS('Bills Log'!$F$6:$F$505,'Bills Log'!$A$6:$A$505,">="&DATE(Settings!$B$5,2,1),'Bills Log'!$A$6:$A$505,"<"&DATE(Settings!$B$5,3,1),'Bills Log'!$B$6:$B$505,Settings!$B$9,'Bills Log'!$C$6:$C$505,$A55) | D55: =SUMIFS('Bills Log'!$F$6:$F$505,'Bills Log'!$A$6:$A$505,">="&DATE(Settings!$B$5,3,1),'Bills Log'!$A$6:$A$505,"<"&DATE(Settings!$B$5,4,1),'Bills Log'!$B$6:$B$505,Settings!$B$9,'Bills Log'!$C$6:$C$505,$A55) | E55: =SUMIFS('Bills Log'!$F$6:$F$505,'Bills Log'!$A$6:$A$505,">="&DATE(Settings!$B$5,4,1),'Bills Log'!$A$6:$A$505,"<"&DATE(Settings!$B$5,5,1),'Bills Log'!$B$6:$B$505,Settings!$B$9,'Bills Log'!$C$6:$C$505,$A55) | F55: =SUMIFS('Bills Log'!$F$6:$F$505,'Bills Log'!$A$6:$A$505,">="&DATE(Settings!$B$5,5,1),'Bills Log'!$A$6:$A$505,"<"&DATE(Settings!$B$5,6,1),'Bills Log'!$B$6:$B$505,Settings!$B$9,'Bills Log'!$C$6:$C$505,$A55) | G55: =SUMIFS('Bills Log'!$F$6:$F$505,'Bills Log'!$A$6:$A$505,">="&DATE(Settings!$B$5,6,1),'Bills Log'!$A$6:$A$505,"<"&DATE(Settings!$B$5,7,1),'Bills Log'!$B$6:$B$505,Settings!$B$9,'Bills Log'!$C$6:$C$505,$A55) | H55: =SUMIFS('Bills Log'!$F$6:$F$505,'Bills Log'!$A$6:$A$505,">="&DATE(Settings!$B$5,7,1),'Bills Log'!$A$6:$A$505,"<"&DATE(Settings!$B$5,8,1),'Bills Log'!$B$6:$B$505,Settings!$B$9,'Bills Log'!$C$6:$C$505,$A55) | I55: =SUMIFS('Bills Log'!$F$6:$F$505,'Bills Log'!$A$6:$A$505,">="&DATE(Settings!$B$5,8,1),'Bills Log'!$A$6:$A$505,"<"&DATE(Settings!$B$5,9,1),'Bills Log'!$B$6:$B$505,Settings!$B$9,'Bills Log'!$C$6:$C$505,$A55) | J55: =SUMIFS('Bills Log'!$F$6:$F$505,'Bills Log'!$A$6:$A$505,">="&DATE(Settings!$B$5,9,1),'Bills Log'!$A$6:$A$505,"<"&DATE(Settings!$B$5,10,1),'Bills Log'!$B$6:$B$505,Settings!$B$9,'Bills Log'!$C$6:$C$505,$A55) | K55: =SUMIFS('Bills Log'!$F$6:$F$505,'Bills Log'!$A$6:$A$505,">="&DATE(Settings!$B$5,10,1),'Bills Log'!$A$6:$A$505,"<"&DATE(Settings!$B$5,11,1),'Bills Log'!$B$6:$B$505,Settings!$B$9,'Bills Log'!$C$6:$C$505,$A55) | L55: =SUMIFS('Bills Log'!$F$6:$F$505,'Bills Log'!$A$6:$A$505,">="&DATE(Settings!$B$5,11,1),'Bills Log'!$A$6:$A$505,"<"&DATE(Settings!$B$5,12,1),'Bills Log'!$B$6:$B$505,Settings!$B$9,'Bills Log'!$C$6:$C$505,$A55) | M55: =SUMIFS('Bills Log'!$F$6:$F$505,'Bills Log'!$A$6:$A$505,">="&DATE(Settings!$B$5,12,1),'Bills Log'!$A$6:$A$505,"<"&DATE(Settings!$B$5+1,1,1),'Bills Log'!$B$6:$B$505,Settings!$B$9,'Bills Log'!$C$6:$C$505,$A55) | N55: =SUM(B55:M55) | O55: =IFERROR(N55/12,0)
A56: Trash | B56: =SUMIFS('Bills Log'!$F$6:$F$505,'Bills Log'!$A$6:$A$505,">="&DATE(Settings!$B$5,1,1),'Bills Log'!$A$6:$A$505,"<"&DATE(Settings!$B$5,2,1),'Bills Log'!$B$6:$B$505,Settings!$B$9,'Bills Log'!$C$6:$C$505,$A56) | C56: =SUMIFS('Bills Log'!$F$6:$F$505,'Bills Log'!$A$6:$A$505,">="&DATE(Settings!$B$5,2,1),'Bills Log'!$A$6:$A$505,"<"&DATE(Settings!$B$5,3,1),'Bills Log'!$B$6:$B$505,Settings!$B$9,'Bills Log'!$C$6:$C$505,$A56) | D56: =SUMIFS('Bills Log'!$F$6:$F$505,'Bills Log'!$A$6:$A$505,">="&DATE(Settings!$B$5,3,1),'Bills Log'!$A$6:$A$505,"<"&DATE(Settings!$B$5,4,1),'Bills Log'!$B$6:$B$505,Settings!$B$9,'Bills Log'!$C$6:$C$505,$A56) | E56: =SUMIFS('Bills Log'!$F$6:$F$505,'Bills Log'!$A$6:$A$505,">="&DATE(Settings!$B$5,4,1),'Bills Log'!$A$6:$A$505,"<"&DATE(Settings!$B$5,5,1),'Bills Log'!$B$6:$B$505,Settings!$B$9,'Bills Log'!$C$6:$C$505,$A56) | F56: =SUMIFS('Bills Log'!$F$6:$F$505,'Bills Log'!$A$6:$A$505,">="&DATE(Settings!$B$5,5,1),'Bills Log'!$A$6:$A$505,"<"&DATE(Settings!$B$5,6,1),'Bills Log'!$B$6:$B$505,Settings!$B$9,'Bills Log'!$C$6:$C$505,$A56) | G56: =SUMIFS('Bills Log'!$F$6:$F$505,'Bills Log'!$A$6:$A$505,">="&DATE(Settings!$B$5,6,1),'Bills Log'!$A$6:$A$505,"<"&DATE(Settings!$B$5,7,1),'Bills Log'!$B$6:$B$505,Settings!$B$9,'Bills Log'!$C$6:$C$505,$A56) | H56: =SUMIFS('Bills Log'!$F$6:$F$505,'Bills Log'!$A$6:$A$505,">="&DATE(Settings!$B$5,7,1),'Bills Log'!$A$6:$A$505,"<"&DATE(Settings!$B$5,8,1),'Bills Log'!$B$6:$B$505,Settings!$B$9,'Bills Log'!$C$6:$C$505,$A56) | I56: =SUMIFS('Bills Log'!$F$6:$F$505,'Bills Log'!$A$6:$A$505,">="&DATE(Settings!$B$5,8,1),'Bills Log'!$A$6:$A$505,"<"&DATE(Settings!$B$5,9,1),'Bills Log'!$B$6:$B$505,Settings!$B$9,'Bills Log'!$C$6:$C$505,$A56) | J56: =SUMIFS('Bills Log'!$F$6:$F$505,'Bills Log'!$A$6:$A$505,">="&DATE(Settings!$B$5,9,1),'Bills Log'!$A$6:$A$505,"<"&DATE(Settings!$B$5,10,1),'Bills Log'!$B$6:$B$505,Settings!$B$9,'Bills Log'!$C$6:$C$505,$A56) | K56: =SUMIFS('Bills Log'!$F$6:$F$505,'Bills Log'!$A$6:$A$505,">="&DATE(Settings!$B$5,10,1),'Bills Log'!$A$6:$A$505,"<"&DATE(Settings!$B$5,11,1),'Bills Log'!$B$6:$B$505,Settings!$B$9,'Bills Log'!$C$6:$C$505,$A56) | L56: =SUMIFS('Bills Log'!$F$6:$F$505,'Bills Log'!$A$6:$A$505,">="&DATE(Settings!$B$5,11,1),'Bills Log'!$A$6:$A$505,"<"&DATE(Settings!$B$5,12,1),'Bills Log'!$B$6:$B$505,Settings!$B$9,'Bills Log'!$C$6:$C$505,$A56) | M56: =SUMIFS('Bills Log'!$F$6:$F$505,'Bills Log'!$A$6:$A$505,">="&DATE(Settings!$B$5,12,1),'Bills Log'!$A$6:$A$505,"<"&DATE(Settings!$B$5+1,1,1),'Bills Log'!$B$6:$B$505,Settings!$B$9,'Bills Log'!$C$6:$C$505,$A56) | N56: =SUM(B56:M56) | O56: =IFERROR(N56/12,0)
A57: Propane | B57: =SUMIFS('Bills Log'!$F$6:$F$505,'Bills Log'!$A$6:$A$505,">="&DATE(Settings!$B$5,1,1),'Bills Log'!$A$6:$A$505,"<"&DATE(Settings!$B$5,2,1),'Bills Log'!$B$6:$B$505,Settings!$B$9,'Bills Log'!$C$6:$C$505,$A57) | C57: =SUMIFS('Bills Log'!$F$6:$F$505,'Bills Log'!$A$6:$A$505,">="&DATE(Settings!$B$5,2,1),'Bills Log'!$A$6:$A$505,"<"&DATE(Settings!$B$5,3,1),'Bills Log'!$B$6:$B$505,Settings!$B$9,'Bills Log'!$C$6:$C$505,$A57) | D57: =SUMIFS('Bills Log'!$F$6:$F$505,'Bills Log'!$A$6:$A$505,">="&DATE(Settings!$B$5,3,1),'Bills Log'!$A$6:$A$505,"<"&DATE(Settings!$B$5,4,1),'Bills Log'!$B$6:$B$505,Settings!$B$9,'Bills Log'!$C$6:$C$505,$A57) | E57: =SUMIFS('Bills Log'!$F$6:$F$505,'Bills Log'!$A$6:$A$505,">="&DATE(Settings!$B$5,4,1),'Bills Log'!$A$6:$A$505,"<"&DATE(Settings!$B$5,5,1),'Bills Log'!$B$6:$B$505,Settings!$B$9,'Bills Log'!$C$6:$C$505,$A57) | F57: =SUMIFS('Bills Log'!$F$6:$F$505,'Bills Log'!$A$6:$A$505,">="&DATE(Settings!$B$5,5,1),'Bills Log'!$A$6:$A$505,"<"&DATE(Settings!$B$5,6,1),'Bills Log'!$B$6:$B$505,Settings!$B$9,'Bills Log'!$C$6:$C$505,$A57) | G57: =SUMIFS('Bills Log'!$F$6:$F$505,'Bills Log'!$A$6:$A$505,">="&DATE(Settings!$B$5,6,1),'Bills Log'!$A$6:$A$505,"<"&DATE(Settings!$B$5,7,1),'Bills Log'!$B$6:$B$505,Settings!$B$9,'Bills Log'!$C$6:$C$505,$A57) | H57: =SUMIFS('Bills Log'!$F$6:$F$505,'Bills Log'!$A$6:$A$505,">="&DATE(Settings!$B$5,7,1),'Bills Log'!$A$6:$A$505,"<"&DATE(Settings!$B$5,8,1),'Bills Log'!$B$6:$B$505,Settings!$B$9,'Bills Log'!$C$6:$C$505,$A57) | I57: =SUMIFS('Bills Log'!$F$6:$F$505,'Bills Log'!$A$6:$A$505,">="&DATE(Settings!$B$5,8,1),'Bills Log'!$A$6:$A$505,"<"&DATE(Settings!$B$5,9,1),'Bills Log'!$B$6:$B$505,Settings!$B$9,'Bills Log'!$C$6:$C$505,$A57) | J57: =SUMIFS('Bills Log'!$F$6:$F$505,'Bills Log'!$A$6:$A$505,">="&DATE(Settings!$B$5,9,1),'Bills Log'!$A$6:$A$505,"<"&DATE(Settings!$B$5,10,1),'Bills Log'!$B$6:$B$505,Settings!$B$9,'Bills Log'!$C$6:$C$505,$A57) | K57: =SUMIFS('Bills Log'!$F$6:$F$505,'Bills Log'!$A$6:$A$505,">="&DATE(Settings!$B$5,10,1),'Bills Log'!$A$6:$A$505,"<"&DATE(Settings!$B$5,11,1),'Bills Log'!$B$6:$B$505,Settings!$B$9,'Bills Log'!$C$6:$C$505,$A57) | L57: =SUMIFS('Bills Log'!$F$6:$F$505,'Bills Log'!$A$6:$A$505,">="&DATE(Settings!$B$5,11,1),'Bills Log'!$A$6:$A$505,"<"&DATE(Settings!$B$5,12,1),'Bills Log'!$B$6:$B$505,Settings!$B$9,'Bills Log'!$C$6:$C$505,$A57) | M57: =SUMIFS('Bills Log'!$F$6:$F$505,'Bills Log'!$A$6:$A$505,">="&DATE(Settings!$B$5,12,1),'Bills Log'!$A$6:$A$505,"<"&DATE(Settings!$B$5+1,1,1),'Bills Log'!$B$6:$B$505,Settings!$B$9,'Bills Log'!$C$6:$C$505,$A57) | N57: =SUM(B57:M57) | O57: =IFERROR(N57/12,0)
A58: TOTAL | B58: =SUM(B52:B57) | C58: =SUM(C52:C57) | D58: =SUM(D52:D57) | E58: =SUM(E52:E57) | F58: =SUM(F52:F57) | G58: =SUM(G52:G57) | H58: =SUM(H52:H57) | I58: =SUM(I52:I57) | ... O58: =SUM(O52:O57)

Sheet Trend & Anomalies
A2: =HYPERLINK("#'Property Matrix'!A1", "← BACK") | D2: TREND & ANOMALIES | J2: =HYPERLINK("#'Settings'!A1", "NEXT →")
A3: Anomalies: | B3: =COUNTIF(H6:H221,"⚠*")
A4: Year-over-year check — anomaly if a month's bill jumped >25% vs prior year
A5: Property | B5: Service | C5: Month | D5: Current Yr $ | E5: Prior Yr $ | F5: YoY % | G5: Δ $ | H5: Anomaly
A6: =Settings!$B$7 | B6: Electric | C6: Jan | D6: =SUMIFS('Bills Log'!$F$6:$F$505,'Bills Log'!$A$6:$A$505,">="&DATE(Settings!$B$5,1,1),'Bills Log'!$A$6:$A$505,"<"&DATE(Settings!$B$5,2,1),'Bills Log'!$B$6:$B$505,A6,'Bills Log'!$C$6:$C$505,B6) | E6: =SUMIFS('Bills Log'!$F$6:$F$505,'Bills Log'!$A$6:$A$505,">="&DATE(Settings!$B$5-1,1,1),'Bills Log'!$A$6:$A$505,"<"&DATE((Settings!$B$5-1),2,1),'Bills Log'!$B$6:$B$505,A6,'Bills Log'!$C$6:$C$505,B6) | F6: =IFERROR(IF(E6=0,"",D6/E6-1),"") | G6: =D6-E6 | H6: =IFERROR(IF(ABS(D6/E6-1)>0.25,"⚠ "&ROUND((D6/E6-1)*100,0)&"%",""),"")
A7: =Settings!$B$7 | B7: Electric | C7: Feb | D7: =SUMIFS('Bills Log'!$F$6:$F$505,'Bills Log'!$A$6:$A$505,">="&DATE(Settings!$B$5,2,1),'Bills Log'!$A$6:$A$505,"<"&DATE(Settings!$B$5,3,1),'Bills Log'!$B$6:$B$505,A7,'Bills Log'!$C$6:$C$505,B7) | E7: =SUMIFS('Bills Log'!$F$6:$F$505,'Bills Log'!$A$6:$A$505,">="&DATE(Settings!$B$5-1,2,1),'Bills Log'!$A$6:$A$505,"<"&DATE((Settings!$B$5-1),3,1),'Bills Log'!$B$6:$B$505,A7,'Bills Log'!$C$6:$C$505,B7) | F7: =IFERROR(IF(E7=0,"",D7/E7-1),"") | G7: =D7-E7 | H7: =IFERROR(IF(ABS(D7/E7-1)>0.25,"⚠ "&ROUND((D7/E7-1)*100,0)&"%",""),"")
A8: =Settings!$B$7 | B8: Electric | C8: Mar | D8: =SUMIFS('Bills Log'!$F$6:$F$505,'Bills Log'!$A$6:$A$505,">="&DATE(Settings!$B$5,3,1),'Bills Log'!$A$6:$A$505,"<"&DATE(Settings!$B$5,4,1),'Bills Log'!$B$6:$B$505,A8,'Bills Log'!$C$6:$C$505,B8) | E8: =SUMIFS('Bills Log'!$F$6:$F$505,'Bills Log'!$A$6:$A$505,">="&DATE(Settings!$B$5-1,3,1),'Bills Log'!$A$6:$A$505,"<"&DATE((Settings!$B$5-1),4,1),'Bills Log'!$B$6:$B$505,A8,'Bills Log'!$C$6:$C$505,B8) | F8: =IFERROR(IF(E8=0,"",D8/E8-1),"") | G8: =D8-E8 | H8: =IFERROR(IF(ABS(D8/E8-1)>0.25,"⚠ "&ROUND((D8/E8-1)*100,0)&"%",""),"")
A9: =Settings!$B$7 | B9: Electric | C9: Apr | D9: =SUMIFS('Bills Log'!$F$6:$F$505,'Bills Log'!$A$6:$A$505,">="&DATE(Settings!$B$5,4,1),'Bills Log'!$A$6:$A$505,"<"&DATE(Settings!$B$5,5,1),'Bills Log'!$B$6:$B$505,A9,'Bills Log'!$C$6:$C$505,B9) | E9: =SUMIFS('Bills Log'!$F$6:$F$505,'Bills Log'!$A$6:$A$505,">="&DATE(Settings!$B$5-1,4,1),'Bills Log'!$A$6:$A$505,"<"&DATE((Settings!$B$5-1),5,1),'Bills Log'!$B$6:$B$505,A9,'Bills Log'!$C$6:$C$505,B9) | F9: =IFERROR(IF(E9=0,"",D9/E9-1),"") | G9: =D9-E9 | H9: =IFERROR(IF(ABS(D9/E9-1)>0.25,"⚠ "&ROUND((D9/E9-1)*100,0)&"%",""),"")
A10: =Settings!$B$7 | B10: Electric | C10: May | D10: =SUMIFS('Bills Log'!$F$6:$F$505,'Bills Log'!$A$6:$A$505,">="&DATE(Settings!$B$5,5,1),'Bills Log'!$A$6:$A$505,"<"&DATE(Settings!$B$5,6,1),'Bills Log'!$B$6:$B$505,A10,'Bills Log'!$C$6:$C$505,B10) | E10: =SUMIFS('Bills Log'!$F$6:$F$505,'Bills Log'!$A$6:$A$505,">="&DATE(Settings!$B$5-1,5,1),'Bills Log'!$A$6:$A$505,"<"&DATE((Settings!$B$5-1),6,1),'Bills Log'!$B$6:$B$505,A10,'Bills Log'!$C$6:$C$505,B10) | F10: =IFERROR(IF(E10=0,"",D10/E10-1),"") | G10: =D10-E10 | H10: =IFERROR(IF(ABS(D10/E10-1)>0.25,"⚠ "&ROUND((D10/E10-1)*100,0)&"%",""),"")
A11: =Settings!$B$7 | B11: Electric | C11: Jun | D11: =SUMIFS('Bills Log'!$F$6:$F$505,'Bills Log'!$A$6:$A$505,">="&DATE(Settings!$B$5,6,1),'Bills Log'!$A$6:$A$505,"<"&DATE(Settings!$B$5,7,1),'Bills Log'!$B$6:$B$505,A11,'Bills Log'!$C$6:$C$505,B11) | E11: =SUMIFS('Bills Log'!$F$6:$F$505,'Bills Log'!$A$6:$A$505,">="&DATE(Settings!$B$5-1,6,1),'Bills Log'!$A$6:$A$505,"<"&DATE((Settings!$B$5-1),7,1),'Bills Log'!$B$6:$B$505,A11,'Bills Log'!$C$6:$C$505,B11) | F11: =IFERROR(IF(E11=0,"",D11/E11-1),"") | G11: =D11-E11 | H11: =IFERROR(IF(ABS(D11/E11-1)>0.25,"⚠ "&ROUND((D11/E11-1)*100,0)&"%",""),"")
A12: =Settings!$B$7 | B12: Electric | C12: Jul | D12: =SUMIFS('Bills Log'!$F$6:$F$505,'Bills Log'!$A$6:$A$505,">="&DATE(Settings!$B$5,7,1),'Bills Log'!$A$6:$A$505,"<"&DATE(Settings!$B$5,8,1),'Bills Log'!$B$6:$B$505,A12,'Bills Log'!$C$6:$C$505,B12) | E12: =SUMIFS('Bills Log'!$F$6:$F$505,'Bills Log'!$A$6:$A$505,">="&DATE(Settings!$B$5-1,7,1),'Bills Log'!$A$6:$A$505,"<"&DATE((Settings!$B$5-1),8,1),'Bills Log'!$B$6:$B$505,A12,'Bills Log'!$C$6:$C$505,B12) | F12: =IFERROR(IF(E12=0,"",D12/E12-1),"") | G12: =D12-E12 | H12: =IFERROR(IF(ABS(D12/E12-1)>0.25,"⚠ "&ROUND((D12/E12-1)*100,0)&"%",""),"")
A13: =Settings!$B$7 | B13: Electric | C13: Aug | D13: =SUMIFS('Bills Log'!$F$6:$F$505,'Bills Log'!$A$6:$A$505,">="&DATE(Settings!$B$5,8,1),'Bills Log'!$A$6:$A$505,"<"&DATE(Settings!$B$5,9,1),'Bills Log'!$B$6:$B$505,A13,'Bills Log'!$C$6:$C$505,B13) | E13: =SUMIFS('Bills Log'!$F$6:$F$505,'Bills Log'!$A$6:$A$505,">="&DATE(Settings!$B$5-1,8,1),'Bills Log'!$A$6:$A$505,"<"&DATE((Settings!$B$5-1),9,1),'Bills Log'!$B$6:$B$505,A13,'Bills Log'!$C$6:$C$505,B13) | F13: =IFERROR(IF(E13=0,"",D13/E13-1),"") | G13: =D13-E13 | H13: =IFERROR(IF(ABS(D13/E13-1)>0.25,"⚠ "&ROUND((D13/E13-1)*100,0)&"%",""),"")
A14: =Settings!$B$7 | B14: Electric | C14: Sep | D14: =SUMIFS('Bills Log'!$F$6:$F$505,'Bills Log'!$A$6:$A$505,">="&DATE(Settings!$B$5,9,1),'Bills Log'!$A$6:$A$505,"<"&DATE(Settings!$B$5,10,1),'Bills Log'!$B$6:$B$505,A14,'Bills Log'!$C$6:$C$505,B14) | E14: =SUMIFS('Bills Log'!$F$6:$F$505,'Bills Log'!$A$6:$A$505,">="&DATE(Settings!$B$5-1,9,1),'Bills Log'!$A$6:$A$505,"<"&DATE((Settings!$B$5-1),10,1),'Bills Log'!$B$6:$B$505,A14,'Bills Log'!$C$6:$C$505,B14) | F14: =IFERROR(IF(E14=0,"",D14/E14-1),"") | G14: =D14-E14 | H14: =IFERROR(IF(ABS(D14/E14-1)>0.25,"⚠ "&ROUND((D14/E14-1)*100,0)&"%",""),"")
A15: =Settings!$B$7 | B15: Electric | C15: Oct | D15: =SUMIFS('Bills Log'!$F$6:$F$505,'Bills Log'!$A$6:$A$505,">="&DATE(Settings!$B$5,10,1),'Bills Log'!$A$6:$A$505,"<"&DATE(Settings!$B$5,11,1),'Bills Log'!$B$6:$B$505,A15,'Bills Log'!$C$6:$C$505,B15) | E15: =SUMIFS('Bills Log'!$F$6:$F$505,'Bills Log'!$A$6:$A$505,">="&DATE(Settings!$B$5-1,10,1),'Bills Log'!$A$6:$A$505,"<"&DATE((Settings!$B$5-1),11,1),'Bills Log'!$B$6:$B$505,A15,'Bills Log'!$C$6:$C$505,B15) | F15: =IFERROR(IF(E15=0,"",D15/E15-1),"") | G15: =D15-E15 | H15: =IFERROR(IF(ABS(D15/E15-1)>0.25,"⚠ "&ROUND((D15/E15-1)*100,0)&"%",""),"")
A16: =Settings!$B$7 | B16: Electric | C16: Nov | D16: =SUMIFS('Bills Log'!$F$6:$F$505,'Bills Log'!$A$6:$A$505,">="&DATE(Settings!$B$5,11,1),'Bills Log'!$A$6:$A$505,"<"&DATE(Settings!$B$5,12,1),'Bills Log'!$B$6:$B$505,A16,'Bills Log'!$C$6:$C$505,B16) | E16: =SUMIFS('Bills Log'!$F$6:$F$505,'Bills Log'!$A$6:$A$505,">="&DATE(Settings!$B$5-1,11,1),'Bills Log'!$A$6:$A$505,"<"&DATE((Settings!$B$5-1),12,1),'Bills Log'!$B$6:$B$505,A16,'Bills Log'!$C$6:$C$505,B16) | F16: =IFERROR(IF(E16=0,"",D16/E16-1),"") | G16: =D16-E16 | H16: =IFERROR(IF(ABS(D16/E16-1)>0.25,"⚠ "&ROUND((D16/E16-1)*100,0)&"%",""),"")
A17: =Settings!$B$7 | B17: Electric | C17: Dec | D17: =SUMIFS('Bills Log'!$F$6:$F$505,'Bills Log'!$A$6:$A$505,">="&DATE(Settings!$B$5,12,1),'Bills Log'!$A$6:$A$505,"<"&DATE(Settings!$B$5+1,1,1),'Bills Log'!$B$6:$B$505,A17,'Bills Log'!$C$6:$C$505,B17) | E17: =SUMIFS('Bills Log'!$F$6:$F$505,'Bills Log'!$A$6:$A$505,">="&DATE(Settings!$B$5-1,12,1),'Bills Log'!$A$6:$A$505,"<"&DATE(Settings!$B$5,1,1),'Bills Log'!$B$6:$B$505,A17,'Bills Log'!$C$6:$C$505,B17) | F17: =IFERROR(IF(E17=0,"",D17/E17-1),"") | G17: =D17-E17 | H17: =IFERROR(IF(ABS(D17/E17-1)>0.25,"⚠ "&ROUND((D17/E17-1)*100,0)&"%",""),"")
A18: =Settings!$B$7 | B18: Gas | C18: Jan | D18: =SUMIFS('Bills Log'!$F$6:$F$505,'Bills Log'!$A$6:$A$505,">="&DATE(Settings!$B$5,1,1),'Bills Log'!$A$6:$A$505,"<"&DATE(Settings!$B$5,2,1),'Bills Log'!$B$6:$B$505,A18,'Bills Log'!$C$6:$C$505,B18) | E18: =SUMIFS('Bills Log'!$F$6:$F$505,'Bills Log'!$A$6:$A$505,">="&DATE(Settings!$B$5-1,1,1),'Bills Log'!$A$6:$A$505,"<"&DATE((Settings!$B$5-1),2,1),'Bills Log'!$B$6:$B$505,A18,'Bills Log'!$C$6:$C$505,B18) | F18: =IFERROR(IF(E18=0,"",D18/E18-1),"") | G18: =D18-E18 | H18: =IFERROR(IF(ABS(D18/E18-1)>0.25,"⚠ "&ROUND((D18/E18-1)*100,0)&"%",""),"")
A19: =Settings!$B$7 | B19: Gas | C19: Feb | D19: =SUMIFS('Bills Log'!$F$6:$F$505,'Bills Log'!$A$6:$A$505,">="&DATE(Settings!$B$5,2,1),'Bills Log'!$A$6:$A$505,"<"&DATE(Settings!$B$5,3,1),'Bills Log'!$B$6:$B$505,A19,'Bills Log'!$C$6:$C$505,B19) | E19: =SUMIFS('Bills Log'!$F$6:$F$505,'Bills Log'!$A$6:$A$505,">="&DATE(Settings!$B$5-1,2,1),'Bills Log'!$A$6:$A$505,"<"&DATE((Settings!$B$5-1),3,1),'Bills Log'!$B$6:$B$505,A19,'Bills Log'!$C$6:$C$505,B19) | F19: =IFERROR(IF(E19=0,"",D19/E19-1),"") | G19: =D19-E19 | H19: =IFERROR(IF(ABS(D19/E19-1)>0.25,"⚠ "&ROUND((D19/E19-1)*100,0)&"%",""),"")
