Workbook

Sheet Start
A2: The STR Ledger
A4: Damage Claim + AirCover Log
A5: When a guest breaks something, this is the calm move.
A7: OPS-002 · v1.0 · DEMO
A10: OPEN CLAIMS | E10: $ AT RISK | I10: RECOVERY RATE
A11: =COUNTIFS('Claims Register'!K6:K205,"<>Paid",'Claims Register'!K6:K205,"<>Closed unpaid",'Claims Register'!A6:A205,"<>") | E11: =SUMIFS('Claims Register'!I6:I205,'Claims Register'!K6:K205,"<>Paid",'Claims Register'!K6:K205,"<>Closed unpaid",'Claims Register'!A6:A205,"<>") | I11: =IFERROR(SUM('Claims Register'!J6:J205)/SUM('Claims Register'!I6:I205),0)
A14: claims still in flight | E14: claimed, not yet recovered | I14: $ recovered ÷ $ claimed
A17: ⚠ DEADLINE WATCH — CLAIMS WITH < 7 DAYS LEFT
A18: Open the Claims Register tab — rows with red 'Days to deadline' values are listed there in priority order. The countdown is keyed to the guest's checkout date plus your filing-window default (Settings → 14 days for Airbnb).
A20: Why this matters: AirCover's standard window is 14 days from guest checkout — OR before the next guest checks in, whichever is sooner. Most denied claims are denied for missing the window, not for weak evidence. Open the Coverage Reference tab for the current policy (verified 2026-05-02).
A25: =HYPERLINK("#'Claims Register'!A1", "Claims Register") | D25: =HYPERLINK("#'Claim Packet'!A1", "New Claim Packet") | G25: =HYPERLINK("#'Coverage Reference'!A1", "Coverage Reference") | J25: =HYPERLINK("#'Message Scripts'!A1", "Message Scripts")
A29: =HYPERLINK("#'Annual Damage P&L'!A1", "Annual Damage P&L") | G29: =HYPERLINK("#'Settings'!A1", "Settings")
A33: 💡 Need full operations coverage? Add the Operator Bundle at thestrledger.com/operator — turnover + maintenance + supply + damage claims + insurance + permits, $197.
A36: Questions? hello@thestrledger.com
A37: OPS-002 · v1.0 · DEMO · Free updates forever

Sheet Claims Register
A2: =HYPERLINK("#'Start'!A1", "← BACK") | D2: CLAIMS REGISTER | J2: =HYPERLINK("#'Claim Packet'!A1", "NEXT →")
A4: Master log — all claims. Days-to-deadline is auto-calculated from checkout date + filing window (Settings → 14 days default).
A5: Date discovered | B5: Property | C5: Guest | D5: Booking ID | E5: Channel | F5: Checkout | G5: Damage description | H5: Category | I5: $ Claimed | J5: $ Recovered | K5: Status | L5: Days to deadline | M5: Recovery % | N5: Notes
A6: 46037 | B6: Smokies Ridge Cabin | C6: Jordan M. | D6: HMABCD123 | E6: Airbnb | F6: 46037 | G6: Coffee table cracked diagonal — guest moved it on uneven floor | H6: Furniture | I6: 340 | J6: 340 | K6: Paid | L6: =IF(AND(F6<>"",K6<>"Paid",K6<>"Closed unpaid"),Settings!$C$27-(TODAY()-F6),"") | M6: =IF(I6>0,J6/I6,"") | N6: Resolved AirCover in 9 days; replacement table sourced from Wayfair.
A7: 46075 | B7: Creek Side | C7: Taylor R. | D7: HMEFGH456 | E7: Airbnb | F7: 46074 | G7: Bedside lamp shattered + linen stain on duvet (red wine) | H7: Decor | I7: 180 | J7: 90 | K7: Paid | L7: =IF(AND(F7<>"",K7<>"Paid",K7<>"Closed unpaid"),Settings!$C$27-(TODAY()-F7),"") | M7: =IF(I7>0,J7/I7,"") | N7: Partial payout — AirCover argued lamp was 'normal wear'; duvet covered.
A8: 46089 | B8: Lakehouse A | C8: Devin K. | D8: HMIJKL789 | E8: Airbnb | F8: 46087 | G8: TV cracked — guest claimed pre-existing; we have arrival photos showing intact | H8: Appliance | I8: 720 | J8: 0 | K8: Disputed | L8: =IF(AND(F8<>"",K8<>"Paid",K8<>"Closed unpaid"),Settings!$C$27-(TODAY()-F8),"") | M8: =IF(I8>0,J8/I8,"") | N8: Open. Arrival-day photos timestamped + sent. Awaiting Airbnb decision.
L9: =IF(AND(F9<>"",K9<>"Paid",K9<>"Closed unpaid"),Settings!$C$27-(TODAY()-F9),"") | M9: =IF(I9>0,J9/I9,"")
L10: =IF(AND(F10<>"",K10<>"Paid",K10<>"Closed unpaid"),Settings!$C$27-(TODAY()-F10),"") | M10: =IF(I10>0,J10/I10,"")
L11: =IF(AND(F11<>"",K11<>"Paid",K11<>"Closed unpaid"),Settings!$C$27-(TODAY()-F11),"") | M11: =IF(I11>0,J11/I11,"")
L12: =IF(AND(F12<>"",K12<>"Paid",K12<>"Closed unpaid"),Settings!$C$27-(TODAY()-F12),"") | M12: =IF(I12>0,J12/I12,"")
L13: =IF(AND(F13<>"",K13<>"Paid",K13<>"Closed unpaid"),Settings!$C$27-(TODAY()-F13),"") | M13: =IF(I13>0,J13/I13,"")
L14: =IF(AND(F14<>"",K14<>"Paid",K14<>"Closed unpaid"),Settings!$C$27-(TODAY()-F14),"") | M14: =IF(I14>0,J14/I14,"")
L15: =IF(AND(F15<>"",K15<>"Paid",K15<>"Closed unpaid"),Settings!$C$27-(TODAY()-F15),"") | M15: =IF(I15>0,J15/I15,"")
L16: =IF(AND(F16<>"",K16<>"Paid",K16<>"Closed unpaid"),Settings!$C$27-(TODAY()-F16),"") | M16: =IF(I16>0,J16/I16,"")
L17: =IF(AND(F17<>"",K17<>"Paid",K17<>"Closed unpaid"),Settings!$C$27-(TODAY()-F17),"") | M17: =IF(I17>0,J17/I17,"")
L18: =IF(AND(F18<>"",K18<>"Paid",K18<>"Closed unpaid"),Settings!$C$27-(TODAY()-F18),"") | M18: =IF(I18>0,J18/I18,"")
L19: =IF(AND(F19<>"",K19<>"Paid",K19<>"Closed unpaid"),Settings!$C$27-(TODAY()-F19),"") | M19: =IF(I19>0,J19/I19,"")
L20: =IF(AND(F20<>"",K20<>"Paid",K20<>"Closed unpaid"),Settings!$C$27-(TODAY()-F20),"") | M20: =IF(I20>0,J20/I20,"")
... L205: =IF(AND(F205<>"",K205<>"Paid",K205<>"Closed unpaid"),Settings!$C$27-(TODAY()-F205),"") | M205: =IF(I205>0,J205/I205,"")

Sheet Claim Packet
A2: =HYPERLINK("#'Claims Register'!A1", "← BACK") | D2: CLAIM PACKET | J2: =HYPERLINK("#'Coverage Reference'!A1", "NEXT →")
A4: Per-claim worksheet — fill from top to bottom. Reuse for next claim (or duplicate this tab if you want to keep history).
A6: §1 INCIDENT
B7: Discovery date: | C7: 46037
B8: Discovery time: | C8: 10:42 AM
B9: Discovered by: | C9: Cleaner — Sarah (Smokies Clean)
B10: Severity (1-5): | C10: 3
B11: Category: | C11: Furniture
B12: Narrative: | C12: Cleaner found the coffee table cracked diagonally across the top after guest checkout. Floor in living area is uneven by ~½ inch; guest had moved the table to set up a board game. Damage is structural — table is no longer usable.
A16: §2 DAMAGE LIST
B17: Item description | G17: Replacement cost | I17: Receipt? | K17: Photo?
B18: West Elm Mid-Century Coffee Table (oak) | G18: 340 | I18: Yes | K18: Yes
B29: Total replacement cost: | G29: =SUM(G18:H27)
A31: §3 EVIDENCE CHECKLIST — AT LEAST 75% TO BE 'SUBMIT-READY'
B32: ✓ | C32: Before-stay photo of item (intact)
B33: ✓ | C33: After-stay photo of damage
B34: ✓ | C34: Replacement receipt or invoice
B35: ✓ | C35: Written guest message acknowledging
B36: — | C36: Second witness if applicable
B37: — | C37: Police report number (if applicable)
B38: ✓ | C38: Date-stamped photos (metadata visible)
B39: ✓ | C39: Original receipt of damaged item
B40: ✓ | C40: Communication log with guest in writing
B41: ✓ | C41: Cleaner statement or text message
B42: ✓ | C42: Photos of contributing context (uneven floor)
B43: ✓ | C43: Inventory of items in room before stay
B45: Completeness score: | C45: =COUNTIF(B32:B43,"✓")/12
B46: Submit-ready? | C46: =IF(C45>=0.75,"✅ Submit-ready","⚠ Gather more evidence")
A48: §4 COMMUNICATIONS LOG
B49: Date / time | E49: Channel | G49: Direction | H49: Summary
B50: 2026-01-15 11:02 AM | E50: Airbnb msg | G50: Out | H50: Notified guest, asked what happened, included photo.
B51: 2026-01-15 02:18 PM | E51: Airbnb msg | G51: In | H51: Guest acknowledged moving table, apologized, declined direct payment.
B52: 2026-01-15 03:30 PM | E52: Airbnb msg | G52: Out | H52: Opened AirCover claim through Resolution Center.
B53: 2026-01-18 09:15 AM | E53: Airbnb msg | G53: In | H53: AirCover requested replacement receipt + serial of damaged item.
B54: 2026-01-18 10:40 AM | E54: Airbnb msg | G54: Out | H54: Sent receipt scan + product page screenshot.
B55: 2026-01-24 01:22 PM | E55: Airbnb email | G55: In | H55: AirCover approved $340 full payout.
A59: §5 TIMELINE
B60: Discovery | C60: 46037
B61: Guest contact opened | C61: 46037
B62: Platform claim escalated | C62: 46037
...

Sheet Coverage Reference
A2: =HYPERLINK("#'Claim Packet'!A1", "← BACK") | D2: COVERAGE REFERENCE | J2: =HYPERLINK("#'Message Scripts'!A1", "NEXT →")
A4: Policy snapshots — verified 2026-05-02. Verify the current policy at each platform's help center before relying on this for a claim.
A6: Airbnb AirCover for Hosts
A7: Reference: https://www.airbnb.com/aircover-for-hosts
A9: ✓ COVERED
A10: • Damage to your home, furnishings, or personal belongings caused by guest
A11: • Pet damage (whether or not pets were disclosed)
A12: • Income lost from cancellations required by guest damage
A13: • Deep cleaning cost from extreme mess (smoke, biohazard)
A14: • Damage from guests' guests / unauthorized parties
A15: • Auto / boat / equipment damage at the listing
A16: • Up to $3M USD in primary host damage protection
A17: • $1M USD in liability for guest injury or guest property damage
... A87: ⚠ Claim policies change frequently. Treat this tab as a starting point, not as legal advice. For high-value claims (>$500), confirm the current policy directly with the platform before submission.

Sheet Message Scripts
A2: =HYPERLINK("#'Coverage Reference'!A1", "← BACK") | D2: MESSAGE SCRIPTS | J2: =HYPERLINK("#'Annual Damage P&L'!A1", "NEXT →")
A4: Five copy-paste scripts for the most-common claim moments. Replace the [BRACKETED] fields with your specifics.
A6: Script 1 — First contact, propose direct resolution
A7: When to send: Within 2-4 hours of damage discovery. Goal: settle direct so you skip the platform process and the guest avoids a claim history. Offer ~70% of replacement cost as a friction-killer.
A9: Subject: Heads up about [item] in your stay
A10: Hi [Guest first name], Hope your trip home was easy. Quick heads-up — when our cleaner arrived this morning, we found [specific damage to specific item]. We're sure it was an accident. Easiest path for both of us: would you be open to sending $[70% of replacement cost] via Airbnb's Resolution Center directly? That covers the replacement and we close it out — no formal claim, no marks on your account. Photos attached for context. Let me know what you think. Thanks, [Your name]
A20: Customize: [Guest first name] · [specific damage to specific item] · [70% of replacement cost] · [Your name]
A23: Script 2 — Formal claim opening
A24: When to send: If guest doesn't respond to Script 1 within 24 hours, OR if guest declined to pay direct. File the platform claim. Tone: factual, not adversarial.
A26: Subject: Filing AirCover claim — [Booking ID]
A27: Hi [Guest first name], Following up on the [damage to item] from your stay — since we weren't able to resolve directly, I'm filing an AirCover claim for $[full replacement cost]. I've attached: before-stay photos showing intact, after-stay photos showing damage, and the replacement receipt. Airbnb may reach out for your side of the story. No action needed from you here unless they ask. Best, [Your name]
A37: Customize: [Guest first name] · [damage to item] · [Booking ID] · [full replacement cost] · [Your name]
A40: Script 3 — Evidence-request response (when AirCover asks for more)
... A85: Customize: [Guest first name] · [Damage to specific item] · [paid in full / partial / disputed]

Sheet Annual Damage P&L
A2: =HYPERLINK("#'Message Scripts'!A1", "← BACK") | D2: ANNUAL DAMAGE P&L | J2: =HYPERLINK("#'Settings'!A1", "NEXT →")
A4: Year-end summary — claims filed, recovery rate, top loss categories, by-property breakdown. Set the year below; everything else auto-pulls.
B6: Tax year: | C6: =YEAR(TODAY())
A8: TOTALS
B9: Total $ claimed: | C9: =SUMPRODUCT((YEAR('Claims Register'!A6:A205)=C6)*'Claims Register'!I6:I205)
B10: Total $ recovered: | C10: =SUMPRODUCT((YEAR('Claims Register'!A6:A205)=C6)*'Claims Register'!J6:J205)
B11: Recovery rate: | C11: =IFERROR(C10/C9,0)
B12: Claim count: | C12: =SUMPRODUCT((YEAR('Claims Register'!A6:A205)=C6)*('Claims Register'!A6:A205<>""))
B13: Avg claim size: | C13: =IFERROR(C9/C12,0)
A15: TOP LOSS CATEGORIES
B16: Furniture | C16: =SUMPRODUCT((YEAR('Claims Register'!A6:A205)=C6)*('Claims Register'!H6:H205=B16)*'Claims Register'!I6:I205)
B17: Appliance | C17: =SUMPRODUCT((YEAR('Claims Register'!A6:A205)=C6)*('Claims Register'!H6:H205=B17)*'Claims Register'!I6:I205)
B18: Decor | C18: =SUMPRODUCT((YEAR('Claims Register'!A6:A205)=C6)*('Claims Register'!H6:H205=B18)*'Claims Register'!I6:I205)
B19: Linen | C19: =SUMPRODUCT((YEAR('Claims Register'!A6:A205)=C6)*('Claims Register'!H6:H205=B19)*'Claims Register'!I6:I205)
B20: Structural | C20: =SUMPRODUCT((YEAR('Claims Register'!A6:A205)=C6)*('Claims Register'!H6:H205=B20)*'Claims Register'!I6:I205)
B21: Other | C21: =SUMPRODUCT((YEAR('Claims Register'!A6:A205)=C6)*('Claims Register'!H6:H205=B21)*'Claims Register'!I6:I205)
A23: BY PROPERTY
B24: Property | C24: $ Claimed | D24: $ Recovered
B25: Smokies Ridge Cabin | C25: =SUMPRODUCT((YEAR('Claims Register'!A6:A205)=C6)*('Claims Register'!B6:B205=B25)*'Claims Register'!I6:I205) | D25: =SUMPRODUCT((YEAR('Claims Register'!A6:A205)=C6)*('Claims Register'!B6:B205=B25)*'Claims Register'!J6:J205)
B26: Creek Side | C26: =SUMPRODUCT((YEAR('Claims Register'!A6:A205)=C6)*('Claims Register'!B6:B205=B26)*'Claims Register'!I6:I205) | D26: =SUMPRODUCT((YEAR('Claims Register'!A6:A205)=C6)*('Claims Register'!B6:B205=B26)*'Claims Register'!J6:J205)
B27: Lakehouse A | C27: =SUMPRODUCT((YEAR('Claims Register'!A6:A205)=C6)*('Claims Register'!B6:B205=B27)*'Claims Register'!I6:I205) | D27: =SUMPRODUCT((YEAR('Claims Register'!A6:A205)=C6)*('Claims Register'!B6:B205=B27)*'Claims Register'!J6:J205)
B28: Lakehouse B | C28: =SUMPRODUCT((YEAR('Claims Register'!A6:A205)=C6)*('Claims Register'!B6:B205=B28)*'Claims Register'!I6:I205) | D28: =SUMPRODUCT((YEAR('Claims Register'!A6:A205)=C6)*('Claims Register'!B6:B205=B28)*'Claims Register'!J6:J205)
B29: Mountain View | C29: =SUMPRODUCT((YEAR('Claims Register'!A6:A205)=C6)*('Claims Register'!B6:B205=B29)*'Claims Register'!I6:I205) | D29: =SUMPRODUCT((YEAR('Claims Register'!A6:A205)=C6)*('Claims Register'!B6:B205=B29)*'Claims Register'!J6:J205)
B30: Downtown Loft | C30: =SUMPRODUCT((YEAR('Claims Register'!A6:A205)=C6)*('Claims Register'!B6:B205=B30)*'Claims Register'!I6:I205) | D30: =SUMPRODUCT((YEAR('Claims Register'!A6:A205)=C6)*('Claims Register'!B6:B205=B30)*'Claims Register'!J6:J205)

Sheet Settings
A2: =HYPERLINK("#'Annual Damage P&L'!A1", "← BACK") | D2: SETTINGS
A4: Edit these lists to match your portfolio + workflow. They drive the dropdowns on the Claims Register and Claim Packet tabs.
B5: Properties | C5: Claim status | D5: Damage category
B6: Smokies Ridge Cabin | C6: Discovered | D6: Furniture
B7: Creek Side | C7: Evidence gathering | D7: Appliance
B8: Lakehouse A | C8: Submitted | D8: Decor
B9: Lakehouse B | C9: Disputed | D9: Linen
B10: Mountain View | C10: Paid | D10: Structural
B11: Downtown Loft | C11: Closed unpaid | D11: Other
C12: Other
B27: Filing window (days): | C27: 14
B28: Default 14 days = Airbnb's standard filing window from guest checkout. VRBO is generally 60 days, Booking.com generally 30. Set this to match your most-common channel or the strictest one.
B30: Coverage Reference verified: | C30: 46144
