Workbook

Sheet Start
A2: The STR Ledger
A4: Cleaner Turnover Checklist + Scorecard
A5: Turnover chaos has a spreadsheet.
A7: OPS-001 · v2.3 · DEMO
A10: WHAT THIS DOES
A11: A 40-item per-turnover checklist your cleaner runs every time, plus a host-side log + Scorecard Dashboard that ranks your cleaners over time. After a few weeks of data, you'll know who your A-team is — by score, issue rate, and time-on-site — instead of relying on gut feel.
A18: HOW TO USE
A19: ① Print the Printable Checklist tab — one per turnover. Hand to your cleaner.
A20: ② Cleaner checks off each item, signs, dates, returns to you (text photo OK).
A21: ③ Open Turnover Log → add a row: date, property, cleaner, items checked, notes.
A22: ④ Open Scorecard Dashboard → see your ranked cleaners + issue rates.
A23: ⑤ Cleaner Roster: list all cleaners — drives the Turnover Log dropdown.
A24: ⑥ (Optional) Supplies Par Levels: per-property stock targets so par-checks are objective.
A27: =HYPERLINK("#'Printable Checklist'!A1", "→ PRINT CHECKLIST (OPEN PRINTABLE)")
A32: TURNOVERS LOGGED | E32: AVG SCORE | I32: ISSUE RATE
A33: =COUNTA('Turnover Log'!A6:A506) | E33: =IFERROR(AVERAGE('Turnover Log'!D6:D506),"—") | I33: =IFERROR(COUNTIF('Turnover Log'!F6:F506,"Yes")/COUNTA('Turnover Log'!A6:A506),"—")
A35: rows on the Turnover Log | E35: items checked / 52 max | I35: turnovers with guest complaints
A39: =HYPERLINK("#'Turnover Log'!A1", "Turnover Log") | D39: =HYPERLINK("#'Scorecard Dashboard'!A1", "Scorecard Dashboard") | G39: =HYPERLINK("#'Cleaner Roster'!A1", "Cleaner Roster") | J39: =HYPERLINK("#'Supplies Par Levels'!A1", "Supplies Par Levels")
A42: 🧰 BEFORE FIRST USE: open the Cleaner Roster tab, replace the 3 sample cleaners with your real ones; open Scorecard Dashboard rows 18-23 and swap sample property names. Then print the Checklist for your next turnover.
A45: 💡 Upgrade to the Full version at thestrledger.com/upgrade — multi-property, depreciation, multi-LLC support.
A48: Questions? hello@thestrledger.com
A49: OPS-001 · v2.3 · Free updates forever

Sheet Printable Checklist
A1: =HYPERLINK("#'Start'!A1", "← START") | C1: =HYPERLINK("#'Turnover Log'!A1", "Log →")
A4: Cleaner Turnover Checklist
A5: Print one per turnover · The STR Ledger
A6: Property: | C6: Date:
A8: BEDROOM (6)
A9: ☐ | B9: Dust all horizontal surfaces (nightstands, dresser, headboard)
A10: ☐ | B10: Strip and replace bed linens (crisp hospital corners)
A11: ☐ | B11: Fresh pillowcases both sides
A12: ☐ | B12: Vacuum under bed
A13: ☐ | B13: Empty wastebasket
A14: ☐ | B14: Check under bed for guest items
A16: BATHROOM (8)
A17: ☐ | B17: Scrub toilet inside + outside base
A18: ☐ | B18: Clean mirror streak-free
A19: ☐ | B19: Wipe + SANITIZE sink, faucet handles, light switches (high-touch, EPA-approved)
A20: ☐ | B20: Scrub shower/tub including drain
A21: ☐ | B21: Replace towels (bath, hand, face)
A22: ☐ | B22: Restock toilet paper (min 2 rolls)
A23: ☐ | B23: Empty wastebasket
A24: ☐ | B24: Check + restock soap, shampoo, body wash to par
A26: KITCHEN (9)
A27: ☐ | B27: Wipe all counters
A28: ☐ | B28: Clean stovetop (all burners + under)
A29: ☐ | B29: Wipe inside microwave
A30: ☐ | B30: Run dishwasher if items inside
A31: ☐ | B31: Wipe fridge exterior + handles
A32: ☐ | B32: Check fridge interior for guest leftovers (discard)
A33: ☐ | B33: Empty trash + replace liner
A34: ☐ | B34: Restock coffee + filters (check par level)
A35: ☐ | B35: SANITIZE high-touch: cabinet handles, faucet, light switches (EPA-approved)
A37: LIVING (6)
A38: ☐ | B38: Vacuum/sweep floors
A39: ☐ | B39: Dust TV + surfaces
A40: ☐ | B40: Fluff + realign pillows + throws
A41: ☐ | B41: Wipe + SANITIZE remote controls, light switches, door knobs (high-touch)
A42: ☐ | B42: Reset all furniture to original position
A43: ☐ | B43: Test wifi connects + speed (note router reset if needed)
A45: OUTDOOR (5)
A46: ☐ | B46: Sweep porch/deck
A47: ☐ | B47: Wipe outdoor furniture if present
...

Sheet Turnover Log
A2: =HYPERLINK("#'Printable Checklist'!A1", "← BACK") | D2: TURNOVER LOG | J2: =HYPERLINK("#'Scorecard Dashboard'!A1", "NEXT →")
A4: One row per turnover — feeds the Scorecard Dashboard
A5: Date | B5: Property | C5: Cleaner | D5: Items Checked (0-52) | E5: Notes/Issues | F5: Guest Complaint? | G5: Minutes on Site
A6: 46095 | B6: Smokies Ridge | C6: Sarah — Smokies Clean | D6: 52 | E6: Perfect turnover | F6: No | G6: 95
A7: 46097 | B7: Creek Side | C7: Miguel — Ridge Housekeeping | D7: 47 | E7: Missed: CO detector test, hot tub strip | F7: No | G7: 110
A8: 46099 | B8: Lakehouse A | C8: Sarah — Smokies Clean | D8: 50 | E8: Minor: 1 pillowcase off-center | F8: No | G8: 90
A9: 46101 | B9: Smokies Ridge | C9: Jamie — Solo | D9: 41 | E9: TP not restocked; shower drain clogged; HVAC filter skipped | F9: Yes | G9: 75
A10: 46102 | B10: Lakehouse B | C10: Miguel — Ridge Housekeeping | D10: 49 | E10: All good | F10: No | G10: 105
A11: 46104 | B11: Smokies Ridge | C11: Sarah — Smokies Clean | D11: 49 | E11: Missed outdoor trash + pest sweep | F11: No | G11: 92
A12: 46106 | B12: Creek Side | C12: Jamie — Solo | D12: 38 | E12: Coffee pods empty; mirror streaked; high-touch sanitize skipped | F12: Yes | G12: 65
A13: 46107 | B13: Mountain View | C13: Miguel — Ridge Housekeeping | D13: 48 | F13: No | G13: 100
A14: 46109 | B14: Lakehouse A | C14: Sarah — Smokies Clean | D14: 52 | F14: No | G14: 88
A15: 46110 | B15: Downtown Loft | C15: Miguel — Ridge Housekeeping | D15: 45 | E15: Dishwasher not run, damage photo log incomplete | F15: No | G15: 85
A16: 46111 | B16: Smokies Ridge | C16: Sarah — Smokies Clean | D16: 48 | E16: Late start — guest arrived early | F16: No | G16: 70
A17: 46113 | B17: Lakehouse B | C17: Jamie — Solo | D17: 44 | E17: Fridge not checked | F17: No | G17: 72
A18: 46115 | B18: Mountain View | C18: Miguel — Ridge Housekeeping | D18: 47 | F18: No | G18: 95
A19: 46117 | B19: Creek Side | C19: Jamie — Solo | D19: 44 | E19: Minor: thermostat not reset | F19: No | G19: 68
A20: 46119 | B20: Lakehouse A | C20: Miguel — Ridge Housekeeping | D20: 50 | F20: No | G20: 100

Sheet Scorecard Dashboard
A2: =HYPERLINK("#'Turnover Log'!A1", "← BACK") | D2: SCORECARD DASHBOARD | J2: =HYPERLINK("#'Cleaner Roster'!A1", "NEXT →")
A4: Rolling metrics per cleaner — auto-calculated from the Turnover Log
A5: Cleaner | B5: Turnovers | C5: Avg Score | D5: Issue Rate | E5: Rank
A6: Sarah — Smokies Clean | B6: =IF(A6="","",COUNTIF('Turnover Log'!C:C,A6)) | C6: =IF(A6="","",IFERROR(AVERAGEIF('Turnover Log'!C:C,A6,'Turnover Log'!D:D),0)) | D6: =IF(A6="","",IFERROR(COUNTIFS('Turnover Log'!C:C,A6,'Turnover Log'!F:F,"Yes")/COUNTIF('Turnover Log'!C:C,A6),0)) | E6: =IF(OR(A6="",B6=0),"",RANK.EQ(C6,$C$6:$C$15,0))
A7: Miguel — Ridge Housekeeping | B7: =IF(A7="","",COUNTIF('Turnover Log'!C:C,A7)) | C7: =IF(A7="","",IFERROR(AVERAGEIF('Turnover Log'!C:C,A7,'Turnover Log'!D:D),0)) | D7: =IF(A7="","",IFERROR(COUNTIFS('Turnover Log'!C:C,A7,'Turnover Log'!F:F,"Yes")/COUNTIF('Turnover Log'!C:C,A7),0)) | E7: =IF(OR(A7="",B7=0),"",RANK.EQ(C7,$C$6:$C$15,0))
A8: Jamie — Solo | B8: =IF(A8="","",COUNTIF('Turnover Log'!C:C,A8)) | C8: =IF(A8="","",IFERROR(AVERAGEIF('Turnover Log'!C:C,A8,'Turnover Log'!D:D),0)) | D8: =IF(A8="","",IFERROR(COUNTIFS('Turnover Log'!C:C,A8,'Turnover Log'!F:F,"Yes")/COUNTIF('Turnover Log'!C:C,A8),0)) | E8: =IF(OR(A8="",B8=0),"",RANK.EQ(C8,$C$6:$C$15,0))
B9: =IF(A9="","",COUNTIF('Turnover Log'!C:C,A9)) | C9: =IF(A9="","",IFERROR(AVERAGEIF('Turnover Log'!C:C,A9,'Turnover Log'!D:D),0)) | D9: =IF(A9="","",IFERROR(COUNTIFS('Turnover Log'!C:C,A9,'Turnover Log'!F:F,"Yes")/COUNTIF('Turnover Log'!C:C,A9),0)) | E9: =IF(OR(A9="",B9=0),"",RANK.EQ(C9,$C$6:$C$15,0))
B10: =IF(A10="","",COUNTIF('Turnover Log'!C:C,A10)) | C10: =IF(A10="","",IFERROR(AVERAGEIF('Turnover Log'!C:C,A10,'Turnover Log'!D:D),0)) | D10: =IF(A10="","",IFERROR(COUNTIFS('Turnover Log'!C:C,A10,'Turnover Log'!F:F,"Yes")/COUNTIF('Turnover Log'!C:C,A10),0)) | E10: =IF(OR(A10="",B10=0),"",RANK.EQ(C10,$C$6:$C$15,0))
B11: =IF(A11="","",COUNTIF('Turnover Log'!C:C,A11)) | C11: =IF(A11="","",IFERROR(AVERAGEIF('Turnover Log'!C:C,A11,'Turnover Log'!D:D),0)) | D11: =IF(A11="","",IFERROR(COUNTIFS('Turnover Log'!C:C,A11,'Turnover Log'!F:F,"Yes")/COUNTIF('Turnover Log'!C:C,A11),0)) | E11: =IF(OR(A11="",B11=0),"",RANK.EQ(C11,$C$6:$C$15,0))
B12: =IF(A12="","",COUNTIF('Turnover Log'!C:C,A12)) | C12: =IF(A12="","",IFERROR(AVERAGEIF('Turnover Log'!C:C,A12,'Turnover Log'!D:D),0)) | D12: =IF(A12="","",IFERROR(COUNTIFS('Turnover Log'!C:C,A12,'Turnover Log'!F:F,"Yes")/COUNTIF('Turnover Log'!C:C,A12),0)) | E12: =IF(OR(A12="",B12=0),"",RANK.EQ(C12,$C$6:$C$15,0))
B13: =IF(A13="","",COUNTIF('Turnover Log'!C:C,A13)) | C13: =IF(A13="","",IFERROR(AVERAGEIF('Turnover Log'!C:C,A13,'Turnover Log'!D:D),0)) | D13: =IF(A13="","",IFERROR(COUNTIFS('Turnover Log'!C:C,A13,'Turnover Log'!F:F,"Yes")/COUNTIF('Turnover Log'!C:C,A13),0)) | E13: =IF(OR(A13="",B13=0),"",RANK.EQ(C13,$C$6:$C$15,0))
B14: =IF(A14="","",COUNTIF('Turnover Log'!C:C,A14)) | C14: =IF(A14="","",IFERROR(AVERAGEIF('Turnover Log'!C:C,A14,'Turnover Log'!D:D),0)) | D14: =IF(A14="","",IFERROR(COUNTIFS('Turnover Log'!C:C,A14,'Turnover Log'!F:F,"Yes")/COUNTIF('Turnover Log'!C:C,A14),0)) | E14: =IF(OR(A14="",B14=0),"",RANK.EQ(C14,$C$6:$C$15,0))
B15: =IF(A15="","",COUNTIF('Turnover Log'!C:C,A15)) | C15: =IF(A15="","",IFERROR(AVERAGEIF('Turnover Log'!C:C,A15,'Turnover Log'!D:D),0)) | D15: =IF(A15="","",IFERROR(COUNTIFS('Turnover Log'!C:C,A15,'Turnover Log'!F:F,"Yes")/COUNTIF('Turnover Log'!C:C,A15),0)) | E15: =IF(OR(A15="",B15=0),"",RANK.EQ(C15,$C$6:$C$15,0))
A17: Properties (source for Turnover Log dropdown):
A18: Smokies Ridge
A19: Creek Side
A20: Lakehouse A
A21: Lakehouse B
A22: Mountain View
A23: Downtown Loft

Sheet Cleaner Roster
A2: =HYPERLINK("#'Scorecard Dashboard'!A1", "← BACK") | D2: CLEANER ROSTER | J2: =HYPERLINK("#'Supplies Par Levels'!A1", "NEXT →")
A4: Your team in one place — feeds the Turnover Log dropdown
A5: Name | B5: Phone | C5: Email | D5: Pay Rate | E5: Start Date | F5: Notes
A6: Sarah — Smokies Clean | B6: (865) 555-0145 | C6: sarah@smokiesclean.com | D6: 45 | E6: 45809 | F6: Flat rate per turnover; reliable
A7: Miguel — Ridge Housekeeping | B7: (865) 555-0177 | C7: miguel@ridgehk.com | D7: 40 | E7: 45884 | F7: Team of 2; can handle back-to-back
A8: Jamie — Solo | B8: (865) 555-0192 | C8: jamie.cleans@gmail.com | D8: 35 | E8: 46032 | F8: New — still ramping

Sheet Supplies Par Levels
A2: =HYPERLINK("#'Cleaner Roster'!A1", "← BACK") | D2: SUPPLIES PAR LEVELS
A4: Per-property stock targets — makes par-checks objective
A5: Property | B5: Coffee pods | C5: Paper towels | D5: TP rolls | E5: Dish pods | F5: Laundry pods | G5: Shampoo | H5: Body wash | I5: Trash bags | J5: Snacks
A6: Smokies Ridge | B6: 12 | C6: 4 | D6: 8 | E6: 30 | F6: 12 | G6: 3 | H6: 3 | I6: 20 | J6: 0
A7: Creek Side | B7: 10 | C7: 3 | D7: 6 | E7: 20 | F7: 10 | G7: 2 | H7: 2 | I7: 15 | J7: 0
A8: Lakehouse A | B8: 15 | C8: 4 | D8: 10 | E8: 30 | F8: 15 | G8: 4 | H8: 4 | I8: 25 | J8: 6
