Workbook

Sheet Welcome
A1: Cleaner Turnover Checklist + Scorecard
A2: Turnover chaos has a spreadsheet.
A3: The STR Ledger · thestrledger.com
A5: How this works
A6: 1. Print tab 2 (Printable Checklist) — one per turnover. Give to cleaner.
A7: 2. Cleaner checks off each item, signs, dates, returns to you.
A8: 3. After turnover, open tab 3 (Turnover Log). Add a row: date, property, cleaner, items checked, notes.
A9: 4. Open tab 4 (Scorecard Dashboard). See who your best cleaner is at a glance.
A10: 5. Tab 5 (Cleaner Roster): list all your cleaners. Dropdown on Turnover Log pulls from here.
A11: 6. Tab 6 (Supplies Par Levels): optional — per-property stock targets.
A13: Before first use
A14: • Go to tab 5, replace the 3 sample cleaners with your real ones.
... A18: 💡 Upgrade to the Full version at thestrledger.com/upgrade — multi-property, depreciation, multi-LLC support.

Sheet Printable Checklist
A1: Turnover Checklist
A2: Print one per turnover
A3: The STR Ledger · thestrledger.com
A4: Property: | C4: Date:
A6: BEDROOM (6)
A7: ☐ | B7: Dust all horizontal surfaces (nightstands, dresser, headboard)
A8: ☐ | B8: Strip and replace bed linens (crisp hospital corners)
A9: ☐ | B9: Fresh pillowcases both sides
A10: ☐ | B10: Vacuum under bed
A11: ☐ | B11: Empty wastebasket
A12: ☐ | B12: Check under bed for guest items
A14: BATHROOM (7)
A15: ☐ | B15: Scrub toilet inside + outside base
A16: ☐ | B16: Clean mirror streak-free
A17: ☐ | B17: Wipe sink + faucet
A18: ☐ | B18: Scrub shower/tub including drain
A19: ☐ | B19: Replace towels (bath, hand, face)
A20: ☐ | B20: Restock toilet paper (min 2 rolls)
A21: ☐ | B21: Empty wastebasket
A23: KITCHEN (8)
A24: ☐ | B24: Wipe all counters
A25: ☐ | B25: Clean stovetop (all burners + under)
A26: ☐ | B26: Wipe inside microwave
A27: ☐ | B27: Run dishwasher if items inside
A28: ☐ | B28: Wipe fridge exterior + handles
A29: ☐ | B29: Check fridge interior for guest leftovers (discard)
A30: ☐ | B30: Empty trash + replace liner
A31: ☐ | B31: Restock coffee + filters (check par level)
A33: LIVING (5)
A34: ☐ | B34: Vacuum/sweep floors
A35: ☐ | B35: Dust TV + surfaces
A36: ☐ | B36: Fluff + realign pillows + throws
A37: ☐ | B37: Wipe remote controls
A38: ☐ | B38: Reset all furniture to original position
A40: OUTDOOR (4)
A41: ☐ | B41: Sweep porch/deck
A42: ☐ | B42: Wipe outdoor furniture if present
A43: ☐ | B43: Check hot tub cover seated + clean
A44: ☐ | B44: Empty outdoor trash
A46: SUPPLIES (4)
...

Sheet Turnover Log
A1: Turnover Log
A2: One row per turnover
A3: The STR Ledger · thestrledger.com
A5: Date | B5: Property | C5: Cleaner | D5: Items Checked (0-40) | E5: Notes/Issues | F5: Guest Complaint? | G5: Minutes on Site
A6: 2026-03-14 | B6: Smokies Ridge | C6: Sarah — Smokies Clean | D6: 40 | E6: Perfect turnover | F6: No | G6: 95
A7: 2026-03-16 | B7: Creek Side | C7: Miguel — Ridge Housekeeping | D7: 36 | E7: Missed: smoke detectors check | F7: No | G7: 110
A8: 2026-03-18 | B8: Lakehouse A | C8: Sarah — Smokies Clean | D8: 39 | E8: Minor: 1 pillowcase off-center | F8: No | G8: 90
A9: 2026-03-20 | B9: Smokies Ridge | C9: Jamie — Solo | D9: 32 | E9: TP not restocked; shower drain clogged | F9: Yes | G9: 75
A10: 2026-03-21 | B10: Lakehouse B | C10: Miguel — Ridge Housekeeping | D10: 38 | E10: All good | F10: No | G10: 105
A11: 2026-03-23 | B11: Smokies Ridge | C11: Sarah — Smokies Clean | D11: 38 | E11: Missed outdoor trash | F11: No | G11: 92
A12: 2026-03-25 | B12: Creek Side | C12: Jamie — Solo | D12: 30 | E12: Coffee pods empty; mirror streaked | F12: Yes | G12: 65
A13: 2026-03-26 | B13: Mountain View | C13: Miguel — Ridge Housekeeping | D13: 37 | F13: No | G13: 100
A14: 2026-03-28 | B14: Lakehouse A | C14: Sarah — Smokies Clean | D14: 40 | F14: No | G14: 88
A15: 2026-03-29 | B15: Downtown Loft | C15: Miguel — Ridge Housekeeping | D15: 35 | E15: Dishwasher not run | F15: No | G15: 85
A16: 2026-03-30 | B16: Smokies Ridge | C16: Sarah — Smokies Clean | D16: 37 | E16: Late start — guest arrived early | F16: No | G16: 70
A17: 2026-04-01 | B17: Lakehouse B | C17: Jamie — Solo | D17: 34 | E17: Fridge not checked | F17: No | G17: 72
A18: 2026-04-03 | B18: Mountain View | C18: Miguel — Ridge Housekeeping | D18: 36 | F18: No | G18: 95
A19: 2026-04-05 | B19: Creek Side | C19: Jamie — Solo | D19: 34 | E19: Minor: thermostat not reset | F19: No | G19: 68
A20: 2026-04-07 | B20: Lakehouse A | C20: Miguel — Ridge Housekeeping | D20: 38 | F20: No | G20: 100

Sheet Scorecard Dashboard
A1: Cleaner Scorecard Dashboard
A2: Rolling metrics per cleaner
A3: The STR Ledger · thestrledger.com
A5: Cleaner | B5: Turnovers | C5: Avg Score | D5: Issue Rate | E5: Rank
A6: Sarah — Smokies Clean | B6: =IF(A6="","",COUNTIF('Turnover Log'!C:C,A6)) | C6: =IF(A6="","",IFERROR(AVERAGEIF('Turnover Log'!C:C,A6,'Turnover Log'!D:D),0)) | D6: =IF(A6="","",IFERROR(COUNTIFS('Turnover Log'!C:C,A6,'Turnover Log'!F:F,"Yes")/COUNTIF('Turnover Log'!C:C,A6),0)) | E6: =IF(OR(A6="",B6=0),"",RANK.EQ(C6,$C$6:$C$15,0))
A7: Miguel — Ridge Housekeeping | B7: =IF(A7="","",COUNTIF('Turnover Log'!C:C,A7)) | C7: =IF(A7="","",IFERROR(AVERAGEIF('Turnover Log'!C:C,A7,'Turnover Log'!D:D),0)) | D7: =IF(A7="","",IFERROR(COUNTIFS('Turnover Log'!C:C,A7,'Turnover Log'!F:F,"Yes")/COUNTIF('Turnover Log'!C:C,A7),0)) | E7: =IF(OR(A7="",B7=0),"",RANK.EQ(C7,$C$6:$C$15,0))
A8: Jamie — Solo | B8: =IF(A8="","",COUNTIF('Turnover Log'!C:C,A8)) | C8: =IF(A8="","",IFERROR(AVERAGEIF('Turnover Log'!C:C,A8,'Turnover Log'!D:D),0)) | D8: =IF(A8="","",IFERROR(COUNTIFS('Turnover Log'!C:C,A8,'Turnover Log'!F:F,"Yes")/COUNTIF('Turnover Log'!C:C,A8),0)) | E8: =IF(OR(A8="",B8=0),"",RANK.EQ(C8,$C$6:$C$15,0))
B9: =IF(A9="","",COUNTIF('Turnover Log'!C:C,A9)) | C9: =IF(A9="","",IFERROR(AVERAGEIF('Turnover Log'!C:C,A9,'Turnover Log'!D:D),0)) | D9: =IF(A9="","",IFERROR(COUNTIFS('Turnover Log'!C:C,A9,'Turnover Log'!F:F,"Yes")/COUNTIF('Turnover Log'!C:C,A9),0)) | E9: =IF(OR(A9="",B9=0),"",RANK.EQ(C9,$C$6:$C$15,0))
B10: =IF(A10="","",COUNTIF('Turnover Log'!C:C,A10)) | C10: =IF(A10="","",IFERROR(AVERAGEIF('Turnover Log'!C:C,A10,'Turnover Log'!D:D),0)) | D10: =IF(A10="","",IFERROR(COUNTIFS('Turnover Log'!C:C,A10,'Turnover Log'!F:F,"Yes")/COUNTIF('Turnover Log'!C:C,A10),0)) | E10: =IF(OR(A10="",B10=0),"",RANK.EQ(C10,$C$6:$C$15,0))
B11: =IF(A11="","",COUNTIF('Turnover Log'!C:C,A11)) | C11: =IF(A11="","",IFERROR(AVERAGEIF('Turnover Log'!C:C,A11,'Turnover Log'!D:D),0)) | D11: =IF(A11="","",IFERROR(COUNTIFS('Turnover Log'!C:C,A11,'Turnover Log'!F:F,"Yes")/COUNTIF('Turnover Log'!C:C,A11),0)) | E11: =IF(OR(A11="",B11=0),"",RANK.EQ(C11,$C$6:$C$15,0))
B12: =IF(A12="","",COUNTIF('Turnover Log'!C:C,A12)) | C12: =IF(A12="","",IFERROR(AVERAGEIF('Turnover Log'!C:C,A12,'Turnover Log'!D:D),0)) | D12: =IF(A12="","",IFERROR(COUNTIFS('Turnover Log'!C:C,A12,'Turnover Log'!F:F,"Yes")/COUNTIF('Turnover Log'!C:C,A12),0)) | E12: =IF(OR(A12="",B12=0),"",RANK.EQ(C12,$C$6:$C$15,0))
B13: =IF(A13="","",COUNTIF('Turnover Log'!C:C,A13)) | C13: =IF(A13="","",IFERROR(AVERAGEIF('Turnover Log'!C:C,A13,'Turnover Log'!D:D),0)) | D13: =IF(A13="","",IFERROR(COUNTIFS('Turnover Log'!C:C,A13,'Turnover Log'!F:F,"Yes")/COUNTIF('Turnover Log'!C:C,A13),0)) | E13: =IF(OR(A13="",B13=0),"",RANK.EQ(C13,$C$6:$C$15,0))
B14: =IF(A14="","",COUNTIF('Turnover Log'!C:C,A14)) | C14: =IF(A14="","",IFERROR(AVERAGEIF('Turnover Log'!C:C,A14,'Turnover Log'!D:D),0)) | D14: =IF(A14="","",IFERROR(COUNTIFS('Turnover Log'!C:C,A14,'Turnover Log'!F:F,"Yes")/COUNTIF('Turnover Log'!C:C,A14),0)) | E14: =IF(OR(A14="",B14=0),"",RANK.EQ(C14,$C$6:$C$15,0))
B15: =IF(A15="","",COUNTIF('Turnover Log'!C:C,A15)) | C15: =IF(A15="","",IFERROR(AVERAGEIF('Turnover Log'!C:C,A15,'Turnover Log'!D:D),0)) | D15: =IF(A15="","",IFERROR(COUNTIFS('Turnover Log'!C:C,A15,'Turnover Log'!F:F,"Yes")/COUNTIF('Turnover Log'!C:C,A15),0)) | E15: =IF(OR(A15="",B15=0),"",RANK.EQ(C15,$C$6:$C$15,0))
A17: Properties (source for Turnover Log dropdown):
A18: Smokies Ridge
A19: Creek Side
A20: Lakehouse A
A21: Lakehouse B
A22: Mountain View
A23: Downtown Loft

Sheet Cleaner Roster
A1: Cleaner Roster
A2: Your team, in one place
A3: The STR Ledger · thestrledger.com
A5: Name | B5: Phone | C5: Email | D5: Pay Rate | E5: Start Date | F5: Notes
A6: Sarah — Smokies Clean | B6: (865) 555-0145 | C6: sarah@smokiesclean.com | D6: 45 | E6: 2025-06-01 | F6: Flat rate per turnover; reliable
A7: Miguel — Ridge Housekeeping | B7: (865) 555-0177 | C7: miguel@ridgehk.com | D7: 40 | E7: 2025-08-15 | F7: Team of 2; can handle back-to-back
A8: Jamie — Solo | B8: (865) 555-0192 | C8: jamie.cleans@gmail.com | D8: 35 | E8: 2026-01-10 | F8: New — still ramping

Sheet Supplies Par Levels
A1: Supplies Par Levels by Property
A2: Bonus: per-property stock targets
A3: The STR Ledger · thestrledger.com
A5: Property | B5: Coffee pods | C5: Paper towels | D5: TP rolls | E5: Dish pods | F5: Laundry pods | G5: Shampoo | H5: Body wash | I5: Trash bags | J5: Snacks
A6: Smokies Ridge | B6: 12 | C6: 4 | D6: 8 | E6: 30 | F6: 12 | G6: 3 | H6: 3 | I6: 20 | J6: 0
A7: Creek Side | B7: 10 | C7: 3 | D7: 6 | E7: 20 | F7: 10 | G7: 2 | H7: 2 | I7: 15 | J7: 0
A8: Lakehouse A | B8: 15 | C8: 4 | D8: 10 | E8: 30 | F8: 15 | G8: 4 | H8: 4 | I8: 25 | J8: 6
