Workbook

Sheet Start
A2: The STR Ledger
A4: Supply Inventory + Par-Level Restock
A5: Never run out of TP between guests again.
A7: OPS-005 · v2.2 · BLANK
A10: WHAT THIS DOES
A11: Tracks consumables (linens, toiletries, cleaning supplies, paper goods) per property with a par level — the minimum quantity you keep on hand. When on-hand drops below par, the item shows up on the Restock List with the shortfall and dollar cost. Vendor Quick Order pages bundle every below-par item into copy-paste shopping lists for Costco, Amazon, Sam's Club, and local stores.
A18: HOW TO USE
A19: ① Settings: edit the property list, vendor list, and category list to match your portfolio.
A20: ② Inventory tab: add every consumable — SKU, item, property, par level, current count, vendor, unit cost.
A21: ③ After each turnover: update the On-hand column. Shortfall and $ to restock recalculate automatically.
A22: ④ Restock List: glance at the count of items below par and the total restock cost — sorted by shortfall.
A23: ⑤ Vendor Quick Order: open the page for the vendor you're shopping at, copy the list, paste into the cart.
A24: ⑥ When supplies arrive: bump the On-hand count and update Last Restocked date — par alerts clear automatically.
A27: =HYPERLINK("#'Inventory'!A6", "→ OPEN INVENTORY (LOG ON-HAND COUNTS)")
A32: ITEMS TRACKED | E32: ITEMS BELOW PAR | I32: $ TO RESTOCK
A33: =COUNTA(Inventory!A6:A205) | E33: =COUNTIF(Inventory!G6:G205,">0") | I33: =SUM(Inventory!K6:K205)
A35: rows on the Inventory tab | E35: need restock now | I35: shortfall × unit cost
A39: =HYPERLINK("#'Restock List'!A1", "→ Restock List") | D39: =HYPERLINK("#'Vendor Quick Order'!A1", "Vendor Quick Order") | G39: =HYPERLINK("#'Inventory'!A1", "Inventory") | J39: =HYPERLINK("#'Settings'!A1", "Settings")
A42: 🧺 PAR-LEVEL RULE: par = (linen sets per turnover × turnovers between restocks) + 1 buffer set. For a 4-bed Queen, 2 turnovers/wk, weekly Costco run → par = (4 × 2) + 4 = 12 sheet sets. Build it in once, stop scrambling forever.
A44: ⚠ Update On-hand counts after every turnover. Stale counts = surprise shortages. The Restock List is only as honest as the column to its left.
A47: Questions? hello@thestrledger.com
A48: OPS-005 · v2.2 · Free updates forever

Sheet Inventory
A2: =HYPERLINK("#'Start'!A1", "← BACK") | D2: INVENTORY | J2: =HYPERLINK("#'Restock List'!A1", "NEXT →")
A4: Master register — SKU, item, property, par, on-hand, vendor, unit cost
A5: SKU | B5: Item | C5: Category | D5: Property | E5: Par | F5: On-hand | G5: Shortfall | H5: Vendor | I5: Unit cost | J5: Reorder qty | K5: $ to restock | L5: Last restocked | M5: Notes
G6: =IF(OR(E6="",F6=""),"",MAX(0,E6-F6)) | K6: =IF(OR(G6="",I6=""),"",G6*I6)
G7: =IF(OR(E7="",F7=""),"",MAX(0,E7-F7)) | K7: =IF(OR(G7="",I7=""),"",G7*I7)
G8: =IF(OR(E8="",F8=""),"",MAX(0,E8-F8)) | K8: =IF(OR(G8="",I8=""),"",G8*I8)
G9: =IF(OR(E9="",F9=""),"",MAX(0,E9-F9)) | K9: =IF(OR(G9="",I9=""),"",G9*I9)
G10: =IF(OR(E10="",F10=""),"",MAX(0,E10-F10)) | K10: =IF(OR(G10="",I10=""),"",G10*I10)
G11: =IF(OR(E11="",F11=""),"",MAX(0,E11-F11)) | K11: =IF(OR(G11="",I11=""),"",G11*I11)
G12: =IF(OR(E12="",F12=""),"",MAX(0,E12-F12)) | K12: =IF(OR(G12="",I12=""),"",G12*I12)
G13: =IF(OR(E13="",F13=""),"",MAX(0,E13-F13)) | K13: =IF(OR(G13="",I13=""),"",G13*I13)
G14: =IF(OR(E14="",F14=""),"",MAX(0,E14-F14)) | K14: =IF(OR(G14="",I14=""),"",G14*I14)
G15: =IF(OR(E15="",F15=""),"",MAX(0,E15-F15)) | K15: =IF(OR(G15="",I15=""),"",G15*I15)
G16: =IF(OR(E16="",F16=""),"",MAX(0,E16-F16)) | K16: =IF(OR(G16="",I16=""),"",G16*I16)
G17: =IF(OR(E17="",F17=""),"",MAX(0,E17-F17)) | K17: =IF(OR(G17="",I17=""),"",G17*I17)
... G205: =IF(OR(E205="",F205=""),"",MAX(0,E205-F205)) | K205: =IF(OR(G205="",I205=""),"",G205*I205)

Sheet Restock List
A2: =HYPERLINK("#'Inventory'!A1", "← BACK") | D2: RESTOCK LIST · WHAT TO BUY NOW | J2: =HYPERLINK("#'Vendor Quick Order'!A1", "NEXT →")
A4: 📄 PRINT THIS LIST — items where on-hand < par, sorted by shortfall (largest first).
A5: ="Items below par: "&COUNTIF(Inventory!G6:G205,">0")&" · $ to restock total: $"&TEXT(SUM(Inventory!K6:K205),"#,##0.00")
A7: SKU | B7: Item | C7: Property | D7: Vendor | E7: Par | F7: On-hand | G7: Shortfall | H7: Unit cost | I7: $ to restock
A8: =IFERROR(IF(IFERROR(AGGREGATE(14,6,(Inventory!$G$6:$G$205+(205-ROW(Inventory!$G$6:$G$205))/10000)/(Inventory!$G$6:$G$205>0),1),"")="","",INDEX(Inventory!$A$6:$A$205,IFERROR(MATCH(IFERROR(AGGREGATE(14,6,(Inventory!$G$6:$G$205+(205-ROW(Inventory!$G$6:$G$205))/10000)/(Inventory!$G$6:$G$205>0),1),""),(Inventory!$G$6:$G$205+(205-ROW(Inventory!$G$6:$G$205))/10000),0),""))),"") | B8: =IFERROR(IF(IFERROR(AGGREGATE(14,6,(Inventory!$G$6:$G$205+(205-ROW(Inventory!$G$6:$G$205))/10000)/(Inventory!$G$6:$G$205>0),1),"")="","",INDEX(Inventory!$B$6:$B$205,IFERROR(MATCH(IFERROR(AGGREGATE(14,6,(Inventory!$G$6:$G$205+(205-ROW(Inventory!$G$6:$G$205))/10000)/(Inventory!$G$6:$G$205>0),1),""),(Inventory!$G$6:$G$205+(205-ROW(Inventory!$G$6:$G$205))/10000),0),""))),"") | C8: =IFERROR(IF(IFERROR(AGGREGATE(14,6,(Inventory!$G$6:$G$205+(205-ROW(Inventory!$G$6:$G$205))/10000)/(Inventory!$G$6:$G$205>0),1),"")="","",INDEX(Inventory!$D$6:$D$205,IFERROR(MATCH(IFERROR(AGGREGATE(14,6,(Inventory!$G$6:$G$205+(205-ROW(Inventory!$G$6:$G$205))/10000)/(Inventory!$G$6:$G$205>0),1),""),(Inventory!$G$6:$G$205+(205-ROW(Inventory!$G$6:$G$205))/10000),0),""))),"") | D8: =IFERROR(IF(IFERROR(AGGREGATE(14,6,(Inventory!$G$6:$G$205+(205-ROW(Inventory!$G$6:$G$205))/10000)/(Inventory!$G$6:$G$205>0),1),"")="","",INDEX(Inventory!$H$6:$H$205,IFERROR(MATCH(IFERROR(AGGREGATE(14,6,(Inventory!$G$6:$G$205+(205-ROW(Inventory!$G$6:$G$205))/10000)/(Inventory!$G$6:$G$205>0),1),""),(Inventory!$G$6:$G$205+(205-ROW(Inventory!$G$6:$G$205))/10000),0),""))),"") | E8: =IFERROR(IF(IFERROR(AGGREGATE(14,6,(Inventory!$G$6:$G$205+(205-ROW(Inventory!$G$6:$G$205))/10000)/(Inventory!$G$6:$G$205>0),1),"")="","",INDEX(Inventory!$E$6:$E$205,IFERROR(MATCH(IFERROR(AGGREGATE(14,6,(Inventory!$G$6:$G$205+(205-ROW(Inventory!$G$6:$G$205))/10000)/(Inventory!$G$6:$G$205>0),1),""),(Inventory!$G$6:$G$205+(205-ROW(Inventory!$G$6:$G$205))/10000),0),""))),"") | F8: =IFERROR(IF(IFERROR(AGGREGATE(14,6,(Inventory!$G$6:$G$205+(205-ROW(Inventory!$G$6:$G$205))/10000)/(Inventory!$G$6:$G$205>0),1),"")="","",INDEX(Inventory!$F$6:$F$205,IFERROR(MATCH(IFERROR(AGGREGATE(14,6,(Inventory!$G$6:$G$205+(205-ROW(Inventory!$G$6:$G$205))/10000)/(Inventory!$G$6:$G$205>0),1),""),(Inventory!$G$6:$G$205+(205-ROW(Inventory!$G$6:$G$205))/10000),0),""))),"") | G8: =IFERROR(IF(IFERROR(AGGREGATE(14,6,(Inventory!$G$6:$G$205+(205-ROW(Inventory!$G$6:$G$205))/10000)/(Inventory!$G$6:$G$205>0),1),"")="","",INDEX(Inventory!$G$6:$G$205,IFERROR(MATCH(IFERROR(AGGREGATE(14,6,(Inventory!$G$6:$G$205+(205-ROW(Inventory!$G$6:$G$205))/10000)/(Inventory!$G$6:$G$205>0),1),""),(Inventory!$G$6:$G$205+(205-ROW(Inventory!$G$6:$G$205))/10000),0),""))),"") | H8: =IFERROR(IF(IFERROR(AGGREGATE(14,6,(Inventory!$G$6:$G$205+(205-ROW(Inventory!$G$6:$G$205))/10000)/(Inventory!$G$6:$G$205>0),1),"")="","",INDEX(Inventory!$I$6:$I$205,IFERROR(MATCH(IFERROR(AGGREGATE(14,6,(Inventory!$G$6:$G$205+(205-ROW(Inventory!$G$6:$G$205))/10000)/(Inventory!$G$6:$G$205>0),1),""),(Inventory!$G$6:$G$205+(205-ROW(Inventory!$G$6:$G$205))/10000),0),""))),"") | I8: =IFERROR(IF(IFERROR(AGGREGATE(14,6,(Inventory!$G$6:$G$205+(205-ROW(Inventory!$G$6:$G$205))/10000)/(Inventory!$G$6:$G$205>0),1),"")="","",INDEX(Inventory!$K$6:$K$205,IFERROR(MATCH(IFERROR(AGGREGATE(14,6,(Inventory!$G$6:$G$205+(205-ROW(Inventory!$G$6:$G$205))/10000)/(Inventory!$G$6:$G$205>0),1),""),(Inventory!$G$6:$G$205+(205-ROW(Inventory!$G$6:$G$205))/10000),0),""))),"")
A9: =IFERROR(IF(IFERROR(AGGREGATE(14,6,(Inventory!$G$6:$G$205+(205-ROW(Inventory!$G$6:$G$205))/10000)/(Inventory!$G$6:$G$205>0),2),"")="","",INDEX(Inventory!$A$6:$A$205,IFERROR(MATCH(IFERROR(AGGREGATE(14,6,(Inventory!$G$6:$G$205+(205-ROW(Inventory!$G$6:$G$205))/10000)/(Inventory!$G$6:$G$205>0),2),""),(Inventory!$G$6:$G$205+(205-ROW(Inventory!$G$6:$G$205))/10000),0),""))),"") | B9: =IFERROR(IF(IFERROR(AGGREGATE(14,6,(Inventory!$G$6:$G$205+(205-ROW(Inventory!$G$6:$G$205))/10000)/(Inventory!$G$6:$G$205>0),2),"")="","",INDEX(Inventory!$B$6:$B$205,IFERROR(MATCH(IFERROR(AGGREGATE(14,6,(Inventory!$G$6:$G$205+(205-ROW(Inventory!$G$6:$G$205))/10000)/(Inventory!$G$6:$G$205>0),2),""),(Inventory!$G$6:$G$205+(205-ROW(Inventory!$G$6:$G$205))/10000),0),""))),"") | C9: =IFERROR(IF(IFERROR(AGGREGATE(14,6,(Inventory!$G$6:$G$205+(205-ROW(Inventory!$G$6:$G$205))/10000)/(Inventory!$G$6:$G$205>0),2),"")="","",INDEX(Inventory!$D$6:$D$205,IFERROR(MATCH(IFERROR(AGGREGATE(14,6,(Inventory!$G$6:$G$205+(205-ROW(Inventory!$G$6:$G$205))/10000)/(Inventory!$G$6:$G$205>0),2),""),(Inventory!$G$6:$G$205+(205-ROW(Inventory!$G$6:$G$205))/10000),0),""))),"") | D9: =IFERROR(IF(IFERROR(AGGREGATE(14,6,(Inventory!$G$6:$G$205+(205-ROW(Inventory!$G$6:$G$205))/10000)/(Inventory!$G$6:$G$205>0),2),"")="","",INDEX(Inventory!$H$6:$H$205,IFERROR(MATCH(IFERROR(AGGREGATE(14,6,(Inventory!$G$6:$G$205+(205-ROW(Inventory!$G$6:$G$205))/10000)/(Inventory!$G$6:$G$205>0),2),""),(Inventory!$G$6:$G$205+(205-ROW(Inventory!$G$6:$G$205))/10000),0),""))),"") | E9: =IFERROR(IF(IFERROR(AGGREGATE(14,6,(Inventory!$G$6:$G$205+(205-ROW(Inventory!$G$6:$G$205))/10000)/(Inventory!$G$6:$G$205>0),2),"")="","",INDEX(Inventory!$E$6:$E$205,IFERROR(MATCH(IFERROR(AGGREGATE(14,6,(Inventory!$G$6:$G$205+(205-ROW(Inventory!$G$6:$G$205))/10000)/(Inventory!$G$6:$G$205>0),2),""),(Inventory!$G$6:$G$205+(205-ROW(Inventory!$G$6:$G$205))/10000),0),""))),"") | F9: =IFERROR(IF(IFERROR(AGGREGATE(14,6,(Inventory!$G$6:$G$205+(205-ROW(Inventory!$G$6:$G$205))/10000)/(Inventory!$G$6:$G$205>0),2),"")="","",INDEX(Inventory!$F$6:$F$205,IFERROR(MATCH(IFERROR(AGGREGATE(14,6,(Inventory!$G$6:$G$205+(205-ROW(Inventory!$G$6:$G$205))/10000)/(Inventory!$G$6:$G$205>0),2),""),(Inventory!$G$6:$G$205+(205-ROW(Inventory!$G$6:$G$205))/10000),0),""))),"") | G9: =IFERROR(IF(IFERROR(AGGREGATE(14,6,(Inventory!$G$6:$G$205+(205-ROW(Inventory!$G$6:$G$205))/10000)/(Inventory!$G$6:$G$205>0),2),"")="","",INDEX(Inventory!$G$6:$G$205,IFERROR(MATCH(IFERROR(AGGREGATE(14,6,(Inventory!$G$6:$G$205+(205-ROW(Inventory!$G$6:$G$205))/10000)/(Inventory!$G$6:$G$205>0),2),""),(Inventory!$G$6:$G$205+(205-ROW(Inventory!$G$6:$G$205))/10000),0),""))),"") | H9: =IFERROR(IF(IFERROR(AGGREGATE(14,6,(Inventory!$G$6:$G$205+(205-ROW(Inventory!$G$6:$G$205))/10000)/(Inventory!$G$6:$G$205>0),2),"")="","",INDEX(Inventory!$I$6:$I$205,IFERROR(MATCH(IFERROR(AGGREGATE(14,6,(Inventory!$G$6:$G$205+(205-ROW(Inventory!$G$6:$G$205))/10000)/(Inventory!$G$6:$G$205>0),2),""),(Inventory!$G$6:$G$205+(205-ROW(Inventory!$G$6:$G$205))/10000),0),""))),"") | I9: =IFERROR(IF(IFERROR(AGGREGATE(14,6,(Inventory!$G$6:$G$205+(205-ROW(Inventory!$G$6:$G$205))/10000)/(Inventory!$G$6:$G$205>0),2),"")="","",INDEX(Inventory!$K$6:$K$205,IFERROR(MATCH(IFERROR(AGGREGATE(14,6,(Inventory!$G$6:$G$205+(205-ROW(Inventory!$G$6:$G$205))/10000)/(Inventory!$G$6:$G$205>0),2),""),(Inventory!$G$6:$G$205+(205-ROW(Inventory!$G$6:$G$205))/10000),0),""))),"")
A10: =IFERROR(IF(IFERROR(AGGREGATE(14,6,(Inventory!$G$6:$G$205+(205-ROW(Inventory!$G$6:$G$205))/10000)/(Inventory!$G$6:$G$205>0),3),"")="","",INDEX(Inventory!$A$6:$A$205,IFERROR(MATCH(IFERROR(AGGREGATE(14,6,(Inventory!$G$6:$G$205+(205-ROW(Inventory!$G$6:$G$205))/10000)/(Inventory!$G$6:$G$205>0),3),""),(Inventory!$G$6:$G$205+(205-ROW(Inventory!$G$6:$G$205))/10000),0),""))),"") | B10: =IFERROR(IF(IFERROR(AGGREGATE(14,6,(Inventory!$G$6:$G$205+(205-ROW(Inventory!$G$6:$G$205))/10000)/(Inventory!$G$6:$G$205>0),3),"")="","",INDEX(Inventory!$B$6:$B$205,IFERROR(MATCH(IFERROR(AGGREGATE(14,6,(Inventory!$G$6:$G$205+(205-ROW(Inventory!$G$6:$G$205))/10000)/(Inventory!$G$6:$G$205>0),3),""),(Inventory!$G$6:$G$205+(205-ROW(Inventory!$G$6:$G$205))/10000),0),""))),"") | C10: =IFERROR(IF(IFERROR(AGGREGATE(14,6,(Inventory!$G$6:$G$205+(205-ROW(Inventory!$G$6:$G$205))/10000)/(Inventory!$G$6:$G$205>0),3),"")="","",INDEX(Inventory!$D$6:$D$205,IFERROR(MATCH(IFERROR(AGGREGATE(14,6,(Inventory!$G$6:$G$205+(205-ROW(Inventory!$G$6:$G$205))/10000)/(Inventory!$G$6:$G$205>0),3),""),(Inventory!$G$6:$G$205+(205-ROW(Inventory!$G$6:$G$205))/10000),0),""))),"") | D10: =IFERROR(IF(IFERROR(AGGREGATE(14,6,(Inventory!$G$6:$G$205+(205-ROW(Inventory!$G$6:$G$205))/10000)/(Inventory!$G$6:$G$205>0),3),"")="","",INDEX(Inventory!$H$6:$H$205,IFERROR(MATCH(IFERROR(AGGREGATE(14,6,(Inventory!$G$6:$G$205+(205-ROW(Inventory!$G$6:$G$205))/10000)/(Inventory!$G$6:$G$205>0),3),""),(Inventory!$G$6:$G$205+(205-ROW(Inventory!$G$6:$G$205))/10000),0),""))),"") | E10: =IFERROR(IF(IFERROR(AGGREGATE(14,6,(Inventory!$G$6:$G$205+(205-ROW(Inventory!$G$6:$G$205))/10000)/(Inventory!$G$6:$G$205>0),3),"")="","",INDEX(Inventory!$E$6:$E$205,IFERROR(MATCH(IFERROR(AGGREGATE(14,6,(Inventory!$G$6:$G$205+(205-ROW(Inventory!$G$6:$G$205))/10000)/(Inventory!$G$6:$G$205>0),3),""),(Inventory!$G$6:$G$205+(205-ROW(Inventory!$G$6:$G$205))/10000),0),""))),"") | F10: =IFERROR(IF(IFERROR(AGGREGATE(14,6,(Inventory!$G$6:$G$205+(205-ROW(Inventory!$G$6:$G$205))/10000)/(Inventory!$G$6:$G$205>0),3),"")="","",INDEX(Inventory!$F$6:$F$205,IFERROR(MATCH(IFERROR(AGGREGATE(14,6,(Inventory!$G$6:$G$205+(205-ROW(Inventory!$G$6:$G$205))/10000)/(Inventory!$G$6:$G$205>0),3),""),(Inventory!$G$6:$G$205+(205-ROW(Inventory!$G$6:$G$205))/10000),0),""))),"") | G10: =IFERROR(IF(IFERROR(AGGREGATE(14,6,(Inventory!$G$6:$G$205+(205-ROW(Inventory!$G$6:$G$205))/10000)/(Inventory!$G$6:$G$205>0),3),"")="","",INDEX(Inventory!$G$6:$G$205,IFERROR(MATCH(IFERROR(AGGREGATE(14,6,(Inventory!$G$6:$G$205+(205-ROW(Inventory!$G$6:$G$205))/10000)/(Inventory!$G$6:$G$205>0),3),""),(Inventory!$G$6:$G$205+(205-ROW(Inventory!$G$6:$G$205))/10000),0),""))),"") | H10: =IFERROR(IF(IFERROR(AGGREGATE(14,6,(Inventory!$G$6:$G$205+(205-ROW(Inventory!$G$6:$G$205))/10000)/(Inventory!$G$6:$G$205>0),3),"")="","",INDEX(Inventory!$I$6:$I$205,IFERROR(MATCH(IFERROR(AGGREGATE(14,6,(Inventory!$G$6:$G$205+(205-ROW(Inventory!$G$6:$G$205))/10000)/(Inventory!$G$6:$G$205>0),3),""),(Inventory!$G$6:$G$205+(205-ROW(Inventory!$G$6:$G$205))/10000),0),""))),"") | I10: =IFERROR(IF(IFERROR(AGGREGATE(14,6,(Inventory!$G$6:$G$205+(205-ROW(Inventory!$G$6:$G$205))/10000)/(Inventory!$G$6:$G$205>0),3),"")="","",INDEX(Inventory!$K$6:$K$205,IFERROR(MATCH(IFERROR(AGGREGATE(14,6,(Inventory!$G$6:$G$205+(205-ROW(Inventory!$G$6:$G$205))/10000)/(Inventory!$G$6:$G$205>0),3),""),(Inventory!$G$6:$G$205+(205-ROW(Inventory!$G$6:$G$205))/10000),0),""))),"")
A11: =IFERROR(IF(IFERROR(AGGREGATE(14,6,(Inventory!$G$6:$G$205+(205-ROW(Inventory!$G$6:$G$205))/10000)/(Inventory!$G$6:$G$205>0),4),"")="","",INDEX(Inventory!$A$6:$A$205,IFERROR(MATCH(IFERROR(AGGREGATE(14,6,(Inventory!$G$6:$G$205+(205-ROW(Inventory!$G$6:$G$205))/10000)/(Inventory!$G$6:$G$205>0),4),""),(Inventory!$G$6:$G$205+(205-ROW(Inventory!$G$6:$G$205))/10000),0),""))),"") | B11: =IFERROR(IF(IFERROR(AGGREGATE(14,6,(Inventory!$G$6:$G$205+(205-ROW(Inventory!$G$6:$G$205))/10000)/(Inventory!$G$6:$G$205>0),4),"")="","",INDEX(Inventory!$B$6:$B$205,IFERROR(MATCH(IFERROR(AGGREGATE(14,6,(Inventory!$G$6:$G$205+(205-ROW(Inventory!$G$6:$G$205))/10000)/(Inventory!$G$6:$G$205>0),4),""),(Inventory!$G$6:$G$205+(205-ROW(Inventory!$G$6:$G$205))/10000),0),""))),"") | C11: =IFERROR(IF(IFERROR(AGGREGATE(14,6,(Inventory!$G$6:$G$205+(205-ROW(Inventory!$G$6:$G$205))/10000)/(Inventory!$G$6:$G$205>0),4),"")="","",INDEX(Inventory!$D$6:$D$205,IFERROR(MATCH(IFERROR(AGGREGATE(14,6,(Inventory!$G$6:$G$205+(205-ROW(Inventory!$G$6:$G$205))/10000)/(Inventory!$G$6:$G$205>0),4),""),(Inventory!$G$6:$G$205+(205-ROW(Inventory!$G$6:$G$205))/10000),0),""))),"") | D11: =IFERROR(IF(IFERROR(AGGREGATE(14,6,(Inventory!$G$6:$G$205+(205-ROW(Inventory!$G$6:$G$205))/10000)/(Inventory!$G$6:$G$205>0),4),"")="","",INDEX(Inventory!$H$6:$H$205,IFERROR(MATCH(IFERROR(AGGREGATE(14,6,(Inventory!$G$6:$G$205+(205-ROW(Inventory!$G$6:$G$205))/10000)/(Inventory!$G$6:$G$205>0),4),""),(Inventory!$G$6:$G$205+(205-ROW(Inventory!$G$6:$G$205))/10000),0),""))),"") | E11: =IFERROR(IF(IFERROR(AGGREGATE(14,6,(Inventory!$G$6:$G$205+(205-ROW(Inventory!$G$6:$G$205))/10000)/(Inventory!$G$6:$G$205>0),4),"")="","",INDEX(Inventory!$E$6:$E$205,IFERROR(MATCH(IFERROR(AGGREGATE(14,6,(Inventory!$G$6:$G$205+(205-ROW(Inventory!$G$6:$G$205))/10000)/(Inventory!$G$6:$G$205>0),4),""),(Inventory!$G$6:$G$205+(205-ROW(Inventory!$G$6:$G$205))/10000),0),""))),"") | F11: =IFERROR(IF(IFERROR(AGGREGATE(14,6,(Inventory!$G$6:$G$205+(205-ROW(Inventory!$G$6:$G$205))/10000)/(Inventory!$G$6:$G$205>0),4),"")="","",INDEX(Inventory!$F$6:$F$205,IFERROR(MATCH(IFERROR(AGGREGATE(14,6,(Inventory!$G$6:$G$205+(205-ROW(Inventory!$G$6:$G$205))/10000)/(Inventory!$G$6:$G$205>0),4),""),(Inventory!$G$6:$G$205+(205-ROW(Inventory!$G$6:$G$205))/10000),0),""))),"") | G11: =IFERROR(IF(IFERROR(AGGREGATE(14,6,(Inventory!$G$6:$G$205+(205-ROW(Inventory!$G$6:$G$205))/10000)/(Inventory!$G$6:$G$205>0),4),"")="","",INDEX(Inventory!$G$6:$G$205,IFERROR(MATCH(IFERROR(AGGREGATE(14,6,(Inventory!$G$6:$G$205+(205-ROW(Inventory!$G$6:$G$205))/10000)/(Inventory!$G$6:$G$205>0),4),""),(Inventory!$G$6:$G$205+(205-ROW(Inventory!$G$6:$G$205))/10000),0),""))),"") | H11: =IFERROR(IF(IFERROR(AGGREGATE(14,6,(Inventory!$G$6:$G$205+(205-ROW(Inventory!$G$6:$G$205))/10000)/(Inventory!$G$6:$G$205>0),4),"")="","",INDEX(Inventory!$I$6:$I$205,IFERROR(MATCH(IFERROR(AGGREGATE(14,6,(Inventory!$G$6:$G$205+(205-ROW(Inventory!$G$6:$G$205))/10000)/(Inventory!$G$6:$G$205>0),4),""),(Inventory!$G$6:$G$205+(205-ROW(Inventory!$G$6:$G$205))/10000),0),""))),"") | I11: =IFERROR(IF(IFERROR(AGGREGATE(14,6,(Inventory!$G$6:$G$205+(205-ROW(Inventory!$G$6:$G$205))/10000)/(Inventory!$G$6:$G$205>0),4),"")="","",INDEX(Inventory!$K$6:$K$205,IFERROR(MATCH(IFERROR(AGGREGATE(14,6,(Inventory!$G$6:$G$205+(205-ROW(Inventory!$G$6:$G$205))/10000)/(Inventory!$G$6:$G$205>0),4),""),(Inventory!$G$6:$G$205+(205-ROW(Inventory!$G$6:$G$205))/10000),0),""))),"")
A12: =IFERROR(IF(IFERROR(AGGREGATE(14,6,(Inventory!$G$6:$G$205+(205-ROW(Inventory!$G$6:$G$205))/10000)/(Inventory!$G$6:$G$205>0),5),"")="","",INDEX(Inventory!$A$6:$A$205,IFERROR(MATCH(IFERROR(AGGREGATE(14,6,(Inventory!$G$6:$G$205+(205-ROW(Inventory!$G$6:$G$205))/10000)/(Inventory!$G$6:$G$205>0),5),""),(Inventory!$G$6:$G$205+(205-ROW(Inventory!$G$6:$G$205))/10000),0),""))),"") | B12: =IFERROR(IF(IFERROR(AGGREGATE(14,6,(Inventory!$G$6:$G$205+(205-ROW(Inventory!$G$6:$G$205))/10000)/(Inventory!$G$6:$G$205>0),5),"")="","",INDEX(Inventory!$B$6:$B$205,IFERROR(MATCH(IFERROR(AGGREGATE(14,6,(Inventory!$G$6:$G$205+(205-ROW(Inventory!$G$6:$G$205))/10000)/(Inventory!$G$6:$G$205>0),5),""),(Inventory!$G$6:$G$205+(205-ROW(Inventory!$G$6:$G$205))/10000),0),""))),"") | C12: =IFERROR(IF(IFERROR(AGGREGATE(14,6,(Inventory!$G$6:$G$205+(205-ROW(Inventory!$G$6:$G$205))/10000)/(Inventory!$G$6:$G$205>0),5),"")="","",INDEX(Inventory!$D$6:$D$205,IFERROR(MATCH(IFERROR(AGGREGATE(14,6,(Inventory!$G$6:$G$205+(205-ROW(Inventory!$G$6:$G$205))/10000)/(Inventory!$G$6:$G$205>0),5),""),(Inventory!$G$6:$G$205+(205-ROW(Inventory!$G$6:$G$205))/10000),0),""))),"") | D12: =IFERROR(IF(IFERROR(AGGREGATE(14,6,(Inventory!$G$6:$G$205+(205-ROW(Inventory!$G$6:$G$205))/10000)/(Inventory!$G$6:$G$205>0),5),"")="","",INDEX(Inventory!$H$6:$H$205,IFERROR(MATCH(IFERROR(AGGREGATE(14,6,(Inventory!$G$6:$G$205+(205-ROW(Inventory!$G$6:$G$205))/10000)/(Inventory!$G$6:$G$205>0),5),""),(Inventory!$G$6:$G$205+(205-ROW(Inventory!$G$6:$G$205))/10000),0),""))),"") | E12: =IFERROR(IF(IFERROR(AGGREGATE(14,6,(Inventory!$G$6:$G$205+(205-ROW(Inventory!$G$6:$G$205))/10000)/(Inventory!$G$6:$G$205>0),5),"")="","",INDEX(Inventory!$E$6:$E$205,IFERROR(MATCH(IFERROR(AGGREGATE(14,6,(Inventory!$G$6:$G$205+(205-ROW(Inventory!$G$6:$G$205))/10000)/(Inventory!$G$6:$G$205>0),5),""),(Inventory!$G$6:$G$205+(205-ROW(Inventory!$G$6:$G$205))/10000),0),""))),"") | F12: =IFERROR(IF(IFERROR(AGGREGATE(14,6,(Inventory!$G$6:$G$205+(205-ROW(Inventory!$G$6:$G$205))/10000)/(Inventory!$G$6:$G$205>0),5),"")="","",INDEX(Inventory!$F$6:$F$205,IFERROR(MATCH(IFERROR(AGGREGATE(14,6,(Inventory!$G$6:$G$205+(205-ROW(Inventory!$G$6:$G$205))/10000)/(Inventory!$G$6:$G$205>0),5),""),(Inventory!$G$6:$G$205+(205-ROW(Inventory!$G$6:$G$205))/10000),0),""))),"") | G12: =IFERROR(IF(IFERROR(AGGREGATE(14,6,(Inventory!$G$6:$G$205+(205-ROW(Inventory!$G$6:$G$205))/10000)/(Inventory!$G$6:$G$205>0),5),"")="","",INDEX(Inventory!$G$6:$G$205,IFERROR(MATCH(IFERROR(AGGREGATE(14,6,(Inventory!$G$6:$G$205+(205-ROW(Inventory!$G$6:$G$205))/10000)/(Inventory!$G$6:$G$205>0),5),""),(Inventory!$G$6:$G$205+(205-ROW(Inventory!$G$6:$G$205))/10000),0),""))),"") | H12: =IFERROR(IF(IFERROR(AGGREGATE(14,6,(Inventory!$G$6:$G$205+(205-ROW(Inventory!$G$6:$G$205))/10000)/(Inventory!$G$6:$G$205>0),5),"")="","",INDEX(Inventory!$I$6:$I$205,IFERROR(MATCH(IFERROR(AGGREGATE(14,6,(Inventory!$G$6:$G$205+(205-ROW(Inventory!$G$6:$G$205))/10000)/(Inventory!$G$6:$G$205>0),5),""),(Inventory!$G$6:$G$205+(205-ROW(Inventory!$G$6:$G$205))/10000),0),""))),"") | I12: =IFERROR(IF(IFERROR(AGGREGATE(14,6,(Inventory!$G$6:$G$205+(205-ROW(Inventory!$G$6:$G$205))/10000)/(Inventory!$G$6:$G$205>0),5),"")="","",INDEX(Inventory!$K$6:$K$205,IFERROR(MATCH(IFERROR(AGGREGATE(14,6,(Inventory!$G$6:$G$205+(205-ROW(Inventory!$G$6:$G$205))/10000)/(Inventory!$G$6:$G$205>0),5),""),(Inventory!$G$6:$G$205+(205-ROW(Inventory!$G$6:$G$205))/10000),0),""))),"")
A13: =IFERROR(IF(IFERROR(AGGREGATE(14,6,(Inventory!$G$6:$G$205+(205-ROW(Inventory!$G$6:$G$205))/10000)/(Inventory!$G$6:$G$205>0),6),"")="","",INDEX(Inventory!$A$6:$A$205,IFERROR(MATCH(IFERROR(AGGREGATE(14,6,(Inventory!$G$6:$G$205+(205-ROW(Inventory!$G$6:$G$205))/10000)/(Inventory!$G$6:$G$205>0),6),""),(Inventory!$G$6:$G$205+(205-ROW(Inventory!$G$6:$G$205))/10000),0),""))),"") | B13: =IFERROR(IF(IFERROR(AGGREGATE(14,6,(Inventory!$G$6:$G$205+(205-ROW(Inventory!$G$6:$G$205))/10000)/(Inventory!$G$6:$G$205>0),6),"")="","",INDEX(Inventory!$B$6:$B$205,IFERROR(MATCH(IFERROR(AGGREGATE(14,6,(Inventory!$G$6:$G$205+(205-ROW(Inventory!$G$6:$G$205))/10000)/(Inventory!$G$6:$G$205>0),6),""),(Inventory!$G$6:$G$205+(205-ROW(Inventory!$G$6:$G$205))/10000),0),""))),"") | C13: =IFERROR(IF(IFERROR(AGGREGATE(14,6,(Inventory!$G$6:$G$205+(205-ROW(Inventory!$G$6:$G$205))/10000)/(Inventory!$G$6:$G$205>0),6),"")="","",INDEX(Inventory!$D$6:$D$205,IFERROR(MATCH(IFERROR(AGGREGATE(14,6,(Inventory!$G$6:$G$205+(205-ROW(Inventory!$G$6:$G$205))/10000)/(Inventory!$G$6:$G$205>0),6),""),(Inventory!$G$6:$G$205+(205-ROW(Inventory!$G$6:$G$205))/10000),0),""))),"") | D13: =IFERROR(IF(IFERROR(AGGREGATE(14,6,(Inventory!$G$6:$G$205+(205-ROW(Inventory!$G$6:$G$205))/10000)/(Inventory!$G$6:$G$205>0),6),"")="","",INDEX(Inventory!$H$6:$H$205,IFERROR(MATCH(IFERROR(AGGREGATE(14,6,(Inventory!$G$6:$G$205+(205-ROW(Inventory!$G$6:$G$205))/10000)/(Inventory!$G$6:$G$205>0),6),""),(Inventory!$G$6:$G$205+(205-ROW(Inventory!$G$6:$G$205))/10000),0),""))),"") | E13: =IFERROR(IF(IFERROR(AGGREGATE(14,6,(Inventory!$G$6:$G$205+(205-ROW(Inventory!$G$6:$G$205))/10000)/(Inventory!$G$6:$G$205>0),6),"")="","",INDEX(Inventory!$E$6:$E$205,IFERROR(MATCH(IFERROR(AGGREGATE(14,6,(Inventory!$G$6:$G$205+(205-ROW(Inventory!$G$6:$G$205))/10000)/(Inventory!$G$6:$G$205>0),6),""),(Inventory!$G$6:$G$205+(205-ROW(Inventory!$G$6:$G$205))/10000),0),""))),"") | F13: =IFERROR(IF(IFERROR(AGGREGATE(14,6,(Inventory!$G$6:$G$205+(205-ROW(Inventory!$G$6:$G$205))/10000)/(Inventory!$G$6:$G$205>0),6),"")="","",INDEX(Inventory!$F$6:$F$205,IFERROR(MATCH(IFERROR(AGGREGATE(14,6,(Inventory!$G$6:$G$205+(205-ROW(Inventory!$G$6:$G$205))/10000)/(Inventory!$G$6:$G$205>0),6),""),(Inventory!$G$6:$G$205+(205-ROW(Inventory!$G$6:$G$205))/10000),0),""))),"") | G13: =IFERROR(IF(IFERROR(AGGREGATE(14,6,(Inventory!$G$6:$G$205+(205-ROW(Inventory!$G$6:$G$205))/10000)/(Inventory!$G$6:$G$205>0),6),"")="","",INDEX(Inventory!$G$6:$G$205,IFERROR(MATCH(IFERROR(AGGREGATE(14,6,(Inventory!$G$6:$G$205+(205-ROW(Inventory!$G$6:$G$205))/10000)/(Inventory!$G$6:$G$205>0),6),""),(Inventory!$G$6:$G$205+(205-ROW(Inventory!$G$6:$G$205))/10000),0),""))),"") | H13: =IFERROR(IF(IFERROR(AGGREGATE(14,6,(Inventory!$G$6:$G$205+(205-ROW(Inventory!$G$6:$G$205))/10000)/(Inventory!$G$6:$G$205>0),6),"")="","",INDEX(Inventory!$I$6:$I$205,IFERROR(MATCH(IFERROR(AGGREGATE(14,6,(Inventory!$G$6:$G$205+(205-ROW(Inventory!$G$6:$G$205))/10000)/(Inventory!$G$6:$G$205>0),6),""),(Inventory!$G$6:$G$205+(205-ROW(Inventory!$G$6:$G$205))/10000),0),""))),"") | I13: =IFERROR(IF(IFERROR(AGGREGATE(14,6,(Inventory!$G$6:$G$205+(205-ROW(Inventory!$G$6:$G$205))/10000)/(Inventory!$G$6:$G$205>0),6),"")="","",INDEX(Inventory!$K$6:$K$205,IFERROR(MATCH(IFERROR(AGGREGATE(14,6,(Inventory!$G$6:$G$205+(205-ROW(Inventory!$G$6:$G$205))/10000)/(Inventory!$G$6:$G$205>0),6),""),(Inventory!$G$6:$G$205+(205-ROW(Inventory!$G$6:$G$205))/10000),0),""))),"")
A14: =IFERROR(IF(IFERROR(AGGREGATE(14,6,(Inventory!$G$6:$G$205+(205-ROW(Inventory!$G$6:$G$205))/10000)/(Inventory!$G$6:$G$205>0),7),"")="","",INDEX(Inventory!$A$6:$A$205,IFERROR(MATCH(IFERROR(AGGREGATE(14,6,(Inventory!$G$6:$G$205+(205-ROW(Inventory!$G$6:$G$205))/10000)/(Inventory!$G$6:$G$205>0),7),""),(Inventory!$G$6:$G$205+(205-ROW(Inventory!$G$6:$G$205))/10000),0),""))),"") | B14: =IFERROR(IF(IFERROR(AGGREGATE(14,6,(Inventory!$G$6:$G$205+(205-ROW(Inventory!$G$6:$G$205))/10000)/(Inventory!$G$6:$G$205>0),7),"")="","",INDEX(Inventory!$B$6:$B$205,IFERROR(MATCH(IFERROR(AGGREGATE(14,6,(Inventory!$G$6:$G$205+(205-ROW(Inventory!$G$6:$G$205))/10000)/(Inventory!$G$6:$G$205>0),7),""),(Inventory!$G$6:$G$205+(205-ROW(Inventory!$G$6:$G$205))/10000),0),""))),"") | C14: =IFERROR(IF(IFERROR(AGGREGATE(14,6,(Inventory!$G$6:$G$205+(205-ROW(Inventory!$G$6:$G$205))/10000)/(Inventory!$G$6:$G$205>0),7),"")="","",INDEX(Inventory!$D$6:$D$205,IFERROR(MATCH(IFERROR(AGGREGATE(14,6,(Inventory!$G$6:$G$205+(205-ROW(Inventory!$G$6:$G$205))/10000)/(Inventory!$G$6:$G$205>0),7),""),(Inventory!$G$6:$G$205+(205-ROW(Inventory!$G$6:$G$205))/10000),0),""))),"") | D14: =IFERROR(IF(IFERROR(AGGREGATE(14,6,(Inventory!$G$6:$G$205+(205-ROW(Inventory!$G$6:$G$205))/10000)/(Inventory!$G$6:$G$205>0),7),"")="","",INDEX(Inventory!$H$6:$H$205,IFERROR(MATCH(IFERROR(AGGREGATE(14,6,(Inventory!$G$6:$G$205+(205-ROW(Inventory!$G$6:$G$205))/10000)/(Inventory!$G$6:$G$205>0),7),""),(Inventory!$G$6:$G$205+(205-ROW(Inventory!$G$6:$G$205))/10000),0),""))),"") | E14: =IFERROR(IF(IFERROR(AGGREGATE(14,6,(Inventory!$G$6:$G$205+(205-ROW(Inventory!$G$6:$G$205))/10000)/(Inventory!$G$6:$G$205>0),7),"")="","",INDEX(Inventory!$E$6:$E$205,IFERROR(MATCH(IFERROR(AGGREGATE(14,6,(Inventory!$G$6:$G$205+(205-ROW(Inventory!$G$6:$G$205))/10000)/(Inventory!$G$6:$G$205>0),7),""),(Inventory!$G$6:$G$205+(205-ROW(Inventory!$G$6:$G$205))/10000),0),""))),"") | F14: =IFERROR(IF(IFERROR(AGGREGATE(14,6,(Inventory!$G$6:$G$205+(205-ROW(Inventory!$G$6:$G$205))/10000)/(Inventory!$G$6:$G$205>0),7),"")="","",INDEX(Inventory!$F$6:$F$205,IFERROR(MATCH(IFERROR(AGGREGATE(14,6,(Inventory!$G$6:$G$205+(205-ROW(Inventory!$G$6:$G$205))/10000)/(Inventory!$G$6:$G$205>0),7),""),(Inventory!$G$6:$G$205+(205-ROW(Inventory!$G$6:$G$205))/10000),0),""))),"") | G14: =IFERROR(IF(IFERROR(AGGREGATE(14,6,(Inventory!$G$6:$G$205+(205-ROW(Inventory!$G$6:$G$205))/10000)/(Inventory!$G$6:$G$205>0),7),"")="","",INDEX(Inventory!$G$6:$G$205,IFERROR(MATCH(IFERROR(AGGREGATE(14,6,(Inventory!$G$6:$G$205+(205-ROW(Inventory!$G$6:$G$205))/10000)/(Inventory!$G$6:$G$205>0),7),""),(Inventory!$G$6:$G$205+(205-ROW(Inventory!$G$6:$G$205))/10000),0),""))),"") | H14: =IFERROR(IF(IFERROR(AGGREGATE(14,6,(Inventory!$G$6:$G$205+(205-ROW(Inventory!$G$6:$G$205))/10000)/(Inventory!$G$6:$G$205>0),7),"")="","",INDEX(Inventory!$I$6:$I$205,IFERROR(MATCH(IFERROR(AGGREGATE(14,6,(Inventory!$G$6:$G$205+(205-ROW(Inventory!$G$6:$G$205))/10000)/(Inventory!$G$6:$G$205>0),7),""),(Inventory!$G$6:$G$205+(205-ROW(Inventory!$G$6:$G$205))/10000),0),""))),"") | I14: =IFERROR(IF(IFERROR(AGGREGATE(14,6,(Inventory!$G$6:$G$205+(205-ROW(Inventory!$G$6:$G$205))/10000)/(Inventory!$G$6:$G$205>0),7),"")="","",INDEX(Inventory!$K$6:$K$205,IFERROR(MATCH(IFERROR(AGGREGATE(14,6,(Inventory!$G$6:$G$205+(205-ROW(Inventory!$G$6:$G$205))/10000)/(Inventory!$G$6:$G$205>0),7),""),(Inventory!$G$6:$G$205+(205-ROW(Inventory!$G$6:$G$205))/10000),0),""))),"")
A15: =IFERROR(IF(IFERROR(AGGREGATE(14,6,(Inventory!$G$6:$G$205+(205-ROW(Inventory!$G$6:$G$205))/10000)/(Inventory!$G$6:$G$205>0),8),"")="","",INDEX(Inventory!$A$6:$A$205,IFERROR(MATCH(IFERROR(AGGREGATE(14,6,(Inventory!$G$6:$G$205+(205-ROW(Inventory!$G$6:$G$205))/10000)/(Inventory!$G$6:$G$205>0),8),""),(Inventory!$G$6:$G$205+(205-ROW(Inventory!$G$6:$G$205))/10000),0),""))),"") | B15: =IFERROR(IF(IFERROR(AGGREGATE(14,6,(Inventory!$G$6:$G$205+(205-ROW(Inventory!$G$6:$G$205))/10000)/(Inventory!$G$6:$G$205>0),8),"")="","",INDEX(Inventory!$B$6:$B$205,IFERROR(MATCH(IFERROR(AGGREGATE(14,6,(Inventory!$G$6:$G$205+(205-ROW(Inventory!$G$6:$G$205))/10000)/(Inventory!$G$6:$G$205>0),8),""),(Inventory!$G$6:$G$205+(205-ROW(Inventory!$G$6:$G$205))/10000),0),""))),"") | C15: =IFERROR(IF(IFERROR(AGGREGATE(14,6,(Inventory!$G$6:$G$205+(205-ROW(Inventory!$G$6:$G$205))/10000)/(Inventory!$G$6:$G$205>0),8),"")="","",INDEX(Inventory!$D$6:$D$205,IFERROR(MATCH(IFERROR(AGGREGATE(14,6,(Inventory!$G$6:$G$205+(205-ROW(Inventory!$G$6:$G$205))/10000)/(Inventory!$G$6:$G$205>0),8),""),(Inventory!$G$6:$G$205+(205-ROW(Inventory!$G$6:$G$205))/10000),0),""))),"") | D15: =IFERROR(IF(IFERROR(AGGREGATE(14,6,(Inventory!$G$6:$G$205+(205-ROW(Inventory!$G$6:$G$205))/10000)/(Inventory!$G$6:$G$205>0),8),"")="","",INDEX(Inventory!$H$6:$H$205,IFERROR(MATCH(IFERROR(AGGREGATE(14,6,(Inventory!$G$6:$G$205+(205-ROW(Inventory!$G$6:$G$205))/10000)/(Inventory!$G$6:$G$205>0),8),""),(Inventory!$G$6:$G$205+(205-ROW(Inventory!$G$6:$G$205))/10000),0),""))),"") | E15: =IFERROR(IF(IFERROR(AGGREGATE(14,6,(Inventory!$G$6:$G$205+(205-ROW(Inventory!$G$6:$G$205))/10000)/(Inventory!$G$6:$G$205>0),8),"")="","",INDEX(Inventory!$E$6:$E$205,IFERROR(MATCH(IFERROR(AGGREGATE(14,6,(Inventory!$G$6:$G$205+(205-ROW(Inventory!$G$6:$G$205))/10000)/(Inventory!$G$6:$G$205>0),8),""),(Inventory!$G$6:$G$205+(205-ROW(Inventory!$G$6:$G$205))/10000),0),""))),"") | F15: =IFERROR(IF(IFERROR(AGGREGATE(14,6,(Inventory!$G$6:$G$205+(205-ROW(Inventory!$G$6:$G$205))/10000)/(Inventory!$G$6:$G$205>0),8),"")="","",INDEX(Inventory!$F$6:$F$205,IFERROR(MATCH(IFERROR(AGGREGATE(14,6,(Inventory!$G$6:$G$205+(205-ROW(Inventory!$G$6:$G$205))/10000)/(Inventory!$G$6:$G$205>0),8),""),(Inventory!$G$6:$G$205+(205-ROW(Inventory!$G$6:$G$205))/10000),0),""))),"") | G15: =IFERROR(IF(IFERROR(AGGREGATE(14,6,(Inventory!$G$6:$G$205+(205-ROW(Inventory!$G$6:$G$205))/10000)/(Inventory!$G$6:$G$205>0),8),"")="","",INDEX(Inventory!$G$6:$G$205,IFERROR(MATCH(IFERROR(AGGREGATE(14,6,(Inventory!$G$6:$G$205+(205-ROW(Inventory!$G$6:$G$205))/10000)/(Inventory!$G$6:$G$205>0),8),""),(Inventory!$G$6:$G$205+(205-ROW(Inventory!$G$6:$G$205))/10000),0),""))),"") | H15: =IFERROR(IF(IFERROR(AGGREGATE(14,6,(Inventory!$G$6:$G$205+(205-ROW(Inventory!$G$6:$G$205))/10000)/(Inventory!$G$6:$G$205>0),8),"")="","",INDEX(Inventory!$I$6:$I$205,IFERROR(MATCH(IFERROR(AGGREGATE(14,6,(Inventory!$G$6:$G$205+(205-ROW(Inventory!$G$6:$G$205))/10000)/(Inventory!$G$6:$G$205>0),8),""),(Inventory!$G$6:$G$205+(205-ROW(Inventory!$G$6:$G$205))/10000),0),""))),"") | I15: =IFERROR(IF(IFERROR(AGGREGATE(14,6,(Inventory!$G$6:$G$205+(205-ROW(Inventory!$G$6:$G$205))/10000)/(Inventory!$G$6:$G$205>0),8),"")="","",INDEX(Inventory!$K$6:$K$205,IFERROR(MATCH(IFERROR(AGGREGATE(14,6,(Inventory!$G$6:$G$205+(205-ROW(Inventory!$G$6:$G$205))/10000)/(Inventory!$G$6:$G$205>0),8),""),(Inventory!$G$6:$G$205+(205-ROW(Inventory!$G$6:$G$205))/10000),0),""))),"")
A16: =IFERROR(IF(IFERROR(AGGREGATE(14,6,(Inventory!$G$6:$G$205+(205-ROW(Inventory!$G$6:$G$205))/10000)/(Inventory!$G$6:$G$205>0),9),"")="","",INDEX(Inventory!$A$6:$A$205,IFERROR(MATCH(IFERROR(AGGREGATE(14,6,(Inventory!$G$6:$G$205+(205-ROW(Inventory!$G$6:$G$205))/10000)/(Inventory!$G$6:$G$205>0),9),""),(Inventory!$G$6:$G$205+(205-ROW(Inventory!$G$6:$G$205))/10000),0),""))),"") | B16: =IFERROR(IF(IFERROR(AGGREGATE(14,6,(Inventory!$G$6:$G$205+(205-ROW(Inventory!$G$6:$G$205))/10000)/(Inventory!$G$6:$G$205>0),9),"")="","",INDEX(Inventory!$B$6:$B$205,IFERROR(MATCH(IFERROR(AGGREGATE(14,6,(Inventory!$G$6:$G$205+(205-ROW(Inventory!$G$6:$G$205))/10000)/(Inventory!$G$6:$G$205>0),9),""),(Inventory!$G$6:$G$205+(205-ROW(Inventory!$G$6:$G$205))/10000),0),""))),"") | C16: =IFERROR(IF(IFERROR(AGGREGATE(14,6,(Inventory!$G$6:$G$205+(205-ROW(Inventory!$G$6:$G$205))/10000)/(Inventory!$G$6:$G$205>0),9),"")="","",INDEX(Inventory!$D$6:$D$205,IFERROR(MATCH(IFERROR(AGGREGATE(14,6,(Inventory!$G$6:$G$205+(205-ROW(Inventory!$G$6:$G$205))/10000)/(Inventory!$G$6:$G$205>0),9),""),(Inventory!$G$6:$G$205+(205-ROW(Inventory!$G$6:$G$205))/10000),0),""))),"") | D16: =IFERROR(IF(IFERROR(AGGREGATE(14,6,(Inventory!$G$6:$G$205+(205-ROW(Inventory!$G$6:$G$205))/10000)/(Inventory!$G$6:$G$205>0),9),"")="","",INDEX(Inventory!$H$6:$H$205,IFERROR(MATCH(IFERROR(AGGREGATE(14,6,(Inventory!$G$6:$G$205+(205-ROW(Inventory!$G$6:$G$205))/10000)/(Inventory!$G$6:$G$205>0),9),""),(Inventory!$G$6:$G$205+(205-ROW(Inventory!$G$6:$G$205))/10000),0),""))),"") | E16: =IFERROR(IF(IFERROR(AGGREGATE(14,6,(Inventory!$G$6:$G$205+(205-ROW(Inventory!$G$6:$G$205))/10000)/(Inventory!$G$6:$G$205>0),9),"")="","",INDEX(Inventory!$E$6:$E$205,IFERROR(MATCH(IFERROR(AGGREGATE(14,6,(Inventory!$G$6:$G$205+(205-ROW(Inventory!$G$6:$G$205))/10000)/(Inventory!$G$6:$G$205>0),9),""),(Inventory!$G$6:$G$205+(205-ROW(Inventory!$G$6:$G$205))/10000),0),""))),"") | F16: =IFERROR(IF(IFERROR(AGGREGATE(14,6,(Inventory!$G$6:$G$205+(205-ROW(Inventory!$G$6:$G$205))/10000)/(Inventory!$G$6:$G$205>0),9),"")="","",INDEX(Inventory!$F$6:$F$205,IFERROR(MATCH(IFERROR(AGGREGATE(14,6,(Inventory!$G$6:$G$205+(205-ROW(Inventory!$G$6:$G$205))/10000)/(Inventory!$G$6:$G$205>0),9),""),(Inventory!$G$6:$G$205+(205-ROW(Inventory!$G$6:$G$205))/10000),0),""))),"") | G16: =IFERROR(IF(IFERROR(AGGREGATE(14,6,(Inventory!$G$6:$G$205+(205-ROW(Inventory!$G$6:$G$205))/10000)/(Inventory!$G$6:$G$205>0),9),"")="","",INDEX(Inventory!$G$6:$G$205,IFERROR(MATCH(IFERROR(AGGREGATE(14,6,(Inventory!$G$6:$G$205+(205-ROW(Inventory!$G$6:$G$205))/10000)/(Inventory!$G$6:$G$205>0),9),""),(Inventory!$G$6:$G$205+(205-ROW(Inventory!$G$6:$G$205))/10000),0),""))),"") | H16: =IFERROR(IF(IFERROR(AGGREGATE(14,6,(Inventory!$G$6:$G$205+(205-ROW(Inventory!$G$6:$G$205))/10000)/(Inventory!$G$6:$G$205>0),9),"")="","",INDEX(Inventory!$I$6:$I$205,IFERROR(MATCH(IFERROR(AGGREGATE(14,6,(Inventory!$G$6:$G$205+(205-ROW(Inventory!$G$6:$G$205))/10000)/(Inventory!$G$6:$G$205>0),9),""),(Inventory!$G$6:$G$205+(205-ROW(Inventory!$G$6:$G$205))/10000),0),""))),"") | I16: =IFERROR(IF(IFERROR(AGGREGATE(14,6,(Inventory!$G$6:$G$205+(205-ROW(Inventory!$G$6:$G$205))/10000)/(Inventory!$G$6:$G$205>0),9),"")="","",INDEX(Inventory!$K$6:$K$205,IFERROR(MATCH(IFERROR(AGGREGATE(14,6,(Inventory!$G$6:$G$205+(205-ROW(Inventory!$G$6:$G$205))/10000)/(Inventory!$G$6:$G$205>0),9),""),(Inventory!$G$6:$G$205+(205-ROW(Inventory!$G$6:$G$205))/10000),0),""))),"")
A17: =IFERROR(IF(IFERROR(AGGREGATE(14,6,(Inventory!$G$6:$G$205+(205-ROW(Inventory!$G$6:$G$205))/10000)/(Inventory!$G$6:$G$205>0),10),"")="","",INDEX(Inventory!$A$6:$A$205,IFERROR(MATCH(IFERROR(AGGREGATE(14,6,(Inventory!$G$6:$G$205+(205-ROW(Inventory!$G$6:$G$205))/10000)/(Inventory!$G$6:$G$205>0),10),""),(Inventory!$G$6:$G$205+(205-ROW(Inventory!$G$6:$G$205))/10000),0),""))),"") | B17: =IFERROR(IF(IFERROR(AGGREGATE(14,6,(Inventory!$G$6:$G$205+(205-ROW(Inventory!$G$6:$G$205))/10000)/(Inventory!$G$6:$G$205>0),10),"")="","",INDEX(Inventory!$B$6:$B$205,IFERROR(MATCH(IFERROR(AGGREGATE(14,6,(Inventory!$G$6:$G$205+(205-ROW(Inventory!$G$6:$G$205))/10000)/(Inventory!$G$6:$G$205>0),10),""),(Inventory!$G$6:$G$205+(205-ROW(Inventory!$G$6:$G$205))/10000),0),""))),"") | C17: =IFERROR(IF(IFERROR(AGGREGATE(14,6,(Inventory!$G$6:$G$205+(205-ROW(Inventory!$G$6:$G$205))/10000)/(Inventory!$G$6:$G$205>0),10),"")="","",INDEX(Inventory!$D$6:$D$205,IFERROR(MATCH(IFERROR(AGGREGATE(14,6,(Inventory!$G$6:$G$205+(205-ROW(Inventory!$G$6:$G$205))/10000)/(Inventory!$G$6:$G$205>0),10),""),(Inventory!$G$6:$G$205+(205-ROW(Inventory!$G$6:$G$205))/10000),0),""))),"") | D17: =IFERROR(IF(IFERROR(AGGREGATE(14,6,(Inventory!$G$6:$G$205+(205-ROW(Inventory!$G$6:$G$205))/10000)/(Inventory!$G$6:$G$205>0),10),"")="","",INDEX(Inventory!$H$6:$H$205,IFERROR(MATCH(IFERROR(AGGREGATE(14,6,(Inventory!$G$6:$G$205+(205-ROW(Inventory!$G$6:$G$205))/10000)/(Inventory!$G$6:$G$205>0),10),""),(Inventory!$G$6:$G$205+(205-ROW(Inventory!$G$6:$G$205))/10000),0),""))),"") | E17: =IFERROR(IF(IFERROR(AGGREGATE(14,6,(Inventory!$G$6:$G$205+(205-ROW(Inventory!$G$6:$G$205))/10000)/(Inventory!$G$6:$G$205>0),10),"")="","",INDEX(Inventory!$E$6:$E$205,IFERROR(MATCH(IFERROR(AGGREGATE(14,6,(Inventory!$G$6:$G$205+(205-ROW(Inventory!$G$6:$G$205))/10000)/(Inventory!$G$6:$G$205>0),10),""),(Inventory!$G$6:$G$205+(205-ROW(Inventory!$G$6:$G$205))/10000),0),""))),"") | F17: =IFERROR(IF(IFERROR(AGGREGATE(14,6,(Inventory!$G$6:$G$205+(205-ROW(Inventory!$G$6:$G$205))/10000)/(Inventory!$G$6:$G$205>0),10),"")="","",INDEX(Inventory!$F$6:$F$205,IFERROR(MATCH(IFERROR(AGGREGATE(14,6,(Inventory!$G$6:$G$205+(205-ROW(Inventory!$G$6:$G$205))/10000)/(Inventory!$G$6:$G$205>0),10),""),(Inventory!$G$6:$G$205+(205-ROW(Inventory!$G$6:$G$205))/10000),0),""))),"") | G17: =IFERROR(IF(IFERROR(AGGREGATE(14,6,(Inventory!$G$6:$G$205+(205-ROW(Inventory!$G$6:$G$205))/10000)/(Inventory!$G$6:$G$205>0),10),"")="","",INDEX(Inventory!$G$6:$G$205,IFERROR(MATCH(IFERROR(AGGREGATE(14,6,(Inventory!$G$6:$G$205+(205-ROW(Inventory!$G$6:$G$205))/10000)/(Inventory!$G$6:$G$205>0),10),""),(Inventory!$G$6:$G$205+(205-ROW(Inventory!$G$6:$G$205))/10000),0),""))),"") | H17: =IFERROR(IF(IFERROR(AGGREGATE(14,6,(Inventory!$G$6:$G$205+(205-ROW(Inventory!$G$6:$G$205))/10000)/(Inventory!$G$6:$G$205>0),10),"")="","",INDEX(Inventory!$I$6:$I$205,IFERROR(MATCH(IFERROR(AGGREGATE(14,6,(Inventory!$G$6:$G$205+(205-ROW(Inventory!$G$6:$G$205))/10000)/(Inventory!$G$6:$G$205>0),10),""),(Inventory!$G$6:$G$205+(205-ROW(Inventory!$G$6:$G$205))/10000),0),""))),"") | I17: =IFERROR(IF(IFERROR(AGGREGATE(14,6,(Inventory!$G$6:$G$205+(205-ROW(Inventory!$G$6:$G$205))/10000)/(Inventory!$G$6:$G$205>0),10),"")="","",INDEX(Inventory!$K$6:$K$205,IFERROR(MATCH(IFERROR(AGGREGATE(14,6,(Inventory!$G$6:$G$205+(205-ROW(Inventory!$G$6:$G$205))/10000)/(Inventory!$G$6:$G$205>0),10),""),(Inventory!$G$6:$G$205+(205-ROW(Inventory!$G$6:$G$205))/10000),0),""))),"")
A18: =IFERROR(IF(IFERROR(AGGREGATE(14,6,(Inventory!$G$6:$G$205+(205-ROW(Inventory!$G$6:$G$205))/10000)/(Inventory!$G$6:$G$205>0),11),"")="","",INDEX(Inventory!$A$6:$A$205,IFERROR(MATCH(IFERROR(AGGREGATE(14,6,(Inventory!$G$6:$G$205+(205-ROW(Inventory!$G$6:$G$205))/10000)/(Inventory!$G$6:$G$205>0),11),""),(Inventory!$G$6:$G$205+(205-ROW(Inventory!$G$6:$G$205))/10000),0),""))),"") | B18: =IFERROR(IF(IFERROR(AGGREGATE(14,6,(Inventory!$G$6:$G$205+(205-ROW(Inventory!$G$6:$G$205))/10000)/(Inventory!$G$6:$G$205>0),11),"")="","",INDEX(Inventory!$B$6:$B$205,IFERROR(MATCH(IFERROR(AGGREGATE(14,6,(Inventory!$G$6:$G$205+(205-ROW(Inventory!$G$6:$G$205))/10000)/(Inventory!$G$6:$G$205>0),11),""),(Inventory!$G$6:$G$205+(205-ROW(Inventory!$G$6:$G$205))/10000),0),""))),"") | C18: =IFERROR(IF(IFERROR(AGGREGATE(14,6,(Inventory!$G$6:$G$205+(205-ROW(Inventory!$G$6:$G$205))/10000)/(Inventory!$G$6:$G$205>0),11),"")="","",INDEX(Inventory!$D$6:$D$205,IFERROR(MATCH(IFERROR(AGGREGATE(14,6,(Inventory!$G$6:$G$205+(205-ROW(Inventory!$G$6:$G$205))/10000)/(Inventory!$G$6:$G$205>0),11),""),(Inventory!$G$6:$G$205+(205-ROW(Inventory!$G$6:$G$205))/10000),0),""))),"") | D18: =IFERROR(IF(IFERROR(AGGREGATE(14,6,(Inventory!$G$6:$G$205+(205-ROW(Inventory!$G$6:$G$205))/10000)/(Inventory!$G$6:$G$205>0),11),"")="","",INDEX(Inventory!$H$6:$H$205,IFERROR(MATCH(IFERROR(AGGREGATE(14,6,(Inventory!$G$6:$G$205+(205-ROW(Inventory!$G$6:$G$205))/10000)/(Inventory!$G$6:$G$205>0),11),""),(Inventory!$G$6:$G$205+(205-ROW(Inventory!$G$6:$G$205))/10000),0),""))),"") | E18: =IFERROR(IF(IFERROR(AGGREGATE(14,6,(Inventory!$G$6:$G$205+(205-ROW(Inventory!$G$6:$G$205))/10000)/(Inventory!$G$6:$G$205>0),11),"")="","",INDEX(Inventory!$E$6:$E$205,IFERROR(MATCH(IFERROR(AGGREGATE(14,6,(Inventory!$G$6:$G$205+(205-ROW(Inventory!$G$6:$G$205))/10000)/(Inventory!$G$6:$G$205>0),11),""),(Inventory!$G$6:$G$205+(205-ROW(Inventory!$G$6:$G$205))/10000),0),""))),"") | F18: =IFERROR(IF(IFERROR(AGGREGATE(14,6,(Inventory!$G$6:$G$205+(205-ROW(Inventory!$G$6:$G$205))/10000)/(Inventory!$G$6:$G$205>0),11),"")="","",INDEX(Inventory!$F$6:$F$205,IFERROR(MATCH(IFERROR(AGGREGATE(14,6,(Inventory!$G$6:$G$205+(205-ROW(Inventory!$G$6:$G$205))/10000)/(Inventory!$G$6:$G$205>0),11),""),(Inventory!$G$6:$G$205+(205-ROW(Inventory!$G$6:$G$205))/10000),0),""))),"") | G18: =IFERROR(IF(IFERROR(AGGREGATE(14,6,(Inventory!$G$6:$G$205+(205-ROW(Inventory!$G$6:$G$205))/10000)/(Inventory!$G$6:$G$205>0),11),"")="","",INDEX(Inventory!$G$6:$G$205,IFERROR(MATCH(IFERROR(AGGREGATE(14,6,(Inventory!$G$6:$G$205+(205-ROW(Inventory!$G$6:$G$205))/10000)/(Inventory!$G$6:$G$205>0),11),""),(Inventory!$G$6:$G$205+(205-ROW(Inventory!$G$6:$G$205))/10000),0),""))),"") | H18: =IFERROR(IF(IFERROR(AGGREGATE(14,6,(Inventory!$G$6:$G$205+(205-ROW(Inventory!$G$6:$G$205))/10000)/(Inventory!$G$6:$G$205>0),11),"")="","",INDEX(Inventory!$I$6:$I$205,IFERROR(MATCH(IFERROR(AGGREGATE(14,6,(Inventory!$G$6:$G$205+(205-ROW(Inventory!$G$6:$G$205))/10000)/(Inventory!$G$6:$G$205>0),11),""),(Inventory!$G$6:$G$205+(205-ROW(Inventory!$G$6:$G$205))/10000),0),""))),"") | I18: =IFERROR(IF(IFERROR(AGGREGATE(14,6,(Inventory!$G$6:$G$205+(205-ROW(Inventory!$G$6:$G$205))/10000)/(Inventory!$G$6:$G$205>0),11),"")="","",INDEX(Inventory!$K$6:$K$205,IFERROR(MATCH(IFERROR(AGGREGATE(14,6,(Inventory!$G$6:$G$205+(205-ROW(Inventory!$G$6:$G$205))/10000)/(Inventory!$G$6:$G$205>0),11),""),(Inventory!$G$6:$G$205+(205-ROW(Inventory!$G$6:$G$205))/10000),0),""))),"")
A19: =IFERROR(IF(IFERROR(AGGREGATE(14,6,(Inventory!$G$6:$G$205+(205-ROW(Inventory!$G$6:$G$205))/10000)/(Inventory!$G$6:$G$205>0),12),"")="","",INDEX(Inventory!$A$6:$A$205,IFERROR(MATCH(IFERROR(AGGREGATE(14,6,(Inventory!$G$6:$G$205+(205-ROW(Inventory!$G$6:$G$205))/10000)/(Inventory!$G$6:$G$205>0),12),""),(Inventory!$G$6:$G$205+(205-ROW(Inventory!$G$6:$G$205))/10000),0),""))),"") | B19: =IFERROR(IF(IFERROR(AGGREGATE(14,6,(Inventory!$G$6:$G$205+(205-ROW(Inventory!$G$6:$G$205))/10000)/(Inventory!$G$6:$G$205>0),12),"")="","",INDEX(Inventory!$B$6:$B$205,IFERROR(MATCH(IFERROR(AGGREGATE(14,6,(Inventory!$G$6:$G$205+(205-ROW(Inventory!$G$6:$G$205))/10000)/(Inventory!$G$6:$G$205>0),12),""),(Inventory!$G$6:$G$205+(205-ROW(Inventory!$G$6:$G$205))/10000),0),""))),"") | C19: =IFERROR(IF(IFERROR(AGGREGATE(14,6,(Inventory!$G$6:$G$205+(205-ROW(Inventory!$G$6:$G$205))/10000)/(Inventory!$G$6:$G$205>0),12),"")="","",INDEX(Inventory!$D$6:$D$205,IFERROR(MATCH(IFERROR(AGGREGATE(14,6,(Inventory!$G$6:$G$205+(205-ROW(Inventory!$G$6:$G$205))/10000)/(Inventory!$G$6:$G$205>0),12),""),(Inventory!$G$6:$G$205+(205-ROW(Inventory!$G$6:$G$205))/10000),0),""))),"") | D19: =IFERROR(IF(IFERROR(AGGREGATE(14,6,(Inventory!$G$6:$G$205+(205-ROW(Inventory!$G$6:$G$205))/10000)/(Inventory!$G$6:$G$205>0),12),"")="","",INDEX(Inventory!$H$6:$H$205,IFERROR(MATCH(IFERROR(AGGREGATE(14,6,(Inventory!$G$6:$G$205+(205-ROW(Inventory!$G$6:$G$205))/10000)/(Inventory!$G$6:$G$205>0),12),""),(Inventory!$G$6:$G$205+(205-ROW(Inventory!$G$6:$G$205))/10000),0),""))),"") | E19: =IFERROR(IF(IFERROR(AGGREGATE(14,6,(Inventory!$G$6:$G$205+(205-ROW(Inventory!$G$6:$G$205))/10000)/(Inventory!$G$6:$G$205>0),12),"")="","",INDEX(Inventory!$E$6:$E$205,IFERROR(MATCH(IFERROR(AGGREGATE(14,6,(Inventory!$G$6:$G$205+(205-ROW(Inventory!$G$6:$G$205))/10000)/(Inventory!$G$6:$G$205>0),12),""),(Inventory!$G$6:$G$205+(205-ROW(Inventory!$G$6:$G$205))/10000),0),""))),"") | F19: =IFERROR(IF(IFERROR(AGGREGATE(14,6,(Inventory!$G$6:$G$205+(205-ROW(Inventory!$G$6:$G$205))/10000)/(Inventory!$G$6:$G$205>0),12),"")="","",INDEX(Inventory!$F$6:$F$205,IFERROR(MATCH(IFERROR(AGGREGATE(14,6,(Inventory!$G$6:$G$205+(205-ROW(Inventory!$G$6:$G$205))/10000)/(Inventory!$G$6:$G$205>0),12),""),(Inventory!$G$6:$G$205+(205-ROW(Inventory!$G$6:$G$205))/10000),0),""))),"") | G19: =IFERROR(IF(IFERROR(AGGREGATE(14,6,(Inventory!$G$6:$G$205+(205-ROW(Inventory!$G$6:$G$205))/10000)/(Inventory!$G$6:$G$205>0),12),"")="","",INDEX(Inventory!$G$6:$G$205,IFERROR(MATCH(IFERROR(AGGREGATE(14,6,(Inventory!$G$6:$G$205+(205-ROW(Inventory!$G$6:$G$205))/10000)/(Inventory!$G$6:$G$205>0),12),""),(Inventory!$G$6:$G$205+(205-ROW(Inventory!$G$6:$G$205))/10000),0),""))),"") | H19: =IFERROR(IF(IFERROR(AGGREGATE(14,6,(Inventory!$G$6:$G$205+(205-ROW(Inventory!$G$6:$G$205))/10000)/(Inventory!$G$6:$G$205>0),12),"")="","",INDEX(Inventory!$I$6:$I$205,IFERROR(MATCH(IFERROR(AGGREGATE(14,6,(Inventory!$G$6:$G$205+(205-ROW(Inventory!$G$6:$G$205))/10000)/(Inventory!$G$6:$G$205>0),12),""),(Inventory!$G$6:$G$205+(205-ROW(Inventory!$G$6:$G$205))/10000),0),""))),"") | I19: =IFERROR(IF(IFERROR(AGGREGATE(14,6,(Inventory!$G$6:$G$205+(205-ROW(Inventory!$G$6:$G$205))/10000)/(Inventory!$G$6:$G$205>0),12),"")="","",INDEX(Inventory!$K$6:$K$205,IFERROR(MATCH(IFERROR(AGGREGATE(14,6,(Inventory!$G$6:$G$205+(205-ROW(Inventory!$G$6:$G$205))/10000)/(Inventory!$G$6:$G$205>0),12),""),(Inventory!$G$6:$G$205+(205-ROW(Inventory!$G$6:$G$205))/10000),0),""))),"")
A20: =IFERROR(IF(IFERROR(AGGREGATE(14,6,(Inventory!$G$6:$G$205+(205-ROW(Inventory!$G$6:$G$205))/10000)/(Inventory!$G$6:$G$205>0),13),"")="","",INDEX(Inventory!$A$6:$A$205,IFERROR(MATCH(IFERROR(AGGREGATE(14,6,(Inventory!$G$6:$G$205+(205-ROW(Inventory!$G$6:$G$205))/10000)/(Inventory!$G$6:$G$205>0),13),""),(Inventory!$G$6:$G$205+(205-ROW(Inventory!$G$6:$G$205))/10000),0),""))),"") | B20: =IFERROR(IF(IFERROR(AGGREGATE(14,6,(Inventory!$G$6:$G$205+(205-ROW(Inventory!$G$6:$G$205))/10000)/(Inventory!$G$6:$G$205>0),13),"")="","",INDEX(Inventory!$B$6:$B$205,IFERROR(MATCH(IFERROR(AGGREGATE(14,6,(Inventory!$G$6:$G$205+(205-ROW(Inventory!$G$6:$G$205))/10000)/(Inventory!$G$6:$G$205>0),13),""),(Inventory!$G$6:$G$205+(205-ROW(Inventory!$G$6:$G$205))/10000),0),""))),"") | C20: =IFERROR(IF(IFERROR(AGGREGATE(14,6,(Inventory!$G$6:$G$205+(205-ROW(Inventory!$G$6:$G$205))/10000)/(Inventory!$G$6:$G$205>0),13),"")="","",INDEX(Inventory!$D$6:$D$205,IFERROR(MATCH(IFERROR(AGGREGATE(14,6,(Inventory!$G$6:$G$205+(205-ROW(Inventory!$G$6:$G$205))/10000)/(Inventory!$G$6:$G$205>0),13),""),(Inventory!$G$6:$G$205+(205-ROW(Inventory!$G$6:$G$205))/10000),0),""))),"") | D20: =IFERROR(IF(IFERROR(AGGREGATE(14,6,(Inventory!$G$6:$G$205+(205-ROW(Inventory!$G$6:$G$205))/10000)/(Inventory!$G$6:$G$205>0),13),"")="","",INDEX(Inventory!$H$6:$H$205,IFERROR(MATCH(IFERROR(AGGREGATE(14,6,(Inventory!$G$6:$G$205+(205-ROW(Inventory!$G$6:$G$205))/10000)/(Inventory!$G$6:$G$205>0),13),""),(Inventory!$G$6:$G$205+(205-ROW(Inventory!$G$6:$G$205))/10000),0),""))),"") | E20: =IFERROR(IF(IFERROR(AGGREGATE(14,6,(Inventory!$G$6:$G$205+(205-ROW(Inventory!$G$6:$G$205))/10000)/(Inventory!$G$6:$G$205>0),13),"")="","",INDEX(Inventory!$E$6:$E$205,IFERROR(MATCH(IFERROR(AGGREGATE(14,6,(Inventory!$G$6:$G$205+(205-ROW(Inventory!$G$6:$G$205))/10000)/(Inventory!$G$6:$G$205>0),13),""),(Inventory!$G$6:$G$205+(205-ROW(Inventory!$G$6:$G$205))/10000),0),""))),"") | F20: =IFERROR(IF(IFERROR(AGGREGATE(14,6,(Inventory!$G$6:$G$205+(205-ROW(Inventory!$G$6:$G$205))/10000)/(Inventory!$G$6:$G$205>0),13),"")="","",INDEX(Inventory!$F$6:$F$205,IFERROR(MATCH(IFERROR(AGGREGATE(14,6,(Inventory!$G$6:$G$205+(205-ROW(Inventory!$G$6:$G$205))/10000)/(Inventory!$G$6:$G$205>0),13),""),(Inventory!$G$6:$G$205+(205-ROW(Inventory!$G$6:$G$205))/10000),0),""))),"") | G20: =IFERROR(IF(IFERROR(AGGREGATE(14,6,(Inventory!$G$6:$G$205+(205-ROW(Inventory!$G$6:$G$205))/10000)/(Inventory!$G$6:$G$205>0),13),"")="","",INDEX(Inventory!$G$6:$G$205,IFERROR(MATCH(IFERROR(AGGREGATE(14,6,(Inventory!$G$6:$G$205+(205-ROW(Inventory!$G$6:$G$205))/10000)/(Inventory!$G$6:$G$205>0),13),""),(Inventory!$G$6:$G$205+(205-ROW(Inventory!$G$6:$G$205))/10000),0),""))),"") | H20: =IFERROR(IF(IFERROR(AGGREGATE(14,6,(Inventory!$G$6:$G$205+(205-ROW(Inventory!$G$6:$G$205))/10000)/(Inventory!$G$6:$G$205>0),13),"")="","",INDEX(Inventory!$I$6:$I$205,IFERROR(MATCH(IFERROR(AGGREGATE(14,6,(Inventory!$G$6:$G$205+(205-ROW(Inventory!$G$6:$G$205))/10000)/(Inventory!$G$6:$G$205>0),13),""),(Inventory!$G$6:$G$205+(205-ROW(Inventory!$G$6:$G$205))/10000),0),""))),"") | I20: =IFERROR(IF(IFERROR(AGGREGATE(14,6,(Inventory!$G$6:$G$205+(205-ROW(Inventory!$G$6:$G$205))/10000)/(Inventory!$G$6:$G$205>0),13),"")="","",INDEX(Inventory!$K$6:$K$205,IFERROR(MATCH(IFERROR(AGGREGATE(14,6,(Inventory!$G$6:$G$205+(205-ROW(Inventory!$G$6:$G$205))/10000)/(Inventory!$G$6:$G$205>0),13),""),(Inventory!$G$6:$G$205+(205-ROW(Inventory!$G$6:$G$205))/10000),0),""))),"")
A21: =IFERROR(IF(IFERROR(AGGREGATE(14,6,(Inventory!$G$6:$G$205+(205-ROW(Inventory!$G$6:$G$205))/10000)/(Inventory!$G$6:$G$205>0),14),"")="","",INDEX(Inventory!$A$6:$A$205,IFERROR(MATCH(IFERROR(AGGREGATE(14,6,(Inventory!$G$6:$G$205+(205-ROW(Inventory!$G$6:$G$205))/10000)/(Inventory!$G$6:$G$205>0),14),""),(Inventory!$G$6:$G$205+(205-ROW(Inventory!$G$6:$G$205))/10000),0),""))),"") | B21: =IFERROR(IF(IFERROR(AGGREGATE(14,6,(Inventory!$G$6:$G$205+(205-ROW(Inventory!$G$6:$G$205))/10000)/(Inventory!$G$6:$G$205>0),14),"")="","",INDEX(Inventory!$B$6:$B$205,IFERROR(MATCH(IFERROR(AGGREGATE(14,6,(Inventory!$G$6:$G$205+(205-ROW(Inventory!$G$6:$G$205))/10000)/(Inventory!$G$6:$G$205>0),14),""),(Inventory!$G$6:$G$205+(205-ROW(Inventory!$G$6:$G$205))/10000),0),""))),"") | C21: =IFERROR(IF(IFERROR(AGGREGATE(14,6,(Inventory!$G$6:$G$205+(205-ROW(Inventory!$G$6:$G$205))/10000)/(Inventory!$G$6:$G$205>0),14),"")="","",INDEX(Inventory!$D$6:$D$205,IFERROR(MATCH(IFERROR(AGGREGATE(14,6,(Inventory!$G$6:$G$205+(205-ROW(Inventory!$G$6:$G$205))/10000)/(Inventory!$G$6:$G$205>0),14),""),(Inventory!$G$6:$G$205+(205-ROW(Inventory!$G$6:$G$205))/10000),0),""))),"") | D21: =IFERROR(IF(IFERROR(AGGREGATE(14,6,(Inventory!$G$6:$G$205+(205-ROW(Inventory!$G$6:$G$205))/10000)/(Inventory!$G$6:$G$205>0),14),"")="","",INDEX(Inventory!$H$6:$H$205,IFERROR(MATCH(IFERROR(AGGREGATE(14,6,(Inventory!$G$6:$G$205+(205-ROW(Inventory!$G$6:$G$205))/10000)/(Inventory!$G$6:$G$205>0),14),""),(Inventory!$G$6:$G$205+(205-ROW(Inventory!$G$6:$G$205))/10000),0),""))),"") | E21: =IFERROR(IF(IFERROR(AGGREGATE(14,6,(Inventory!$G$6:$G$205+(205-ROW(Inventory!$G$6:$G$205))/10000)/(Inventory!$G$6:$G$205>0),14),"")="","",INDEX(Inventory!$E$6:$E$205,IFERROR(MATCH(IFERROR(AGGREGATE(14,6,(Inventory!$G$6:$G$205+(205-ROW(Inventory!$G$6:$G$205))/10000)/(Inventory!$G$6:$G$205>0),14),""),(Inventory!$G$6:$G$205+(205-ROW(Inventory!$G$6:$G$205))/10000),0),""))),"") | F21: =IFERROR(IF(IFERROR(AGGREGATE(14,6,(Inventory!$G$6:$G$205+(205-ROW(Inventory!$G$6:$G$205))/10000)/(Inventory!$G$6:$G$205>0),14),"")="","",INDEX(Inventory!$F$6:$F$205,IFERROR(MATCH(IFERROR(AGGREGATE(14,6,(Inventory!$G$6:$G$205+(205-ROW(Inventory!$G$6:$G$205))/10000)/(Inventory!$G$6:$G$205>0),14),""),(Inventory!$G$6:$G$205+(205-ROW(Inventory!$G$6:$G$205))/10000),0),""))),"") | G21: =IFERROR(IF(IFERROR(AGGREGATE(14,6,(Inventory!$G$6:$G$205+(205-ROW(Inventory!$G$6:$G$205))/10000)/(Inventory!$G$6:$G$205>0),14),"")="","",INDEX(Inventory!$G$6:$G$205,IFERROR(MATCH(IFERROR(AGGREGATE(14,6,(Inventory!$G$6:$G$205+(205-ROW(Inventory!$G$6:$G$205))/10000)/(Inventory!$G$6:$G$205>0),14),""),(Inventory!$G$6:$G$205+(205-ROW(Inventory!$G$6:$G$205))/10000),0),""))),"") | H21: =IFERROR(IF(IFERROR(AGGREGATE(14,6,(Inventory!$G$6:$G$205+(205-ROW(Inventory!$G$6:$G$205))/10000)/(Inventory!$G$6:$G$205>0),14),"")="","",INDEX(Inventory!$I$6:$I$205,IFERROR(MATCH(IFERROR(AGGREGATE(14,6,(Inventory!$G$6:$G$205+(205-ROW(Inventory!$G$6:$G$205))/10000)/(Inventory!$G$6:$G$205>0),14),""),(Inventory!$G$6:$G$205+(205-ROW(Inventory!$G$6:$G$205))/10000),0),""))),"") | I21: =IFERROR(IF(IFERROR(AGGREGATE(14,6,(Inventory!$G$6:$G$205+(205-ROW(Inventory!$G$6:$G$205))/10000)/(Inventory!$G$6:$G$205>0),14),"")="","",INDEX(Inventory!$K$6:$K$205,IFERROR(MATCH(IFERROR(AGGREGATE(14,6,(Inventory!$G$6:$G$205+(205-ROW(Inventory!$G$6:$G$205))/10000)/(Inventory!$G$6:$G$205>0),14),""),(Inventory!$G$6:$G$205+(205-ROW(Inventory!$G$6:$G$205))/10000),0),""))),"")
A22: =IFERROR(IF(IFERROR(AGGREGATE(14,6,(Inventory!$G$6:$G$205+(205-ROW(Inventory!$G$6:$G$205))/10000)/(Inventory!$G$6:$G$205>0),15),"")="","",INDEX(Inventory!$A$6:$A$205,IFERROR(MATCH(IFERROR(AGGREGATE(14,6,(Inventory!$G$6:$G$205+(205-ROW(Inventory!$G$6:$G$205))/10000)/(Inventory!$G$6:$G$205>0),15),""),(Inventory!$G$6:$G$205+(205-ROW(Inventory!$G$6:$G$205))/10000),0),""))),"") | B22: =IFERROR(IF(IFERROR(AGGREGATE(14,6,(Inventory!$G$6:$G$205+(205-ROW(Inventory!$G$6:$G$205))/10000)/(Inventory!$G$6:$G$205>0),15),"")="","",INDEX(Inventory!$B$6:$B$205,IFERROR(MATCH(IFERROR(AGGREGATE(14,6,(Inventory!$G$6:$G$205+(205-ROW(Inventory!$G$6:$G$205))/10000)/(Inventory!$G$6:$G$205>0),15),""),(Inventory!$G$6:$G$205+(205-ROW(Inventory!$G$6:$G$205))/10000),0),""))),"") | C22: =IFERROR(IF(IFERROR(AGGREGATE(14,6,(Inventory!$G$6:$G$205+(205-ROW(Inventory!$G$6:$G$205))/10000)/(Inventory!$G$6:$G$205>0),15),"")="","",INDEX(Inventory!$D$6:$D$205,IFERROR(MATCH(IFERROR(AGGREGATE(14,6,(Inventory!$G$6:$G$205+(205-ROW(Inventory!$G$6:$G$205))/10000)/(Inventory!$G$6:$G$205>0),15),""),(Inventory!$G$6:$G$205+(205-ROW(Inventory!$G$6:$G$205))/10000),0),""))),"") | D22: =IFERROR(IF(IFERROR(AGGREGATE(14,6,(Inventory!$G$6:$G$205+(205-ROW(Inventory!$G$6:$G$205))/10000)/(Inventory!$G$6:$G$205>0),15),"")="","",INDEX(Inventory!$H$6:$H$205,IFERROR(MATCH(IFERROR(AGGREGATE(14,6,(Inventory!$G$6:$G$205+(205-ROW(Inventory!$G$6:$G$205))/10000)/(Inventory!$G$6:$G$205>0),15),""),(Inventory!$G$6:$G$205+(205-ROW(Inventory!$G$6:$G$205))/10000),0),""))),"") | E22: =IFERROR(IF(IFERROR(AGGREGATE(14,6,(Inventory!$G$6:$G$205+(205-ROW(Inventory!$G$6:$G$205))/10000)/(Inventory!$G$6:$G$205>0),15),"")="","",INDEX(Inventory!$E$6:$E$205,IFERROR(MATCH(IFERROR(AGGREGATE(14,6,(Inventory!$G$6:$G$205+(205-ROW(Inventory!$G$6:$G$205))/10000)/(Inventory!$G$6:$G$205>0),15),""),(Inventory!$G$6:$G$205+(205-ROW(Inventory!$G$6:$G$205))/10000),0),""))),"") | F22: =IFERROR(IF(IFERROR(AGGREGATE(14,6,(Inventory!$G$6:$G$205+(205-ROW(Inventory!$G$6:$G$205))/10000)/(Inventory!$G$6:$G$205>0),15),"")="","",INDEX(Inventory!$F$6:$F$205,IFERROR(MATCH(IFERROR(AGGREGATE(14,6,(Inventory!$G$6:$G$205+(205-ROW(Inventory!$G$6:$G$205))/10000)/(Inventory!$G$6:$G$205>0),15),""),(Inventory!$G$6:$G$205+(205-ROW(Inventory!$G$6:$G$205))/10000),0),""))),"") | G22: =IFERROR(IF(IFERROR(AGGREGATE(14,6,(Inventory!$G$6:$G$205+(205-ROW(Inventory!$G$6:$G$205))/10000)/(Inventory!$G$6:$G$205>0),15),"")="","",INDEX(Inventory!$G$6:$G$205,IFERROR(MATCH(IFERROR(AGGREGATE(14,6,(Inventory!$G$6:$G$205+(205-ROW(Inventory!$G$6:$G$205))/10000)/(Inventory!$G$6:$G$205>0),15),""),(Inventory!$G$6:$G$205+(205-ROW(Inventory!$G$6:$G$205))/10000),0),""))),"") | H22: =IFERROR(IF(IFERROR(AGGREGATE(14,6,(Inventory!$G$6:$G$205+(205-ROW(Inventory!$G$6:$G$205))/10000)/(Inventory!$G$6:$G$205>0),15),"")="","",INDEX(Inventory!$I$6:$I$205,IFERROR(MATCH(IFERROR(AGGREGATE(14,6,(Inventory!$G$6:$G$205+(205-ROW(Inventory!$G$6:$G$205))/10000)/(Inventory!$G$6:$G$205>0),15),""),(Inventory!$G$6:$G$205+(205-ROW(Inventory!$G$6:$G$205))/10000),0),""))),"") | I22: =IFERROR(IF(IFERROR(AGGREGATE(14,6,(Inventory!$G$6:$G$205+(205-ROW(Inventory!$G$6:$G$205))/10000)/(Inventory!$G$6:$G$205>0),15),"")="","",INDEX(Inventory!$K$6:$K$205,IFERROR(MATCH(IFERROR(AGGREGATE(14,6,(Inventory!$G$6:$G$205+(205-ROW(Inventory!$G$6:$G$205))/10000)/(Inventory!$G$6:$G$205>0),15),""),(Inventory!$G$6:$G$205+(205-ROW(Inventory!$G$6:$G$205))/10000),0),""))),"")
A23: =IFERROR(IF(IFERROR(AGGREGATE(14,6,(Inventory!$G$6:$G$205+(205-ROW(Inventory!$G$6:$G$205))/10000)/(Inventory!$G$6:$G$205>0),16),"")="","",INDEX(Inventory!$A$6:$A$205,IFERROR(MATCH(IFERROR(AGGREGATE(14,6,(Inventory!$G$6:$G$205+(205-ROW(Inventory!$G$6:$G$205))/10000)/(Inventory!$G$6:$G$205>0),16),""),(Inventory!$G$6:$G$205+(205-ROW(Inventory!$G$6:$G$205))/10000),0),""))),"") | B23: =IFERROR(IF(IFERROR(AGGREGATE(14,6,(Inventory!$G$6:$G$205+(205-ROW(Inventory!$G$6:$G$205))/10000)/(Inventory!$G$6:$G$205>0),16),"")="","",INDEX(Inventory!$B$6:$B$205,IFERROR(MATCH(IFERROR(AGGREGATE(14,6,(Inventory!$G$6:$G$205+(205-ROW(Inventory!$G$6:$G$205))/10000)/(Inventory!$G$6:$G$205>0),16),""),(Inventory!$G$6:$G$205+(205-ROW(Inventory!$G$6:$G$205))/10000),0),""))),"") | C23: =IFERROR(IF(IFERROR(AGGREGATE(14,6,(Inventory!$G$6:$G$205+(205-ROW(Inventory!$G$6:$G$205))/10000)/(Inventory!$G$6:$G$205>0),16),"")="","",INDEX(Inventory!$D$6:$D$205,IFERROR(MATCH(IFERROR(AGGREGATE(14,6,(Inventory!$G$6:$G$205+(205-ROW(Inventory!$G$6:$G$205))/10000)/(Inventory!$G$6:$G$205>0),16),""),(Inventory!$G$6:$G$205+(205-ROW(Inventory!$G$6:$G$205))/10000),0),""))),"") | D23: =IFERROR(IF(IFERROR(AGGREGATE(14,6,(Inventory!$G$6:$G$205+(205-ROW(Inventory!$G$6:$G$205))/10000)/(Inventory!$G$6:$G$205>0),16),"")="","",INDEX(Inventory!$H$6:$H$205,IFERROR(MATCH(IFERROR(AGGREGATE(14,6,(Inventory!$G$6:$G$205+(205-ROW(Inventory!$G$6:$G$205))/10000)/(Inventory!$G$6:$G$205>0),16),""),(Inventory!$G$6:$G$205+(205-ROW(Inventory!$G$6:$G$205))/10000),0),""))),"") | E23: =IFERROR(IF(IFERROR(AGGREGATE(14,6,(Inventory!$G$6:$G$205+(205-ROW(Inventory!$G$6:$G$205))/10000)/(Inventory!$G$6:$G$205>0),16),"")="","",INDEX(Inventory!$E$6:$E$205,IFERROR(MATCH(IFERROR(AGGREGATE(14,6,(Inventory!$G$6:$G$205+(205-ROW(Inventory!$G$6:$G$205))/10000)/(Inventory!$G$6:$G$205>0),16),""),(Inventory!$G$6:$G$205+(205-ROW(Inventory!$G$6:$G$205))/10000),0),""))),"") | F23: =IFERROR(IF(IFERROR(AGGREGATE(14,6,(Inventory!$G$6:$G$205+(205-ROW(Inventory!$G$6:$G$205))/10000)/(Inventory!$G$6:$G$205>0),16),"")="","",INDEX(Inventory!$F$6:$F$205,IFERROR(MATCH(IFERROR(AGGREGATE(14,6,(Inventory!$G$6:$G$205+(205-ROW(Inventory!$G$6:$G$205))/10000)/(Inventory!$G$6:$G$205>0),16),""),(Inventory!$G$6:$G$205+(205-ROW(Inventory!$G$6:$G$205))/10000),0),""))),"") | G23: =IFERROR(IF(IFERROR(AGGREGATE(14,6,(Inventory!$G$6:$G$205+(205-ROW(Inventory!$G$6:$G$205))/10000)/(Inventory!$G$6:$G$205>0),16),"")="","",INDEX(Inventory!$G$6:$G$205,IFERROR(MATCH(IFERROR(AGGREGATE(14,6,(Inventory!$G$6:$G$205+(205-ROW(Inventory!$G$6:$G$205))/10000)/(Inventory!$G$6:$G$205>0),16),""),(Inventory!$G$6:$G$205+(205-ROW(Inventory!$G$6:$G$205))/10000),0),""))),"") | H23: =IFERROR(IF(IFERROR(AGGREGATE(14,6,(Inventory!$G$6:$G$205+(205-ROW(Inventory!$G$6:$G$205))/10000)/(Inventory!$G$6:$G$205>0),16),"")="","",INDEX(Inventory!$I$6:$I$205,IFERROR(MATCH(IFERROR(AGGREGATE(14,6,(Inventory!$G$6:$G$205+(205-ROW(Inventory!$G$6:$G$205))/10000)/(Inventory!$G$6:$G$205>0),16),""),(Inventory!$G$6:$G$205+(205-ROW(Inventory!$G$6:$G$205))/10000),0),""))),"") | I23: =IFERROR(IF(IFERROR(AGGREGATE(14,6,(Inventory!$G$6:$G$205+(205-ROW(Inventory!$G$6:$G$205))/10000)/(Inventory!$G$6:$G$205>0),16),"")="","",INDEX(Inventory!$K$6:$K$205,IFERROR(MATCH(IFERROR(AGGREGATE(14,6,(Inventory!$G$6:$G$205+(205-ROW(Inventory!$G$6:$G$205))/10000)/(Inventory!$G$6:$G$205>0),16),""),(Inventory!$G$6:$G$205+(205-ROW(Inventory!$G$6:$G$205))/10000),0),""))),"")
