Workbook

Sheet Start
A2: The STR Ledger
A4: Insurance Policy Tracker
A5: Every policy on one page — gaps, renewals, claims.
A7: OPS-008 · v1.0 · BLANK
A10: ACTIVE POLICIES | E10: ANNUAL PREMIUM | I10: EXPIRING ≤ 60 DAYS
A11: =COUNTA('Policies'!A7:A36) | E11: =SUM('Policies'!G7:G36) | I11: =COUNTIFS('Policies'!J7:J36,">=0",'Policies'!J7:J36,"<=60")
A14: policies on the register | E14: total annual premium | I14: policies due in next 60 days
A17: =IF(COUNTIFS('Policies'!J7:J36,">=0",'Policies'!J7:J36,"<=60")>0,"RENEWAL WINDOW OPEN — One or more policies expire in the next 60 days. Quote replacements before lapse; lapsed STR coverage means no liability protection during a guest stay.","ALL CLEAR — No policies in the 60-day renewal window.")
A19: HOW TO USE THIS WORKBOOK
A20: 1. Log every policy on the Policies tab — STR dwelling, umbrella, auto, equipment. 2. Walk the Coverage Map to find gaps (a property with no liability coverage = uninsured exposure). 3. Use Premium Forecast for cash-flow planning around renewal months. 4. When you file a claim, log it on the Claim Log so renewal discussions have the history.
A25: =HYPERLINK("#'Policies'!A1", "Policies") | D25: =HYPERLINK("#'Coverage Map'!A1", "Coverage Map") | G25: =HYPERLINK("#'Premium Forecast'!A1", "Premium Forecast") | J25: =HYPERLINK("#'Claim Log'!A1", "Claim Log")
A29: =HYPERLINK("#'Settings'!A1", "Settings")
A33: Need full operations coverage? Add the Operator Bundle at thestrledger.com/operator — turnover + maintenance + supply + damage claims + insurance + permits, $197.
A36: Questions? hello@thestrledger.com
A37: OPS-008 · v1.0 · BLANK · Free updates forever

Sheet Policies
A2: =HYPERLINK("#'Start'!A1", "← BACK") | D2: POLICIES | J2: =HYPERLINK("#'Coverage Map'!A1", "NEXT →")
A4: One row per policy. Days-to-expiration auto-calculates; Status flips to Renew soon (<60d) or Expired (<0d) automatically.
A6: Policy # | B6: Carrier | C6: Type | D6: Property | E6: Coverage limit | F6: Deductible | G6: Annual premium | H6: Effective date | I6: Expiration date | J6: Days | K6: Status | L6: Agent name | M6: Agent phone | N6: Notes
J7: =IF(I7<>"",I7-TODAY(),"") | K7: =IF(I7="","",IF(J7<0,"Expired",IF(J7<60,"Renew soon","Active")))
J8: =IF(I8<>"",I8-TODAY(),"") | K8: =IF(I8="","",IF(J8<0,"Expired",IF(J8<60,"Renew soon","Active")))
J9: =IF(I9<>"",I9-TODAY(),"") | K9: =IF(I9="","",IF(J9<0,"Expired",IF(J9<60,"Renew soon","Active")))
J10: =IF(I10<>"",I10-TODAY(),"") | K10: =IF(I10="","",IF(J10<0,"Expired",IF(J10<60,"Renew soon","Active")))
J11: =IF(I11<>"",I11-TODAY(),"") | K11: =IF(I11="","",IF(J11<0,"Expired",IF(J11<60,"Renew soon","Active")))
J12: =IF(I12<>"",I12-TODAY(),"") | K12: =IF(I12="","",IF(J12<0,"Expired",IF(J12<60,"Renew soon","Active")))
J13: =IF(I13<>"",I13-TODAY(),"") | K13: =IF(I13="","",IF(J13<0,"Expired",IF(J13<60,"Renew soon","Active")))
J14: =IF(I14<>"",I14-TODAY(),"") | K14: =IF(I14="","",IF(J14<0,"Expired",IF(J14<60,"Renew soon","Active")))
J15: =IF(I15<>"",I15-TODAY(),"") | K15: =IF(I15="","",IF(J15<0,"Expired",IF(J15<60,"Renew soon","Active")))
J16: =IF(I16<>"",I16-TODAY(),"") | K16: =IF(I16="","",IF(J16<0,"Expired",IF(J16<60,"Renew soon","Active")))
J17: =IF(I17<>"",I17-TODAY(),"") | K17: =IF(I17="","",IF(J17<0,"Expired",IF(J17<60,"Renew soon","Active")))
J18: =IF(I18<>"",I18-TODAY(),"") | K18: =IF(I18="","",IF(J18<0,"Expired",IF(J18<60,"Renew soon","Active")))
... J36: =IF(I36<>"",I36-TODAY(),"") | K36: =IF(I36="","",IF(J36<0,"Expired",IF(J36<60,"Renew soon","Active")))

Sheet Coverage Map
A2: =HYPERLINK("#'Policies'!A1", "← BACK") | D2: COVERAGE MAP | J2: =HYPERLINK("#'Premium Forecast'!A1", "NEXT →")
A4: Per-property coverage matrix. Each cell shows the limit if the property carries that coverage type, or GAP if there's no policy in force. Walk the GAPs before renewals.
A6: Property | B6: STR Dwelling | C6: Umbrella Liability | D6: Loss of Rents | E6: Auto | F6: Equipment | G6: Cyber | H6: Total limit
A7: =IFERROR(IF(Settings!B6="","",Settings!B6),"") | B7: =IF(A7="","",IF(SUMIFS(Policies!G7:G36,Policies!D7:D36,A7,Policies!C7:C36,"STR Dwelling")+SUMIFS(Policies!G7:G36,Policies!D7:D36,"Portfolio-wide",Policies!C7:C36,"STR Dwelling")=0,"GAP",SUMIFS(Policies!E7:E36,Policies!D7:D36,A7,Policies!C7:C36,"STR Dwelling")+SUMIFS(Policies!E7:E36,Policies!D7:D36,"Portfolio-wide",Policies!C7:C36,"STR Dwelling"))) | C7: =IF(A7="","",IF(SUMIFS(Policies!G7:G36,Policies!D7:D36,A7,Policies!C7:C36,"Umbrella Liability")+SUMIFS(Policies!G7:G36,Policies!D7:D36,"Portfolio-wide",Policies!C7:C36,"Umbrella Liability")=0,"GAP",SUMIFS(Policies!E7:E36,Policies!D7:D36,A7,Policies!C7:C36,"Umbrella Liability")+SUMIFS(Policies!E7:E36,Policies!D7:D36,"Portfolio-wide",Policies!C7:C36,"Umbrella Liability"))) | D7: =IF(A7="","",IF(SUMIFS(Policies!G7:G36,Policies!D7:D36,A7,Policies!C7:C36,"Loss of Rents")+SUMIFS(Policies!G7:G36,Policies!D7:D36,"Portfolio-wide",Policies!C7:C36,"Loss of Rents")=0,"GAP",SUMIFS(Policies!E7:E36,Policies!D7:D36,A7,Policies!C7:C36,"Loss of Rents")+SUMIFS(Policies!E7:E36,Policies!D7:D36,"Portfolio-wide",Policies!C7:C36,"Loss of Rents"))) | E7: =IF(A7="","",IF(SUMIFS(Policies!G7:G36,Policies!D7:D36,A7,Policies!C7:C36,"Auto")+SUMIFS(Policies!G7:G36,Policies!D7:D36,"Portfolio-wide",Policies!C7:C36,"Auto")=0,"GAP",SUMIFS(Policies!E7:E36,Policies!D7:D36,A7,Policies!C7:C36,"Auto")+SUMIFS(Policies!E7:E36,Policies!D7:D36,"Portfolio-wide",Policies!C7:C36,"Auto"))) | F7: =IF(A7="","",IF(SUMIFS(Policies!G7:G36,Policies!D7:D36,A7,Policies!C7:C36,"Equipment")+SUMIFS(Policies!G7:G36,Policies!D7:D36,"Portfolio-wide",Policies!C7:C36,"Equipment")=0,"GAP",SUMIFS(Policies!E7:E36,Policies!D7:D36,A7,Policies!C7:C36,"Equipment")+SUMIFS(Policies!E7:E36,Policies!D7:D36,"Portfolio-wide",Policies!C7:C36,"Equipment"))) | G7: =IF(A7="","",IF(SUMIFS(Policies!G7:G36,Policies!D7:D36,A7,Policies!C7:C36,"Cyber")+SUMIFS(Policies!G7:G36,Policies!D7:D36,"Portfolio-wide",Policies!C7:C36,"Cyber")=0,"GAP",SUMIFS(Policies!E7:E36,Policies!D7:D36,A7,Policies!C7:C36,"Cyber")+SUMIFS(Policies!E7:E36,Policies!D7:D36,"Portfolio-wide",Policies!C7:C36,"Cyber"))) | H7: =IF(A7="","",SUMIFS(Policies!E7:E36,Policies!D7:D36,A7))
A8: =IFERROR(IF(Settings!B7="","",Settings!B7),"") | B8: =IF(A8="","",IF(SUMIFS(Policies!G7:G36,Policies!D7:D36,A8,Policies!C7:C36,"STR Dwelling")+SUMIFS(Policies!G7:G36,Policies!D7:D36,"Portfolio-wide",Policies!C7:C36,"STR Dwelling")=0,"GAP",SUMIFS(Policies!E7:E36,Policies!D7:D36,A8,Policies!C7:C36,"STR Dwelling")+SUMIFS(Policies!E7:E36,Policies!D7:D36,"Portfolio-wide",Policies!C7:C36,"STR Dwelling"))) | C8: =IF(A8="","",IF(SUMIFS(Policies!G7:G36,Policies!D7:D36,A8,Policies!C7:C36,"Umbrella Liability")+SUMIFS(Policies!G7:G36,Policies!D7:D36,"Portfolio-wide",Policies!C7:C36,"Umbrella Liability")=0,"GAP",SUMIFS(Policies!E7:E36,Policies!D7:D36,A8,Policies!C7:C36,"Umbrella Liability")+SUMIFS(Policies!E7:E36,Policies!D7:D36,"Portfolio-wide",Policies!C7:C36,"Umbrella Liability"))) | D8: =IF(A8="","",IF(SUMIFS(Policies!G7:G36,Policies!D7:D36,A8,Policies!C7:C36,"Loss of Rents")+SUMIFS(Policies!G7:G36,Policies!D7:D36,"Portfolio-wide",Policies!C7:C36,"Loss of Rents")=0,"GAP",SUMIFS(Policies!E7:E36,Policies!D7:D36,A8,Policies!C7:C36,"Loss of Rents")+SUMIFS(Policies!E7:E36,Policies!D7:D36,"Portfolio-wide",Policies!C7:C36,"Loss of Rents"))) | E8: =IF(A8="","",IF(SUMIFS(Policies!G7:G36,Policies!D7:D36,A8,Policies!C7:C36,"Auto")+SUMIFS(Policies!G7:G36,Policies!D7:D36,"Portfolio-wide",Policies!C7:C36,"Auto")=0,"GAP",SUMIFS(Policies!E7:E36,Policies!D7:D36,A8,Policies!C7:C36,"Auto")+SUMIFS(Policies!E7:E36,Policies!D7:D36,"Portfolio-wide",Policies!C7:C36,"Auto"))) | F8: =IF(A8="","",IF(SUMIFS(Policies!G7:G36,Policies!D7:D36,A8,Policies!C7:C36,"Equipment")+SUMIFS(Policies!G7:G36,Policies!D7:D36,"Portfolio-wide",Policies!C7:C36,"Equipment")=0,"GAP",SUMIFS(Policies!E7:E36,Policies!D7:D36,A8,Policies!C7:C36,"Equipment")+SUMIFS(Policies!E7:E36,Policies!D7:D36,"Portfolio-wide",Policies!C7:C36,"Equipment"))) | G8: =IF(A8="","",IF(SUMIFS(Policies!G7:G36,Policies!D7:D36,A8,Policies!C7:C36,"Cyber")+SUMIFS(Policies!G7:G36,Policies!D7:D36,"Portfolio-wide",Policies!C7:C36,"Cyber")=0,"GAP",SUMIFS(Policies!E7:E36,Policies!D7:D36,A8,Policies!C7:C36,"Cyber")+SUMIFS(Policies!E7:E36,Policies!D7:D36,"Portfolio-wide",Policies!C7:C36,"Cyber"))) | H8: =IF(A8="","",SUMIFS(Policies!E7:E36,Policies!D7:D36,A8))
A9: =IFERROR(IF(Settings!B8="","",Settings!B8),"") | B9: =IF(A9="","",IF(SUMIFS(Policies!G7:G36,Policies!D7:D36,A9,Policies!C7:C36,"STR Dwelling")+SUMIFS(Policies!G7:G36,Policies!D7:D36,"Portfolio-wide",Policies!C7:C36,"STR Dwelling")=0,"GAP",SUMIFS(Policies!E7:E36,Policies!D7:D36,A9,Policies!C7:C36,"STR Dwelling")+SUMIFS(Policies!E7:E36,Policies!D7:D36,"Portfolio-wide",Policies!C7:C36,"STR Dwelling"))) | C9: =IF(A9="","",IF(SUMIFS(Policies!G7:G36,Policies!D7:D36,A9,Policies!C7:C36,"Umbrella Liability")+SUMIFS(Policies!G7:G36,Policies!D7:D36,"Portfolio-wide",Policies!C7:C36,"Umbrella Liability")=0,"GAP",SUMIFS(Policies!E7:E36,Policies!D7:D36,A9,Policies!C7:C36,"Umbrella Liability")+SUMIFS(Policies!E7:E36,Policies!D7:D36,"Portfolio-wide",Policies!C7:C36,"Umbrella Liability"))) | D9: =IF(A9="","",IF(SUMIFS(Policies!G7:G36,Policies!D7:D36,A9,Policies!C7:C36,"Loss of Rents")+SUMIFS(Policies!G7:G36,Policies!D7:D36,"Portfolio-wide",Policies!C7:C36,"Loss of Rents")=0,"GAP",SUMIFS(Policies!E7:E36,Policies!D7:D36,A9,Policies!C7:C36,"Loss of Rents")+SUMIFS(Policies!E7:E36,Policies!D7:D36,"Portfolio-wide",Policies!C7:C36,"Loss of Rents"))) | E9: =IF(A9="","",IF(SUMIFS(Policies!G7:G36,Policies!D7:D36,A9,Policies!C7:C36,"Auto")+SUMIFS(Policies!G7:G36,Policies!D7:D36,"Portfolio-wide",Policies!C7:C36,"Auto")=0,"GAP",SUMIFS(Policies!E7:E36,Policies!D7:D36,A9,Policies!C7:C36,"Auto")+SUMIFS(Policies!E7:E36,Policies!D7:D36,"Portfolio-wide",Policies!C7:C36,"Auto"))) | F9: =IF(A9="","",IF(SUMIFS(Policies!G7:G36,Policies!D7:D36,A9,Policies!C7:C36,"Equipment")+SUMIFS(Policies!G7:G36,Policies!D7:D36,"Portfolio-wide",Policies!C7:C36,"Equipment")=0,"GAP",SUMIFS(Policies!E7:E36,Policies!D7:D36,A9,Policies!C7:C36,"Equipment")+SUMIFS(Policies!E7:E36,Policies!D7:D36,"Portfolio-wide",Policies!C7:C36,"Equipment"))) | G9: =IF(A9="","",IF(SUMIFS(Policies!G7:G36,Policies!D7:D36,A9,Policies!C7:C36,"Cyber")+SUMIFS(Policies!G7:G36,Policies!D7:D36,"Portfolio-wide",Policies!C7:C36,"Cyber")=0,"GAP",SUMIFS(Policies!E7:E36,Policies!D7:D36,A9,Policies!C7:C36,"Cyber")+SUMIFS(Policies!E7:E36,Policies!D7:D36,"Portfolio-wide",Policies!C7:C36,"Cyber"))) | H9: =IF(A9="","",SUMIFS(Policies!E7:E36,Policies!D7:D36,A9))
A10: =IFERROR(IF(Settings!B9="","",Settings!B9),"") | B10: =IF(A10="","",IF(SUMIFS(Policies!G7:G36,Policies!D7:D36,A10,Policies!C7:C36,"STR Dwelling")+SUMIFS(Policies!G7:G36,Policies!D7:D36,"Portfolio-wide",Policies!C7:C36,"STR Dwelling")=0,"GAP",SUMIFS(Policies!E7:E36,Policies!D7:D36,A10,Policies!C7:C36,"STR Dwelling")+SUMIFS(Policies!E7:E36,Policies!D7:D36,"Portfolio-wide",Policies!C7:C36,"STR Dwelling"))) | C10: =IF(A10="","",IF(SUMIFS(Policies!G7:G36,Policies!D7:D36,A10,Policies!C7:C36,"Umbrella Liability")+SUMIFS(Policies!G7:G36,Policies!D7:D36,"Portfolio-wide",Policies!C7:C36,"Umbrella Liability")=0,"GAP",SUMIFS(Policies!E7:E36,Policies!D7:D36,A10,Policies!C7:C36,"Umbrella Liability")+SUMIFS(Policies!E7:E36,Policies!D7:D36,"Portfolio-wide",Policies!C7:C36,"Umbrella Liability"))) | D10: =IF(A10="","",IF(SUMIFS(Policies!G7:G36,Policies!D7:D36,A10,Policies!C7:C36,"Loss of Rents")+SUMIFS(Policies!G7:G36,Policies!D7:D36,"Portfolio-wide",Policies!C7:C36,"Loss of Rents")=0,"GAP",SUMIFS(Policies!E7:E36,Policies!D7:D36,A10,Policies!C7:C36,"Loss of Rents")+SUMIFS(Policies!E7:E36,Policies!D7:D36,"Portfolio-wide",Policies!C7:C36,"Loss of Rents"))) | E10: =IF(A10="","",IF(SUMIFS(Policies!G7:G36,Policies!D7:D36,A10,Policies!C7:C36,"Auto")+SUMIFS(Policies!G7:G36,Policies!D7:D36,"Portfolio-wide",Policies!C7:C36,"Auto")=0,"GAP",SUMIFS(Policies!E7:E36,Policies!D7:D36,A10,Policies!C7:C36,"Auto")+SUMIFS(Policies!E7:E36,Policies!D7:D36,"Portfolio-wide",Policies!C7:C36,"Auto"))) | F10: =IF(A10="","",IF(SUMIFS(Policies!G7:G36,Policies!D7:D36,A10,Policies!C7:C36,"Equipment")+SUMIFS(Policies!G7:G36,Policies!D7:D36,"Portfolio-wide",Policies!C7:C36,"Equipment")=0,"GAP",SUMIFS(Policies!E7:E36,Policies!D7:D36,A10,Policies!C7:C36,"Equipment")+SUMIFS(Policies!E7:E36,Policies!D7:D36,"Portfolio-wide",Policies!C7:C36,"Equipment"))) | G10: =IF(A10="","",IF(SUMIFS(Policies!G7:G36,Policies!D7:D36,A10,Policies!C7:C36,"Cyber")+SUMIFS(Policies!G7:G36,Policies!D7:D36,"Portfolio-wide",Policies!C7:C36,"Cyber")=0,"GAP",SUMIFS(Policies!E7:E36,Policies!D7:D36,A10,Policies!C7:C36,"Cyber")+SUMIFS(Policies!E7:E36,Policies!D7:D36,"Portfolio-wide",Policies!C7:C36,"Cyber"))) | H10: =IF(A10="","",SUMIFS(Policies!E7:E36,Policies!D7:D36,A10))
A11: =IFERROR(IF(Settings!B10="","",Settings!B10),"") | B11: =IF(A11="","",IF(SUMIFS(Policies!G7:G36,Policies!D7:D36,A11,Policies!C7:C36,"STR Dwelling")+SUMIFS(Policies!G7:G36,Policies!D7:D36,"Portfolio-wide",Policies!C7:C36,"STR Dwelling")=0,"GAP",SUMIFS(Policies!E7:E36,Policies!D7:D36,A11,Policies!C7:C36,"STR Dwelling")+SUMIFS(Policies!E7:E36,Policies!D7:D36,"Portfolio-wide",Policies!C7:C36,"STR Dwelling"))) | C11: =IF(A11="","",IF(SUMIFS(Policies!G7:G36,Policies!D7:D36,A11,Policies!C7:C36,"Umbrella Liability")+SUMIFS(Policies!G7:G36,Policies!D7:D36,"Portfolio-wide",Policies!C7:C36,"Umbrella Liability")=0,"GAP",SUMIFS(Policies!E7:E36,Policies!D7:D36,A11,Policies!C7:C36,"Umbrella Liability")+SUMIFS(Policies!E7:E36,Policies!D7:D36,"Portfolio-wide",Policies!C7:C36,"Umbrella Liability"))) | D11: =IF(A11="","",IF(SUMIFS(Policies!G7:G36,Policies!D7:D36,A11,Policies!C7:C36,"Loss of Rents")+SUMIFS(Policies!G7:G36,Policies!D7:D36,"Portfolio-wide",Policies!C7:C36,"Loss of Rents")=0,"GAP",SUMIFS(Policies!E7:E36,Policies!D7:D36,A11,Policies!C7:C36,"Loss of Rents")+SUMIFS(Policies!E7:E36,Policies!D7:D36,"Portfolio-wide",Policies!C7:C36,"Loss of Rents"))) | E11: =IF(A11="","",IF(SUMIFS(Policies!G7:G36,Policies!D7:D36,A11,Policies!C7:C36,"Auto")+SUMIFS(Policies!G7:G36,Policies!D7:D36,"Portfolio-wide",Policies!C7:C36,"Auto")=0,"GAP",SUMIFS(Policies!E7:E36,Policies!D7:D36,A11,Policies!C7:C36,"Auto")+SUMIFS(Policies!E7:E36,Policies!D7:D36,"Portfolio-wide",Policies!C7:C36,"Auto"))) | F11: =IF(A11="","",IF(SUMIFS(Policies!G7:G36,Policies!D7:D36,A11,Policies!C7:C36,"Equipment")+SUMIFS(Policies!G7:G36,Policies!D7:D36,"Portfolio-wide",Policies!C7:C36,"Equipment")=0,"GAP",SUMIFS(Policies!E7:E36,Policies!D7:D36,A11,Policies!C7:C36,"Equipment")+SUMIFS(Policies!E7:E36,Policies!D7:D36,"Portfolio-wide",Policies!C7:C36,"Equipment"))) | G11: =IF(A11="","",IF(SUMIFS(Policies!G7:G36,Policies!D7:D36,A11,Policies!C7:C36,"Cyber")+SUMIFS(Policies!G7:G36,Policies!D7:D36,"Portfolio-wide",Policies!C7:C36,"Cyber")=0,"GAP",SUMIFS(Policies!E7:E36,Policies!D7:D36,A11,Policies!C7:C36,"Cyber")+SUMIFS(Policies!E7:E36,Policies!D7:D36,"Portfolio-wide",Policies!C7:C36,"Cyber"))) | H11: =IF(A11="","",SUMIFS(Policies!E7:E36,Policies!D7:D36,A11))
A12: =IFERROR(IF(Settings!B11="","",Settings!B11),"") | B12: =IF(A12="","",IF(SUMIFS(Policies!G7:G36,Policies!D7:D36,A12,Policies!C7:C36,"STR Dwelling")+SUMIFS(Policies!G7:G36,Policies!D7:D36,"Portfolio-wide",Policies!C7:C36,"STR Dwelling")=0,"GAP",SUMIFS(Policies!E7:E36,Policies!D7:D36,A12,Policies!C7:C36,"STR Dwelling")+SUMIFS(Policies!E7:E36,Policies!D7:D36,"Portfolio-wide",Policies!C7:C36,"STR Dwelling"))) | C12: =IF(A12="","",IF(SUMIFS(Policies!G7:G36,Policies!D7:D36,A12,Policies!C7:C36,"Umbrella Liability")+SUMIFS(Policies!G7:G36,Policies!D7:D36,"Portfolio-wide",Policies!C7:C36,"Umbrella Liability")=0,"GAP",SUMIFS(Policies!E7:E36,Policies!D7:D36,A12,Policies!C7:C36,"Umbrella Liability")+SUMIFS(Policies!E7:E36,Policies!D7:D36,"Portfolio-wide",Policies!C7:C36,"Umbrella Liability"))) | D12: =IF(A12="","",IF(SUMIFS(Policies!G7:G36,Policies!D7:D36,A12,Policies!C7:C36,"Loss of Rents")+SUMIFS(Policies!G7:G36,Policies!D7:D36,"Portfolio-wide",Policies!C7:C36,"Loss of Rents")=0,"GAP",SUMIFS(Policies!E7:E36,Policies!D7:D36,A12,Policies!C7:C36,"Loss of Rents")+SUMIFS(Policies!E7:E36,Policies!D7:D36,"Portfolio-wide",Policies!C7:C36,"Loss of Rents"))) | E12: =IF(A12="","",IF(SUMIFS(Policies!G7:G36,Policies!D7:D36,A12,Policies!C7:C36,"Auto")+SUMIFS(Policies!G7:G36,Policies!D7:D36,"Portfolio-wide",Policies!C7:C36,"Auto")=0,"GAP",SUMIFS(Policies!E7:E36,Policies!D7:D36,A12,Policies!C7:C36,"Auto")+SUMIFS(Policies!E7:E36,Policies!D7:D36,"Portfolio-wide",Policies!C7:C36,"Auto"))) | F12: =IF(A12="","",IF(SUMIFS(Policies!G7:G36,Policies!D7:D36,A12,Policies!C7:C36,"Equipment")+SUMIFS(Policies!G7:G36,Policies!D7:D36,"Portfolio-wide",Policies!C7:C36,"Equipment")=0,"GAP",SUMIFS(Policies!E7:E36,Policies!D7:D36,A12,Policies!C7:C36,"Equipment")+SUMIFS(Policies!E7:E36,Policies!D7:D36,"Portfolio-wide",Policies!C7:C36,"Equipment"))) | G12: =IF(A12="","",IF(SUMIFS(Policies!G7:G36,Policies!D7:D36,A12,Policies!C7:C36,"Cyber")+SUMIFS(Policies!G7:G36,Policies!D7:D36,"Portfolio-wide",Policies!C7:C36,"Cyber")=0,"GAP",SUMIFS(Policies!E7:E36,Policies!D7:D36,A12,Policies!C7:C36,"Cyber")+SUMIFS(Policies!E7:E36,Policies!D7:D36,"Portfolio-wide",Policies!C7:C36,"Cyber"))) | H12: =IF(A12="","",SUMIFS(Policies!E7:E36,Policies!D7:D36,A12))
A13: =IFERROR(IF(Settings!B12="","",Settings!B12),"") | B13: =IF(A13="","",IF(SUMIFS(Policies!G7:G36,Policies!D7:D36,A13,Policies!C7:C36,"STR Dwelling")+SUMIFS(Policies!G7:G36,Policies!D7:D36,"Portfolio-wide",Policies!C7:C36,"STR Dwelling")=0,"GAP",SUMIFS(Policies!E7:E36,Policies!D7:D36,A13,Policies!C7:C36,"STR Dwelling")+SUMIFS(Policies!E7:E36,Policies!D7:D36,"Portfolio-wide",Policies!C7:C36,"STR Dwelling"))) | C13: =IF(A13="","",IF(SUMIFS(Policies!G7:G36,Policies!D7:D36,A13,Policies!C7:C36,"Umbrella Liability")+SUMIFS(Policies!G7:G36,Policies!D7:D36,"Portfolio-wide",Policies!C7:C36,"Umbrella Liability")=0,"GAP",SUMIFS(Policies!E7:E36,Policies!D7:D36,A13,Policies!C7:C36,"Umbrella Liability")+SUMIFS(Policies!E7:E36,Policies!D7:D36,"Portfolio-wide",Policies!C7:C36,"Umbrella Liability"))) | D13: =IF(A13="","",IF(SUMIFS(Policies!G7:G36,Policies!D7:D36,A13,Policies!C7:C36,"Loss of Rents")+SUMIFS(Policies!G7:G36,Policies!D7:D36,"Portfolio-wide",Policies!C7:C36,"Loss of Rents")=0,"GAP",SUMIFS(Policies!E7:E36,Policies!D7:D36,A13,Policies!C7:C36,"Loss of Rents")+SUMIFS(Policies!E7:E36,Policies!D7:D36,"Portfolio-wide",Policies!C7:C36,"Loss of Rents"))) | E13: =IF(A13="","",IF(SUMIFS(Policies!G7:G36,Policies!D7:D36,A13,Policies!C7:C36,"Auto")+SUMIFS(Policies!G7:G36,Policies!D7:D36,"Portfolio-wide",Policies!C7:C36,"Auto")=0,"GAP",SUMIFS(Policies!E7:E36,Policies!D7:D36,A13,Policies!C7:C36,"Auto")+SUMIFS(Policies!E7:E36,Policies!D7:D36,"Portfolio-wide",Policies!C7:C36,"Auto"))) | F13: =IF(A13="","",IF(SUMIFS(Policies!G7:G36,Policies!D7:D36,A13,Policies!C7:C36,"Equipment")+SUMIFS(Policies!G7:G36,Policies!D7:D36,"Portfolio-wide",Policies!C7:C36,"Equipment")=0,"GAP",SUMIFS(Policies!E7:E36,Policies!D7:D36,A13,Policies!C7:C36,"Equipment")+SUMIFS(Policies!E7:E36,Policies!D7:D36,"Portfolio-wide",Policies!C7:C36,"Equipment"))) | G13: =IF(A13="","",IF(SUMIFS(Policies!G7:G36,Policies!D7:D36,A13,Policies!C7:C36,"Cyber")+SUMIFS(Policies!G7:G36,Policies!D7:D36,"Portfolio-wide",Policies!C7:C36,"Cyber")=0,"GAP",SUMIFS(Policies!E7:E36,Policies!D7:D36,A13,Policies!C7:C36,"Cyber")+SUMIFS(Policies!E7:E36,Policies!D7:D36,"Portfolio-wide",Policies!C7:C36,"Cyber"))) | H13: =IF(A13="","",SUMIFS(Policies!E7:E36,Policies!D7:D36,A13))
A14: =IFERROR(IF(Settings!B13="","",Settings!B13),"") | B14: =IF(A14="","",IF(SUMIFS(Policies!G7:G36,Policies!D7:D36,A14,Policies!C7:C36,"STR Dwelling")+SUMIFS(Policies!G7:G36,Policies!D7:D36,"Portfolio-wide",Policies!C7:C36,"STR Dwelling")=0,"GAP",SUMIFS(Policies!E7:E36,Policies!D7:D36,A14,Policies!C7:C36,"STR Dwelling")+SUMIFS(Policies!E7:E36,Policies!D7:D36,"Portfolio-wide",Policies!C7:C36,"STR Dwelling"))) | C14: =IF(A14="","",IF(SUMIFS(Policies!G7:G36,Policies!D7:D36,A14,Policies!C7:C36,"Umbrella Liability")+SUMIFS(Policies!G7:G36,Policies!D7:D36,"Portfolio-wide",Policies!C7:C36,"Umbrella Liability")=0,"GAP",SUMIFS(Policies!E7:E36,Policies!D7:D36,A14,Policies!C7:C36,"Umbrella Liability")+SUMIFS(Policies!E7:E36,Policies!D7:D36,"Portfolio-wide",Policies!C7:C36,"Umbrella Liability"))) | D14: =IF(A14="","",IF(SUMIFS(Policies!G7:G36,Policies!D7:D36,A14,Policies!C7:C36,"Loss of Rents")+SUMIFS(Policies!G7:G36,Policies!D7:D36,"Portfolio-wide",Policies!C7:C36,"Loss of Rents")=0,"GAP",SUMIFS(Policies!E7:E36,Policies!D7:D36,A14,Policies!C7:C36,"Loss of Rents")+SUMIFS(Policies!E7:E36,Policies!D7:D36,"Portfolio-wide",Policies!C7:C36,"Loss of Rents"))) | E14: =IF(A14="","",IF(SUMIFS(Policies!G7:G36,Policies!D7:D36,A14,Policies!C7:C36,"Auto")+SUMIFS(Policies!G7:G36,Policies!D7:D36,"Portfolio-wide",Policies!C7:C36,"Auto")=0,"GAP",SUMIFS(Policies!E7:E36,Policies!D7:D36,A14,Policies!C7:C36,"Auto")+SUMIFS(Policies!E7:E36,Policies!D7:D36,"Portfolio-wide",Policies!C7:C36,"Auto"))) | F14: =IF(A14="","",IF(SUMIFS(Policies!G7:G36,Policies!D7:D36,A14,Policies!C7:C36,"Equipment")+SUMIFS(Policies!G7:G36,Policies!D7:D36,"Portfolio-wide",Policies!C7:C36,"Equipment")=0,"GAP",SUMIFS(Policies!E7:E36,Policies!D7:D36,A14,Policies!C7:C36,"Equipment")+SUMIFS(Policies!E7:E36,Policies!D7:D36,"Portfolio-wide",Policies!C7:C36,"Equipment"))) | G14: =IF(A14="","",IF(SUMIFS(Policies!G7:G36,Policies!D7:D36,A14,Policies!C7:C36,"Cyber")+SUMIFS(Policies!G7:G36,Policies!D7:D36,"Portfolio-wide",Policies!C7:C36,"Cyber")=0,"GAP",SUMIFS(Policies!E7:E36,Policies!D7:D36,A14,Policies!C7:C36,"Cyber")+SUMIFS(Policies!E7:E36,Policies!D7:D36,"Portfolio-wide",Policies!C7:C36,"Cyber"))) | H14: =IF(A14="","",SUMIFS(Policies!E7:E36,Policies!D7:D36,A14))
A15: =IFERROR(IF(Settings!B14="","",Settings!B14),"") | B15: =IF(A15="","",IF(SUMIFS(Policies!G7:G36,Policies!D7:D36,A15,Policies!C7:C36,"STR Dwelling")+SUMIFS(Policies!G7:G36,Policies!D7:D36,"Portfolio-wide",Policies!C7:C36,"STR Dwelling")=0,"GAP",SUMIFS(Policies!E7:E36,Policies!D7:D36,A15,Policies!C7:C36,"STR Dwelling")+SUMIFS(Policies!E7:E36,Policies!D7:D36,"Portfolio-wide",Policies!C7:C36,"STR Dwelling"))) | C15: =IF(A15="","",IF(SUMIFS(Policies!G7:G36,Policies!D7:D36,A15,Policies!C7:C36,"Umbrella Liability")+SUMIFS(Policies!G7:G36,Policies!D7:D36,"Portfolio-wide",Policies!C7:C36,"Umbrella Liability")=0,"GAP",SUMIFS(Policies!E7:E36,Policies!D7:D36,A15,Policies!C7:C36,"Umbrella Liability")+SUMIFS(Policies!E7:E36,Policies!D7:D36,"Portfolio-wide",Policies!C7:C36,"Umbrella Liability"))) | D15: =IF(A15="","",IF(SUMIFS(Policies!G7:G36,Policies!D7:D36,A15,Policies!C7:C36,"Loss of Rents")+SUMIFS(Policies!G7:G36,Policies!D7:D36,"Portfolio-wide",Policies!C7:C36,"Loss of Rents")=0,"GAP",SUMIFS(Policies!E7:E36,Policies!D7:D36,A15,Policies!C7:C36,"Loss of Rents")+SUMIFS(Policies!E7:E36,Policies!D7:D36,"Portfolio-wide",Policies!C7:C36,"Loss of Rents"))) | E15: =IF(A15="","",IF(SUMIFS(Policies!G7:G36,Policies!D7:D36,A15,Policies!C7:C36,"Auto")+SUMIFS(Policies!G7:G36,Policies!D7:D36,"Portfolio-wide",Policies!C7:C36,"Auto")=0,"GAP",SUMIFS(Policies!E7:E36,Policies!D7:D36,A15,Policies!C7:C36,"Auto")+SUMIFS(Policies!E7:E36,Policies!D7:D36,"Portfolio-wide",Policies!C7:C36,"Auto"))) | F15: =IF(A15="","",IF(SUMIFS(Policies!G7:G36,Policies!D7:D36,A15,Policies!C7:C36,"Equipment")+SUMIFS(Policies!G7:G36,Policies!D7:D36,"Portfolio-wide",Policies!C7:C36,"Equipment")=0,"GAP",SUMIFS(Policies!E7:E36,Policies!D7:D36,A15,Policies!C7:C36,"Equipment")+SUMIFS(Policies!E7:E36,Policies!D7:D36,"Portfolio-wide",Policies!C7:C36,"Equipment"))) | G15: =IF(A15="","",IF(SUMIFS(Policies!G7:G36,Policies!D7:D36,A15,Policies!C7:C36,"Cyber")+SUMIFS(Policies!G7:G36,Policies!D7:D36,"Portfolio-wide",Policies!C7:C36,"Cyber")=0,"GAP",SUMIFS(Policies!E7:E36,Policies!D7:D36,A15,Policies!C7:C36,"Cyber")+SUMIFS(Policies!E7:E36,Policies!D7:D36,"Portfolio-wide",Policies!C7:C36,"Cyber"))) | H15: =IF(A15="","",SUMIFS(Policies!E7:E36,Policies!D7:D36,A15))
A16: =IFERROR(IF(Settings!B15="","",Settings!B15),"") | B16: =IF(A16="","",IF(SUMIFS(Policies!G7:G36,Policies!D7:D36,A16,Policies!C7:C36,"STR Dwelling")+SUMIFS(Policies!G7:G36,Policies!D7:D36,"Portfolio-wide",Policies!C7:C36,"STR Dwelling")=0,"GAP",SUMIFS(Policies!E7:E36,Policies!D7:D36,A16,Policies!C7:C36,"STR Dwelling")+SUMIFS(Policies!E7:E36,Policies!D7:D36,"Portfolio-wide",Policies!C7:C36,"STR Dwelling"))) | C16: =IF(A16="","",IF(SUMIFS(Policies!G7:G36,Policies!D7:D36,A16,Policies!C7:C36,"Umbrella Liability")+SUMIFS(Policies!G7:G36,Policies!D7:D36,"Portfolio-wide",Policies!C7:C36,"Umbrella Liability")=0,"GAP",SUMIFS(Policies!E7:E36,Policies!D7:D36,A16,Policies!C7:C36,"Umbrella Liability")+SUMIFS(Policies!E7:E36,Policies!D7:D36,"Portfolio-wide",Policies!C7:C36,"Umbrella Liability"))) | D16: =IF(A16="","",IF(SUMIFS(Policies!G7:G36,Policies!D7:D36,A16,Policies!C7:C36,"Loss of Rents")+SUMIFS(Policies!G7:G36,Policies!D7:D36,"Portfolio-wide",Policies!C7:C36,"Loss of Rents")=0,"GAP",SUMIFS(Policies!E7:E36,Policies!D7:D36,A16,Policies!C7:C36,"Loss of Rents")+SUMIFS(Policies!E7:E36,Policies!D7:D36,"Portfolio-wide",Policies!C7:C36,"Loss of Rents"))) | E16: =IF(A16="","",IF(SUMIFS(Policies!G7:G36,Policies!D7:D36,A16,Policies!C7:C36,"Auto")+SUMIFS(Policies!G7:G36,Policies!D7:D36,"Portfolio-wide",Policies!C7:C36,"Auto")=0,"GAP",SUMIFS(Policies!E7:E36,Policies!D7:D36,A16,Policies!C7:C36,"Auto")+SUMIFS(Policies!E7:E36,Policies!D7:D36,"Portfolio-wide",Policies!C7:C36,"Auto"))) | F16: =IF(A16="","",IF(SUMIFS(Policies!G7:G36,Policies!D7:D36,A16,Policies!C7:C36,"Equipment")+SUMIFS(Policies!G7:G36,Policies!D7:D36,"Portfolio-wide",Policies!C7:C36,"Equipment")=0,"GAP",SUMIFS(Policies!E7:E36,Policies!D7:D36,A16,Policies!C7:C36,"Equipment")+SUMIFS(Policies!E7:E36,Policies!D7:D36,"Portfolio-wide",Policies!C7:C36,"Equipment"))) | G16: =IF(A16="","",IF(SUMIFS(Policies!G7:G36,Policies!D7:D36,A16,Policies!C7:C36,"Cyber")+SUMIFS(Policies!G7:G36,Policies!D7:D36,"Portfolio-wide",Policies!C7:C36,"Cyber")=0,"GAP",SUMIFS(Policies!E7:E36,Policies!D7:D36,A16,Policies!C7:C36,"Cyber")+SUMIFS(Policies!E7:E36,Policies!D7:D36,"Portfolio-wide",Policies!C7:C36,"Cyber"))) | H16: =IF(A16="","",SUMIFS(Policies!E7:E36,Policies!D7:D36,A16))
A18: Portfolio total | H18: =SUM(H7:H16)
A20: =IF(COUNTIF(B7:G16,"GAP")>0,"COVERAGE GAPS: "&COUNTIF(B7:G16,"GAP")&" — review the red cells above. Each gap is uninsured exposure.","NO COVERAGE GAPS — every property carries coverage in every column.")

Sheet Premium Forecast
A2: =HYPERLINK("#'Coverage Map'!A1", "← BACK") | D2: PREMIUM FORECAST | J2: =HYPERLINK("#'Claim Log'!A1", "NEXT →")
A4: 24-month renewal calendar. Premium falls in the month each policy's expiration date hits. Use the totals row for cash-flow planning.
A6: Policy # | B6: Carrier | C6: Property | D6: =TEXT(DATE(Settings!$B$5,1,1),"yyyy-mm") | E6: =TEXT(DATE(Settings!$B$5,2,1),"yyyy-mm") | F6: =TEXT(DATE(Settings!$B$5,3,1),"yyyy-mm") | G6: =TEXT(DATE(Settings!$B$5,4,1),"yyyy-mm") | H6: =TEXT(DATE(Settings!$B$5,5,1),"yyyy-mm") | I6: =TEXT(DATE(Settings!$B$5,6,1),"yyyy-mm") | J6: =TEXT(DATE(Settings!$B$5,7,1),"yyyy-mm") | K6: =TEXT(DATE(Settings!$B$5,8,1),"yyyy-mm") | L6: =TEXT(DATE(Settings!$B$5,9,1),"yyyy-mm") | M6: =TEXT(DATE(Settings!$B$5,10,1),"yyyy-mm") | N6: =TEXT(DATE(Settings!$B$5,11,1),"yyyy-mm") | O6: =TEXT(DATE(Settings!$B$5,12,1),"yyyy-mm") | P6: =TEXT(DATE(Settings!$B$5,13,1),"yyyy-mm") | Q6: =TEXT(DATE(Settings!$B$5,14,1),"yyyy-mm") | R6: =TEXT(DATE(Settings!$B$5,15,1),"yyyy-mm") | S6: =TEXT(DATE(Settings!$B$5,16,1),"yyyy-mm") | T6: =TEXT(DATE(Settings!$B$5,17,1),"yyyy-mm") | U6: =TEXT(DATE(Settings!$B$5,18,1),"yyyy-mm") | V6: =TEXT(DATE(Settings!$B$5,19,1),"yyyy-mm") | W6: =TEXT(DATE(Settings!$B$5,20,1),"yyyy-mm") | X6: =TEXT(DATE(Settings!$B$5,21,1),"yyyy-mm") | Y6: =TEXT(DATE(Settings!$B$5,22,1),"yyyy-mm") | Z6: =TEXT(DATE(Settings!$B$5,23,1),"yyyy-mm") | AA6: =TEXT(DATE(Settings!$B$5,24,1),"yyyy-mm") | AB6: Row total
A7: =IF(Policies!A7="","",Policies!A7) | B7: =IF(Policies!B7="","",Policies!B7) | C7: =IF(Policies!D7="","",Policies!D7) | D7: =IF(Policies!I7="","",IF((YEAR(Policies!I7)*12+MONTH(Policies!I7))=(Settings!$B$5*12+1),Policies!G7,"")) | E7: =IF(Policies!I7="","",IF((YEAR(Policies!I7)*12+MONTH(Policies!I7))=(Settings!$B$5*12+2),Policies!G7,"")) | F7: =IF(Policies!I7="","",IF((YEAR(Policies!I7)*12+MONTH(Policies!I7))=(Settings!$B$5*12+3),Policies!G7,"")) | G7: =IF(Policies!I7="","",IF((YEAR(Policies!I7)*12+MONTH(Policies!I7))=(Settings!$B$5*12+4),Policies!G7,"")) | H7: =IF(Policies!I7="","",IF((YEAR(Policies!I7)*12+MONTH(Policies!I7))=(Settings!$B$5*12+5),Policies!G7,"")) | I7: =IF(Policies!I7="","",IF((YEAR(Policies!I7)*12+MONTH(Policies!I7))=(Settings!$B$5*12+6),Policies!G7,"")) | J7: =IF(Policies!I7="","",IF((YEAR(Policies!I7)*12+MONTH(Policies!I7))=(Settings!$B$5*12+7),Policies!G7,"")) | K7: =IF(Policies!I7="","",IF((YEAR(Policies!I7)*12+MONTH(Policies!I7))=(Settings!$B$5*12+8),Policies!G7,"")) | L7: =IF(Policies!I7="","",IF((YEAR(Policies!I7)*12+MONTH(Policies!I7))=(Settings!$B$5*12+9),Policies!G7,"")) | M7: =IF(Policies!I7="","",IF((YEAR(Policies!I7)*12+MONTH(Policies!I7))=(Settings!$B$5*12+10),Policies!G7,"")) | N7: =IF(Policies!I7="","",IF((YEAR(Policies!I7)*12+MONTH(Policies!I7))=(Settings!$B$5*12+11),Policies!G7,"")) | O7: =IF(Policies!I7="","",IF((YEAR(Policies!I7)*12+MONTH(Policies!I7))=(Settings!$B$5*12+12),Policies!G7,"")) | P7: =IF(Policies!I7="","",IF((YEAR(Policies!I7)*12+MONTH(Policies!I7))=(Settings!$B$5*12+13),Policies!G7,"")) | Q7: =IF(Policies!I7="","",IF((YEAR(Policies!I7)*12+MONTH(Policies!I7))=(Settings!$B$5*12+14),Policies!G7,"")) | R7: =IF(Policies!I7="","",IF((YEAR(Policies!I7)*12+MONTH(Policies!I7))=(Settings!$B$5*12+15),Policies!G7,"")) | S7: =IF(Policies!I7="","",IF((YEAR(Policies!I7)*12+MONTH(Policies!I7))=(Settings!$B$5*12+16),Policies!G7,"")) | T7: =IF(Policies!I7="","",IF((YEAR(Policies!I7)*12+MONTH(Policies!I7))=(Settings!$B$5*12+17),Policies!G7,"")) | U7: =IF(Policies!I7="","",IF((YEAR(Policies!I7)*12+MONTH(Policies!I7))=(Settings!$B$5*12+18),Policies!G7,"")) | V7: =IF(Policies!I7="","",IF((YEAR(Policies!I7)*12+MONTH(Policies!I7))=(Settings!$B$5*12+19),Policies!G7,"")) | W7: =IF(Policies!I7="","",IF((YEAR(Policies!I7)*12+MONTH(Policies!I7))=(Settings!$B$5*12+20),Policies!G7,"")) | X7: =IF(Policies!I7="","",IF((YEAR(Policies!I7)*12+MONTH(Policies!I7))=(Settings!$B$5*12+21),Policies!G7,"")) | Y7: =IF(Policies!I7="","",IF((YEAR(Policies!I7)*12+MONTH(Policies!I7))=(Settings!$B$5*12+22),Policies!G7,"")) | Z7: =IF(Policies!I7="","",IF((YEAR(Policies!I7)*12+MONTH(Policies!I7))=(Settings!$B$5*12+23),Policies!G7,"")) | AA7: =IF(Policies!I7="","",IF((YEAR(Policies!I7)*12+MONTH(Policies!I7))=(Settings!$B$5*12+24),Policies!G7,"")) | AB7: =IF(SUM(D7:AA7)=0,"",SUM(D7:AA7))
A8: =IF(Policies!A8="","",Policies!A8) | B8: =IF(Policies!B8="","",Policies!B8) | C8: =IF(Policies!D8="","",Policies!D8) | D8: =IF(Policies!I8="","",IF((YEAR(Policies!I8)*12+MONTH(Policies!I8))=(Settings!$B$5*12+1),Policies!G8,"")) | E8: =IF(Policies!I8="","",IF((YEAR(Policies!I8)*12+MONTH(Policies!I8))=(Settings!$B$5*12+2),Policies!G8,"")) | F8: =IF(Policies!I8="","",IF((YEAR(Policies!I8)*12+MONTH(Policies!I8))=(Settings!$B$5*12+3),Policies!G8,"")) | G8: =IF(Policies!I8="","",IF((YEAR(Policies!I8)*12+MONTH(Policies!I8))=(Settings!$B$5*12+4),Policies!G8,"")) | H8: =IF(Policies!I8="","",IF((YEAR(Policies!I8)*12+MONTH(Policies!I8))=(Settings!$B$5*12+5),Policies!G8,"")) | I8: =IF(Policies!I8="","",IF((YEAR(Policies!I8)*12+MONTH(Policies!I8))=(Settings!$B$5*12+6),Policies!G8,"")) | J8: =IF(Policies!I8="","",IF((YEAR(Policies!I8)*12+MONTH(Policies!I8))=(Settings!$B$5*12+7),Policies!G8,"")) | K8: =IF(Policies!I8="","",IF((YEAR(Policies!I8)*12+MONTH(Policies!I8))=(Settings!$B$5*12+8),Policies!G8,"")) | L8: =IF(Policies!I8="","",IF((YEAR(Policies!I8)*12+MONTH(Policies!I8))=(Settings!$B$5*12+9),Policies!G8,"")) | M8: =IF(Policies!I8="","",IF((YEAR(Policies!I8)*12+MONTH(Policies!I8))=(Settings!$B$5*12+10),Policies!G8,"")) | N8: =IF(Policies!I8="","",IF((YEAR(Policies!I8)*12+MONTH(Policies!I8))=(Settings!$B$5*12+11),Policies!G8,"")) | O8: =IF(Policies!I8="","",IF((YEAR(Policies!I8)*12+MONTH(Policies!I8))=(Settings!$B$5*12+12),Policies!G8,"")) | P8: =IF(Policies!I8="","",IF((YEAR(Policies!I8)*12+MONTH(Policies!I8))=(Settings!$B$5*12+13),Policies!G8,"")) | Q8: =IF(Policies!I8="","",IF((YEAR(Policies!I8)*12+MONTH(Policies!I8))=(Settings!$B$5*12+14),Policies!G8,"")) | R8: =IF(Policies!I8="","",IF((YEAR(Policies!I8)*12+MONTH(Policies!I8))=(Settings!$B$5*12+15),Policies!G8,"")) | S8: =IF(Policies!I8="","",IF((YEAR(Policies!I8)*12+MONTH(Policies!I8))=(Settings!$B$5*12+16),Policies!G8,"")) | T8: =IF(Policies!I8="","",IF((YEAR(Policies!I8)*12+MONTH(Policies!I8))=(Settings!$B$5*12+17),Policies!G8,"")) | U8: =IF(Policies!I8="","",IF((YEAR(Policies!I8)*12+MONTH(Policies!I8))=(Settings!$B$5*12+18),Policies!G8,"")) | V8: =IF(Policies!I8="","",IF((YEAR(Policies!I8)*12+MONTH(Policies!I8))=(Settings!$B$5*12+19),Policies!G8,"")) | W8: =IF(Policies!I8="","",IF((YEAR(Policies!I8)*12+MONTH(Policies!I8))=(Settings!$B$5*12+20),Policies!G8,"")) | X8: =IF(Policies!I8="","",IF((YEAR(Policies!I8)*12+MONTH(Policies!I8))=(Settings!$B$5*12+21),Policies!G8,"")) | Y8: =IF(Policies!I8="","",IF((YEAR(Policies!I8)*12+MONTH(Policies!I8))=(Settings!$B$5*12+22),Policies!G8,"")) | Z8: =IF(Policies!I8="","",IF((YEAR(Policies!I8)*12+MONTH(Policies!I8))=(Settings!$B$5*12+23),Policies!G8,"")) | AA8: =IF(Policies!I8="","",IF((YEAR(Policies!I8)*12+MONTH(Policies!I8))=(Settings!$B$5*12+24),Policies!G8,"")) | AB8: =IF(SUM(D8:AA8)=0,"",SUM(D8:AA8))
A9: =IF(Policies!A9="","",Policies!A9) | B9: =IF(Policies!B9="","",Policies!B9) | C9: =IF(Policies!D9="","",Policies!D9) | D9: =IF(Policies!I9="","",IF((YEAR(Policies!I9)*12+MONTH(Policies!I9))=(Settings!$B$5*12+1),Policies!G9,"")) | E9: =IF(Policies!I9="","",IF((YEAR(Policies!I9)*12+MONTH(Policies!I9))=(Settings!$B$5*12+2),Policies!G9,"")) | F9: =IF(Policies!I9="","",IF((YEAR(Policies!I9)*12+MONTH(Policies!I9))=(Settings!$B$5*12+3),Policies!G9,"")) | G9: =IF(Policies!I9="","",IF((YEAR(Policies!I9)*12+MONTH(Policies!I9))=(Settings!$B$5*12+4),Policies!G9,"")) | H9: =IF(Policies!I9="","",IF((YEAR(Policies!I9)*12+MONTH(Policies!I9))=(Settings!$B$5*12+5),Policies!G9,"")) | I9: =IF(Policies!I9="","",IF((YEAR(Policies!I9)*12+MONTH(Policies!I9))=(Settings!$B$5*12+6),Policies!G9,"")) | J9: =IF(Policies!I9="","",IF((YEAR(Policies!I9)*12+MONTH(Policies!I9))=(Settings!$B$5*12+7),Policies!G9,"")) | K9: =IF(Policies!I9="","",IF((YEAR(Policies!I9)*12+MONTH(Policies!I9))=(Settings!$B$5*12+8),Policies!G9,"")) | L9: =IF(Policies!I9="","",IF((YEAR(Policies!I9)*12+MONTH(Policies!I9))=(Settings!$B$5*12+9),Policies!G9,"")) | M9: =IF(Policies!I9="","",IF((YEAR(Policies!I9)*12+MONTH(Policies!I9))=(Settings!$B$5*12+10),Policies!G9,"")) | N9: =IF(Policies!I9="","",IF((YEAR(Policies!I9)*12+MONTH(Policies!I9))=(Settings!$B$5*12+11),Policies!G9,"")) | O9: =IF(Policies!I9="","",IF((YEAR(Policies!I9)*12+MONTH(Policies!I9))=(Settings!$B$5*12+12),Policies!G9,"")) | P9: =IF(Policies!I9="","",IF((YEAR(Policies!I9)*12+MONTH(Policies!I9))=(Settings!$B$5*12+13),Policies!G9,"")) | Q9: =IF(Policies!I9="","",IF((YEAR(Policies!I9)*12+MONTH(Policies!I9))=(Settings!$B$5*12+14),Policies!G9,"")) | R9: =IF(Policies!I9="","",IF((YEAR(Policies!I9)*12+MONTH(Policies!I9))=(Settings!$B$5*12+15),Policies!G9,"")) | S9: =IF(Policies!I9="","",IF((YEAR(Policies!I9)*12+MONTH(Policies!I9))=(Settings!$B$5*12+16),Policies!G9,"")) | T9: =IF(Policies!I9="","",IF((YEAR(Policies!I9)*12+MONTH(Policies!I9))=(Settings!$B$5*12+17),Policies!G9,"")) | U9: =IF(Policies!I9="","",IF((YEAR(Policies!I9)*12+MONTH(Policies!I9))=(Settings!$B$5*12+18),Policies!G9,"")) | V9: =IF(Policies!I9="","",IF((YEAR(Policies!I9)*12+MONTH(Policies!I9))=(Settings!$B$5*12+19),Policies!G9,"")) | W9: =IF(Policies!I9="","",IF((YEAR(Policies!I9)*12+MONTH(Policies!I9))=(Settings!$B$5*12+20),Policies!G9,"")) | X9: =IF(Policies!I9="","",IF((YEAR(Policies!I9)*12+MONTH(Policies!I9))=(Settings!$B$5*12+21),Policies!G9,"")) | Y9: =IF(Policies!I9="","",IF((YEAR(Policies!I9)*12+MONTH(Policies!I9))=(Settings!$B$5*12+22),Policies!G9,"")) | Z9: =IF(Policies!I9="","",IF((YEAR(Policies!I9)*12+MONTH(Policies!I9))=(Settings!$B$5*12+23),Policies!G9,"")) | AA9: =IF(Policies!I9="","",IF((YEAR(Policies!I9)*12+MONTH(Policies!I9))=(Settings!$B$5*12+24),Policies!G9,"")) | AB9: =IF(SUM(D9:AA9)=0,"",SUM(D9:AA9))
A10: =IF(Policies!A10="","",Policies!A10) | B10: =IF(Policies!B10="","",Policies!B10) | C10: =IF(Policies!D10="","",Policies!D10) | D10: =IF(Policies!I10="","",IF((YEAR(Policies!I10)*12+MONTH(Policies!I10))=(Settings!$B$5*12+1),Policies!G10,"")) | E10: =IF(Policies!I10="","",IF((YEAR(Policies!I10)*12+MONTH(Policies!I10))=(Settings!$B$5*12+2),Policies!G10,"")) | F10: =IF(Policies!I10="","",IF((YEAR(Policies!I10)*12+MONTH(Policies!I10))=(Settings!$B$5*12+3),Policies!G10,"")) | G10: =IF(Policies!I10="","",IF((YEAR(Policies!I10)*12+MONTH(Policies!I10))=(Settings!$B$5*12+4),Policies!G10,"")) | H10: =IF(Policies!I10="","",IF((YEAR(Policies!I10)*12+MONTH(Policies!I10))=(Settings!$B$5*12+5),Policies!G10,"")) | I10: =IF(Policies!I10="","",IF((YEAR(Policies!I10)*12+MONTH(Policies!I10))=(Settings!$B$5*12+6),Policies!G10,"")) | J10: =IF(Policies!I10="","",IF((YEAR(Policies!I10)*12+MONTH(Policies!I10))=(Settings!$B$5*12+7),Policies!G10,"")) | K10: =IF(Policies!I10="","",IF((YEAR(Policies!I10)*12+MONTH(Policies!I10))=(Settings!$B$5*12+8),Policies!G10,"")) | L10: =IF(Policies!I10="","",IF((YEAR(Policies!I10)*12+MONTH(Policies!I10))=(Settings!$B$5*12+9),Policies!G10,"")) | M10: =IF(Policies!I10="","",IF((YEAR(Policies!I10)*12+MONTH(Policies!I10))=(Settings!$B$5*12+10),Policies!G10,"")) | N10: =IF(Policies!I10="","",IF((YEAR(Policies!I10)*12+MONTH(Policies!I10))=(Settings!$B$5*12+11),Policies!G10,"")) | O10: =IF(Policies!I10="","",IF((YEAR(Policies!I10)*12+MONTH(Policies!I10))=(Settings!$B$5*12+12),Policies!G10,"")) | P10: =IF(Policies!I10="","",IF((YEAR(Policies!I10)*12+MONTH(Policies!I10))=(Settings!$B$5*12+13),Policies!G10,"")) | Q10: =IF(Policies!I10="","",IF((YEAR(Policies!I10)*12+MONTH(Policies!I10))=(Settings!$B$5*12+14),Policies!G10,"")) | R10: =IF(Policies!I10="","",IF((YEAR(Policies!I10)*12+MONTH(Policies!I10))=(Settings!$B$5*12+15),Policies!G10,"")) | S10: =IF(Policies!I10="","",IF((YEAR(Policies!I10)*12+MONTH(Policies!I10))=(Settings!$B$5*12+16),Policies!G10,"")) | T10: =IF(Policies!I10="","",IF((YEAR(Policies!I10)*12+MONTH(Policies!I10))=(Settings!$B$5*12+17),Policies!G10,"")) | U10: =IF(Policies!I10="","",IF((YEAR(Policies!I10)*12+MONTH(Policies!I10))=(Settings!$B$5*12+18),Policies!G10,"")) | V10: =IF(Policies!I10="","",IF((YEAR(Policies!I10)*12+MONTH(Policies!I10))=(Settings!$B$5*12+19),Policies!G10,"")) | W10: =IF(Policies!I10="","",IF((YEAR(Policies!I10)*12+MONTH(Policies!I10))=(Settings!$B$5*12+20),Policies!G10,"")) | X10: =IF(Policies!I10="","",IF((YEAR(Policies!I10)*12+MONTH(Policies!I10))=(Settings!$B$5*12+21),Policies!G10,"")) | Y10: =IF(Policies!I10="","",IF((YEAR(Policies!I10)*12+MONTH(Policies!I10))=(Settings!$B$5*12+22),Policies!G10,"")) | Z10: =IF(Policies!I10="","",IF((YEAR(Policies!I10)*12+MONTH(Policies!I10))=(Settings!$B$5*12+23),Policies!G10,"")) | AA10: =IF(Policies!I10="","",IF((YEAR(Policies!I10)*12+MONTH(Policies!I10))=(Settings!$B$5*12+24),Policies!G10,"")) | AB10: =IF(SUM(D10:AA10)=0,"",SUM(D10:AA10))
A11: =IF(Policies!A11="","",Policies!A11) | B11: =IF(Policies!B11="","",Policies!B11) | C11: =IF(Policies!D11="","",Policies!D11) | D11: =IF(Policies!I11="","",IF((YEAR(Policies!I11)*12+MONTH(Policies!I11))=(Settings!$B$5*12+1),Policies!G11,"")) | E11: =IF(Policies!I11="","",IF((YEAR(Policies!I11)*12+MONTH(Policies!I11))=(Settings!$B$5*12+2),Policies!G11,"")) | F11: =IF(Policies!I11="","",IF((YEAR(Policies!I11)*12+MONTH(Policies!I11))=(Settings!$B$5*12+3),Policies!G11,"")) | G11: =IF(Policies!I11="","",IF((YEAR(Policies!I11)*12+MONTH(Policies!I11))=(Settings!$B$5*12+4),Policies!G11,"")) | H11: =IF(Policies!I11="","",IF((YEAR(Policies!I11)*12+MONTH(Policies!I11))=(Settings!$B$5*12+5),Policies!G11,"")) | I11: =IF(Policies!I11="","",IF((YEAR(Policies!I11)*12+MONTH(Policies!I11))=(Settings!$B$5*12+6),Policies!G11,"")) | J11: =IF(Policies!I11="","",IF((YEAR(Policies!I11)*12+MONTH(Policies!I11))=(Settings!$B$5*12+7),Policies!G11,"")) | K11: =IF(Policies!I11="","",IF((YEAR(Policies!I11)*12+MONTH(Policies!I11))=(Settings!$B$5*12+8),Policies!G11,"")) | L11: =IF(Policies!I11="","",IF((YEAR(Policies!I11)*12+MONTH(Policies!I11))=(Settings!$B$5*12+9),Policies!G11,"")) | M11: =IF(Policies!I11="","",IF((YEAR(Policies!I11)*12+MONTH(Policies!I11))=(Settings!$B$5*12+10),Policies!G11,"")) | N11: =IF(Policies!I11="","",IF((YEAR(Policies!I11)*12+MONTH(Policies!I11))=(Settings!$B$5*12+11),Policies!G11,"")) | O11: =IF(Policies!I11="","",IF((YEAR(Policies!I11)*12+MONTH(Policies!I11))=(Settings!$B$5*12+12),Policies!G11,"")) | P11: =IF(Policies!I11="","",IF((YEAR(Policies!I11)*12+MONTH(Policies!I11))=(Settings!$B$5*12+13),Policies!G11,"")) | Q11: =IF(Policies!I11="","",IF((YEAR(Policies!I11)*12+MONTH(Policies!I11))=(Settings!$B$5*12+14),Policies!G11,"")) | R11: =IF(Policies!I11="","",IF((YEAR(Policies!I11)*12+MONTH(Policies!I11))=(Settings!$B$5*12+15),Policies!G11,"")) | S11: =IF(Policies!I11="","",IF((YEAR(Policies!I11)*12+MONTH(Policies!I11))=(Settings!$B$5*12+16),Policies!G11,"")) | T11: =IF(Policies!I11="","",IF((YEAR(Policies!I11)*12+MONTH(Policies!I11))=(Settings!$B$5*12+17),Policies!G11,"")) | U11: =IF(Policies!I11="","",IF((YEAR(Policies!I11)*12+MONTH(Policies!I11))=(Settings!$B$5*12+18),Policies!G11,"")) | V11: =IF(Policies!I11="","",IF((YEAR(Policies!I11)*12+MONTH(Policies!I11))=(Settings!$B$5*12+19),Policies!G11,"")) | W11: =IF(Policies!I11="","",IF((YEAR(Policies!I11)*12+MONTH(Policies!I11))=(Settings!$B$5*12+20),Policies!G11,"")) | X11: =IF(Policies!I11="","",IF((YEAR(Policies!I11)*12+MONTH(Policies!I11))=(Settings!$B$5*12+21),Policies!G11,"")) | Y11: =IF(Policies!I11="","",IF((YEAR(Policies!I11)*12+MONTH(Policies!I11))=(Settings!$B$5*12+22),Policies!G11,"")) | Z11: =IF(Policies!I11="","",IF((YEAR(Policies!I11)*12+MONTH(Policies!I11))=(Settings!$B$5*12+23),Policies!G11,"")) | AA11: =IF(Policies!I11="","",IF((YEAR(Policies!I11)*12+MONTH(Policies!I11))=(Settings!$B$5*12+24),Policies!G11,"")) | AB11: =IF(SUM(D11:AA11)=0,"",SUM(D11:AA11))
A12: =IF(Policies!A12="","",Policies!A12) | B12: =IF(Policies!B12="","",Policies!B12) | C12: =IF(Policies!D12="","",Policies!D12) | D12: =IF(Policies!I12="","",IF((YEAR(Policies!I12)*12+MONTH(Policies!I12))=(Settings!$B$5*12+1),Policies!G12,"")) | E12: =IF(Policies!I12="","",IF((YEAR(Policies!I12)*12+MONTH(Policies!I12))=(Settings!$B$5*12+2),Policies!G12,"")) | F12: =IF(Policies!I12="","",IF((YEAR(Policies!I12)*12+MONTH(Policies!I12))=(Settings!$B$5*12+3),Policies!G12,"")) | G12: =IF(Policies!I12="","",IF((YEAR(Policies!I12)*12+MONTH(Policies!I12))=(Settings!$B$5*12+4),Policies!G12,"")) | H12: =IF(Policies!I12="","",IF((YEAR(Policies!I12)*12+MONTH(Policies!I12))=(Settings!$B$5*12+5),Policies!G12,"")) | I12: =IF(Policies!I12="","",IF((YEAR(Policies!I12)*12+MONTH(Policies!I12))=(Settings!$B$5*12+6),Policies!G12,"")) | J12: =IF(Policies!I12="","",IF((YEAR(Policies!I12)*12+MONTH(Policies!I12))=(Settings!$B$5*12+7),Policies!G12,"")) | K12: =IF(Policies!I12="","",IF((YEAR(Policies!I12)*12+MONTH(Policies!I12))=(Settings!$B$5*12+8),Policies!G12,"")) | L12: =IF(Policies!I12="","",IF((YEAR(Policies!I12)*12+MONTH(Policies!I12))=(Settings!$B$5*12+9),Policies!G12,"")) | M12: =IF(Policies!I12="","",IF((YEAR(Policies!I12)*12+MONTH(Policies!I12))=(Settings!$B$5*12+10),Policies!G12,"")) | N12: =IF(Policies!I12="","",IF((YEAR(Policies!I12)*12+MONTH(Policies!I12))=(Settings!$B$5*12+11),Policies!G12,"")) | O12: =IF(Policies!I12="","",IF((YEAR(Policies!I12)*12+MONTH(Policies!I12))=(Settings!$B$5*12+12),Policies!G12,"")) | P12: =IF(Policies!I12="","",IF((YEAR(Policies!I12)*12+MONTH(Policies!I12))=(Settings!$B$5*12+13),Policies!G12,"")) | Q12: =IF(Policies!I12="","",IF((YEAR(Policies!I12)*12+MONTH(Policies!I12))=(Settings!$B$5*12+14),Policies!G12,"")) | R12: =IF(Policies!I12="","",IF((YEAR(Policies!I12)*12+MONTH(Policies!I12))=(Settings!$B$5*12+15),Policies!G12,"")) | S12: =IF(Policies!I12="","",IF((YEAR(Policies!I12)*12+MONTH(Policies!I12))=(Settings!$B$5*12+16),Policies!G12,"")) | T12: =IF(Policies!I12="","",IF((YEAR(Policies!I12)*12+MONTH(Policies!I12))=(Settings!$B$5*12+17),Policies!G12,"")) | U12: =IF(Policies!I12="","",IF((YEAR(Policies!I12)*12+MONTH(Policies!I12))=(Settings!$B$5*12+18),Policies!G12,"")) | V12: =IF(Policies!I12="","",IF((YEAR(Policies!I12)*12+MONTH(Policies!I12))=(Settings!$B$5*12+19),Policies!G12,"")) | W12: =IF(Policies!I12="","",IF((YEAR(Policies!I12)*12+MONTH(Policies!I12))=(Settings!$B$5*12+20),Policies!G12,"")) | X12: =IF(Policies!I12="","",IF((YEAR(Policies!I12)*12+MONTH(Policies!I12))=(Settings!$B$5*12+21),Policies!G12,"")) | Y12: =IF(Policies!I12="","",IF((YEAR(Policies!I12)*12+MONTH(Policies!I12))=(Settings!$B$5*12+22),Policies!G12,"")) | Z12: =IF(Policies!I12="","",IF((YEAR(Policies!I12)*12+MONTH(Policies!I12))=(Settings!$B$5*12+23),Policies!G12,"")) | AA12: =IF(Policies!I12="","",IF((YEAR(Policies!I12)*12+MONTH(Policies!I12))=(Settings!$B$5*12+24),Policies!G12,"")) | AB12: =IF(SUM(D12:AA12)=0,"",SUM(D12:AA12))
A13: =IF(Policies!A13="","",Policies!A13) | B13: =IF(Policies!B13="","",Policies!B13) | C13: =IF(Policies!D13="","",Policies!D13) | D13: =IF(Policies!I13="","",IF((YEAR(Policies!I13)*12+MONTH(Policies!I13))=(Settings!$B$5*12+1),Policies!G13,"")) | E13: =IF(Policies!I13="","",IF((YEAR(Policies!I13)*12+MONTH(Policies!I13))=(Settings!$B$5*12+2),Policies!G13,"")) | F13: =IF(Policies!I13="","",IF((YEAR(Policies!I13)*12+MONTH(Policies!I13))=(Settings!$B$5*12+3),Policies!G13,"")) | G13: =IF(Policies!I13="","",IF((YEAR(Policies!I13)*12+MONTH(Policies!I13))=(Settings!$B$5*12+4),Policies!G13,"")) | H13: =IF(Policies!I13="","",IF((YEAR(Policies!I13)*12+MONTH(Policies!I13))=(Settings!$B$5*12+5),Policies!G13,"")) | I13: =IF(Policies!I13="","",IF((YEAR(Policies!I13)*12+MONTH(Policies!I13))=(Settings!$B$5*12+6),Policies!G13,"")) | J13: =IF(Policies!I13="","",IF((YEAR(Policies!I13)*12+MONTH(Policies!I13))=(Settings!$B$5*12+7),Policies!G13,"")) | K13: =IF(Policies!I13="","",IF((YEAR(Policies!I13)*12+MONTH(Policies!I13))=(Settings!$B$5*12+8),Policies!G13,"")) | L13: =IF(Policies!I13="","",IF((YEAR(Policies!I13)*12+MONTH(Policies!I13))=(Settings!$B$5*12+9),Policies!G13,"")) | M13: =IF(Policies!I13="","",IF((YEAR(Policies!I13)*12+MONTH(Policies!I13))=(Settings!$B$5*12+10),Policies!G13,"")) | N13: =IF(Policies!I13="","",IF((YEAR(Policies!I13)*12+MONTH(Policies!I13))=(Settings!$B$5*12+11),Policies!G13,"")) | O13: =IF(Policies!I13="","",IF((YEAR(Policies!I13)*12+MONTH(Policies!I13))=(Settings!$B$5*12+12),Policies!G13,"")) | P13: =IF(Policies!I13="","",IF((YEAR(Policies!I13)*12+MONTH(Policies!I13))=(Settings!$B$5*12+13),Policies!G13,"")) | Q13: =IF(Policies!I13="","",IF((YEAR(Policies!I13)*12+MONTH(Policies!I13))=(Settings!$B$5*12+14),Policies!G13,"")) | R13: =IF(Policies!I13="","",IF((YEAR(Policies!I13)*12+MONTH(Policies!I13))=(Settings!$B$5*12+15),Policies!G13,"")) | S13: =IF(Policies!I13="","",IF((YEAR(Policies!I13)*12+MONTH(Policies!I13))=(Settings!$B$5*12+16),Policies!G13,"")) | T13: =IF(Policies!I13="","",IF((YEAR(Policies!I13)*12+MONTH(Policies!I13))=(Settings!$B$5*12+17),Policies!G13,"")) | U13: =IF(Policies!I13="","",IF((YEAR(Policies!I13)*12+MONTH(Policies!I13))=(Settings!$B$5*12+18),Policies!G13,"")) | V13: =IF(Policies!I13="","",IF((YEAR(Policies!I13)*12+MONTH(Policies!I13))=(Settings!$B$5*12+19),Policies!G13,"")) | W13: =IF(Policies!I13="","",IF((YEAR(Policies!I13)*12+MONTH(Policies!I13))=(Settings!$B$5*12+20),Policies!G13,"")) | X13: =IF(Policies!I13="","",IF((YEAR(Policies!I13)*12+MONTH(Policies!I13))=(Settings!$B$5*12+21),Policies!G13,"")) | Y13: =IF(Policies!I13="","",IF((YEAR(Policies!I13)*12+MONTH(Policies!I13))=(Settings!$B$5*12+22),Policies!G13,"")) | Z13: =IF(Policies!I13="","",IF((YEAR(Policies!I13)*12+MONTH(Policies!I13))=(Settings!$B$5*12+23),Policies!G13,"")) | AA13: =IF(Policies!I13="","",IF((YEAR(Policies!I13)*12+MONTH(Policies!I13))=(Settings!$B$5*12+24),Policies!G13,"")) | AB13: =IF(SUM(D13:AA13)=0,"",SUM(D13:AA13))
A14: =IF(Policies!A14="","",Policies!A14) | B14: =IF(Policies!B14="","",Policies!B14) | C14: =IF(Policies!D14="","",Policies!D14) | D14: =IF(Policies!I14="","",IF((YEAR(Policies!I14)*12+MONTH(Policies!I14))=(Settings!$B$5*12+1),Policies!G14,"")) | E14: =IF(Policies!I14="","",IF((YEAR(Policies!I14)*12+MONTH(Policies!I14))=(Settings!$B$5*12+2),Policies!G14,"")) | F14: =IF(Policies!I14="","",IF((YEAR(Policies!I14)*12+MONTH(Policies!I14))=(Settings!$B$5*12+3),Policies!G14,"")) | G14: =IF(Policies!I14="","",IF((YEAR(Policies!I14)*12+MONTH(Policies!I14))=(Settings!$B$5*12+4),Policies!G14,"")) | H14: =IF(Policies!I14="","",IF((YEAR(Policies!I14)*12+MONTH(Policies!I14))=(Settings!$B$5*12+5),Policies!G14,"")) | I14: =IF(Policies!I14="","",IF((YEAR(Policies!I14)*12+MONTH(Policies!I14))=(Settings!$B$5*12+6),Policies!G14,"")) | J14: =IF(Policies!I14="","",IF((YEAR(Policies!I14)*12+MONTH(Policies!I14))=(Settings!$B$5*12+7),Policies!G14,"")) | K14: =IF(Policies!I14="","",IF((YEAR(Policies!I14)*12+MONTH(Policies!I14))=(Settings!$B$5*12+8),Policies!G14,"")) | L14: =IF(Policies!I14="","",IF((YEAR(Policies!I14)*12+MONTH(Policies!I14))=(Settings!$B$5*12+9),Policies!G14,"")) | M14: =IF(Policies!I14="","",IF((YEAR(Policies!I14)*12+MONTH(Policies!I14))=(Settings!$B$5*12+10),Policies!G14,"")) | N14: =IF(Policies!I14="","",IF((YEAR(Policies!I14)*12+MONTH(Policies!I14))=(Settings!$B$5*12+11),Policies!G14,"")) | O14: =IF(Policies!I14="","",IF((YEAR(Policies!I14)*12+MONTH(Policies!I14))=(Settings!$B$5*12+12),Policies!G14,"")) | P14: =IF(Policies!I14="","",IF((YEAR(Policies!I14)*12+MONTH(Policies!I14))=(Settings!$B$5*12+13),Policies!G14,"")) | Q14: =IF(Policies!I14="","",IF((YEAR(Policies!I14)*12+MONTH(Policies!I14))=(Settings!$B$5*12+14),Policies!G14,"")) | R14: =IF(Policies!I14="","",IF((YEAR(Policies!I14)*12+MONTH(Policies!I14))=(Settings!$B$5*12+15),Policies!G14,"")) | S14: =IF(Policies!I14="","",IF((YEAR(Policies!I14)*12+MONTH(Policies!I14))=(Settings!$B$5*12+16),Policies!G14,"")) | T14: =IF(Policies!I14="","",IF((YEAR(Policies!I14)*12+MONTH(Policies!I14))=(Settings!$B$5*12+17),Policies!G14,"")) | U14: =IF(Policies!I14="","",IF((YEAR(Policies!I14)*12+MONTH(Policies!I14))=(Settings!$B$5*12+18),Policies!G14,"")) | V14: =IF(Policies!I14="","",IF((YEAR(Policies!I14)*12+MONTH(Policies!I14))=(Settings!$B$5*12+19),Policies!G14,"")) | W14: =IF(Policies!I14="","",IF((YEAR(Policies!I14)*12+MONTH(Policies!I14))=(Settings!$B$5*12+20),Policies!G14,"")) | X14: =IF(Policies!I14="","",IF((YEAR(Policies!I14)*12+MONTH(Policies!I14))=(Settings!$B$5*12+21),Policies!G14,"")) | Y14: =IF(Policies!I14="","",IF((YEAR(Policies!I14)*12+MONTH(Policies!I14))=(Settings!$B$5*12+22),Policies!G14,"")) | Z14: =IF(Policies!I14="","",IF((YEAR(Policies!I14)*12+MONTH(Policies!I14))=(Settings!$B$5*12+23),Policies!G14,"")) | AA14: =IF(Policies!I14="","",IF((YEAR(Policies!I14)*12+MONTH(Policies!I14))=(Settings!$B$5*12+24),Policies!G14,"")) | AB14: =IF(SUM(D14:AA14)=0,"",SUM(D14:AA14))
A15: =IF(Policies!A15="","",Policies!A15) | B15: =IF(Policies!B15="","",Policies!B15) | C15: =IF(Policies!D15="","",Policies!D15) | D15: =IF(Policies!I15="","",IF((YEAR(Policies!I15)*12+MONTH(Policies!I15))=(Settings!$B$5*12+1),Policies!G15,"")) | E15: =IF(Policies!I15="","",IF((YEAR(Policies!I15)*12+MONTH(Policies!I15))=(Settings!$B$5*12+2),Policies!G15,"")) | F15: =IF(Policies!I15="","",IF((YEAR(Policies!I15)*12+MONTH(Policies!I15))=(Settings!$B$5*12+3),Policies!G15,"")) | G15: =IF(Policies!I15="","",IF((YEAR(Policies!I15)*12+MONTH(Policies!I15))=(Settings!$B$5*12+4),Policies!G15,"")) | H15: =IF(Policies!I15="","",IF((YEAR(Policies!I15)*12+MONTH(Policies!I15))=(Settings!$B$5*12+5),Policies!G15,"")) | I15: =IF(Policies!I15="","",IF((YEAR(Policies!I15)*12+MONTH(Policies!I15))=(Settings!$B$5*12+6),Policies!G15,"")) | J15: =IF(Policies!I15="","",IF((YEAR(Policies!I15)*12+MONTH(Policies!I15))=(Settings!$B$5*12+7),Policies!G15,"")) | K15: =IF(Policies!I15="","",IF((YEAR(Policies!I15)*12+MONTH(Policies!I15))=(Settings!$B$5*12+8),Policies!G15,"")) | L15: =IF(Policies!I15="","",IF((YEAR(Policies!I15)*12+MONTH(Policies!I15))=(Settings!$B$5*12+9),Policies!G15,"")) | M15: =IF(Policies!I15="","",IF((YEAR(Policies!I15)*12+MONTH(Policies!I15))=(Settings!$B$5*12+10),Policies!G15,"")) | N15: =IF(Policies!I15="","",IF((YEAR(Policies!I15)*12+MONTH(Policies!I15))=(Settings!$B$5*12+11),Policies!G15,"")) | O15: =IF(Policies!I15="","",IF((YEAR(Policies!I15)*12+MONTH(Policies!I15))=(Settings!$B$5*12+12),Policies!G15,"")) | P15: =IF(Policies!I15="","",IF((YEAR(Policies!I15)*12+MONTH(Policies!I15))=(Settings!$B$5*12+13),Policies!G15,"")) | Q15: =IF(Policies!I15="","",IF((YEAR(Policies!I15)*12+MONTH(Policies!I15))=(Settings!$B$5*12+14),Policies!G15,"")) | R15: =IF(Policies!I15="","",IF((YEAR(Policies!I15)*12+MONTH(Policies!I15))=(Settings!$B$5*12+15),Policies!G15,"")) | S15: =IF(Policies!I15="","",IF((YEAR(Policies!I15)*12+MONTH(Policies!I15))=(Settings!$B$5*12+16),Policies!G15,"")) | T15: =IF(Policies!I15="","",IF((YEAR(Policies!I15)*12+MONTH(Policies!I15))=(Settings!$B$5*12+17),Policies!G15,"")) | U15: =IF(Policies!I15="","",IF((YEAR(Policies!I15)*12+MONTH(Policies!I15))=(Settings!$B$5*12+18),Policies!G15,"")) | V15: =IF(Policies!I15="","",IF((YEAR(Policies!I15)*12+MONTH(Policies!I15))=(Settings!$B$5*12+19),Policies!G15,"")) | W15: =IF(Policies!I15="","",IF((YEAR(Policies!I15)*12+MONTH(Policies!I15))=(Settings!$B$5*12+20),Policies!G15,"")) | X15: =IF(Policies!I15="","",IF((YEAR(Policies!I15)*12+MONTH(Policies!I15))=(Settings!$B$5*12+21),Policies!G15,"")) | Y15: =IF(Policies!I15="","",IF((YEAR(Policies!I15)*12+MONTH(Policies!I15))=(Settings!$B$5*12+22),Policies!G15,"")) | Z15: =IF(Policies!I15="","",IF((YEAR(Policies!I15)*12+MONTH(Policies!I15))=(Settings!$B$5*12+23),Policies!G15,"")) | AA15: =IF(Policies!I15="","",IF((YEAR(Policies!I15)*12+MONTH(Policies!I15))=(Settings!$B$5*12+24),Policies!G15,"")) | AB15: =IF(SUM(D15:AA15)=0,"",SUM(D15:AA15))
A16: =IF(Policies!A16="","",Policies!A16) | B16: =IF(Policies!B16="","",Policies!B16) | C16: =IF(Policies!D16="","",Policies!D16) | D16: =IF(Policies!I16="","",IF((YEAR(Policies!I16)*12+MONTH(Policies!I16))=(Settings!$B$5*12+1),Policies!G16,"")) | E16: =IF(Policies!I16="","",IF((YEAR(Policies!I16)*12+MONTH(Policies!I16))=(Settings!$B$5*12+2),Policies!G16,"")) | F16: =IF(Policies!I16="","",IF((YEAR(Policies!I16)*12+MONTH(Policies!I16))=(Settings!$B$5*12+3),Policies!G16,"")) | G16: =IF(Policies!I16="","",IF((YEAR(Policies!I16)*12+MONTH(Policies!I16))=(Settings!$B$5*12+4),Policies!G16,"")) | H16: =IF(Policies!I16="","",IF((YEAR(Policies!I16)*12+MONTH(Policies!I16))=(Settings!$B$5*12+5),Policies!G16,"")) | I16: =IF(Policies!I16="","",IF((YEAR(Policies!I16)*12+MONTH(Policies!I16))=(Settings!$B$5*12+6),Policies!G16,"")) | J16: =IF(Policies!I16="","",IF((YEAR(Policies!I16)*12+MONTH(Policies!I16))=(Settings!$B$5*12+7),Policies!G16,"")) | K16: =IF(Policies!I16="","",IF((YEAR(Policies!I16)*12+MONTH(Policies!I16))=(Settings!$B$5*12+8),Policies!G16,"")) | L16: =IF(Policies!I16="","",IF((YEAR(Policies!I16)*12+MONTH(Policies!I16))=(Settings!$B$5*12+9),Policies!G16,"")) | M16: =IF(Policies!I16="","",IF((YEAR(Policies!I16)*12+MONTH(Policies!I16))=(Settings!$B$5*12+10),Policies!G16,"")) | N16: =IF(Policies!I16="","",IF((YEAR(Policies!I16)*12+MONTH(Policies!I16))=(Settings!$B$5*12+11),Policies!G16,"")) | O16: =IF(Policies!I16="","",IF((YEAR(Policies!I16)*12+MONTH(Policies!I16))=(Settings!$B$5*12+12),Policies!G16,"")) | P16: =IF(Policies!I16="","",IF((YEAR(Policies!I16)*12+MONTH(Policies!I16))=(Settings!$B$5*12+13),Policies!G16,"")) | Q16: =IF(Policies!I16="","",IF((YEAR(Policies!I16)*12+MONTH(Policies!I16))=(Settings!$B$5*12+14),Policies!G16,"")) | R16: =IF(Policies!I16="","",IF((YEAR(Policies!I16)*12+MONTH(Policies!I16))=(Settings!$B$5*12+15),Policies!G16,"")) | S16: =IF(Policies!I16="","",IF((YEAR(Policies!I16)*12+MONTH(Policies!I16))=(Settings!$B$5*12+16),Policies!G16,"")) | T16: =IF(Policies!I16="","",IF((YEAR(Policies!I16)*12+MONTH(Policies!I16))=(Settings!$B$5*12+17),Policies!G16,"")) | U16: =IF(Policies!I16="","",IF((YEAR(Policies!I16)*12+MONTH(Policies!I16))=(Settings!$B$5*12+18),Policies!G16,"")) | V16: =IF(Policies!I16="","",IF((YEAR(Policies!I16)*12+MONTH(Policies!I16))=(Settings!$B$5*12+19),Policies!G16,"")) | W16: =IF(Policies!I16="","",IF((YEAR(Policies!I16)*12+MONTH(Policies!I16))=(Settings!$B$5*12+20),Policies!G16,"")) | X16: =IF(Policies!I16="","",IF((YEAR(Policies!I16)*12+MONTH(Policies!I16))=(Settings!$B$5*12+21),Policies!G16,"")) | Y16: =IF(Policies!I16="","",IF((YEAR(Policies!I16)*12+MONTH(Policies!I16))=(Settings!$B$5*12+22),Policies!G16,"")) | Z16: =IF(Policies!I16="","",IF((YEAR(Policies!I16)*12+MONTH(Policies!I16))=(Settings!$B$5*12+23),Policies!G16,"")) | AA16: =IF(Policies!I16="","",IF((YEAR(Policies!I16)*12+MONTH(Policies!I16))=(Settings!$B$5*12+24),Policies!G16,"")) | AB16: =IF(SUM(D16:AA16)=0,"",SUM(D16:AA16))
