Workbook

Sheet Start
A2: The STR Ledger
A4: Multi-Owner Consolidated Reporting
A5: Which owner relationships are worth keeping. Which ones to fire.
A7: PAM-004 · v1.0 · DEMO
A10: MANAGED PROPERTIES | D10: TOTAL COMMISSION YTD | G10: TOP OWNER | J10: LOWEST NPS
A11: =COUNTA('Settings'!$B$23:$B$52) | D11: =SUM('Owners'!$I$6:$I$20) | G11: =IFERROR(INDEX('Owners'!$B$6:$B$20,MATCH(MAX('Owners'!$I$6:$I$20),'Owners'!$I$6:$I$20,0)),"—") | J11: =IFERROR(INDEX('Owners'!$B$6:$B$20,MATCH(MIN('Owners'!$J$6:$J$20),'Owners'!$J$6:$J$20,0)),"—")
A14: in active portfolio | D14: across all owners | G14: highest commission YTD | J14: weakest relationship
A17: PRO PAM WORKFLOW
A18: (1) Owners — log every owner you manage with NPS + agreement terms.
A19: (2) Time Allocation — track every hour you spend, tagged to owner + property.
A20: (3) Pam P&L — your business income (commission) less your expenses.
A21: (4) Per-Owner Dashboard — see commission, hours, $/hr per owner.
A22: (5) Owner Profitability — ranked. Bottom-3 in red. Decide who to fire.
A25: =HYPERLINK("#'Owners'!A1", "Owners") | D25: =HYPERLINK("#'Per-Owner Dashboard'!A1", "Per-Owner Dashboard") | G25: =HYPERLINK("#'Pam P&L'!A1", "Pam P&L") | J25: =HYPERLINK("#'Time Allocation'!A1", "Time Allocation")
A29: =HYPERLINK("#'Owner Profitability'!A1", "→ Owner Profitability") | G29: =HYPERLINK("#'Settings'!A1", "Settings")
A33: Manage cleaners + commissions + multi-owner reporting in one bundle? Get the Pro Manager Bundle at thestrledger.com/pro-manager — saves $1,000+ vs individual SKUs.
A36: Questions? hello@thestrledger.com
A37: PAM-004 · v1.0 · DEMO · Free updates forever

Sheet Owners
A2: =HYPERLINK("#'Start'!A1", "← BACK") | D2: OWNERS | J2: =HYPERLINK("#'Per-Owner Dashboard'!A1", "NEXT →")
A4: One row per owner relationship. Capacity 15. Active year on Settings (B5).
A5: Owner ID | B5: Owner name | C5: Email | D5: Phone | E5: Properties (count) | F5: Agreement start | G5: Agreement type | H5: Commission % avg | I5: Total commission YTD | J5: NPS (1-10) | K5: Status | L5: Notes
A6: OWN-01 | B6: Lakeside Holdings LLC | C6: owner1@lakeside.example | D6: (865) 555-0114 | E6: =IF(B6="","",COUNTIF('Settings'!$C$23:$C$52,B6)) | F6: 45292 | G6: % of revenue | H6: 0.2 | I6: 32000 | J6: 9 | K6: Active | L6: 5 properties — flagship account.
A7: OWN-02 | B7: Maddox Trust | C7: owner2@maddox.example | D7: (865) 555-0122 | E7: =IF(B7="","",COUNTIF('Settings'!$C$23:$C$52,B7)) | F7: 45809 | G7: % of revenue | H7: 0.15 | I7: 18000 | J7: 8 | K7: Active | L7: 3 properties — growing portfolio.
A8: OWN-03 | B8: Highland Properties LLC | C8: owner3@highland.example | D8: (865) 555-0138 | E8: =IF(B8="","",COUNTIF('Settings'!$C$23:$C$52,B8)) | F8: 45870 | G8: Hybrid (base + %) | H8: 0.1 | I8: 11000 | J8: 7 | K8: Active | L8: 2 properties — consider commission bump at renewal.
A9: OWN-04 | B9: Brookline Estates | C9: owner4@brookline.example | D9: (865) 555-0151 | E9: =IF(B9="","",COUNTIF('Settings'!$C$23:$C$52,B9)) | F9: 45748 | G9: % of revenue | H9: 0.12 | I9: 4500 | J9: 5 | K9: Churning | L9: 2 properties — high-touch, low margin. Fire candidate.
E10: =IF(B10="","",COUNTIF('Settings'!$C$23:$C$52,B10))
E11: =IF(B11="","",COUNTIF('Settings'!$C$23:$C$52,B11))
E12: =IF(B12="","",COUNTIF('Settings'!$C$23:$C$52,B12))
E13: =IF(B13="","",COUNTIF('Settings'!$C$23:$C$52,B13))
E14: =IF(B14="","",COUNTIF('Settings'!$C$23:$C$52,B14))
E15: =IF(B15="","",COUNTIF('Settings'!$C$23:$C$52,B15))
E16: =IF(B16="","",COUNTIF('Settings'!$C$23:$C$52,B16))
E17: =IF(B17="","",COUNTIF('Settings'!$C$23:$C$52,B17))
E18: =IF(B18="","",COUNTIF('Settings'!$C$23:$C$52,B18))
E19: =IF(B19="","",COUNTIF('Settings'!$C$23:$C$52,B19))
E20: =IF(B20="","",COUNTIF('Settings'!$C$23:$C$52,B20))

Sheet Per-Owner Dashboard
A2: =HYPERLINK("#'Owners'!A1", "← BACK") | D2: PER-OWNER DASHBOARD | J2: =HYPERLINK("#'Pam P&L'!A1", "NEXT →")
A4: One section per owner. Active year drives YTD figures (Settings!B5).
A6: =IFERROR("OWNER " & 1 & ": " & 'Owners'!B6, "OWNER " & 1)
B7: Metric | C7: Properties | D7: YTD revenue | E7: YTD commission | F7: YTD hours | G7: $/hr | H7: Notes
B8: Totals | C8: =IFERROR('Owners'!E6,0) | D8: =IFERROR('Owners'!I6/'Owners'!H6,0) | E8: =IFERROR('Owners'!I6,0) | F8: =IFERROR(SUMIFS('Time Allocation'!$E$6:$E$1005,'Time Allocation'!$B$6:$B$1005,'Owners'!B6,'Time Allocation'!$F$6:$F$1005,'Settings'!$B$5),0) | G8: =IFERROR(E8/F8,0) | H8: =IFERROR('Owners'!L6,"")
B9: 12-month commission trend (chart on row block below)
A14: =IFERROR("OWNER " & 2 & ": " & 'Owners'!B7, "OWNER " & 2)
B15: Metric | C15: Properties | D15: YTD revenue | E15: YTD commission | F15: YTD hours | G15: $/hr | H15: Notes
B16: Totals | C16: =IFERROR('Owners'!E7,0) | D16: =IFERROR('Owners'!I7/'Owners'!H7,0) | E16: =IFERROR('Owners'!I7,0) | F16: =IFERROR(SUMIFS('Time Allocation'!$E$6:$E$1005,'Time Allocation'!$B$6:$B$1005,'Owners'!B7,'Time Allocation'!$F$6:$F$1005,'Settings'!$B$5),0) | G16: =IFERROR(E16/F16,0) | H16: =IFERROR('Owners'!L7,"")
B17: 12-month commission trend (chart on row block below)
A22: =IFERROR("OWNER " & 3 & ": " & 'Owners'!B8, "OWNER " & 3)
B23: Metric | C23: Properties | D23: YTD revenue | E23: YTD commission | F23: YTD hours | G23: $/hr | H23: Notes
B24: Totals | C24: =IFERROR('Owners'!E8,0) | D24: =IFERROR('Owners'!I8/'Owners'!H8,0) | E24: =IFERROR('Owners'!I8,0) | F24: =IFERROR(SUMIFS('Time Allocation'!$E$6:$E$1005,'Time Allocation'!$B$6:$B$1005,'Owners'!B8,'Time Allocation'!$F$6:$F$1005,'Settings'!$B$5),0) | G24: =IFERROR(E24/F24,0) | H24: =IFERROR('Owners'!L8,"")
B25: 12-month commission trend (chart on row block below)
A30: =IFERROR("OWNER " & 4 & ": " & 'Owners'!B9, "OWNER " & 4)
B31: Metric | C31: Properties | D31: YTD revenue | E31: YTD commission | F31: YTD hours | G31: $/hr | H31: Notes
B32: Totals | C32: =IFERROR('Owners'!E9,0) | D32: =IFERROR('Owners'!I9/'Owners'!H9,0) | E32: =IFERROR('Owners'!I9,0) | F32: =IFERROR(SUMIFS('Time Allocation'!$E$6:$E$1005,'Time Allocation'!$B$6:$B$1005,'Owners'!B9,'Time Allocation'!$F$6:$F$1005,'Settings'!$B$5),0) | G32: =IFERROR(E32/F32,0) | H32: =IFERROR('Owners'!L9,"")
B33: 12-month commission trend (chart on row block below)

Sheet Pam P&L
A2: =HYPERLINK("#'Per-Owner Dashboard'!A1", "← BACK") | D2: PAM P&L | J2: =HYPERLINK("#'Time Allocation'!A1", "NEXT →")
A4: Pam's business P&L — commission revenue less your expenses. Active year on Settings!B5.
A5: Line item | B5: Jan | C5: Feb | D5: Mar | E5: Apr | F5: May | G5: Jun | H5: Jul | I5: Aug | J5: Sep | K5: Oct | L5: Nov | M5: Dec | N5: YTD
A6: Commission revenue (per-owner sum) | B6: 4200 | C6: 4400 | D6: 5800 | E6: 6100 | F6: 6400 | G6: 6200 | H6: 6800 | I6: 6500 | J6: 5800 | K6: 5200 | L6: 4400 | M6: 3700 | N6: =SUM(B6:M6)
A7: Bonus / one-off income | B7: 0 | C7: 0 | D7: 250 | E7: 0 | F7: 0 | G7: 500 | H7: 0 | I7: 0 | J7: 0 | K7: 350 | L7: 0 | M7: 0 | N7: =SUM(B7:M7)
A8: TOTAL INCOME | B8: =SUM(B6:B7) | C8: =SUM(C6:C7) | D8: =SUM(D6:D7) | E8: =SUM(E6:E7) | F8: =SUM(F6:F7) | G8: =SUM(G6:G7) | H8: =SUM(H6:H7) | I8: =SUM(I6:I7) | ... N8: =SUM(N6:N7)
A9: EXPENSES
A10: Software (PMS, accounting, comms) | B10: 420 | C10: 420 | D10: 420 | E10: 420 | F10: 420 | G10: 420 | H10: 420 | I10: 420 | J10: 420 | K10: 420 | L10: 420 | M10: 420 | N10: =SUM(B10:M10)
A11: Insurance (E&O / liability) | B11: 180 | C11: 180 | D11: 180 | E11: 180 | F11: 180 | G11: 180 | H11: 180 | I11: 180 | J11: 180 | K11: 180 | L11: 180 | M11: 180 | N11: =SUM(B11:M11)
A12: Contractor payments (non-pass-through) | B12: 220 | C12: 180 | D12: 240 | E12: 260 | F12: 320 | G12: 280 | H12: 300 | I12: 290 | J12: 250 | K12: 220 | L12: 180 | M12: 160 | N12: =SUM(B12:M12)
A13: Marketing | B13: 120 | C13: 120 | D13: 240 | E13: 180 | F13: 180 | G13: 180 | H13: 240 | I13: 180 | J13: 120 | K13: 120 | L13: 80 | M13: 80 | N13: =SUM(B13:M13)
A14: Office | B14: 140 | C14: 140 | D14: 140 | E14: 140 | F14: 140 | G14: 140 | H14: 140 | I14: 140 | J14: 140 | K14: 140 | L14: 140 | M14: 140 | N14: =SUM(B14:M14)
A15: Mileage (deductible) | B15: 85 | C15: 78 | D15: 142 | E15: 168 | F15: 195 | G15: 188 | H15: 210 | I15: 192 | J15: 168 | K15: 142 | L15: 96 | M15: 88 | N15: =SUM(B15:M15)
A16: Meals | B16: 38 | C16: 42 | D16: 64 | E16: 78 | F16: 82 | G16: 78 | H16: 88 | I16: 78 | J16: 64 | K16: 52 | L16: 38 | M16: 32 | N16: =SUM(B16:M16)
A17: Other | B17: 25 | C17: 25 | D17: 50 | E17: 25 | F17: 25 | G17: 75 | H17: 25 | I17: 25 | J17: 25 | K17: 50 | L17: 25 | M17: 25 | N17: =SUM(B17:M17)
A18: TOTAL EXPENSES | B18: =SUM(B10:B17) | C18: =SUM(C10:C17) | D18: =SUM(D10:D17) | E18: =SUM(E10:E17) | F18: =SUM(F10:F17) | G18: =SUM(G10:G17) | H18: =SUM(H10:H17) | I18: =SUM(I10:I17) | ... N18: =SUM(N10:N17)
A20: NOI (Income − Expenses) | B20: =B8-B18 | C20: =C8-C18 | D20: =D8-D18 | E20: =E8-E18 | F20: =F8-F18 | G20: =G8-G18 | H20: =H8-H18 | I20: =I8-I18 | ... N20: =N8-N18
A21: NOI margin | N21: =IFERROR(N20/N8,0)

Sheet Time Allocation
A2: =HYPERLINK("#'Pam P&L'!A1", "← BACK") | D2: TIME ALLOCATION | J2: =HYPERLINK("#'Owner Profitability'!A1", "NEXT →")
A4: Append-only log of every hour you work, tagged to owner + property + activity. Capacity 1000 rows.
A5: Date | B5: Owner | C5: Property | D5: Activity | E5: Hours | F5: Year (auto) | G5: Notes
A6: 46026 | B6: Lakeside Holdings LLC | C6: Smokies Ridge Cabin | D6: Listing mgmt | E6: 2.5 | F6: =IF(A6="","",YEAR(A6)) | G6: Q1 listing refresh
A7: 46030 | B7: Lakeside Holdings LLC | C7: Creek Side | D7: Guest comms | E7: 3 | F7: =IF(A7="","",YEAR(A7)) | G7: Pre-arrival batch
A8: 46037 | B8: Lakeside Holdings LLC | C8: Lakehouse A | D8: Vendor coord | E8: 1.8 | F8: =IF(A8="","",YEAR(A8)) | G8: HVAC scheduling
A9: 46044 | B9: Lakeside Holdings LLC | C9: Pine Vale Retreat | D9: Reporting | E9: 2.2 | F9: =IF(A9="","",YEAR(A9)) | G9: Owner statement prep
A10: 46051 | B10: Lakeside Holdings LLC | C10: Cedar Lakehouse | D10: Maintenance | E10: 1.5 | F10: =IF(A10="","",YEAR(A10)) | G10: Walk-through
A11: 46056 | B11: Lakeside Holdings LLC | C11: Smokies Ridge Cabin | D11: Guest comms | E11: 2.8 | F11: =IF(A11="","",YEAR(A11))
A12: 46063 | B12: Lakeside Holdings LLC | C12: Creek Side | D12: Listing mgmt | E12: 1.5 | F12: =IF(A12="","",YEAR(A12)) | G12: Photo update
A13: 46070 | B13: Lakeside Holdings LLC | C13: Lakehouse A | D13: Reporting | E13: 2 | F13: =IF(A13="","",YEAR(A13))
A14: 46077 | B14: Lakeside Holdings LLC | C14: Pine Vale Retreat | D14: Vendor coord | E14: 1.2 | F14: =IF(A14="","",YEAR(A14)) | G14: Cleaner onboarding
A15: 46085 | B15: Lakeside Holdings LLC | C15: Cedar Lakehouse | D15: Guest comms | E15: 3.5 | F15: =IF(A15="","",YEAR(A15)) | G15: High-volume month
A16: 46092 | B16: Lakeside Holdings LLC | C16: Smokies Ridge Cabin | D16: Maintenance | E16: 2 | F16: =IF(A16="","",YEAR(A16)) | G16: Plumbing follow-up
A17: 46099 | B17: Lakeside Holdings LLC | C17: Creek Side | D17: Reporting | E17: 2.5 | F17: =IF(A17="","",YEAR(A17)) | G17: Q1 close
A18: 46106 | B18: Lakeside Holdings LLC | C18: Lakehouse A | D18: Listing mgmt | E18: 1.8 | F18: =IF(A18="","",YEAR(A18))
A19: 46114 | B19: Lakeside Holdings LLC | C19: Pine Vale Retreat | D19: Guest comms | E19: 2.4 | F19: =IF(A19="","",YEAR(A19))
A20: 46121 | B20: Lakeside Holdings LLC | C20: Cedar Lakehouse | D20: Vendor coord | E20: 1.5 | F20: =IF(A20="","",YEAR(A20))
A21: 46128 | B21: Lakeside Holdings LLC | C21: Smokies Ridge Cabin | D21: Reporting | E21: 2.2 | F21: =IF(A21="","",YEAR(A21))
A22: 46135 | B22: Lakeside Holdings LLC | C22: Creek Side | D22: Maintenance | E22: 1.8 | F22: =IF(A22="","",YEAR(A22))
A23: 46143 | B23: Lakeside Holdings LLC | C23: Lakehouse A | D23: Guest comms | E23: 3.2 | F23: =IF(A23="","",YEAR(A23)) | G23: Memorial wknd surge
A24: 46150 | B24: Lakeside Holdings LLC | C24: Pine Vale Retreat | D24: Listing mgmt | E24: 2 | F24: =IF(A24="","",YEAR(A24))
A25: 46157 | B25: Lakeside Holdings LLC | C25: Cedar Lakehouse | D25: Vendor coord | E25: 1.5 | F25: =IF(A25="","",YEAR(A25))
A26: 46164 | B26: Lakeside Holdings LLC | C26: Smokies Ridge Cabin | D26: Reporting | E26: 2 | F26: =IF(A26="","",YEAR(A26))
A27: 46171 | B27: Lakeside Holdings LLC | C27: Creek Side | D27: Maintenance | E27: 2.5 | F27: =IF(A27="","",YEAR(A27))
A28: 46178 | B28: Lakeside Holdings LLC | C28: Lakehouse A | D28: Guest comms | E28: 3 | F28: =IF(A28="","",YEAR(A28))
A29: 46185 | B29: Lakeside Holdings LLC | C29: Pine Vale Retreat | D29: Listing mgmt | E29: 1.8 | F29: =IF(A29="","",YEAR(A29))
A30: 46192 | B30: Lakeside Holdings LLC | C30: Cedar Lakehouse | D30: Reporting | E30: 2.2 | F30: =IF(A30="","",YEAR(A30))
A31: 46199 | B31: Lakeside Holdings LLC | C31: Smokies Ridge Cabin | D31: Vendor coord | E31: 1.5 | F31: =IF(A31="","",YEAR(A31))
A32: 46206 | B32: Lakeside Holdings LLC | C32: Creek Side | D32: Guest comms | E32: 3.5 | F32: =IF(A32="","",YEAR(A32)) | G32: July 4 surge
A33: 46213 | B33: Lakeside Holdings LLC | C33: Lakehouse A | D33: Maintenance | E33: 2 | F33: =IF(A33="","",YEAR(A33))
A34: 46220 | B34: Lakeside Holdings LLC | C34: Pine Vale Retreat | D34: Reporting | E34: 2 | F34: =IF(A34="","",YEAR(A34))
A35: 46227 | B35: Lakeside Holdings LLC | C35: Cedar Lakehouse | D35: Listing mgmt | E35: 1.5 | F35: =IF(A35="","",YEAR(A35))
A36: 46234 | B36: Lakeside Holdings LLC | C36: Smokies Ridge Cabin | D36: Guest comms | E36: 2.5 | F36: =IF(A36="","",YEAR(A36))
A37: 46241 | B37: Lakeside Holdings LLC | C37: Creek Side | D37: Vendor coord | E37: 1.8 | F37: =IF(A37="","",YEAR(A37))
A38: 46248 | B38: Lakeside Holdings LLC | C38: Lakehouse A | D38: Reporting | E38: 2 | F38: =IF(A38="","",YEAR(A38))
A39: 46255 | B39: Lakeside Holdings LLC | C39: Pine Vale Retreat | D39: Maintenance | E39: 2.2 | F39: =IF(A39="","",YEAR(A39))
A40: 46262 | B40: Lakeside Holdings LLC | C40: Cedar Lakehouse | D40: Guest comms | E40: 2.5 | F40: =IF(A40="","",YEAR(A40))
A41: 46269 | B41: Lakeside Holdings LLC | C41: Smokies Ridge Cabin | D41: Listing mgmt | E41: 1.5 | F41: =IF(A41="","",YEAR(A41)) | G41: Q4 prep
A42: 46276 | B42: Lakeside Holdings LLC | C42: Creek Side | D42: Reporting | E42: 2 | F42: =IF(A42="","",YEAR(A42))
...

Sheet Owner Profitability
A2: =HYPERLINK("#'Time Allocation'!A1", "← BACK") | D2: OWNER PROFITABILITY | J2: =HYPERLINK("#'Settings'!A1", "NEXT →")
A4: Per-owner profitability — commission ÷ hours = $/hr. Bottom-3 highlighted red. Consider firing low-margin relationships.
A5: Owner | B5: Commission YTD | C5: Hours YTD | D5: $/hr | E5: Rank | F5: Verdict
A6: =IFERROR('Owners'!B6,"") | B6: =IFERROR('Owners'!I6,0) | C6: =IF('Owners'!B6="",0,SUMIFS('Time Allocation'!$E$6:$E$1005,'Time Allocation'!$B$6:$B$1005,'Owners'!B6,'Time Allocation'!$F$6:$F$1005,'Settings'!$B$5)) | D6: =IFERROR(B6/C6,0) | E6: =IF(A6="","",RANK(D6,$D$6:$D$20,0)) | F6: =IF(A6="","",IF(D6>=150,"Keep — strong",IF(D6>=100,"OK — monitor",IF(D6>=50,"Renegotiate","Fire candidate"))))
A7: =IFERROR('Owners'!B7,"") | B7: =IFERROR('Owners'!I7,0) | C7: =IF('Owners'!B7="",0,SUMIFS('Time Allocation'!$E$6:$E$1005,'Time Allocation'!$B$6:$B$1005,'Owners'!B7,'Time Allocation'!$F$6:$F$1005,'Settings'!$B$5)) | D7: =IFERROR(B7/C7,0) | E7: =IF(A7="","",RANK(D7,$D$6:$D$20,0)) | F7: =IF(A7="","",IF(D7>=150,"Keep — strong",IF(D7>=100,"OK — monitor",IF(D7>=50,"Renegotiate","Fire candidate"))))
A8: =IFERROR('Owners'!B8,"") | B8: =IFERROR('Owners'!I8,0) | C8: =IF('Owners'!B8="",0,SUMIFS('Time Allocation'!$E$6:$E$1005,'Time Allocation'!$B$6:$B$1005,'Owners'!B8,'Time Allocation'!$F$6:$F$1005,'Settings'!$B$5)) | D8: =IFERROR(B8/C8,0) | E8: =IF(A8="","",RANK(D8,$D$6:$D$20,0)) | F8: =IF(A8="","",IF(D8>=150,"Keep — strong",IF(D8>=100,"OK — monitor",IF(D8>=50,"Renegotiate","Fire candidate"))))
A9: =IFERROR('Owners'!B9,"") | B9: =IFERROR('Owners'!I9,0) | C9: =IF('Owners'!B9="",0,SUMIFS('Time Allocation'!$E$6:$E$1005,'Time Allocation'!$B$6:$B$1005,'Owners'!B9,'Time Allocation'!$F$6:$F$1005,'Settings'!$B$5)) | D9: =IFERROR(B9/C9,0) | E9: =IF(A9="","",RANK(D9,$D$6:$D$20,0)) | F9: =IF(A9="","",IF(D9>=150,"Keep — strong",IF(D9>=100,"OK — monitor",IF(D9>=50,"Renegotiate","Fire candidate"))))
A10: =IFERROR('Owners'!B10,"") | B10: =IFERROR('Owners'!I10,0) | C10: =IF('Owners'!B10="",0,SUMIFS('Time Allocation'!$E$6:$E$1005,'Time Allocation'!$B$6:$B$1005,'Owners'!B10,'Time Allocation'!$F$6:$F$1005,'Settings'!$B$5)) | D10: =IFERROR(B10/C10,0) | E10: =IF(A10="","",RANK(D10,$D$6:$D$20,0)) | F10: =IF(A10="","",IF(D10>=150,"Keep — strong",IF(D10>=100,"OK — monitor",IF(D10>=50,"Renegotiate","Fire candidate"))))
A11: =IFERROR('Owners'!B11,"") | B11: =IFERROR('Owners'!I11,0) | C11: =IF('Owners'!B11="",0,SUMIFS('Time Allocation'!$E$6:$E$1005,'Time Allocation'!$B$6:$B$1005,'Owners'!B11,'Time Allocation'!$F$6:$F$1005,'Settings'!$B$5)) | D11: =IFERROR(B11/C11,0) | E11: =IF(A11="","",RANK(D11,$D$6:$D$20,0)) | F11: =IF(A11="","",IF(D11>=150,"Keep — strong",IF(D11>=100,"OK — monitor",IF(D11>=50,"Renegotiate","Fire candidate"))))
A12: =IFERROR('Owners'!B12,"") | B12: =IFERROR('Owners'!I12,0) | C12: =IF('Owners'!B12="",0,SUMIFS('Time Allocation'!$E$6:$E$1005,'Time Allocation'!$B$6:$B$1005,'Owners'!B12,'Time Allocation'!$F$6:$F$1005,'Settings'!$B$5)) | D12: =IFERROR(B12/C12,0) | E12: =IF(A12="","",RANK(D12,$D$6:$D$20,0)) | F12: =IF(A12="","",IF(D12>=150,"Keep — strong",IF(D12>=100,"OK — monitor",IF(D12>=50,"Renegotiate","Fire candidate"))))
A13: =IFERROR('Owners'!B13,"") | B13: =IFERROR('Owners'!I13,0) | C13: =IF('Owners'!B13="",0,SUMIFS('Time Allocation'!$E$6:$E$1005,'Time Allocation'!$B$6:$B$1005,'Owners'!B13,'Time Allocation'!$F$6:$F$1005,'Settings'!$B$5)) | D13: =IFERROR(B13/C13,0) | E13: =IF(A13="","",RANK(D13,$D$6:$D$20,0)) | F13: =IF(A13="","",IF(D13>=150,"Keep — strong",IF(D13>=100,"OK — monitor",IF(D13>=50,"Renegotiate","Fire candidate"))))
A14: =IFERROR('Owners'!B14,"") | B14: =IFERROR('Owners'!I14,0) | C14: =IF('Owners'!B14="",0,SUMIFS('Time Allocation'!$E$6:$E$1005,'Time Allocation'!$B$6:$B$1005,'Owners'!B14,'Time Allocation'!$F$6:$F$1005,'Settings'!$B$5)) | D14: =IFERROR(B14/C14,0) | E14: =IF(A14="","",RANK(D14,$D$6:$D$20,0)) | F14: =IF(A14="","",IF(D14>=150,"Keep — strong",IF(D14>=100,"OK — monitor",IF(D14>=50,"Renegotiate","Fire candidate"))))
A15: =IFERROR('Owners'!B15,"") | B15: =IFERROR('Owners'!I15,0) | C15: =IF('Owners'!B15="",0,SUMIFS('Time Allocation'!$E$6:$E$1005,'Time Allocation'!$B$6:$B$1005,'Owners'!B15,'Time Allocation'!$F$6:$F$1005,'Settings'!$B$5)) | D15: =IFERROR(B15/C15,0) | E15: =IF(A15="","",RANK(D15,$D$6:$D$20,0)) | F15: =IF(A15="","",IF(D15>=150,"Keep — strong",IF(D15>=100,"OK — monitor",IF(D15>=50,"Renegotiate","Fire candidate"))))
A16: =IFERROR('Owners'!B16,"") | B16: =IFERROR('Owners'!I16,0) | C16: =IF('Owners'!B16="",0,SUMIFS('Time Allocation'!$E$6:$E$1005,'Time Allocation'!$B$6:$B$1005,'Owners'!B16,'Time Allocation'!$F$6:$F$1005,'Settings'!$B$5)) | D16: =IFERROR(B16/C16,0) | E16: =IF(A16="","",RANK(D16,$D$6:$D$20,0)) | F16: =IF(A16="","",IF(D16>=150,"Keep — strong",IF(D16>=100,"OK — monitor",IF(D16>=50,"Renegotiate","Fire candidate"))))
A17: =IFERROR('Owners'!B17,"") | B17: =IFERROR('Owners'!I17,0) | C17: =IF('Owners'!B17="",0,SUMIFS('Time Allocation'!$E$6:$E$1005,'Time Allocation'!$B$6:$B$1005,'Owners'!B17,'Time Allocation'!$F$6:$F$1005,'Settings'!$B$5)) | D17: =IFERROR(B17/C17,0) | E17: =IF(A17="","",RANK(D17,$D$6:$D$20,0)) | F17: =IF(A17="","",IF(D17>=150,"Keep — strong",IF(D17>=100,"OK — monitor",IF(D17>=50,"Renegotiate","Fire candidate"))))
... A20: =IFERROR('Owners'!B20,"") | B20: =IFERROR('Owners'!I20,0) | C20: =IF('Owners'!B20="",0,SUMIFS('Time Allocation'!$E$6:$E$1005,'Time Allocation'!$B$6:$B$1005,'Owners'!B20,'Time Allocation'!$F$6:$F$1005,'Settings'!$B$5)) | D20: =IFERROR(B20/C20,0) | E20: =IF(A20="","",RANK(D20,$D$6:$D$20,0)) | F20: =IF(A20="","",IF(D20>=150,"Keep — strong",IF(D20>=100,"OK — monitor",IF(D20>=50,"Renegotiate","Fire candidate"))))
A22: Tip: select rows 6-20 → Data → Sort → by $/hr descending to see best-to-worst order. Red rows = bottom-3 — your fire candidates.

Sheet Settings
A2: =HYPERLINK("#'Owner Profitability'!A1", "← BACK") | D2: SETTINGS
A4: Active year drives every YTD figure. Owner + property lists feed dropdowns.
A5: Active year: | B5: 2026
A6: OWNER LIST (B7:B21 — capacity 15)
A7: Owner #1 | B7: Lakeside Holdings LLC
A8: Owner #2 | B8: Maddox Trust
A9: Owner #3 | B9: Highland Properties LLC
A10: Owner #4 | B10: Brookline Estates
A11: Owner #5
A12: Owner #6
A13: Owner #7
A14: Owner #8
A15: Owner #9
A16: Owner #10
A17: Owner #11
A18: Owner #12
A19: Owner #13
A20: Owner #14
A21: Owner #15
A22: PROPERTY LIST (B23:C52 — capacity 30)
A23: Property #1 | B23: Smokies Ridge Cabin | C23: Lakeside Holdings LLC
A24: Property #2 | B24: Creek Side | C24: Lakeside Holdings LLC
A25: Property #3 | B25: Lakehouse A | C25: Lakeside Holdings LLC
A26: Property #4 | B26: Pine Vale Retreat | C26: Lakeside Holdings LLC
A27: Property #5 | B27: Cedar Lakehouse | C27: Lakeside Holdings LLC
A28: Property #6 | B28: Mountain Loft | C28: Maddox Trust
A29: Property #7 | B29: Forest Cabin | C29: Maddox Trust
A30: Property #8 | B30: Riverbend Cottage | C30: Maddox Trust
A31: Property #9 | B31: Highland Hideaway | C31: Highland Properties LLC
A32: Property #10 | B32: Smoky View Lodge | C32: Highland Properties LLC
A33: Property #11 | B33: Brookline Bungalow | C33: Brookline Estates
A34: Property #12 | B34: Birch Hollow | C34: Brookline Estates
A35: Property #13
A36: Property #14
A37: Property #15
A38: Property #16
A39: Property #17
A40: Property #18
A41: Property #19
A42: Property #20
...
