Workbook

Sheet Start
A2: The STR Ledger
A4: Cleaner CRM + Payroll
A5: Your cleaning team — paid right, rated honestly, 1099-ready.
A7: PAM-002 · v2.3 · DEMO
A10: WHAT THIS DOES
A11: Once you cross 5+ properties, your cleaning team becomes a small business of its own. This workbook tracks every cleaner (CRM), logs every turnover (hours, flat fee, bonus, inspection rating), runs payroll in one click, and rolls totals into a 1099-NEC year-end summary that drops straight into TAX-003. Stop paying late, stop rehiring drama, and walk into January with clean books.
A18: ACTIVE CLEANERS | D18: TURNOVERS YTD | G18: $ PAID YTD | J18: TOP PERFORMER
A19: =COUNTIF(Cleaners!M6:M55,"Y") | D19: =SUMPRODUCT((YEAR('Turnover Assignment'!A6:A1005)=Settings!$B$5)*('Turnover Assignment'!A6:A1005<>"")) | G19: =SUMPRODUCT((YEAR('Turnover Assignment'!A6:A1005)=Settings!$B$5)*'Turnover Assignment'!K6:K1005) | J19: =IFERROR(INDEX(Performance!A6:A55,MATCH(MAX(Performance!C6:C55),Performance!C6:C55,0)),"—")
A21: on roster | D21: in active year | G21: all cleaner pay | J21: by avg rating
A25: =HYPERLINK("#'Cleaners'!A6", "→ ADD A CLEANER (OPEN CLEANERS CRM)")
A30: =HYPERLINK("#'Turnover Assignment'!A1", "Turnover Assignment") | D30: =HYPERLINK("#'Payroll Run'!A1", "Payroll Run") | G30: =HYPERLINK("#'Performance'!A1", "Performance") | J30: =HYPERLINK("#'1099-NEC Year-End'!A1", "1099-NEC Year-End")
A33: HOW TO USE
A34: ① Cleaners tab: enter every team member — pay rate, W-9 status, certifications, service area.
A35: ② Turnover Assignment: log every cleaning AS IT HAPPENS — hours, flat fee, bonus, rating.
A36: ③ Payroll Run: set the period start/end → totals roll up per cleaner. Print and pay.
A37: ④ Performance: review monthly — flag top performers, decide who to coach or cut.
A38: ⑤ 1099-NEC Year-End: in January, copy totals into TAX-003 1099-NEC tracker.
A41: ⚠ Pay any cleaner $600+ in a calendar year and you owe them a 1099-NEC by January 31 (IRS Pub 1220, $60–$660 penalty per missed form). Year-End tab tracks who crosses the line.
A43: 💡 Upgrade to the Full version at thestrledger.com/upgrade — multi-property, depreciation, multi-LLC support.
A46: Questions? hello@thestrledger.com
A47: PAM-002 · v2.3 · Free updates forever

Sheet Cleaners
A2: =HYPERLINK("#'Start'!A1", "← BACK") | D2: CLEANERS CRM | J2: =HYPERLINK("#'Turnover Assignment'!A1", "NEXT →")
A4: Add every cleaner — pay rate, W-9 status, certifications, service area
A5: Cleaner ID | B5: Name | C5: Phone | D5: Email | E5: Address | F5: EIN/SSN last4 | G5: W-9? | H5: Pay rate type | I5: Hourly $ | J5: Per-turnover $ | K5: Service area | L5: Certifications | M5: Active? | N5: Avg rating | O5: Notes
A6: C-001 | B6: Sarah Mitchell | C6: (865) 555-0145 | D6: sarah@smokiesclean.com | E6: 147 Pine St, Gatlinburg, TN 37738 | F6: 4421 | G6: Yes | H6: Per-turnover | I6: 0 | J6: 120 | K6: Gatlinburg, Pigeon Forge | L6: Insured, bonded, COVID-19 | M6: Y | N6: =IFERROR(VLOOKUP(B6,Performance!$A$6:$D$55,4,FALSE),"") | O6: Top performer — keep on rotation
A7: C-002 | B7: Maria Gonzalez | C7: (865) 555-0192 | D7: maria@cleanmtn.com | E7: 82 Ridge Ln, Pigeon Forge, TN 37863 | F7: 8810 | G7: Yes | H7: Hourly | I7: 28 | J7: 0 | K7: Pigeon Forge, Sevierville | L7: Insured | M7: Y | N7: =IFERROR(VLOOKUP(B7,Performance!$A$6:$D$55,4,FALSE),"") | O7: Reliable, slow on linens
A8: C-003 | B8: Jenny Park | C8: (865) 555-0211 | D8: jenny@parkclean.com | E8: 9 Oak Dr, Sevierville, TN 37862 | F8: 5573 | G8: Yes | H8: Hybrid | I8: 22 | J8: 90 | K8: Sevierville, Knoxville | L8: Insured, bonded | M8: Y | N8: =IFERROR(VLOOKUP(B8,Performance!$A$6:$D$55,4,FALSE),"") | O8: Backup for Sarah
A9: C-004 | B9: Tom Bradley | C9: (865) 555-0166 | D9: tom@bradleyturn.com | E9: 55 Lake Rd, Gatlinburg, TN 37738 | F9: 2298 | G9: No | H9: Per-turnover | I9: 0 | J9: 110 | K9: Gatlinburg | L9: Bonded | M9: Y | N9: =IFERROR(VLOOKUP(B9,Performance!$A$6:$D$55,4,FALSE),"") | O9: Need W-9 — request before next pay
A10: C-005 | B10: Lisa Chen | C10: (865) 555-0177 | D10: lisa@chenclean.net | E10: 21 Cherry St, Knoxville, TN 37902 | F10: 6634 | G10: Yes | H10: Per-turnover | I10: 0 | J10: 115 | K10: Knoxville | L10: Insured, bonded, eco | M10: Y | N10: =IFERROR(VLOOKUP(B10,Performance!$A$6:$D$55,4,FALSE),"")
A11: C-006 | B11: Backup Helper | C11: (865) 555-0188 | D11: — | E11: Various | F11: — | G11: No | H11: Hourly | I11: 20 | J11: 0 | K11: Local only | L11: — | M11: N | N11: =IFERROR(VLOOKUP(B11,Performance!$A$6:$D$55,4,FALSE),"") | O11: Inactive — used Q1 only
N12: =IFERROR(VLOOKUP(B12,Performance!$A$6:$D$55,4,FALSE),"")
N13: =IFERROR(VLOOKUP(B13,Performance!$A$6:$D$55,4,FALSE),"")
N14: =IFERROR(VLOOKUP(B14,Performance!$A$6:$D$55,4,FALSE),"")
N15: =IFERROR(VLOOKUP(B15,Performance!$A$6:$D$55,4,FALSE),"")
N16: =IFERROR(VLOOKUP(B16,Performance!$A$6:$D$55,4,FALSE),"")
N17: =IFERROR(VLOOKUP(B17,Performance!$A$6:$D$55,4,FALSE),"")
N18: =IFERROR(VLOOKUP(B18,Performance!$A$6:$D$55,4,FALSE),"")
N19: =IFERROR(VLOOKUP(B19,Performance!$A$6:$D$55,4,FALSE),"")
N20: =IFERROR(VLOOKUP(B20,Performance!$A$6:$D$55,4,FALSE),"")
N21: =IFERROR(VLOOKUP(B21,Performance!$A$6:$D$55,4,FALSE),"")
N22: =IFERROR(VLOOKUP(B22,Performance!$A$6:$D$55,4,FALSE),"")
N23: =IFERROR(VLOOKUP(B23,Performance!$A$6:$D$55,4,FALSE),"")
... N35: =IFERROR(VLOOKUP(B35,Performance!$A$6:$D$55,4,FALSE),"")

Sheet Turnover Assignment
A2: =HYPERLINK("#'Cleaners'!A1", "← BACK") | D2: TURNOVER ASSIGNMENT | J2: =HYPERLINK("#'Payroll Run'!A1", "NEXT →")
A4: Log every turnover AS IT HAPPENS — hours, flat fee, bonus, inspection rating
A5: Date | B5: Property | C5: Cleaner | D5: Hours | E5: Per-turn $ | F5: Bonus $ | G5: Hourly $ (lkup) | H5: Status | I5: Inspection rating | J5: Notes | K5: Total payment
A6: 46023 | B6: Creek Side | C6: Sarah Mitchell | D6: 3 | E6: 120 | F6: 25 | G6: =IFERROR(VLOOKUP(C6,Cleaners!$B$6:$I$35,8,FALSE),0) | H6: Inspected | I6: 4.6 | K6: =IF(C6="","",IFERROR(D6,0)*G6+IFERROR(E6,0)+IFERROR(F6,0))
A7: 46024 | B7: Smokies Ridge | C7: Sarah Mitchell | D7: 3.25 | E7: 120 | G7: =IFERROR(VLOOKUP(C7,Cleaners!$B$6:$I$35,8,FALSE),0) | H7: Inspected | I7: 4.7 | K7: =IF(C7="","",IFERROR(D7,0)*G7+IFERROR(E7,0)+IFERROR(F7,0))
A8: 46025 | B8: Lakehouse A | C8: Sarah Mitchell | D8: 3.5 | E8: 120 | G8: =IFERROR(VLOOKUP(C8,Cleaners!$B$6:$I$35,8,FALSE),0) | H8: Inspected | I8: 4.8 | K8: =IF(C8="","",IFERROR(D8,0)*G8+IFERROR(E8,0)+IFERROR(F8,0))
A9: 46026 | B9: Creek Side | C9: Sarah Mitchell | D9: 3.75 | E9: 120 | G9: =IFERROR(VLOOKUP(C9,Cleaners!$B$6:$I$35,8,FALSE),0) | H9: Inspected | I9: 4.9 | K9: =IF(C9="","",IFERROR(D9,0)*G9+IFERROR(E9,0)+IFERROR(F9,0))
A10: 46027 | B10: Smokies Ridge | C10: Sarah Mitchell | D10: 4 | E10: 120 | G10: =IFERROR(VLOOKUP(C10,Cleaners!$B$6:$I$35,8,FALSE),0) | H10: Inspected | I10: 5 | K10: =IF(C10="","",IFERROR(D10,0)*G10+IFERROR(E10,0)+IFERROR(F10,0))
A11: 46028 | B11: Lakehouse A | C11: Sarah Mitchell | D11: 3 | E11: 120 | G11: =IFERROR(VLOOKUP(C11,Cleaners!$B$6:$I$35,8,FALSE),0) | H11: Inspected | I11: 5 | K11: =IF(C11="","",IFERROR(D11,0)*G11+IFERROR(E11,0)+IFERROR(F11,0))
A12: 46029 | B12: Creek Side | C12: Sarah Mitchell | D12: 3.25 | E12: 120 | G12: =IFERROR(VLOOKUP(C12,Cleaners!$B$6:$I$35,8,FALSE),0) | H12: Inspected | I12: 5 | K12: =IF(C12="","",IFERROR(D12,0)*G12+IFERROR(E12,0)+IFERROR(F12,0))
A13: 46030 | B13: Smokies Ridge | C13: Sarah Mitchell | D13: 3.5 | E13: 120 | G13: =IFERROR(VLOOKUP(C13,Cleaners!$B$6:$I$35,8,FALSE),0) | H13: Inspected | I13: 4.6 | K13: =IF(C13="","",IFERROR(D13,0)*G13+IFERROR(E13,0)+IFERROR(F13,0))
A14: 46031 | B14: Lakehouse A | C14: Sarah Mitchell | D14: 3.75 | E14: 120 | G14: =IFERROR(VLOOKUP(C14,Cleaners!$B$6:$I$35,8,FALSE),0) | H14: Inspected | I14: 4.7 | K14: =IF(C14="","",IFERROR(D14,0)*G14+IFERROR(E14,0)+IFERROR(F14,0))
A15: 46032 | B15: Creek Side | C15: Sarah Mitchell | D15: 4 | E15: 120 | G15: =IFERROR(VLOOKUP(C15,Cleaners!$B$6:$I$35,8,FALSE),0) | H15: Inspected | I15: 4.8 | K15: =IF(C15="","",IFERROR(D15,0)*G15+IFERROR(E15,0)+IFERROR(F15,0))
A16: 46033 | B16: Smokies Ridge | C16: Sarah Mitchell | D16: 3 | E16: 120 | G16: =IFERROR(VLOOKUP(C16,Cleaners!$B$6:$I$35,8,FALSE),0) | H16: Inspected | I16: 4.9 | K16: =IF(C16="","",IFERROR(D16,0)*G16+IFERROR(E16,0)+IFERROR(F16,0))
A17: 46034 | B17: Lakehouse A | C17: Sarah Mitchell | D17: 3.25 | E17: 120 | G17: =IFERROR(VLOOKUP(C17,Cleaners!$B$6:$I$35,8,FALSE),0) | H17: Inspected | I17: 5 | K17: =IF(C17="","",IFERROR(D17,0)*G17+IFERROR(E17,0)+IFERROR(F17,0))
A18: 46035 | B18: Creek Side | C18: Sarah Mitchell | D18: 3.5 | E18: 120 | F18: 25 | G18: =IFERROR(VLOOKUP(C18,Cleaners!$B$6:$I$35,8,FALSE),0) | H18: Inspected | I18: 5 | K18: =IF(C18="","",IFERROR(D18,0)*G18+IFERROR(E18,0)+IFERROR(F18,0))
A19: 46036 | B19: Smokies Ridge | C19: Sarah Mitchell | D19: 3.75 | E19: 120 | G19: =IFERROR(VLOOKUP(C19,Cleaners!$B$6:$I$35,8,FALSE),0) | H19: Inspected | I19: 5 | K19: =IF(C19="","",IFERROR(D19,0)*G19+IFERROR(E19,0)+IFERROR(F19,0))
A20: 46037 | B20: Lakehouse A | C20: Sarah Mitchell | D20: 4 | E20: 120 | G20: =IFERROR(VLOOKUP(C20,Cleaners!$B$6:$I$35,8,FALSE),0) | H20: Inspected | I20: 4.6 | K20: =IF(C20="","",IFERROR(D20,0)*G20+IFERROR(E20,0)+IFERROR(F20,0))
A21: 46038 | B21: Creek Side | C21: Sarah Mitchell | D21: 3 | E21: 120 | G21: =IFERROR(VLOOKUP(C21,Cleaners!$B$6:$I$35,8,FALSE),0) | H21: Inspected | I21: 4.7 | K21: =IF(C21="","",IFERROR(D21,0)*G21+IFERROR(E21,0)+IFERROR(F21,0))
A22: 46039 | B22: Smokies Ridge | C22: Sarah Mitchell | D22: 3.25 | E22: 120 | G22: =IFERROR(VLOOKUP(C22,Cleaners!$B$6:$I$35,8,FALSE),0) | H22: Inspected | I22: 4.8 | K22: =IF(C22="","",IFERROR(D22,0)*G22+IFERROR(E22,0)+IFERROR(F22,0))
A23: 46040 | B23: Lakehouse A | C23: Sarah Mitchell | D23: 3.5 | E23: 120 | G23: =IFERROR(VLOOKUP(C23,Cleaners!$B$6:$I$35,8,FALSE),0) | H23: Inspected | I23: 4.9 | K23: =IF(C23="","",IFERROR(D23,0)*G23+IFERROR(E23,0)+IFERROR(F23,0))
A24: 46041 | B24: Creek Side | C24: Sarah Mitchell | D24: 3.75 | E24: 120 | G24: =IFERROR(VLOOKUP(C24,Cleaners!$B$6:$I$35,8,FALSE),0) | H24: Inspected | I24: 5 | K24: =IF(C24="","",IFERROR(D24,0)*G24+IFERROR(E24,0)+IFERROR(F24,0))
A25: 46042 | B25: Smokies Ridge | C25: Sarah Mitchell | D25: 4 | E25: 120 | G25: =IFERROR(VLOOKUP(C25,Cleaners!$B$6:$I$35,8,FALSE),0) | H25: Inspected | I25: 5 | K25: =IF(C25="","",IFERROR(D25,0)*G25+IFERROR(E25,0)+IFERROR(F25,0))
A26: 46043 | B26: Lakehouse A | C26: Sarah Mitchell | D26: 3 | E26: 120 | G26: =IFERROR(VLOOKUP(C26,Cleaners!$B$6:$I$35,8,FALSE),0) | H26: Inspected | I26: 5 | K26: =IF(C26="","",IFERROR(D26,0)*G26+IFERROR(E26,0)+IFERROR(F26,0))
A27: 46044 | B27: Creek Side | C27: Sarah Mitchell | D27: 3.25 | E27: 120 | G27: =IFERROR(VLOOKUP(C27,Cleaners!$B$6:$I$35,8,FALSE),0) | H27: Inspected | I27: 4.6 | K27: =IF(C27="","",IFERROR(D27,0)*G27+IFERROR(E27,0)+IFERROR(F27,0))
A28: 46045 | B28: Smokies Ridge | C28: Sarah Mitchell | D28: 3.5 | E28: 120 | G28: =IFERROR(VLOOKUP(C28,Cleaners!$B$6:$I$35,8,FALSE),0) | H28: Inspected | I28: 4.7 | K28: =IF(C28="","",IFERROR(D28,0)*G28+IFERROR(E28,0)+IFERROR(F28,0))
A29: 46046 | B29: Lakehouse A | C29: Sarah Mitchell | D29: 3.75 | E29: 120 | G29: =IFERROR(VLOOKUP(C29,Cleaners!$B$6:$I$35,8,FALSE),0) | H29: Inspected | I29: 4.8 | K29: =IF(C29="","",IFERROR(D29,0)*G29+IFERROR(E29,0)+IFERROR(F29,0))
A30: 46047 | B30: Creek Side | C30: Sarah Mitchell | D30: 4 | E30: 120 | F30: 25 | G30: =IFERROR(VLOOKUP(C30,Cleaners!$B$6:$I$35,8,FALSE),0) | H30: Inspected | I30: 4.9 | K30: =IF(C30="","",IFERROR(D30,0)*G30+IFERROR(E30,0)+IFERROR(F30,0))
A31: 46048 | B31: Smokies Ridge | C31: Sarah Mitchell | D31: 3 | E31: 120 | G31: =IFERROR(VLOOKUP(C31,Cleaners!$B$6:$I$35,8,FALSE),0) | H31: Inspected | I31: 5 | K31: =IF(C31="","",IFERROR(D31,0)*G31+IFERROR(E31,0)+IFERROR(F31,0))
A32: 46049 | B32: Lakehouse A | C32: Sarah Mitchell | D32: 3.25 | E32: 120 | G32: =IFERROR(VLOOKUP(C32,Cleaners!$B$6:$I$35,8,FALSE),0) | H32: Inspected | I32: 5 | K32: =IF(C32="","",IFERROR(D32,0)*G32+IFERROR(E32,0)+IFERROR(F32,0))
A33: 46050 | B33: Creek Side | C33: Sarah Mitchell | D33: 3.5 | E33: 120 | G33: =IFERROR(VLOOKUP(C33,Cleaners!$B$6:$I$35,8,FALSE),0) | H33: Inspected | I33: 5 | K33: =IF(C33="","",IFERROR(D33,0)*G33+IFERROR(E33,0)+IFERROR(F33,0))
A34: 46051 | B34: Smokies Ridge | C34: Sarah Mitchell | D34: 3.75 | E34: 120 | G34: =IFERROR(VLOOKUP(C34,Cleaners!$B$6:$I$35,8,FALSE),0) | H34: Inspected | I34: 4.6 | K34: =IF(C34="","",IFERROR(D34,0)*G34+IFERROR(E34,0)+IFERROR(F34,0))
A35: 46052 | B35: Lakehouse A | C35: Sarah Mitchell | D35: 4 | E35: 120 | G35: =IFERROR(VLOOKUP(C35,Cleaners!$B$6:$I$35,8,FALSE),0) | H35: Inspected | I35: 4.7 | K35: =IF(C35="","",IFERROR(D35,0)*G35+IFERROR(E35,0)+IFERROR(F35,0))
A36: 46053 | B36: Creek Side | C36: Sarah Mitchell | D36: 3 | E36: 120 | G36: =IFERROR(VLOOKUP(C36,Cleaners!$B$6:$I$35,8,FALSE),0) | H36: Inspected | I36: 4.8 | K36: =IF(C36="","",IFERROR(D36,0)*G36+IFERROR(E36,0)+IFERROR(F36,0))
A37: 46054 | B37: Smokies Ridge | C37: Sarah Mitchell | D37: 3.25 | E37: 120 | G37: =IFERROR(VLOOKUP(C37,Cleaners!$B$6:$I$35,8,FALSE),0) | H37: Inspected | I37: 4.9 | K37: =IF(C37="","",IFERROR(D37,0)*G37+IFERROR(E37,0)+IFERROR(F37,0))
A38: 46055 | B38: Lakehouse A | C38: Sarah Mitchell | D38: 3.5 | E38: 120 | G38: =IFERROR(VLOOKUP(C38,Cleaners!$B$6:$I$35,8,FALSE),0) | H38: Inspected | I38: 5 | K38: =IF(C38="","",IFERROR(D38,0)*G38+IFERROR(E38,0)+IFERROR(F38,0))
A39: 46056 | B39: Creek Side | C39: Sarah Mitchell | D39: 3.75 | E39: 120 | G39: =IFERROR(VLOOKUP(C39,Cleaners!$B$6:$I$35,8,FALSE),0) | H39: Inspected | I39: 5 | K39: =IF(C39="","",IFERROR(D39,0)*G39+IFERROR(E39,0)+IFERROR(F39,0))
A40: 46057 | B40: Smokies Ridge | C40: Sarah Mitchell | D40: 4 | E40: 120 | G40: =IFERROR(VLOOKUP(C40,Cleaners!$B$6:$I$35,8,FALSE),0) | H40: Inspected | I40: 5 | K40: =IF(C40="","",IFERROR(D40,0)*G40+IFERROR(E40,0)+IFERROR(F40,0))
A41: 46058 | B41: Lakehouse A | C41: Sarah Mitchell | D41: 3 | E41: 120 | G41: =IFERROR(VLOOKUP(C41,Cleaners!$B$6:$I$35,8,FALSE),0) | H41: Inspected | I41: 4.6 | K41: =IF(C41="","",IFERROR(D41,0)*G41+IFERROR(E41,0)+IFERROR(F41,0))
A42: 46059 | B42: Creek Side | C42: Sarah Mitchell | D42: 3.25 | E42: 120 | F42: 25 | G42: =IFERROR(VLOOKUP(C42,Cleaners!$B$6:$I$35,8,FALSE),0) | H42: Inspected | I42: 4.7 | K42: =IF(C42="","",IFERROR(D42,0)*G42+IFERROR(E42,0)+IFERROR(F42,0))
...

Sheet Payroll Run
A2: =HYPERLINK("#'Turnover Assignment'!A1", "← BACK") | D2: PAYROLL RUN | J2: =HYPERLINK("#'Performance'!A1", "NEXT →")
A4: Set period dates → totals roll up per cleaner. Print this tab to pay.
A5: Period start: | B5: 46023
A6: Period end: | B6: 46036
A8: Cleaner | B8: Turnovers | C8: Hours | D8: Hourly $ | E8: Per-turn $ | F8: Bonuses | G8: Gross pay
A9: =IF(Cleaners!B6="","",Cleaners!B6) | B9: =IF(A9="","",COUNTIFS('Turnover Assignment'!$C$6:$C$1005,A9,'Turnover Assignment'!$A$6:$A$1005,">="&$B$5,'Turnover Assignment'!$A$6:$A$1005,"<="&$B$6)) | C9: =IF(A9="","",SUMIFS('Turnover Assignment'!$D$6:$D$1005,'Turnover Assignment'!$C$6:$C$1005,A9,'Turnover Assignment'!$A$6:$A$1005,">="&$B$5,'Turnover Assignment'!$A$6:$A$1005,"<="&$B$6)) | D9: =IF(A9="","",C9*IFERROR(VLOOKUP(A9,Cleaners!$B$6:$I$35,8,FALSE),0)) | E9: =IF(A9="","",SUMIFS('Turnover Assignment'!$E$6:$E$1005,'Turnover Assignment'!$C$6:$C$1005,A9,'Turnover Assignment'!$A$6:$A$1005,">="&$B$5,'Turnover Assignment'!$A$6:$A$1005,"<="&$B$6)) | F9: =IF(A9="","",SUMIFS('Turnover Assignment'!$F$6:$F$1005,'Turnover Assignment'!$C$6:$C$1005,A9,'Turnover Assignment'!$A$6:$A$1005,">="&$B$5,'Turnover Assignment'!$A$6:$A$1005,"<="&$B$6)) | G9: =IF(A9="","",D9+E9+F9)
A10: =IF(Cleaners!B7="","",Cleaners!B7) | B10: =IF(A10="","",COUNTIFS('Turnover Assignment'!$C$6:$C$1005,A10,'Turnover Assignment'!$A$6:$A$1005,">="&$B$5,'Turnover Assignment'!$A$6:$A$1005,"<="&$B$6)) | C10: =IF(A10="","",SUMIFS('Turnover Assignment'!$D$6:$D$1005,'Turnover Assignment'!$C$6:$C$1005,A10,'Turnover Assignment'!$A$6:$A$1005,">="&$B$5,'Turnover Assignment'!$A$6:$A$1005,"<="&$B$6)) | D10: =IF(A10="","",C10*IFERROR(VLOOKUP(A10,Cleaners!$B$6:$I$35,8,FALSE),0)) | E10: =IF(A10="","",SUMIFS('Turnover Assignment'!$E$6:$E$1005,'Turnover Assignment'!$C$6:$C$1005,A10,'Turnover Assignment'!$A$6:$A$1005,">="&$B$5,'Turnover Assignment'!$A$6:$A$1005,"<="&$B$6)) | F10: =IF(A10="","",SUMIFS('Turnover Assignment'!$F$6:$F$1005,'Turnover Assignment'!$C$6:$C$1005,A10,'Turnover Assignment'!$A$6:$A$1005,">="&$B$5,'Turnover Assignment'!$A$6:$A$1005,"<="&$B$6)) | G10: =IF(A10="","",D10+E10+F10)
A11: =IF(Cleaners!B8="","",Cleaners!B8) | B11: =IF(A11="","",COUNTIFS('Turnover Assignment'!$C$6:$C$1005,A11,'Turnover Assignment'!$A$6:$A$1005,">="&$B$5,'Turnover Assignment'!$A$6:$A$1005,"<="&$B$6)) | C11: =IF(A11="","",SUMIFS('Turnover Assignment'!$D$6:$D$1005,'Turnover Assignment'!$C$6:$C$1005,A11,'Turnover Assignment'!$A$6:$A$1005,">="&$B$5,'Turnover Assignment'!$A$6:$A$1005,"<="&$B$6)) | D11: =IF(A11="","",C11*IFERROR(VLOOKUP(A11,Cleaners!$B$6:$I$35,8,FALSE),0)) | E11: =IF(A11="","",SUMIFS('Turnover Assignment'!$E$6:$E$1005,'Turnover Assignment'!$C$6:$C$1005,A11,'Turnover Assignment'!$A$6:$A$1005,">="&$B$5,'Turnover Assignment'!$A$6:$A$1005,"<="&$B$6)) | F11: =IF(A11="","",SUMIFS('Turnover Assignment'!$F$6:$F$1005,'Turnover Assignment'!$C$6:$C$1005,A11,'Turnover Assignment'!$A$6:$A$1005,">="&$B$5,'Turnover Assignment'!$A$6:$A$1005,"<="&$B$6)) | G11: =IF(A11="","",D11+E11+F11)
A12: =IF(Cleaners!B9="","",Cleaners!B9) | B12: =IF(A12="","",COUNTIFS('Turnover Assignment'!$C$6:$C$1005,A12,'Turnover Assignment'!$A$6:$A$1005,">="&$B$5,'Turnover Assignment'!$A$6:$A$1005,"<="&$B$6)) | C12: =IF(A12="","",SUMIFS('Turnover Assignment'!$D$6:$D$1005,'Turnover Assignment'!$C$6:$C$1005,A12,'Turnover Assignment'!$A$6:$A$1005,">="&$B$5,'Turnover Assignment'!$A$6:$A$1005,"<="&$B$6)) | D12: =IF(A12="","",C12*IFERROR(VLOOKUP(A12,Cleaners!$B$6:$I$35,8,FALSE),0)) | E12: =IF(A12="","",SUMIFS('Turnover Assignment'!$E$6:$E$1005,'Turnover Assignment'!$C$6:$C$1005,A12,'Turnover Assignment'!$A$6:$A$1005,">="&$B$5,'Turnover Assignment'!$A$6:$A$1005,"<="&$B$6)) | F12: =IF(A12="","",SUMIFS('Turnover Assignment'!$F$6:$F$1005,'Turnover Assignment'!$C$6:$C$1005,A12,'Turnover Assignment'!$A$6:$A$1005,">="&$B$5,'Turnover Assignment'!$A$6:$A$1005,"<="&$B$6)) | G12: =IF(A12="","",D12+E12+F12)
A13: =IF(Cleaners!B10="","",Cleaners!B10) | B13: =IF(A13="","",COUNTIFS('Turnover Assignment'!$C$6:$C$1005,A13,'Turnover Assignment'!$A$6:$A$1005,">="&$B$5,'Turnover Assignment'!$A$6:$A$1005,"<="&$B$6)) | C13: =IF(A13="","",SUMIFS('Turnover Assignment'!$D$6:$D$1005,'Turnover Assignment'!$C$6:$C$1005,A13,'Turnover Assignment'!$A$6:$A$1005,">="&$B$5,'Turnover Assignment'!$A$6:$A$1005,"<="&$B$6)) | D13: =IF(A13="","",C13*IFERROR(VLOOKUP(A13,Cleaners!$B$6:$I$35,8,FALSE),0)) | E13: =IF(A13="","",SUMIFS('Turnover Assignment'!$E$6:$E$1005,'Turnover Assignment'!$C$6:$C$1005,A13,'Turnover Assignment'!$A$6:$A$1005,">="&$B$5,'Turnover Assignment'!$A$6:$A$1005,"<="&$B$6)) | F13: =IF(A13="","",SUMIFS('Turnover Assignment'!$F$6:$F$1005,'Turnover Assignment'!$C$6:$C$1005,A13,'Turnover Assignment'!$A$6:$A$1005,">="&$B$5,'Turnover Assignment'!$A$6:$A$1005,"<="&$B$6)) | G13: =IF(A13="","",D13+E13+F13)
A14: =IF(Cleaners!B11="","",Cleaners!B11) | B14: =IF(A14="","",COUNTIFS('Turnover Assignment'!$C$6:$C$1005,A14,'Turnover Assignment'!$A$6:$A$1005,">="&$B$5,'Turnover Assignment'!$A$6:$A$1005,"<="&$B$6)) | C14: =IF(A14="","",SUMIFS('Turnover Assignment'!$D$6:$D$1005,'Turnover Assignment'!$C$6:$C$1005,A14,'Turnover Assignment'!$A$6:$A$1005,">="&$B$5,'Turnover Assignment'!$A$6:$A$1005,"<="&$B$6)) | D14: =IF(A14="","",C14*IFERROR(VLOOKUP(A14,Cleaners!$B$6:$I$35,8,FALSE),0)) | E14: =IF(A14="","",SUMIFS('Turnover Assignment'!$E$6:$E$1005,'Turnover Assignment'!$C$6:$C$1005,A14,'Turnover Assignment'!$A$6:$A$1005,">="&$B$5,'Turnover Assignment'!$A$6:$A$1005,"<="&$B$6)) | F14: =IF(A14="","",SUMIFS('Turnover Assignment'!$F$6:$F$1005,'Turnover Assignment'!$C$6:$C$1005,A14,'Turnover Assignment'!$A$6:$A$1005,">="&$B$5,'Turnover Assignment'!$A$6:$A$1005,"<="&$B$6)) | G14: =IF(A14="","",D14+E14+F14)
A15: =IF(Cleaners!B12="","",Cleaners!B12) | B15: =IF(A15="","",COUNTIFS('Turnover Assignment'!$C$6:$C$1005,A15,'Turnover Assignment'!$A$6:$A$1005,">="&$B$5,'Turnover Assignment'!$A$6:$A$1005,"<="&$B$6)) | C15: =IF(A15="","",SUMIFS('Turnover Assignment'!$D$6:$D$1005,'Turnover Assignment'!$C$6:$C$1005,A15,'Turnover Assignment'!$A$6:$A$1005,">="&$B$5,'Turnover Assignment'!$A$6:$A$1005,"<="&$B$6)) | D15: =IF(A15="","",C15*IFERROR(VLOOKUP(A15,Cleaners!$B$6:$I$35,8,FALSE),0)) | E15: =IF(A15="","",SUMIFS('Turnover Assignment'!$E$6:$E$1005,'Turnover Assignment'!$C$6:$C$1005,A15,'Turnover Assignment'!$A$6:$A$1005,">="&$B$5,'Turnover Assignment'!$A$6:$A$1005,"<="&$B$6)) | F15: =IF(A15="","",SUMIFS('Turnover Assignment'!$F$6:$F$1005,'Turnover Assignment'!$C$6:$C$1005,A15,'Turnover Assignment'!$A$6:$A$1005,">="&$B$5,'Turnover Assignment'!$A$6:$A$1005,"<="&$B$6)) | G15: =IF(A15="","",D15+E15+F15)
A16: =IF(Cleaners!B13="","",Cleaners!B13) | B16: =IF(A16="","",COUNTIFS('Turnover Assignment'!$C$6:$C$1005,A16,'Turnover Assignment'!$A$6:$A$1005,">="&$B$5,'Turnover Assignment'!$A$6:$A$1005,"<="&$B$6)) | C16: =IF(A16="","",SUMIFS('Turnover Assignment'!$D$6:$D$1005,'Turnover Assignment'!$C$6:$C$1005,A16,'Turnover Assignment'!$A$6:$A$1005,">="&$B$5,'Turnover Assignment'!$A$6:$A$1005,"<="&$B$6)) | D16: =IF(A16="","",C16*IFERROR(VLOOKUP(A16,Cleaners!$B$6:$I$35,8,FALSE),0)) | E16: =IF(A16="","",SUMIFS('Turnover Assignment'!$E$6:$E$1005,'Turnover Assignment'!$C$6:$C$1005,A16,'Turnover Assignment'!$A$6:$A$1005,">="&$B$5,'Turnover Assignment'!$A$6:$A$1005,"<="&$B$6)) | F16: =IF(A16="","",SUMIFS('Turnover Assignment'!$F$6:$F$1005,'Turnover Assignment'!$C$6:$C$1005,A16,'Turnover Assignment'!$A$6:$A$1005,">="&$B$5,'Turnover Assignment'!$A$6:$A$1005,"<="&$B$6)) | G16: =IF(A16="","",D16+E16+F16)
A17: =IF(Cleaners!B14="","",Cleaners!B14) | B17: =IF(A17="","",COUNTIFS('Turnover Assignment'!$C$6:$C$1005,A17,'Turnover Assignment'!$A$6:$A$1005,">="&$B$5,'Turnover Assignment'!$A$6:$A$1005,"<="&$B$6)) | C17: =IF(A17="","",SUMIFS('Turnover Assignment'!$D$6:$D$1005,'Turnover Assignment'!$C$6:$C$1005,A17,'Turnover Assignment'!$A$6:$A$1005,">="&$B$5,'Turnover Assignment'!$A$6:$A$1005,"<="&$B$6)) | D17: =IF(A17="","",C17*IFERROR(VLOOKUP(A17,Cleaners!$B$6:$I$35,8,FALSE),0)) | E17: =IF(A17="","",SUMIFS('Turnover Assignment'!$E$6:$E$1005,'Turnover Assignment'!$C$6:$C$1005,A17,'Turnover Assignment'!$A$6:$A$1005,">="&$B$5,'Turnover Assignment'!$A$6:$A$1005,"<="&$B$6)) | F17: =IF(A17="","",SUMIFS('Turnover Assignment'!$F$6:$F$1005,'Turnover Assignment'!$C$6:$C$1005,A17,'Turnover Assignment'!$A$6:$A$1005,">="&$B$5,'Turnover Assignment'!$A$6:$A$1005,"<="&$B$6)) | G17: =IF(A17="","",D17+E17+F17)
A18: =IF(Cleaners!B15="","",Cleaners!B15) | B18: =IF(A18="","",COUNTIFS('Turnover Assignment'!$C$6:$C$1005,A18,'Turnover Assignment'!$A$6:$A$1005,">="&$B$5,'Turnover Assignment'!$A$6:$A$1005,"<="&$B$6)) | C18: =IF(A18="","",SUMIFS('Turnover Assignment'!$D$6:$D$1005,'Turnover Assignment'!$C$6:$C$1005,A18,'Turnover Assignment'!$A$6:$A$1005,">="&$B$5,'Turnover Assignment'!$A$6:$A$1005,"<="&$B$6)) | D18: =IF(A18="","",C18*IFERROR(VLOOKUP(A18,Cleaners!$B$6:$I$35,8,FALSE),0)) | E18: =IF(A18="","",SUMIFS('Turnover Assignment'!$E$6:$E$1005,'Turnover Assignment'!$C$6:$C$1005,A18,'Turnover Assignment'!$A$6:$A$1005,">="&$B$5,'Turnover Assignment'!$A$6:$A$1005,"<="&$B$6)) | F18: =IF(A18="","",SUMIFS('Turnover Assignment'!$F$6:$F$1005,'Turnover Assignment'!$C$6:$C$1005,A18,'Turnover Assignment'!$A$6:$A$1005,">="&$B$5,'Turnover Assignment'!$A$6:$A$1005,"<="&$B$6)) | G18: =IF(A18="","",D18+E18+F18)
A19: =IF(Cleaners!B16="","",Cleaners!B16) | B19: =IF(A19="","",COUNTIFS('Turnover Assignment'!$C$6:$C$1005,A19,'Turnover Assignment'!$A$6:$A$1005,">="&$B$5,'Turnover Assignment'!$A$6:$A$1005,"<="&$B$6)) | C19: =IF(A19="","",SUMIFS('Turnover Assignment'!$D$6:$D$1005,'Turnover Assignment'!$C$6:$C$1005,A19,'Turnover Assignment'!$A$6:$A$1005,">="&$B$5,'Turnover Assignment'!$A$6:$A$1005,"<="&$B$6)) | D19: =IF(A19="","",C19*IFERROR(VLOOKUP(A19,Cleaners!$B$6:$I$35,8,FALSE),0)) | E19: =IF(A19="","",SUMIFS('Turnover Assignment'!$E$6:$E$1005,'Turnover Assignment'!$C$6:$C$1005,A19,'Turnover Assignment'!$A$6:$A$1005,">="&$B$5,'Turnover Assignment'!$A$6:$A$1005,"<="&$B$6)) | F19: =IF(A19="","",SUMIFS('Turnover Assignment'!$F$6:$F$1005,'Turnover Assignment'!$C$6:$C$1005,A19,'Turnover Assignment'!$A$6:$A$1005,">="&$B$5,'Turnover Assignment'!$A$6:$A$1005,"<="&$B$6)) | G19: =IF(A19="","",D19+E19+F19)
A20: =IF(Cleaners!B17="","",Cleaners!B17) | B20: =IF(A20="","",COUNTIFS('Turnover Assignment'!$C$6:$C$1005,A20,'Turnover Assignment'!$A$6:$A$1005,">="&$B$5,'Turnover Assignment'!$A$6:$A$1005,"<="&$B$6)) | C20: =IF(A20="","",SUMIFS('Turnover Assignment'!$D$6:$D$1005,'Turnover Assignment'!$C$6:$C$1005,A20,'Turnover Assignment'!$A$6:$A$1005,">="&$B$5,'Turnover Assignment'!$A$6:$A$1005,"<="&$B$6)) | D20: =IF(A20="","",C20*IFERROR(VLOOKUP(A20,Cleaners!$B$6:$I$35,8,FALSE),0)) | E20: =IF(A20="","",SUMIFS('Turnover Assignment'!$E$6:$E$1005,'Turnover Assignment'!$C$6:$C$1005,A20,'Turnover Assignment'!$A$6:$A$1005,">="&$B$5,'Turnover Assignment'!$A$6:$A$1005,"<="&$B$6)) | F20: =IF(A20="","",SUMIFS('Turnover Assignment'!$F$6:$F$1005,'Turnover Assignment'!$C$6:$C$1005,A20,'Turnover Assignment'!$A$6:$A$1005,">="&$B$5,'Turnover Assignment'!$A$6:$A$1005,"<="&$B$6)) | G20: =IF(A20="","",D20+E20+F20)
... A38: =IF(Cleaners!B35="","",Cleaners!B35) | B38: =IF(A38="","",COUNTIFS('Turnover Assignment'!$C$6:$C$1005,A38,'Turnover Assignment'!$A$6:$A$1005,">="&$B$5,'Turnover Assignment'!$A$6:$A$1005,"<="&$B$6)) | C38: =IF(A38="","",SUMIFS('Turnover Assignment'!$D$6:$D$1005,'Turnover Assignment'!$C$6:$C$1005,A38,'Turnover Assignment'!$A$6:$A$1005,">="&$B$5,'Turnover Assignment'!$A$6:$A$1005,"<="&$B$6)) | D38: =IF(A38="","",C38*IFERROR(VLOOKUP(A38,Cleaners!$B$6:$I$35,8,FALSE),0)) | E38: =IF(A38="","",SUMIFS('Turnover Assignment'!$E$6:$E$1005,'Turnover Assignment'!$C$6:$C$1005,A38,'Turnover Assignment'!$A$6:$A$1005,">="&$B$5,'Turnover Assignment'!$A$6:$A$1005,"<="&$B$6)) | F38: =IF(A38="","",SUMIFS('Turnover Assignment'!$F$6:$F$1005,'Turnover Assignment'!$C$6:$C$1005,A38,'Turnover Assignment'!$A$6:$A$1005,">="&$B$5,'Turnover Assignment'!$A$6:$A$1005,"<="&$B$6)) | G38: =IF(A38="","",D38+E38+F38)
A40: TOTALS | B40: =SUM(B9:B38) | C40: =SUM(C9:C38) | D40: =SUM(D9:D38) | E40: =SUM(E9:E38) | F40: =SUM(F9:F38) | G40: =SUM(G9:G38)

Sheet Performance
A2: =HYPERLINK("#'Payroll Run'!A1", "← BACK") | D2: PERFORMANCE | J2: =HYPERLINK("#'1099-NEC Year-End'!A1", "NEXT →")
A4: Per-cleaner scorecard — review monthly to coach, flag, or cut
A5: Cleaner | B5: Turnovers YTD | C5: Avg rating | D5: Avg hrs/turn | E5: Complaints | F5: Performance flag
A6: =IF(Cleaners!B6="","",Cleaners!B6) | B6: =IF(A6="","",SUMPRODUCT(('Turnover Assignment'!$C$6:$C$1005=A6)*(YEAR('Turnover Assignment'!$A$6:$A$1005)=Settings!$B$5))) | C6: =IF(A6="","",IFERROR(AVERAGEIFS('Turnover Assignment'!$I$6:$I$1005,'Turnover Assignment'!$C$6:$C$1005,A6,'Turnover Assignment'!$I$6:$I$1005,">0"),"")) | D6: =IF(A6="","",IFERROR(AVERAGEIFS('Turnover Assignment'!$D$6:$D$1005,'Turnover Assignment'!$C$6:$C$1005,A6,'Turnover Assignment'!$D$6:$D$1005,">0"),"")) | F6: =IF(A6="","",IF(C6="","Insufficient data",IF(AND(C6>=4.7,IFERROR(E6,0)<=1),"Top performer",IF(OR(C6<4.0,IFERROR(E6,0)>=3),"Needs review","Standard"))))
A7: =IF(Cleaners!B7="","",Cleaners!B7) | B7: =IF(A7="","",SUMPRODUCT(('Turnover Assignment'!$C$6:$C$1005=A7)*(YEAR('Turnover Assignment'!$A$6:$A$1005)=Settings!$B$5))) | C7: =IF(A7="","",IFERROR(AVERAGEIFS('Turnover Assignment'!$I$6:$I$1005,'Turnover Assignment'!$C$6:$C$1005,A7,'Turnover Assignment'!$I$6:$I$1005,">0"),"")) | D7: =IF(A7="","",IFERROR(AVERAGEIFS('Turnover Assignment'!$D$6:$D$1005,'Turnover Assignment'!$C$6:$C$1005,A7,'Turnover Assignment'!$D$6:$D$1005,">0"),"")) | F7: =IF(A7="","",IF(C7="","Insufficient data",IF(AND(C7>=4.7,IFERROR(E7,0)<=1),"Top performer",IF(OR(C7<4.0,IFERROR(E7,0)>=3),"Needs review","Standard"))))
A8: =IF(Cleaners!B8="","",Cleaners!B8) | B8: =IF(A8="","",SUMPRODUCT(('Turnover Assignment'!$C$6:$C$1005=A8)*(YEAR('Turnover Assignment'!$A$6:$A$1005)=Settings!$B$5))) | C8: =IF(A8="","",IFERROR(AVERAGEIFS('Turnover Assignment'!$I$6:$I$1005,'Turnover Assignment'!$C$6:$C$1005,A8,'Turnover Assignment'!$I$6:$I$1005,">0"),"")) | D8: =IF(A8="","",IFERROR(AVERAGEIFS('Turnover Assignment'!$D$6:$D$1005,'Turnover Assignment'!$C$6:$C$1005,A8,'Turnover Assignment'!$D$6:$D$1005,">0"),"")) | F8: =IF(A8="","",IF(C8="","Insufficient data",IF(AND(C8>=4.7,IFERROR(E8,0)<=1),"Top performer",IF(OR(C8<4.0,IFERROR(E8,0)>=3),"Needs review","Standard"))))
A9: =IF(Cleaners!B9="","",Cleaners!B9) | B9: =IF(A9="","",SUMPRODUCT(('Turnover Assignment'!$C$6:$C$1005=A9)*(YEAR('Turnover Assignment'!$A$6:$A$1005)=Settings!$B$5))) | C9: =IF(A9="","",IFERROR(AVERAGEIFS('Turnover Assignment'!$I$6:$I$1005,'Turnover Assignment'!$C$6:$C$1005,A9,'Turnover Assignment'!$I$6:$I$1005,">0"),"")) | D9: =IF(A9="","",IFERROR(AVERAGEIFS('Turnover Assignment'!$D$6:$D$1005,'Turnover Assignment'!$C$6:$C$1005,A9,'Turnover Assignment'!$D$6:$D$1005,">0"),"")) | F9: =IF(A9="","",IF(C9="","Insufficient data",IF(AND(C9>=4.7,IFERROR(E9,0)<=1),"Top performer",IF(OR(C9<4.0,IFERROR(E9,0)>=3),"Needs review","Standard"))))
A10: =IF(Cleaners!B10="","",Cleaners!B10) | B10: =IF(A10="","",SUMPRODUCT(('Turnover Assignment'!$C$6:$C$1005=A10)*(YEAR('Turnover Assignment'!$A$6:$A$1005)=Settings!$B$5))) | C10: =IF(A10="","",IFERROR(AVERAGEIFS('Turnover Assignment'!$I$6:$I$1005,'Turnover Assignment'!$C$6:$C$1005,A10,'Turnover Assignment'!$I$6:$I$1005,">0"),"")) | D10: =IF(A10="","",IFERROR(AVERAGEIFS('Turnover Assignment'!$D$6:$D$1005,'Turnover Assignment'!$C$6:$C$1005,A10,'Turnover Assignment'!$D$6:$D$1005,">0"),"")) | F10: =IF(A10="","",IF(C10="","Insufficient data",IF(AND(C10>=4.7,IFERROR(E10,0)<=1),"Top performer",IF(OR(C10<4.0,IFERROR(E10,0)>=3),"Needs review","Standard"))))
A11: =IF(Cleaners!B11="","",Cleaners!B11) | B11: =IF(A11="","",SUMPRODUCT(('Turnover Assignment'!$C$6:$C$1005=A11)*(YEAR('Turnover Assignment'!$A$6:$A$1005)=Settings!$B$5))) | C11: =IF(A11="","",IFERROR(AVERAGEIFS('Turnover Assignment'!$I$6:$I$1005,'Turnover Assignment'!$C$6:$C$1005,A11,'Turnover Assignment'!$I$6:$I$1005,">0"),"")) | D11: =IF(A11="","",IFERROR(AVERAGEIFS('Turnover Assignment'!$D$6:$D$1005,'Turnover Assignment'!$C$6:$C$1005,A11,'Turnover Assignment'!$D$6:$D$1005,">0"),"")) | F11: =IF(A11="","",IF(C11="","Insufficient data",IF(AND(C11>=4.7,IFERROR(E11,0)<=1),"Top performer",IF(OR(C11<4.0,IFERROR(E11,0)>=3),"Needs review","Standard"))))
A12: =IF(Cleaners!B12="","",Cleaners!B12) | B12: =IF(A12="","",SUMPRODUCT(('Turnover Assignment'!$C$6:$C$1005=A12)*(YEAR('Turnover Assignment'!$A$6:$A$1005)=Settings!$B$5))) | C12: =IF(A12="","",IFERROR(AVERAGEIFS('Turnover Assignment'!$I$6:$I$1005,'Turnover Assignment'!$C$6:$C$1005,A12,'Turnover Assignment'!$I$6:$I$1005,">0"),"")) | D12: =IF(A12="","",IFERROR(AVERAGEIFS('Turnover Assignment'!$D$6:$D$1005,'Turnover Assignment'!$C$6:$C$1005,A12,'Turnover Assignment'!$D$6:$D$1005,">0"),"")) | F12: =IF(A12="","",IF(C12="","Insufficient data",IF(AND(C12>=4.7,IFERROR(E12,0)<=1),"Top performer",IF(OR(C12<4.0,IFERROR(E12,0)>=3),"Needs review","Standard"))))
A13: =IF(Cleaners!B13="","",Cleaners!B13) | B13: =IF(A13="","",SUMPRODUCT(('Turnover Assignment'!$C$6:$C$1005=A13)*(YEAR('Turnover Assignment'!$A$6:$A$1005)=Settings!$B$5))) | C13: =IF(A13="","",IFERROR(AVERAGEIFS('Turnover Assignment'!$I$6:$I$1005,'Turnover Assignment'!$C$6:$C$1005,A13,'Turnover Assignment'!$I$6:$I$1005,">0"),"")) | D13: =IF(A13="","",IFERROR(AVERAGEIFS('Turnover Assignment'!$D$6:$D$1005,'Turnover Assignment'!$C$6:$C$1005,A13,'Turnover Assignment'!$D$6:$D$1005,">0"),"")) | F13: =IF(A13="","",IF(C13="","Insufficient data",IF(AND(C13>=4.7,IFERROR(E13,0)<=1),"Top performer",IF(OR(C13<4.0,IFERROR(E13,0)>=3),"Needs review","Standard"))))
A14: =IF(Cleaners!B14="","",Cleaners!B14) | B14: =IF(A14="","",SUMPRODUCT(('Turnover Assignment'!$C$6:$C$1005=A14)*(YEAR('Turnover Assignment'!$A$6:$A$1005)=Settings!$B$5))) | C14: =IF(A14="","",IFERROR(AVERAGEIFS('Turnover Assignment'!$I$6:$I$1005,'Turnover Assignment'!$C$6:$C$1005,A14,'Turnover Assignment'!$I$6:$I$1005,">0"),"")) | D14: =IF(A14="","",IFERROR(AVERAGEIFS('Turnover Assignment'!$D$6:$D$1005,'Turnover Assignment'!$C$6:$C$1005,A14,'Turnover Assignment'!$D$6:$D$1005,">0"),"")) | F14: =IF(A14="","",IF(C14="","Insufficient data",IF(AND(C14>=4.7,IFERROR(E14,0)<=1),"Top performer",IF(OR(C14<4.0,IFERROR(E14,0)>=3),"Needs review","Standard"))))
A15: =IF(Cleaners!B15="","",Cleaners!B15) | B15: =IF(A15="","",SUMPRODUCT(('Turnover Assignment'!$C$6:$C$1005=A15)*(YEAR('Turnover Assignment'!$A$6:$A$1005)=Settings!$B$5))) | C15: =IF(A15="","",IFERROR(AVERAGEIFS('Turnover Assignment'!$I$6:$I$1005,'Turnover Assignment'!$C$6:$C$1005,A15,'Turnover Assignment'!$I$6:$I$1005,">0"),"")) | D15: =IF(A15="","",IFERROR(AVERAGEIFS('Turnover Assignment'!$D$6:$D$1005,'Turnover Assignment'!$C$6:$C$1005,A15,'Turnover Assignment'!$D$6:$D$1005,">0"),"")) | F15: =IF(A15="","",IF(C15="","Insufficient data",IF(AND(C15>=4.7,IFERROR(E15,0)<=1),"Top performer",IF(OR(C15<4.0,IFERROR(E15,0)>=3),"Needs review","Standard"))))
A16: =IF(Cleaners!B16="","",Cleaners!B16) | B16: =IF(A16="","",SUMPRODUCT(('Turnover Assignment'!$C$6:$C$1005=A16)*(YEAR('Turnover Assignment'!$A$6:$A$1005)=Settings!$B$5))) | C16: =IF(A16="","",IFERROR(AVERAGEIFS('Turnover Assignment'!$I$6:$I$1005,'Turnover Assignment'!$C$6:$C$1005,A16,'Turnover Assignment'!$I$6:$I$1005,">0"),"")) | D16: =IF(A16="","",IFERROR(AVERAGEIFS('Turnover Assignment'!$D$6:$D$1005,'Turnover Assignment'!$C$6:$C$1005,A16,'Turnover Assignment'!$D$6:$D$1005,">0"),"")) | F16: =IF(A16="","",IF(C16="","Insufficient data",IF(AND(C16>=4.7,IFERROR(E16,0)<=1),"Top performer",IF(OR(C16<4.0,IFERROR(E16,0)>=3),"Needs review","Standard"))))
A17: =IF(Cleaners!B17="","",Cleaners!B17) | B17: =IF(A17="","",SUMPRODUCT(('Turnover Assignment'!$C$6:$C$1005=A17)*(YEAR('Turnover Assignment'!$A$6:$A$1005)=Settings!$B$5))) | C17: =IF(A17="","",IFERROR(AVERAGEIFS('Turnover Assignment'!$I$6:$I$1005,'Turnover Assignment'!$C$6:$C$1005,A17,'Turnover Assignment'!$I$6:$I$1005,">0"),"")) | D17: =IF(A17="","",IFERROR(AVERAGEIFS('Turnover Assignment'!$D$6:$D$1005,'Turnover Assignment'!$C$6:$C$1005,A17,'Turnover Assignment'!$D$6:$D$1005,">0"),"")) | F17: =IF(A17="","",IF(C17="","Insufficient data",IF(AND(C17>=4.7,IFERROR(E17,0)<=1),"Top performer",IF(OR(C17<4.0,IFERROR(E17,0)>=3),"Needs review","Standard"))))
... A55: =IF(Cleaners!B55="","",Cleaners!B55) | B55: =IF(A55="","",SUMPRODUCT(('Turnover Assignment'!$C$6:$C$1005=A55)*(YEAR('Turnover Assignment'!$A$6:$A$1005)=Settings!$B$5))) | C55: =IF(A55="","",IFERROR(AVERAGEIFS('Turnover Assignment'!$I$6:$I$1005,'Turnover Assignment'!$C$6:$C$1005,A55,'Turnover Assignment'!$I$6:$I$1005,">0"),"")) | D55: =IF(A55="","",IFERROR(AVERAGEIFS('Turnover Assignment'!$D$6:$D$1005,'Turnover Assignment'!$C$6:$C$1005,A55,'Turnover Assignment'!$D$6:$D$1005,">0"),"")) | F55: =IF(A55="","",IF(C55="","Insufficient data",IF(AND(C55>=4.7,IFERROR(E55,0)<=1),"Top performer",IF(OR(C55<4.0,IFERROR(E55,0)>=3),"Needs review","Standard"))))

Sheet 1099-NEC Year-End
A2: =HYPERLINK("#'Performance'!A1", "← BACK") | D2: 1099-NEC YEAR-END · FOR YOUR CPA | J2: =HYPERLINK("#'Settings'!A1", "NEXT →")
A4: 📄 Year-end totals per cleaner — drops directly into TAX-003 1099-NEC tracker
A5: Cleaner | B5: Total paid YTD | C5: 1099 required? | D5: W-9 on file? | E5: Mailing address ready? | F5: Status
A6: =IF(Cleaners!B6="","",Cleaners!B6) | B6: =IF(A6="","",SUMPRODUCT(('Turnover Assignment'!$C$6:$C$1005=A6)*(YEAR('Turnover Assignment'!$A$6:$A$1005)=Settings!$B$5)*'Turnover Assignment'!$K$6:$K$1005)) | C6: =IF(A6="","",IF(B6>=Settings!$B$20,"✓ Required","Below threshold")) | D6: =IF(A6="","",IFERROR(VLOOKUP(A6,Cleaners!$B$6:$G$35,6,FALSE),"?")) | E6: =IF(A6="","",IF(IFERROR(VLOOKUP(A6,Cleaners!$B$6:$E$35,4,FALSE),"")="","⚠ Missing","✓ On file")) | F6: =IF(A6="","",IF(C6="✓ Required",IF(AND(D6="Yes",LEFT(E6,1)="✓"),"✓ Ready to file","⚠ Missing W-9 or address"),"n/a"))
A7: =IF(Cleaners!B7="","",Cleaners!B7) | B7: =IF(A7="","",SUMPRODUCT(('Turnover Assignment'!$C$6:$C$1005=A7)*(YEAR('Turnover Assignment'!$A$6:$A$1005)=Settings!$B$5)*'Turnover Assignment'!$K$6:$K$1005)) | C7: =IF(A7="","",IF(B7>=Settings!$B$20,"✓ Required","Below threshold")) | D7: =IF(A7="","",IFERROR(VLOOKUP(A7,Cleaners!$B$6:$G$35,6,FALSE),"?")) | E7: =IF(A7="","",IF(IFERROR(VLOOKUP(A7,Cleaners!$B$6:$E$35,4,FALSE),"")="","⚠ Missing","✓ On file")) | F7: =IF(A7="","",IF(C7="✓ Required",IF(AND(D7="Yes",LEFT(E7,1)="✓"),"✓ Ready to file","⚠ Missing W-9 or address"),"n/a"))
A8: =IF(Cleaners!B8="","",Cleaners!B8) | B8: =IF(A8="","",SUMPRODUCT(('Turnover Assignment'!$C$6:$C$1005=A8)*(YEAR('Turnover Assignment'!$A$6:$A$1005)=Settings!$B$5)*'Turnover Assignment'!$K$6:$K$1005)) | C8: =IF(A8="","",IF(B8>=Settings!$B$20,"✓ Required","Below threshold")) | D8: =IF(A8="","",IFERROR(VLOOKUP(A8,Cleaners!$B$6:$G$35,6,FALSE),"?")) | E8: =IF(A8="","",IF(IFERROR(VLOOKUP(A8,Cleaners!$B$6:$E$35,4,FALSE),"")="","⚠ Missing","✓ On file")) | F8: =IF(A8="","",IF(C8="✓ Required",IF(AND(D8="Yes",LEFT(E8,1)="✓"),"✓ Ready to file","⚠ Missing W-9 or address"),"n/a"))
A9: =IF(Cleaners!B9="","",Cleaners!B9) | B9: =IF(A9="","",SUMPRODUCT(('Turnover Assignment'!$C$6:$C$1005=A9)*(YEAR('Turnover Assignment'!$A$6:$A$1005)=Settings!$B$5)*'Turnover Assignment'!$K$6:$K$1005)) | C9: =IF(A9="","",IF(B9>=Settings!$B$20,"✓ Required","Below threshold")) | D9: =IF(A9="","",IFERROR(VLOOKUP(A9,Cleaners!$B$6:$G$35,6,FALSE),"?")) | E9: =IF(A9="","",IF(IFERROR(VLOOKUP(A9,Cleaners!$B$6:$E$35,4,FALSE),"")="","⚠ Missing","✓ On file")) | F9: =IF(A9="","",IF(C9="✓ Required",IF(AND(D9="Yes",LEFT(E9,1)="✓"),"✓ Ready to file","⚠ Missing W-9 or address"),"n/a"))
A10: =IF(Cleaners!B10="","",Cleaners!B10) | B10: =IF(A10="","",SUMPRODUCT(('Turnover Assignment'!$C$6:$C$1005=A10)*(YEAR('Turnover Assignment'!$A$6:$A$1005)=Settings!$B$5)*'Turnover Assignment'!$K$6:$K$1005)) | C10: =IF(A10="","",IF(B10>=Settings!$B$20,"✓ Required","Below threshold")) | D10: =IF(A10="","",IFERROR(VLOOKUP(A10,Cleaners!$B$6:$G$35,6,FALSE),"?")) | E10: =IF(A10="","",IF(IFERROR(VLOOKUP(A10,Cleaners!$B$6:$E$35,4,FALSE),"")="","⚠ Missing","✓ On file")) | F10: =IF(A10="","",IF(C10="✓ Required",IF(AND(D10="Yes",LEFT(E10,1)="✓"),"✓ Ready to file","⚠ Missing W-9 or address"),"n/a"))
A11: =IF(Cleaners!B11="","",Cleaners!B11) | B11: =IF(A11="","",SUMPRODUCT(('Turnover Assignment'!$C$6:$C$1005=A11)*(YEAR('Turnover Assignment'!$A$6:$A$1005)=Settings!$B$5)*'Turnover Assignment'!$K$6:$K$1005)) | C11: =IF(A11="","",IF(B11>=Settings!$B$20,"✓ Required","Below threshold")) | D11: =IF(A11="","",IFERROR(VLOOKUP(A11,Cleaners!$B$6:$G$35,6,FALSE),"?")) | E11: =IF(A11="","",IF(IFERROR(VLOOKUP(A11,Cleaners!$B$6:$E$35,4,FALSE),"")="","⚠ Missing","✓ On file")) | F11: =IF(A11="","",IF(C11="✓ Required",IF(AND(D11="Yes",LEFT(E11,1)="✓"),"✓ Ready to file","⚠ Missing W-9 or address"),"n/a"))
A12: =IF(Cleaners!B12="","",Cleaners!B12) | B12: =IF(A12="","",SUMPRODUCT(('Turnover Assignment'!$C$6:$C$1005=A12)*(YEAR('Turnover Assignment'!$A$6:$A$1005)=Settings!$B$5)*'Turnover Assignment'!$K$6:$K$1005)) | C12: =IF(A12="","",IF(B12>=Settings!$B$20,"✓ Required","Below threshold")) | D12: =IF(A12="","",IFERROR(VLOOKUP(A12,Cleaners!$B$6:$G$35,6,FALSE),"?")) | E12: =IF(A12="","",IF(IFERROR(VLOOKUP(A12,Cleaners!$B$6:$E$35,4,FALSE),"")="","⚠ Missing","✓ On file")) | F12: =IF(A12="","",IF(C12="✓ Required",IF(AND(D12="Yes",LEFT(E12,1)="✓"),"✓ Ready to file","⚠ Missing W-9 or address"),"n/a"))
A13: =IF(Cleaners!B13="","",Cleaners!B13) | B13: =IF(A13="","",SUMPRODUCT(('Turnover Assignment'!$C$6:$C$1005=A13)*(YEAR('Turnover Assignment'!$A$6:$A$1005)=Settings!$B$5)*'Turnover Assignment'!$K$6:$K$1005)) | C13: =IF(A13="","",IF(B13>=Settings!$B$20,"✓ Required","Below threshold")) | D13: =IF(A13="","",IFERROR(VLOOKUP(A13,Cleaners!$B$6:$G$35,6,FALSE),"?")) | E13: =IF(A13="","",IF(IFERROR(VLOOKUP(A13,Cleaners!$B$6:$E$35,4,FALSE),"")="","⚠ Missing","✓ On file")) | F13: =IF(A13="","",IF(C13="✓ Required",IF(AND(D13="Yes",LEFT(E13,1)="✓"),"✓ Ready to file","⚠ Missing W-9 or address"),"n/a"))
A14: =IF(Cleaners!B14="","",Cleaners!B14) | B14: =IF(A14="","",SUMPRODUCT(('Turnover Assignment'!$C$6:$C$1005=A14)*(YEAR('Turnover Assignment'!$A$6:$A$1005)=Settings!$B$5)*'Turnover Assignment'!$K$6:$K$1005)) | C14: =IF(A14="","",IF(B14>=Settings!$B$20,"✓ Required","Below threshold")) | D14: =IF(A14="","",IFERROR(VLOOKUP(A14,Cleaners!$B$6:$G$35,6,FALSE),"?")) | E14: =IF(A14="","",IF(IFERROR(VLOOKUP(A14,Cleaners!$B$6:$E$35,4,FALSE),"")="","⚠ Missing","✓ On file")) | F14: =IF(A14="","",IF(C14="✓ Required",IF(AND(D14="Yes",LEFT(E14,1)="✓"),"✓ Ready to file","⚠ Missing W-9 or address"),"n/a"))
A15: =IF(Cleaners!B15="","",Cleaners!B15) | B15: =IF(A15="","",SUMPRODUCT(('Turnover Assignment'!$C$6:$C$1005=A15)*(YEAR('Turnover Assignment'!$A$6:$A$1005)=Settings!$B$5)*'Turnover Assignment'!$K$6:$K$1005)) | C15: =IF(A15="","",IF(B15>=Settings!$B$20,"✓ Required","Below threshold")) | D15: =IF(A15="","",IFERROR(VLOOKUP(A15,Cleaners!$B$6:$G$35,6,FALSE),"?")) | E15: =IF(A15="","",IF(IFERROR(VLOOKUP(A15,Cleaners!$B$6:$E$35,4,FALSE),"")="","⚠ Missing","✓ On file")) | F15: =IF(A15="","",IF(C15="✓ Required",IF(AND(D15="Yes",LEFT(E15,1)="✓"),"✓ Ready to file","⚠ Missing W-9 or address"),"n/a"))
A16: =IF(Cleaners!B16="","",Cleaners!B16) | B16: =IF(A16="","",SUMPRODUCT(('Turnover Assignment'!$C$6:$C$1005=A16)*(YEAR('Turnover Assignment'!$A$6:$A$1005)=Settings!$B$5)*'Turnover Assignment'!$K$6:$K$1005)) | C16: =IF(A16="","",IF(B16>=Settings!$B$20,"✓ Required","Below threshold")) | D16: =IF(A16="","",IFERROR(VLOOKUP(A16,Cleaners!$B$6:$G$35,6,FALSE),"?")) | E16: =IF(A16="","",IF(IFERROR(VLOOKUP(A16,Cleaners!$B$6:$E$35,4,FALSE),"")="","⚠ Missing","✓ On file")) | F16: =IF(A16="","",IF(C16="✓ Required",IF(AND(D16="Yes",LEFT(E16,1)="✓"),"✓ Ready to file","⚠ Missing W-9 or address"),"n/a"))
A17: =IF(Cleaners!B17="","",Cleaners!B17) | B17: =IF(A17="","",SUMPRODUCT(('Turnover Assignment'!$C$6:$C$1005=A17)*(YEAR('Turnover Assignment'!$A$6:$A$1005)=Settings!$B$5)*'Turnover Assignment'!$K$6:$K$1005)) | C17: =IF(A17="","",IF(B17>=Settings!$B$20,"✓ Required","Below threshold")) | D17: =IF(A17="","",IFERROR(VLOOKUP(A17,Cleaners!$B$6:$G$35,6,FALSE),"?")) | E17: =IF(A17="","",IF(IFERROR(VLOOKUP(A17,Cleaners!$B$6:$E$35,4,FALSE),"")="","⚠ Missing","✓ On file")) | F17: =IF(A17="","",IF(C17="✓ Required",IF(AND(D17="Yes",LEFT(E17,1)="✓"),"✓ Ready to file","⚠ Missing W-9 or address"),"n/a"))
... A35: =IF(Cleaners!B35="","",Cleaners!B35) | B35: =IF(A35="","",SUMPRODUCT(('Turnover Assignment'!$C$6:$C$1005=A35)*(YEAR('Turnover Assignment'!$A$6:$A$1005)=Settings!$B$5)*'Turnover Assignment'!$K$6:$K$1005)) | C35: =IF(A35="","",IF(B35>=Settings!$B$20,"✓ Required","Below threshold")) | D35: =IF(A35="","",IFERROR(VLOOKUP(A35,Cleaners!$B$6:$G$35,6,FALSE),"?")) | E35: =IF(A35="","",IF(IFERROR(VLOOKUP(A35,Cleaners!$B$6:$E$35,4,FALSE),"")="","⚠ Missing","✓ On file")) | F35: =IF(A35="","",IF(C35="✓ Required",IF(AND(D35="Yes",LEFT(E35,1)="✓"),"✓ Ready to file","⚠ Missing W-9 or address"),"n/a"))
A38: Summary
A39: Cleaners requiring 1099: | B39: =COUNTIF(C6:C35,"✓ Required")
A40: Of those, ready to file: | B40: =COUNTIF(F6:F35,"✓ Ready to file")
A41: Of those, missing W-9 or address: | B41: =COUNTIF(C6:C35,"✓ Required")-COUNTIF(F6:F35,"✓ Ready to file")
A42: Total 1099-NEC $ volume: | B42: =SUMIFS(B6:B35,C6:C35,"✓ Required")

Sheet Settings
A2: =HYPERLINK("#'1099-NEC Year-End'!A1", "← BACK") | D2: SETTINGS
A4: Active year · property list · pay cadence · 1099 threshold
A5: Active tax year: | B5: 2026
A6: All YTD formulas filter on this year. Update once each January after you archive the prior year's data.
A7: Properties (used in Turnover dropdown):
B8: Smokies Ridge
B9: Creek Side
B10: Lakehouse A
B11: Mountain View
B12: Downtown Loft
A18: Payment cadence: | B18: Bi-weekly
A20: 1099-NEC threshold ($): | B20: 600
A21: $600 is locked by IRS rule. Don't change unless the IRS publishes a new threshold (rare) — Year-End formulas filter on this cell.
A23: Year-end Archive
A24: Each January, copy YTD totals into the row for the closing year, then clear the Turnover Assignment log for the new year (keep Cleaners).
A25: Year | B25: Active cleaners | C25: Turnovers | D25: Total $ paid
A26: 2024
A27: 2025
A28: 2026
A29: 2027
A30: 2028
A31: 2029
A32: 2030
