Workbook

Sheet Start
A2: The STR Ledger
A4: Commission / Split Calculator
A5: Co-host commissions, owed clearly — every booking, every month.
A7: PAM-003 · v1.0 · DEMO
A10: COMMISSION YTD | D10: PROPERTIES MANAGED | G10: OWNERS PAID | J10: TOP EARNER
A11: =SUMPRODUCT((YEAR('Bookings Log'!$A$6:$A$505)=Settings!$B$5)*'Bookings Log'!$L$6:$L$505) | D11: =COUNTA('Co-Host Agreements'!A6:A20) | G11: =SUMPRODUCT(('Bookings Log'!$N$6:$N$505="Paid")*(YEAR('Bookings Log'!$A$6:$A$505)=Settings!$B$5)*'Bookings Log'!$M$6:$M$505) | J11: =IFERROR(INDEX('Year-End Summary'!$A$8:$A$22,MATCH(MAX('Year-End Summary'!$F$8:$F$22),'Year-End Summary'!$F$8:$F$22,0)),"—")
A14: earned this year | D14: active co-host agreements | G14: owner share, YTD paid | J14: highest commission property
A17: MONTHLY WORKFLOW
A18: 1. Confirm each property's split agreement on Co-Host Agreements (% of NET / GROSS / Flat / Hybrid).
A19: 2. Log every booking on Bookings Log — gross, cleaning, platform fee. Commission auto-computes.
A20: 3. Open Monthly Statements → pick property + month → review the printable owner statement.
A21: 4. Mark each booking Paid once you receive your commission. Pending > 30 days will highlight.
A22: 5. At year-end, open Year-End Summary — properties at >= $600 commission flag for 1099-NEC.
A25: =HYPERLINK("#'Co-Host Agreements'!A1", "Co-Host Agreements") | D25: =HYPERLINK("#'Bookings Log'!A1", "-> Bookings Log") | G25: =HYPERLINK("#'Monthly Statements'!A1", "Monthly Statements") | J25: =HYPERLINK("#'Year-End Summary'!A1", "Year-End Summary")
A29: =HYPERLINK("#'Settings'!A1", "Settings - property list, owner list, active year")
A33: Bundle: Owner Reporting + Commission Split + Cleaner Tracker = the Pro Co-Host Toolkit at thestrledger.com/pro-cohost.
A36: Questions? hello@thestrledger.com
A37: PAM-003 - v1.0 - DEMO - Free updates forever

Sheet Co-Host Agreements
A2: =HYPERLINK("#'Start'!A1", "← BACK") | D2: CO-HOST AGREEMENTS | J2: =HYPERLINK("#'Bookings Log'!A1", "NEXT →")
A4: One row per property arrangement. Capacity 15. Commission formulas on Bookings Log VLOOKUP into this table by Property name.
A5: Property | B5: Owner name | C5: Owner email | D5: Agreement type | E5: Co-host % | F5: Flat $/booking | G5: Co-host pays cleaner? | H5: Co-host pays platform fees? | I5: Reimbursable items | J5: Effective date | K5: Notes
A6: Smokies Ridge | B6: Lakeside Holdings LLC | C6: owner1@lakeside.example | D6: % of NET | E6: 0.2 | F6: 0 | G6: No | H6: No | I6: Repairs > $200, supplies | J6: 45658 | K6: 20% of NET. Owner pays cleaner directly via Venmo.
A7: Lakehouse | B7: Lakeside Holdings LLC | C7: owner1@lakeside.example | D7: % of NET | E7: 0.15 | F7: 0 | G7: No | H7: No | I7: Repairs > $200, supplies | J7: 45717 | K7: 15% of NET; owner pays cleaner directly.
A8: Creek Side | B8: Maddox Trust | C8: owner2@maddox.example | D8: Flat per booking | E8: 0 | F8: 75 | G8: Yes | H8: No | I8: Reimburse cleaner from owner monthly | J8: 45762 | K8: $75 per booking flat; co-host pays cleaner, reimbursed monthly.
A9: Ridge Top | B9: Maddox Trust | C9: owner2@maddox.example | D9: Hybrid (Flat + % of NET) | E9: 0.08 | F9: 50 | G9: Yes | H9: No | I9: Reimburse cleaner from owner monthly | J9: 45778 | K9: $50/booking + 8% of NET; co-host fronts cleaner cost.

Sheet Bookings Log
A2: =HYPERLINK("#'Co-Host Agreements'!A1", "← BACK") | D2: BOOKINGS LOG | J2: =HYPERLINK("#'Monthly Statements'!A1", "NEXT →")
A4: All bookings, all properties. Capacity 500. NET = Gross - Cleaning - Platform - Other. Commission auto-computes from agreement type.
A5: Booking date | B5: Property | C5: Guest | D5: Booking ID | E5: Channel | F5: Gross revenue | G5: Cleaning fee | H5: Platform fee | I5: Other deductions | J5: NET to property | K5: Co-host % | L5: Co-host commission $ | M5: Owner share $ | N5: Payment status | O5: Notes
A6: 46026 | B6: Smokies Ridge | C6: Avery G. | D6: AB-90011 | E6: Airbnb | F6: 1620 | G6: 150 | H6: 243 | I6: 0 | J6: =IF(F6="","",F6-IF(IFERROR(VLOOKUP(B6,'Co-Host Agreements'!$A$6:$K$20,7,FALSE),"No")="Yes",G6,0)-IF(IFERROR(VLOOKUP(B6,'Co-Host Agreements'!$A$6:$K$20,8,FALSE),"No")="Yes",H6,0)-N(I6)) | K6: =IFERROR(VLOOKUP(B6,'Co-Host Agreements'!$A$6:$K$20,5,FALSE),0) | L6: =IF(B6="","",IFS(IFERROR(VLOOKUP(B6,'Co-Host Agreements'!$A$6:$K$20,4,FALSE),"")="% of NET",J6*K6,IFERROR(VLOOKUP(B6,'Co-Host Agreements'!$A$6:$K$20,4,FALSE),"")="% of GROSS",F6*K6,IFERROR(VLOOKUP(B6,'Co-Host Agreements'!$A$6:$K$20,4,FALSE),"")="Flat per booking",IFERROR(VLOOKUP(B6,'Co-Host Agreements'!$A$6:$K$20,6,FALSE),0),IFERROR(VLOOKUP(B6,'Co-Host Agreements'!$A$6:$K$20,4,FALSE),"")="Hybrid (Flat + % of NET)",IFERROR(VLOOKUP(B6,'Co-Host Agreements'!$A$6:$K$20,6,FALSE),0)+J6*K6,TRUE,0)) | M6: =IF(B6="","",J6-L6) | N6: Paid
A7: 46033 | B7: Smokies Ridge | C7: Marshall H. | D7: AB-90012 | E7: Airbnb | F7: 1480 | G7: 150 | H7: 222 | I7: 0 | J7: =IF(F7="","",F7-IF(IFERROR(VLOOKUP(B7,'Co-Host Agreements'!$A$6:$K$20,7,FALSE),"No")="Yes",G7,0)-IF(IFERROR(VLOOKUP(B7,'Co-Host Agreements'!$A$6:$K$20,8,FALSE),"No")="Yes",H7,0)-N(I7)) | K7: =IFERROR(VLOOKUP(B7,'Co-Host Agreements'!$A$6:$K$20,5,FALSE),0) | L7: =IF(B7="","",IFS(IFERROR(VLOOKUP(B7,'Co-Host Agreements'!$A$6:$K$20,4,FALSE),"")="% of NET",J7*K7,IFERROR(VLOOKUP(B7,'Co-Host Agreements'!$A$6:$K$20,4,FALSE),"")="% of GROSS",F7*K7,IFERROR(VLOOKUP(B7,'Co-Host Agreements'!$A$6:$K$20,4,FALSE),"")="Flat per booking",IFERROR(VLOOKUP(B7,'Co-Host Agreements'!$A$6:$K$20,6,FALSE),0),IFERROR(VLOOKUP(B7,'Co-Host Agreements'!$A$6:$K$20,4,FALSE),"")="Hybrid (Flat + % of NET)",IFERROR(VLOOKUP(B7,'Co-Host Agreements'!$A$6:$K$20,6,FALSE),0)+J7*K7,TRUE,0)) | M7: =IF(B7="","",J7-L7) | N7: Paid
A8: 46040 | B8: Smokies Ridge | C8: Priya R. | D8: VR-50221 | E8: VRBO | F8: 1740 | G8: 150 | H8: 139 | I8: 0 | J8: =IF(F8="","",F8-IF(IFERROR(VLOOKUP(B8,'Co-Host Agreements'!$A$6:$K$20,7,FALSE),"No")="Yes",G8,0)-IF(IFERROR(VLOOKUP(B8,'Co-Host Agreements'!$A$6:$K$20,8,FALSE),"No")="Yes",H8,0)-N(I8)) | K8: =IFERROR(VLOOKUP(B8,'Co-Host Agreements'!$A$6:$K$20,5,FALSE),0) | L8: =IF(B8="","",IFS(IFERROR(VLOOKUP(B8,'Co-Host Agreements'!$A$6:$K$20,4,FALSE),"")="% of NET",J8*K8,IFERROR(VLOOKUP(B8,'Co-Host Agreements'!$A$6:$K$20,4,FALSE),"")="% of GROSS",F8*K8,IFERROR(VLOOKUP(B8,'Co-Host Agreements'!$A$6:$K$20,4,FALSE),"")="Flat per booking",IFERROR(VLOOKUP(B8,'Co-Host Agreements'!$A$6:$K$20,6,FALSE),0),IFERROR(VLOOKUP(B8,'Co-Host Agreements'!$A$6:$K$20,4,FALSE),"")="Hybrid (Flat + % of NET)",IFERROR(VLOOKUP(B8,'Co-Host Agreements'!$A$6:$K$20,6,FALSE),0)+J8*K8,TRUE,0)) | M8: =IF(B8="","",J8-L8) | N8: Paid
A9: 46047 | B9: Smokies Ridge | C9: Casey N. | D9: DR-00031 | E9: Direct | F9: 1380 | G9: 150 | H9: 0 | I9: 0 | J9: =IF(F9="","",F9-IF(IFERROR(VLOOKUP(B9,'Co-Host Agreements'!$A$6:$K$20,7,FALSE),"No")="Yes",G9,0)-IF(IFERROR(VLOOKUP(B9,'Co-Host Agreements'!$A$6:$K$20,8,FALSE),"No")="Yes",H9,0)-N(I9)) | K9: =IFERROR(VLOOKUP(B9,'Co-Host Agreements'!$A$6:$K$20,5,FALSE),0) | L9: =IF(B9="","",IFS(IFERROR(VLOOKUP(B9,'Co-Host Agreements'!$A$6:$K$20,4,FALSE),"")="% of NET",J9*K9,IFERROR(VLOOKUP(B9,'Co-Host Agreements'!$A$6:$K$20,4,FALSE),"")="% of GROSS",F9*K9,IFERROR(VLOOKUP(B9,'Co-Host Agreements'!$A$6:$K$20,4,FALSE),"")="Flat per booking",IFERROR(VLOOKUP(B9,'Co-Host Agreements'!$A$6:$K$20,6,FALSE),0),IFERROR(VLOOKUP(B9,'Co-Host Agreements'!$A$6:$K$20,4,FALSE),"")="Hybrid (Flat + % of NET)",IFERROR(VLOOKUP(B9,'Co-Host Agreements'!$A$6:$K$20,6,FALSE),0)+J9*K9,TRUE,0)) | M9: =IF(B9="","",J9-L9) | N9: Paid | O9: Direct booking
A10: 46054 | B10: Smokies Ridge | C10: Devon S. | D10: AB-90013 | E10: Airbnb | F10: 1340 | G10: 150 | H10: 201 | I10: 0 | J10: =IF(F10="","",F10-IF(IFERROR(VLOOKUP(B10,'Co-Host Agreements'!$A$6:$K$20,7,FALSE),"No")="Yes",G10,0)-IF(IFERROR(VLOOKUP(B10,'Co-Host Agreements'!$A$6:$K$20,8,FALSE),"No")="Yes",H10,0)-N(I10)) | K10: =IFERROR(VLOOKUP(B10,'Co-Host Agreements'!$A$6:$K$20,5,FALSE),0) | L10: =IF(B10="","",IFS(IFERROR(VLOOKUP(B10,'Co-Host Agreements'!$A$6:$K$20,4,FALSE),"")="% of NET",J10*K10,IFERROR(VLOOKUP(B10,'Co-Host Agreements'!$A$6:$K$20,4,FALSE),"")="% of GROSS",F10*K10,IFERROR(VLOOKUP(B10,'Co-Host Agreements'!$A$6:$K$20,4,FALSE),"")="Flat per booking",IFERROR(VLOOKUP(B10,'Co-Host Agreements'!$A$6:$K$20,6,FALSE),0),IFERROR(VLOOKUP(B10,'Co-Host Agreements'!$A$6:$K$20,4,FALSE),"")="Hybrid (Flat + % of NET)",IFERROR(VLOOKUP(B10,'Co-Host Agreements'!$A$6:$K$20,6,FALSE),0)+J10*K10,TRUE,0)) | M10: =IF(B10="","",J10-L10) | N10: Paid
A11: 46061 | B11: Smokies Ridge | C11: Hailey M. | D11: AB-90014 | E11: Airbnb | F11: 1480 | G11: 150 | H11: 222 | I11: 0 | J11: =IF(F11="","",F11-IF(IFERROR(VLOOKUP(B11,'Co-Host Agreements'!$A$6:$K$20,7,FALSE),"No")="Yes",G11,0)-IF(IFERROR(VLOOKUP(B11,'Co-Host Agreements'!$A$6:$K$20,8,FALSE),"No")="Yes",H11,0)-N(I11)) | K11: =IFERROR(VLOOKUP(B11,'Co-Host Agreements'!$A$6:$K$20,5,FALSE),0) | L11: =IF(B11="","",IFS(IFERROR(VLOOKUP(B11,'Co-Host Agreements'!$A$6:$K$20,4,FALSE),"")="% of NET",J11*K11,IFERROR(VLOOKUP(B11,'Co-Host Agreements'!$A$6:$K$20,4,FALSE),"")="% of GROSS",F11*K11,IFERROR(VLOOKUP(B11,'Co-Host Agreements'!$A$6:$K$20,4,FALSE),"")="Flat per booking",IFERROR(VLOOKUP(B11,'Co-Host Agreements'!$A$6:$K$20,6,FALSE),0),IFERROR(VLOOKUP(B11,'Co-Host Agreements'!$A$6:$K$20,4,FALSE),"")="Hybrid (Flat + % of NET)",IFERROR(VLOOKUP(B11,'Co-Host Agreements'!$A$6:$K$20,6,FALSE),0)+J11*K11,TRUE,0)) | M11: =IF(B11="","",J11-L11) | N11: Paid
A12: 46068 | B12: Smokies Ridge | C12: Patrice O. | D12: AB-90015 | E12: Airbnb | F12: 1680 | G12: 150 | H12: 252 | I12: 0 | J12: =IF(F12="","",F12-IF(IFERROR(VLOOKUP(B12,'Co-Host Agreements'!$A$6:$K$20,7,FALSE),"No")="Yes",G12,0)-IF(IFERROR(VLOOKUP(B12,'Co-Host Agreements'!$A$6:$K$20,8,FALSE),"No")="Yes",H12,0)-N(I12)) | K12: =IFERROR(VLOOKUP(B12,'Co-Host Agreements'!$A$6:$K$20,5,FALSE),0) | L12: =IF(B12="","",IFS(IFERROR(VLOOKUP(B12,'Co-Host Agreements'!$A$6:$K$20,4,FALSE),"")="% of NET",J12*K12,IFERROR(VLOOKUP(B12,'Co-Host Agreements'!$A$6:$K$20,4,FALSE),"")="% of GROSS",F12*K12,IFERROR(VLOOKUP(B12,'Co-Host Agreements'!$A$6:$K$20,4,FALSE),"")="Flat per booking",IFERROR(VLOOKUP(B12,'Co-Host Agreements'!$A$6:$K$20,6,FALSE),0),IFERROR(VLOOKUP(B12,'Co-Host Agreements'!$A$6:$K$20,4,FALSE),"")="Hybrid (Flat + % of NET)",IFERROR(VLOOKUP(B12,'Co-Host Agreements'!$A$6:$K$20,6,FALSE),0)+J12*K12,TRUE,0)) | M12: =IF(B12="","",J12-L12) | N12: Paid
A13: 46075 | B13: Smokies Ridge | C13: Chen W. | D13: AB-90016 | E13: Airbnb | F13: 1540 | G13: 150 | H13: 231 | I13: 0 | J13: =IF(F13="","",F13-IF(IFERROR(VLOOKUP(B13,'Co-Host Agreements'!$A$6:$K$20,7,FALSE),"No")="Yes",G13,0)-IF(IFERROR(VLOOKUP(B13,'Co-Host Agreements'!$A$6:$K$20,8,FALSE),"No")="Yes",H13,0)-N(I13)) | K13: =IFERROR(VLOOKUP(B13,'Co-Host Agreements'!$A$6:$K$20,5,FALSE),0) | L13: =IF(B13="","",IFS(IFERROR(VLOOKUP(B13,'Co-Host Agreements'!$A$6:$K$20,4,FALSE),"")="% of NET",J13*K13,IFERROR(VLOOKUP(B13,'Co-Host Agreements'!$A$6:$K$20,4,FALSE),"")="% of GROSS",F13*K13,IFERROR(VLOOKUP(B13,'Co-Host Agreements'!$A$6:$K$20,4,FALSE),"")="Flat per booking",IFERROR(VLOOKUP(B13,'Co-Host Agreements'!$A$6:$K$20,6,FALSE),0),IFERROR(VLOOKUP(B13,'Co-Host Agreements'!$A$6:$K$20,4,FALSE),"")="Hybrid (Flat + % of NET)",IFERROR(VLOOKUP(B13,'Co-Host Agreements'!$A$6:$K$20,6,FALSE),0)+J13*K13,TRUE,0)) | M13: =IF(B13="","",J13-L13) | N13: Paid
A14: 46082 | B14: Smokies Ridge | C14: Tomás A. | D14: VR-50222 | E14: VRBO | F14: 1620 | G14: 150 | H14: 130 | I14: 0 | J14: =IF(F14="","",F14-IF(IFERROR(VLOOKUP(B14,'Co-Host Agreements'!$A$6:$K$20,7,FALSE),"No")="Yes",G14,0)-IF(IFERROR(VLOOKUP(B14,'Co-Host Agreements'!$A$6:$K$20,8,FALSE),"No")="Yes",H14,0)-N(I14)) | K14: =IFERROR(VLOOKUP(B14,'Co-Host Agreements'!$A$6:$K$20,5,FALSE),0) | L14: =IF(B14="","",IFS(IFERROR(VLOOKUP(B14,'Co-Host Agreements'!$A$6:$K$20,4,FALSE),"")="% of NET",J14*K14,IFERROR(VLOOKUP(B14,'Co-Host Agreements'!$A$6:$K$20,4,FALSE),"")="% of GROSS",F14*K14,IFERROR(VLOOKUP(B14,'Co-Host Agreements'!$A$6:$K$20,4,FALSE),"")="Flat per booking",IFERROR(VLOOKUP(B14,'Co-Host Agreements'!$A$6:$K$20,6,FALSE),0),IFERROR(VLOOKUP(B14,'Co-Host Agreements'!$A$6:$K$20,4,FALSE),"")="Hybrid (Flat + % of NET)",IFERROR(VLOOKUP(B14,'Co-Host Agreements'!$A$6:$K$20,6,FALSE),0)+J14*K14,TRUE,0)) | M14: =IF(B14="","",J14-L14) | N14: Paid
A15: 46089 | B15: Smokies Ridge | C15: Reese F. | D15: AB-90017 | E15: Airbnb | F15: 1880 | G15: 150 | H15: 282 | I15: 0 | J15: =IF(F15="","",F15-IF(IFERROR(VLOOKUP(B15,'Co-Host Agreements'!$A$6:$K$20,7,FALSE),"No")="Yes",G15,0)-IF(IFERROR(VLOOKUP(B15,'Co-Host Agreements'!$A$6:$K$20,8,FALSE),"No")="Yes",H15,0)-N(I15)) | K15: =IFERROR(VLOOKUP(B15,'Co-Host Agreements'!$A$6:$K$20,5,FALSE),0) | L15: =IF(B15="","",IFS(IFERROR(VLOOKUP(B15,'Co-Host Agreements'!$A$6:$K$20,4,FALSE),"")="% of NET",J15*K15,IFERROR(VLOOKUP(B15,'Co-Host Agreements'!$A$6:$K$20,4,FALSE),"")="% of GROSS",F15*K15,IFERROR(VLOOKUP(B15,'Co-Host Agreements'!$A$6:$K$20,4,FALSE),"")="Flat per booking",IFERROR(VLOOKUP(B15,'Co-Host Agreements'!$A$6:$K$20,6,FALSE),0),IFERROR(VLOOKUP(B15,'Co-Host Agreements'!$A$6:$K$20,4,FALSE),"")="Hybrid (Flat + % of NET)",IFERROR(VLOOKUP(B15,'Co-Host Agreements'!$A$6:$K$20,6,FALSE),0)+J15*K15,TRUE,0)) | M15: =IF(B15="","",J15-L15) | N15: Paid
A16: 46096 | B16: Smokies Ridge | C16: Olympia V. | D16: DR-00032 | E16: Direct | F16: 1740 | G16: 150 | H16: 0 | I16: 0 | J16: =IF(F16="","",F16-IF(IFERROR(VLOOKUP(B16,'Co-Host Agreements'!$A$6:$K$20,7,FALSE),"No")="Yes",G16,0)-IF(IFERROR(VLOOKUP(B16,'Co-Host Agreements'!$A$6:$K$20,8,FALSE),"No")="Yes",H16,0)-N(I16)) | K16: =IFERROR(VLOOKUP(B16,'Co-Host Agreements'!$A$6:$K$20,5,FALSE),0) | L16: =IF(B16="","",IFS(IFERROR(VLOOKUP(B16,'Co-Host Agreements'!$A$6:$K$20,4,FALSE),"")="% of NET",J16*K16,IFERROR(VLOOKUP(B16,'Co-Host Agreements'!$A$6:$K$20,4,FALSE),"")="% of GROSS",F16*K16,IFERROR(VLOOKUP(B16,'Co-Host Agreements'!$A$6:$K$20,4,FALSE),"")="Flat per booking",IFERROR(VLOOKUP(B16,'Co-Host Agreements'!$A$6:$K$20,6,FALSE),0),IFERROR(VLOOKUP(B16,'Co-Host Agreements'!$A$6:$K$20,4,FALSE),"")="Hybrid (Flat + % of NET)",IFERROR(VLOOKUP(B16,'Co-Host Agreements'!$A$6:$K$20,6,FALSE),0)+J16*K16,TRUE,0)) | M16: =IF(B16="","",J16-L16) | N16: Paid
A17: 46103 | B17: Smokies Ridge | C17: Sasha B. | D17: AB-90018 | E17: Airbnb | F17: 1640 | G17: 150 | H17: 246 | I17: 0 | J17: =IF(F17="","",F17-IF(IFERROR(VLOOKUP(B17,'Co-Host Agreements'!$A$6:$K$20,7,FALSE),"No")="Yes",G17,0)-IF(IFERROR(VLOOKUP(B17,'Co-Host Agreements'!$A$6:$K$20,8,FALSE),"No")="Yes",H17,0)-N(I17)) | K17: =IFERROR(VLOOKUP(B17,'Co-Host Agreements'!$A$6:$K$20,5,FALSE),0) | L17: =IF(B17="","",IFS(IFERROR(VLOOKUP(B17,'Co-Host Agreements'!$A$6:$K$20,4,FALSE),"")="% of NET",J17*K17,IFERROR(VLOOKUP(B17,'Co-Host Agreements'!$A$6:$K$20,4,FALSE),"")="% of GROSS",F17*K17,IFERROR(VLOOKUP(B17,'Co-Host Agreements'!$A$6:$K$20,4,FALSE),"")="Flat per booking",IFERROR(VLOOKUP(B17,'Co-Host Agreements'!$A$6:$K$20,6,FALSE),0),IFERROR(VLOOKUP(B17,'Co-Host Agreements'!$A$6:$K$20,4,FALSE),"")="Hybrid (Flat + % of NET)",IFERROR(VLOOKUP(B17,'Co-Host Agreements'!$A$6:$K$20,6,FALSE),0)+J17*K17,TRUE,0)) | M17: =IF(B17="","",J17-L17) | N17: Paid
A18: 46110 | B18: Smokies Ridge | C18: Wells D. | D18: AB-90019 | E18: Airbnb | F18: 1380 | G18: 150 | H18: 207 | I18: 0 | J18: =IF(F18="","",F18-IF(IFERROR(VLOOKUP(B18,'Co-Host Agreements'!$A$6:$K$20,7,FALSE),"No")="Yes",G18,0)-IF(IFERROR(VLOOKUP(B18,'Co-Host Agreements'!$A$6:$K$20,8,FALSE),"No")="Yes",H18,0)-N(I18)) | K18: =IFERROR(VLOOKUP(B18,'Co-Host Agreements'!$A$6:$K$20,5,FALSE),0) | L18: =IF(B18="","",IFS(IFERROR(VLOOKUP(B18,'Co-Host Agreements'!$A$6:$K$20,4,FALSE),"")="% of NET",J18*K18,IFERROR(VLOOKUP(B18,'Co-Host Agreements'!$A$6:$K$20,4,FALSE),"")="% of GROSS",F18*K18,IFERROR(VLOOKUP(B18,'Co-Host Agreements'!$A$6:$K$20,4,FALSE),"")="Flat per booking",IFERROR(VLOOKUP(B18,'Co-Host Agreements'!$A$6:$K$20,6,FALSE),0),IFERROR(VLOOKUP(B18,'Co-Host Agreements'!$A$6:$K$20,4,FALSE),"")="Hybrid (Flat + % of NET)",IFERROR(VLOOKUP(B18,'Co-Host Agreements'!$A$6:$K$20,6,FALSE),0)+J18*K18,TRUE,0)) | M18: =IF(B18="","",J18-L18) | N18: Paid
A19: 46117 | B19: Smokies Ridge | C19: Indira K. | D19: AB-90020 | E19: Airbnb | F19: 1740 | G19: 150 | H19: 261 | I19: 0 | J19: =IF(F19="","",F19-IF(IFERROR(VLOOKUP(B19,'Co-Host Agreements'!$A$6:$K$20,7,FALSE),"No")="Yes",G19,0)-IF(IFERROR(VLOOKUP(B19,'Co-Host Agreements'!$A$6:$K$20,8,FALSE),"No")="Yes",H19,0)-N(I19)) | K19: =IFERROR(VLOOKUP(B19,'Co-Host Agreements'!$A$6:$K$20,5,FALSE),0) | L19: =IF(B19="","",IFS(IFERROR(VLOOKUP(B19,'Co-Host Agreements'!$A$6:$K$20,4,FALSE),"")="% of NET",J19*K19,IFERROR(VLOOKUP(B19,'Co-Host Agreements'!$A$6:$K$20,4,FALSE),"")="% of GROSS",F19*K19,IFERROR(VLOOKUP(B19,'Co-Host Agreements'!$A$6:$K$20,4,FALSE),"")="Flat per booking",IFERROR(VLOOKUP(B19,'Co-Host Agreements'!$A$6:$K$20,6,FALSE),0),IFERROR(VLOOKUP(B19,'Co-Host Agreements'!$A$6:$K$20,4,FALSE),"")="Hybrid (Flat + % of NET)",IFERROR(VLOOKUP(B19,'Co-Host Agreements'!$A$6:$K$20,6,FALSE),0)+J19*K19,TRUE,0)) | M19: =IF(B19="","",J19-L19) | N19: Paid
A20: 46124 | B20: Smokies Ridge | C20: Brennan E. | D20: AB-90021 | E20: Airbnb | F20: 1480 | G20: 150 | H20: 222 | I20: 0 | J20: =IF(F20="","",F20-IF(IFERROR(VLOOKUP(B20,'Co-Host Agreements'!$A$6:$K$20,7,FALSE),"No")="Yes",G20,0)-IF(IFERROR(VLOOKUP(B20,'Co-Host Agreements'!$A$6:$K$20,8,FALSE),"No")="Yes",H20,0)-N(I20)) | K20: =IFERROR(VLOOKUP(B20,'Co-Host Agreements'!$A$6:$K$20,5,FALSE),0) | L20: =IF(B20="","",IFS(IFERROR(VLOOKUP(B20,'Co-Host Agreements'!$A$6:$K$20,4,FALSE),"")="% of NET",J20*K20,IFERROR(VLOOKUP(B20,'Co-Host Agreements'!$A$6:$K$20,4,FALSE),"")="% of GROSS",F20*K20,IFERROR(VLOOKUP(B20,'Co-Host Agreements'!$A$6:$K$20,4,FALSE),"")="Flat per booking",IFERROR(VLOOKUP(B20,'Co-Host Agreements'!$A$6:$K$20,6,FALSE),0),IFERROR(VLOOKUP(B20,'Co-Host Agreements'!$A$6:$K$20,4,FALSE),"")="Hybrid (Flat + % of NET)",IFERROR(VLOOKUP(B20,'Co-Host Agreements'!$A$6:$K$20,6,FALSE),0)+J20*K20,TRUE,0)) | M20: =IF(B20="","",J20-L20) | N20: Paid
A21: 46131 | B21: Smokies Ridge | C21: Nadia L. | D21: VR-50223 | E21: VRBO | F21: 1620 | G21: 150 | H21: 130 | I21: 0 | J21: =IF(F21="","",F21-IF(IFERROR(VLOOKUP(B21,'Co-Host Agreements'!$A$6:$K$20,7,FALSE),"No")="Yes",G21,0)-IF(IFERROR(VLOOKUP(B21,'Co-Host Agreements'!$A$6:$K$20,8,FALSE),"No")="Yes",H21,0)-N(I21)) | K21: =IFERROR(VLOOKUP(B21,'Co-Host Agreements'!$A$6:$K$20,5,FALSE),0) | L21: =IF(B21="","",IFS(IFERROR(VLOOKUP(B21,'Co-Host Agreements'!$A$6:$K$20,4,FALSE),"")="% of NET",J21*K21,IFERROR(VLOOKUP(B21,'Co-Host Agreements'!$A$6:$K$20,4,FALSE),"")="% of GROSS",F21*K21,IFERROR(VLOOKUP(B21,'Co-Host Agreements'!$A$6:$K$20,4,FALSE),"")="Flat per booking",IFERROR(VLOOKUP(B21,'Co-Host Agreements'!$A$6:$K$20,6,FALSE),0),IFERROR(VLOOKUP(B21,'Co-Host Agreements'!$A$6:$K$20,4,FALSE),"")="Hybrid (Flat + % of NET)",IFERROR(VLOOKUP(B21,'Co-Host Agreements'!$A$6:$K$20,6,FALSE),0)+J21*K21,TRUE,0)) | M21: =IF(B21="","",J21-L21) | N21: Paid
... A111: 46178 | B111: Ridge Top | C111: Fox V. | D111: AB-93017 | E111: Airbnb | F111: 1480 | G111: 110 | H111: 222 | I111: 0 | J111: =IF(F111="","",F111-IF(IFERROR(VLOOKUP(B111,'Co-Host Agreements'!$A$6:$K$20,7,FALSE),"No")="Yes",G111,0)-IF(IFERROR(VLOOKUP(B111,'Co-Host Agreements'!$A$6:$K$20,8,FALSE),"No")="Yes",H111,0)-N(I111)) | K111: =IFERROR(VLOOKUP(B111,'Co-Host Agreements'!$A$6:$K$20,5,FALSE),0) | L111: =IF(B111="","",IFS(IFERROR(VLOOKUP(B111,'Co-Host Agreements'!$A$6:$K$20,4,FALSE),"")="% of NET",J111*K111,IFERROR(VLOOKUP(B111,'Co-Host Agreements'!$A$6:$K$20,4,FALSE),"")="% of GROSS",F111*K111,IFERROR(VLOOKUP(B111,'Co-Host Agreements'!$A$6:$K$20,4,FALSE),"")="Flat per booking",IFERROR(VLOOKUP(B111,'Co-Host Agreements'!$A$6:$K$20,6,FALSE),0),IFERROR(VLOOKUP(B111,'Co-Host Agreements'!$A$6:$K$20,4,FALSE),"")="Hybrid (Flat + % of NET)",IFERROR(VLOOKUP(B111,'Co-Host Agreements'!$A$6:$K$20,6,FALSE),0)+J111*K111,TRUE,0)) | M111: =IF(B111="","",J111-L111) | N111: Pending
J112: =IF(F112="","",F112-IF(IFERROR(VLOOKUP(B112,'Co-Host Agreements'!$A$6:$K$20,7,FALSE),"No")="Yes",G112,0)-IF(IFERROR(VLOOKUP(B112,'Co-Host Agreements'!$A$6:$K$20,8,FALSE),"No")="Yes",H112,0)-N(I112)) | K112: =IFERROR(VLOOKUP(B112,'Co-Host Agreements'!$A$6:$K$20,5,FALSE),0) | L112: =IF(B112="","",IFS(IFERROR(VLOOKUP(B112,'Co-Host Agreements'!$A$6:$K$20,4,FALSE),"")="% of NET",J112*K112,IFERROR(VLOOKUP(B112,'Co-Host Agreements'!$A$6:$K$20,4,FALSE),"")="% of GROSS",F112*K112,IFERROR(VLOOKUP(B112,'Co-Host Agreements'!$A$6:$K$20,4,FALSE),"")="Flat per booking",IFERROR(VLOOKUP(B112,'Co-Host Agreements'!$A$6:$K$20,6,FALSE),0),IFERROR(VLOOKUP(B112,'Co-Host Agreements'!$A$6:$K$20,4,FALSE),"")="Hybrid (Flat + % of NET)",IFERROR(VLOOKUP(B112,'Co-Host Agreements'!$A$6:$K$20,6,FALSE),0)+J112*K112,TRUE,0)) | M112: =IF(B112="","",J112-L112)
J113: =IF(F113="","",F113-IF(IFERROR(VLOOKUP(B113,'Co-Host Agreements'!$A$6:$K$20,7,FALSE),"No")="Yes",G113,0)-IF(IFERROR(VLOOKUP(B113,'Co-Host Agreements'!$A$6:$K$20,8,FALSE),"No")="Yes",H113,0)-N(I113)) | K113: =IFERROR(VLOOKUP(B113,'Co-Host Agreements'!$A$6:$K$20,5,FALSE),0) | L113: =IF(B113="","",IFS(IFERROR(VLOOKUP(B113,'Co-Host Agreements'!$A$6:$K$20,4,FALSE),"")="% of NET",J113*K113,IFERROR(VLOOKUP(B113,'Co-Host Agreements'!$A$6:$K$20,4,FALSE),"")="% of GROSS",F113*K113,IFERROR(VLOOKUP(B113,'Co-Host Agreements'!$A$6:$K$20,4,FALSE),"")="Flat per booking",IFERROR(VLOOKUP(B113,'Co-Host Agreements'!$A$6:$K$20,6,FALSE),0),IFERROR(VLOOKUP(B113,'Co-Host Agreements'!$A$6:$K$20,4,FALSE),"")="Hybrid (Flat + % of NET)",IFERROR(VLOOKUP(B113,'Co-Host Agreements'!$A$6:$K$20,6,FALSE),0)+J113*K113,TRUE,0)) | M113: =IF(B113="","",J113-L113)
J114: =IF(F114="","",F114-IF(IFERROR(VLOOKUP(B114,'Co-Host Agreements'!$A$6:$K$20,7,FALSE),"No")="Yes",G114,0)-IF(IFERROR(VLOOKUP(B114,'Co-Host Agreements'!$A$6:$K$20,8,FALSE),"No")="Yes",H114,0)-N(I114)) | K114: =IFERROR(VLOOKUP(B114,'Co-Host Agreements'!$A$6:$K$20,5,FALSE),0) | L114: =IF(B114="","",IFS(IFERROR(VLOOKUP(B114,'Co-Host Agreements'!$A$6:$K$20,4,FALSE),"")="% of NET",J114*K114,IFERROR(VLOOKUP(B114,'Co-Host Agreements'!$A$6:$K$20,4,FALSE),"")="% of GROSS",F114*K114,IFERROR(VLOOKUP(B114,'Co-Host Agreements'!$A$6:$K$20,4,FALSE),"")="Flat per booking",IFERROR(VLOOKUP(B114,'Co-Host Agreements'!$A$6:$K$20,6,FALSE),0),IFERROR(VLOOKUP(B114,'Co-Host Agreements'!$A$6:$K$20,4,FALSE),"")="Hybrid (Flat + % of NET)",IFERROR(VLOOKUP(B114,'Co-Host Agreements'!$A$6:$K$20,6,FALSE),0)+J114*K114,TRUE,0)) | M114: =IF(B114="","",J114-L114)
J115: =IF(F115="","",F115-IF(IFERROR(VLOOKUP(B115,'Co-Host Agreements'!$A$6:$K$20,7,FALSE),"No")="Yes",G115,0)-IF(IFERROR(VLOOKUP(B115,'Co-Host Agreements'!$A$6:$K$20,8,FALSE),"No")="Yes",H115,0)-N(I115)) | K115: =IFERROR(VLOOKUP(B115,'Co-Host Agreements'!$A$6:$K$20,5,FALSE),0) | L115: =IF(B115="","",IFS(IFERROR(VLOOKUP(B115,'Co-Host Agreements'!$A$6:$K$20,4,FALSE),"")="% of NET",J115*K115,IFERROR(VLOOKUP(B115,'Co-Host Agreements'!$A$6:$K$20,4,FALSE),"")="% of GROSS",F115*K115,IFERROR(VLOOKUP(B115,'Co-Host Agreements'!$A$6:$K$20,4,FALSE),"")="Flat per booking",IFERROR(VLOOKUP(B115,'Co-Host Agreements'!$A$6:$K$20,6,FALSE),0),IFERROR(VLOOKUP(B115,'Co-Host Agreements'!$A$6:$K$20,4,FALSE),"")="Hybrid (Flat + % of NET)",IFERROR(VLOOKUP(B115,'Co-Host Agreements'!$A$6:$K$20,6,FALSE),0)+J115*K115,TRUE,0)) | M115: =IF(B115="","",J115-L115)
J116: =IF(F116="","",F116-IF(IFERROR(VLOOKUP(B116,'Co-Host Agreements'!$A$6:$K$20,7,FALSE),"No")="Yes",G116,0)-IF(IFERROR(VLOOKUP(B116,'Co-Host Agreements'!$A$6:$K$20,8,FALSE),"No")="Yes",H116,0)-N(I116)) | K116: =IFERROR(VLOOKUP(B116,'Co-Host Agreements'!$A$6:$K$20,5,FALSE),0) | L116: =IF(B116="","",IFS(IFERROR(VLOOKUP(B116,'Co-Host Agreements'!$A$6:$K$20,4,FALSE),"")="% of NET",J116*K116,IFERROR(VLOOKUP(B116,'Co-Host Agreements'!$A$6:$K$20,4,FALSE),"")="% of GROSS",F116*K116,IFERROR(VLOOKUP(B116,'Co-Host Agreements'!$A$6:$K$20,4,FALSE),"")="Flat per booking",IFERROR(VLOOKUP(B116,'Co-Host Agreements'!$A$6:$K$20,6,FALSE),0),IFERROR(VLOOKUP(B116,'Co-Host Agreements'!$A$6:$K$20,4,FALSE),"")="Hybrid (Flat + % of NET)",IFERROR(VLOOKUP(B116,'Co-Host Agreements'!$A$6:$K$20,6,FALSE),0)+J116*K116,TRUE,0)) | M116: =IF(B116="","",J116-L116)
J117: =IF(F117="","",F117-IF(IFERROR(VLOOKUP(B117,'Co-Host Agreements'!$A$6:$K$20,7,FALSE),"No")="Yes",G117,0)-IF(IFERROR(VLOOKUP(B117,'Co-Host Agreements'!$A$6:$K$20,8,FALSE),"No")="Yes",H117,0)-N(I117)) | K117: =IFERROR(VLOOKUP(B117,'Co-Host Agreements'!$A$6:$K$20,5,FALSE),0) | L117: =IF(B117="","",IFS(IFERROR(VLOOKUP(B117,'Co-Host Agreements'!$A$6:$K$20,4,FALSE),"")="% of NET",J117*K117,IFERROR(VLOOKUP(B117,'Co-Host Agreements'!$A$6:$K$20,4,FALSE),"")="% of GROSS",F117*K117,IFERROR(VLOOKUP(B117,'Co-Host Agreements'!$A$6:$K$20,4,FALSE),"")="Flat per booking",IFERROR(VLOOKUP(B117,'Co-Host Agreements'!$A$6:$K$20,6,FALSE),0),IFERROR(VLOOKUP(B117,'Co-Host Agreements'!$A$6:$K$20,4,FALSE),"")="Hybrid (Flat + % of NET)",IFERROR(VLOOKUP(B117,'Co-Host Agreements'!$A$6:$K$20,6,FALSE),0)+J117*K117,TRUE,0)) | M117: =IF(B117="","",J117-L117)
J118: =IF(F118="","",F118-IF(IFERROR(VLOOKUP(B118,'Co-Host Agreements'!$A$6:$K$20,7,FALSE),"No")="Yes",G118,0)-IF(IFERROR(VLOOKUP(B118,'Co-Host Agreements'!$A$6:$K$20,8,FALSE),"No")="Yes",H118,0)-N(I118)) | K118: =IFERROR(VLOOKUP(B118,'Co-Host Agreements'!$A$6:$K$20,5,FALSE),0) | L118: =IF(B118="","",IFS(IFERROR(VLOOKUP(B118,'Co-Host Agreements'!$A$6:$K$20,4,FALSE),"")="% of NET",J118*K118,IFERROR(VLOOKUP(B118,'Co-Host Agreements'!$A$6:$K$20,4,FALSE),"")="% of GROSS",F118*K118,IFERROR(VLOOKUP(B118,'Co-Host Agreements'!$A$6:$K$20,4,FALSE),"")="Flat per booking",IFERROR(VLOOKUP(B118,'Co-Host Agreements'!$A$6:$K$20,6,FALSE),0),IFERROR(VLOOKUP(B118,'Co-Host Agreements'!$A$6:$K$20,4,FALSE),"")="Hybrid (Flat + % of NET)",IFERROR(VLOOKUP(B118,'Co-Host Agreements'!$A$6:$K$20,6,FALSE),0)+J118*K118,TRUE,0)) | M118: =IF(B118="","",J118-L118)
J119: =IF(F119="","",F119-IF(IFERROR(VLOOKUP(B119,'Co-Host Agreements'!$A$6:$K$20,7,FALSE),"No")="Yes",G119,0)-IF(IFERROR(VLOOKUP(B119,'Co-Host Agreements'!$A$6:$K$20,8,FALSE),"No")="Yes",H119,0)-N(I119)) | K119: =IFERROR(VLOOKUP(B119,'Co-Host Agreements'!$A$6:$K$20,5,FALSE),0) | L119: =IF(B119="","",IFS(IFERROR(VLOOKUP(B119,'Co-Host Agreements'!$A$6:$K$20,4,FALSE),"")="% of NET",J119*K119,IFERROR(VLOOKUP(B119,'Co-Host Agreements'!$A$6:$K$20,4,FALSE),"")="% of GROSS",F119*K119,IFERROR(VLOOKUP(B119,'Co-Host Agreements'!$A$6:$K$20,4,FALSE),"")="Flat per booking",IFERROR(VLOOKUP(B119,'Co-Host Agreements'!$A$6:$K$20,6,FALSE),0),IFERROR(VLOOKUP(B119,'Co-Host Agreements'!$A$6:$K$20,4,FALSE),"")="Hybrid (Flat + % of NET)",IFERROR(VLOOKUP(B119,'Co-Host Agreements'!$A$6:$K$20,6,FALSE),0)+J119*K119,TRUE,0)) | M119: =IF(B119="","",J119-L119)
J120: =IF(F120="","",F120-IF(IFERROR(VLOOKUP(B120,'Co-Host Agreements'!$A$6:$K$20,7,FALSE),"No")="Yes",G120,0)-IF(IFERROR(VLOOKUP(B120,'Co-Host Agreements'!$A$6:$K$20,8,FALSE),"No")="Yes",H120,0)-N(I120)) | K120: =IFERROR(VLOOKUP(B120,'Co-Host Agreements'!$A$6:$K$20,5,FALSE),0) | L120: =IF(B120="","",IFS(IFERROR(VLOOKUP(B120,'Co-Host Agreements'!$A$6:$K$20,4,FALSE),"")="% of NET",J120*K120,IFERROR(VLOOKUP(B120,'Co-Host Agreements'!$A$6:$K$20,4,FALSE),"")="% of GROSS",F120*K120,IFERROR(VLOOKUP(B120,'Co-Host Agreements'!$A$6:$K$20,4,FALSE),"")="Flat per booking",IFERROR(VLOOKUP(B120,'Co-Host Agreements'!$A$6:$K$20,6,FALSE),0),IFERROR(VLOOKUP(B120,'Co-Host Agreements'!$A$6:$K$20,4,FALSE),"")="Hybrid (Flat + % of NET)",IFERROR(VLOOKUP(B120,'Co-Host Agreements'!$A$6:$K$20,6,FALSE),0)+J120*K120,TRUE,0)) | M120: =IF(B120="","",J120-L120)
J121: =IF(F121="","",F121-IF(IFERROR(VLOOKUP(B121,'Co-Host Agreements'!$A$6:$K$20,7,FALSE),"No")="Yes",G121,0)-IF(IFERROR(VLOOKUP(B121,'Co-Host Agreements'!$A$6:$K$20,8,FALSE),"No")="Yes",H121,0)-N(I121)) | K121: =IFERROR(VLOOKUP(B121,'Co-Host Agreements'!$A$6:$K$20,5,FALSE),0) | L121: =IF(B121="","",IFS(IFERROR(VLOOKUP(B121,'Co-Host Agreements'!$A$6:$K$20,4,FALSE),"")="% of NET",J121*K121,IFERROR(VLOOKUP(B121,'Co-Host Agreements'!$A$6:$K$20,4,FALSE),"")="% of GROSS",F121*K121,IFERROR(VLOOKUP(B121,'Co-Host Agreements'!$A$6:$K$20,4,FALSE),"")="Flat per booking",IFERROR(VLOOKUP(B121,'Co-Host Agreements'!$A$6:$K$20,6,FALSE),0),IFERROR(VLOOKUP(B121,'Co-Host Agreements'!$A$6:$K$20,4,FALSE),"")="Hybrid (Flat + % of NET)",IFERROR(VLOOKUP(B121,'Co-Host Agreements'!$A$6:$K$20,6,FALSE),0)+J121*K121,TRUE,0)) | M121: =IF(B121="","",J121-L121)
J122: =IF(F122="","",F122-IF(IFERROR(VLOOKUP(B122,'Co-Host Agreements'!$A$6:$K$20,7,FALSE),"No")="Yes",G122,0)-IF(IFERROR(VLOOKUP(B122,'Co-Host Agreements'!$A$6:$K$20,8,FALSE),"No")="Yes",H122,0)-N(I122)) | K122: =IFERROR(VLOOKUP(B122,'Co-Host Agreements'!$A$6:$K$20,5,FALSE),0) | L122: =IF(B122="","",IFS(IFERROR(VLOOKUP(B122,'Co-Host Agreements'!$A$6:$K$20,4,FALSE),"")="% of NET",J122*K122,IFERROR(VLOOKUP(B122,'Co-Host Agreements'!$A$6:$K$20,4,FALSE),"")="% of GROSS",F122*K122,IFERROR(VLOOKUP(B122,'Co-Host Agreements'!$A$6:$K$20,4,FALSE),"")="Flat per booking",IFERROR(VLOOKUP(B122,'Co-Host Agreements'!$A$6:$K$20,6,FALSE),0),IFERROR(VLOOKUP(B122,'Co-Host Agreements'!$A$6:$K$20,4,FALSE),"")="Hybrid (Flat + % of NET)",IFERROR(VLOOKUP(B122,'Co-Host Agreements'!$A$6:$K$20,6,FALSE),0)+J122*K122,TRUE,0)) | M122: =IF(B122="","",J122-L122)
J123: =IF(F123="","",F123-IF(IFERROR(VLOOKUP(B123,'Co-Host Agreements'!$A$6:$K$20,7,FALSE),"No")="Yes",G123,0)-IF(IFERROR(VLOOKUP(B123,'Co-Host Agreements'!$A$6:$K$20,8,FALSE),"No")="Yes",H123,0)-N(I123)) | K123: =IFERROR(VLOOKUP(B123,'Co-Host Agreements'!$A$6:$K$20,5,FALSE),0) | L123: =IF(B123="","",IFS(IFERROR(VLOOKUP(B123,'Co-Host Agreements'!$A$6:$K$20,4,FALSE),"")="% of NET",J123*K123,IFERROR(VLOOKUP(B123,'Co-Host Agreements'!$A$6:$K$20,4,FALSE),"")="% of GROSS",F123*K123,IFERROR(VLOOKUP(B123,'Co-Host Agreements'!$A$6:$K$20,4,FALSE),"")="Flat per booking",IFERROR(VLOOKUP(B123,'Co-Host Agreements'!$A$6:$K$20,6,FALSE),0),IFERROR(VLOOKUP(B123,'Co-Host Agreements'!$A$6:$K$20,4,FALSE),"")="Hybrid (Flat + % of NET)",IFERROR(VLOOKUP(B123,'Co-Host Agreements'!$A$6:$K$20,6,FALSE),0)+J123*K123,TRUE,0)) | M123: =IF(B123="","",J123-L123)
... J505: =IF(F505="","",F505-IF(IFERROR(VLOOKUP(B505,'Co-Host Agreements'!$A$6:$K$20,7,FALSE),"No")="Yes",G505,0)-IF(IFERROR(VLOOKUP(B505,'Co-Host Agreements'!$A$6:$K$20,8,FALSE),"No")="Yes",H505,0)-N(I505)) | K505: =IFERROR(VLOOKUP(B505,'Co-Host Agreements'!$A$6:$K$20,5,FALSE),0) | L505: =IF(B505="","",IFS(IFERROR(VLOOKUP(B505,'Co-Host Agreements'!$A$6:$K$20,4,FALSE),"")="% of NET",J505*K505,IFERROR(VLOOKUP(B505,'Co-Host Agreements'!$A$6:$K$20,4,FALSE),"")="% of GROSS",F505*K505,IFERROR(VLOOKUP(B505,'Co-Host Agreements'!$A$6:$K$20,4,FALSE),"")="Flat per booking",IFERROR(VLOOKUP(B505,'Co-Host Agreements'!$A$6:$K$20,6,FALSE),0),IFERROR(VLOOKUP(B505,'Co-Host Agreements'!$A$6:$K$20,4,FALSE),"")="Hybrid (Flat + % of NET)",IFERROR(VLOOKUP(B505,'Co-Host Agreements'!$A$6:$K$20,6,FALSE),0)+J505*K505,TRUE,0)) | M505: =IF(B505="","",J505-L505)

Sheet Monthly Statements
B1: =HYPERLINK("#'Start'!A1", "<- back to dashboard")
B3: MONTHLY COMMISSION STATEMENT
B6: Property: | C6: Smokies Ridge
B7: Period: | C7: 3 | D7: month | E7: =Settings!B5 | F7: year (Settings)
B9: Owner: | C9: =IFERROR(VLOOKUP($C$6,'Co-Host Agreements'!$A$6:$K$20,2,FALSE)&" - "&VLOOKUP($C$6,'Co-Host Agreements'!$A$6:$K$20,3,FALSE),"")
B10: Agreement: | C10: =IFERROR(VLOOKUP($C$6,'Co-Host Agreements'!$A$6:$K$20,4,FALSE),"")
B12: BOOKINGS THIS MONTH
B13: Date | C13: Guest | D13: Gross | E13: Deductions | F13: NET | G13: Commission
B14: =IFERROR(INDEX('Bookings Log'!$A$6:$A$505,IFERROR(SMALL(IF((MONTH('Bookings Log'!$A$6:$A$505)=$C$7)*(YEAR('Bookings Log'!$A$6:$A$505)=$E$7)*('Bookings Log'!$B$6:$B$505=$C$6),ROW('Bookings Log'!$A$6:$A$505)-5),1),"")),"") | C14: =IFERROR(INDEX('Bookings Log'!$C$6:$C$505,IFERROR(SMALL(IF((MONTH('Bookings Log'!$A$6:$A$505)=$C$7)*(YEAR('Bookings Log'!$A$6:$A$505)=$E$7)*('Bookings Log'!$B$6:$B$505=$C$6),ROW('Bookings Log'!$A$6:$A$505)-5),1),"")),"") | D14: =IFERROR(INDEX('Bookings Log'!$F$6:$F$505,IFERROR(SMALL(IF((MONTH('Bookings Log'!$A$6:$A$505)=$C$7)*(YEAR('Bookings Log'!$A$6:$A$505)=$E$7)*('Bookings Log'!$B$6:$B$505=$C$6),ROW('Bookings Log'!$A$6:$A$505)-5),1),"")),"") | E14: =IFERROR(INDEX('Bookings Log'!$F$6:$F$505,IFERROR(SMALL(IF((MONTH('Bookings Log'!$A$6:$A$505)=$C$7)*(YEAR('Bookings Log'!$A$6:$A$505)=$E$7)*('Bookings Log'!$B$6:$B$505=$C$6),ROW('Bookings Log'!$A$6:$A$505)-5),1),""))-INDEX('Bookings Log'!$J$6:$J$505,IFERROR(SMALL(IF((MONTH('Bookings Log'!$A$6:$A$505)=$C$7)*(YEAR('Bookings Log'!$A$6:$A$505)=$E$7)*('Bookings Log'!$B$6:$B$505=$C$6),ROW('Bookings Log'!$A$6:$A$505)-5),1),"")),"") | F14: =IFERROR(INDEX('Bookings Log'!$J$6:$J$505,IFERROR(SMALL(IF((MONTH('Bookings Log'!$A$6:$A$505)=$C$7)*(YEAR('Bookings Log'!$A$6:$A$505)=$E$7)*('Bookings Log'!$B$6:$B$505=$C$6),ROW('Bookings Log'!$A$6:$A$505)-5),1),"")),"") | G14: =IFERROR(INDEX('Bookings Log'!$L$6:$L$505,IFERROR(SMALL(IF((MONTH('Bookings Log'!$A$6:$A$505)=$C$7)*(YEAR('Bookings Log'!$A$6:$A$505)=$E$7)*('Bookings Log'!$B$6:$B$505=$C$6),ROW('Bookings Log'!$A$6:$A$505)-5),1),"")),"")
B15: =IFERROR(INDEX('Bookings Log'!$A$6:$A$505,IFERROR(SMALL(IF((MONTH('Bookings Log'!$A$6:$A$505)=$C$7)*(YEAR('Bookings Log'!$A$6:$A$505)=$E$7)*('Bookings Log'!$B$6:$B$505=$C$6),ROW('Bookings Log'!$A$6:$A$505)-5),2),"")),"") | C15: =IFERROR(INDEX('Bookings Log'!$C$6:$C$505,IFERROR(SMALL(IF((MONTH('Bookings Log'!$A$6:$A$505)=$C$7)*(YEAR('Bookings Log'!$A$6:$A$505)=$E$7)*('Bookings Log'!$B$6:$B$505=$C$6),ROW('Bookings Log'!$A$6:$A$505)-5),2),"")),"") | D15: =IFERROR(INDEX('Bookings Log'!$F$6:$F$505,IFERROR(SMALL(IF((MONTH('Bookings Log'!$A$6:$A$505)=$C$7)*(YEAR('Bookings Log'!$A$6:$A$505)=$E$7)*('Bookings Log'!$B$6:$B$505=$C$6),ROW('Bookings Log'!$A$6:$A$505)-5),2),"")),"") | E15: =IFERROR(INDEX('Bookings Log'!$F$6:$F$505,IFERROR(SMALL(IF((MONTH('Bookings Log'!$A$6:$A$505)=$C$7)*(YEAR('Bookings Log'!$A$6:$A$505)=$E$7)*('Bookings Log'!$B$6:$B$505=$C$6),ROW('Bookings Log'!$A$6:$A$505)-5),2),""))-INDEX('Bookings Log'!$J$6:$J$505,IFERROR(SMALL(IF((MONTH('Bookings Log'!$A$6:$A$505)=$C$7)*(YEAR('Bookings Log'!$A$6:$A$505)=$E$7)*('Bookings Log'!$B$6:$B$505=$C$6),ROW('Bookings Log'!$A$6:$A$505)-5),2),"")),"") | F15: =IFERROR(INDEX('Bookings Log'!$J$6:$J$505,IFERROR(SMALL(IF((MONTH('Bookings Log'!$A$6:$A$505)=$C$7)*(YEAR('Bookings Log'!$A$6:$A$505)=$E$7)*('Bookings Log'!$B$6:$B$505=$C$6),ROW('Bookings Log'!$A$6:$A$505)-5),2),"")),"") | G15: =IFERROR(INDEX('Bookings Log'!$L$6:$L$505,IFERROR(SMALL(IF((MONTH('Bookings Log'!$A$6:$A$505)=$C$7)*(YEAR('Bookings Log'!$A$6:$A$505)=$E$7)*('Bookings Log'!$B$6:$B$505=$C$6),ROW('Bookings Log'!$A$6:$A$505)-5),2),"")),"")
B16: =IFERROR(INDEX('Bookings Log'!$A$6:$A$505,IFERROR(SMALL(IF((MONTH('Bookings Log'!$A$6:$A$505)=$C$7)*(YEAR('Bookings Log'!$A$6:$A$505)=$E$7)*('Bookings Log'!$B$6:$B$505=$C$6),ROW('Bookings Log'!$A$6:$A$505)-5),3),"")),"") | C16: =IFERROR(INDEX('Bookings Log'!$C$6:$C$505,IFERROR(SMALL(IF((MONTH('Bookings Log'!$A$6:$A$505)=$C$7)*(YEAR('Bookings Log'!$A$6:$A$505)=$E$7)*('Bookings Log'!$B$6:$B$505=$C$6),ROW('Bookings Log'!$A$6:$A$505)-5),3),"")),"") | D16: =IFERROR(INDEX('Bookings Log'!$F$6:$F$505,IFERROR(SMALL(IF((MONTH('Bookings Log'!$A$6:$A$505)=$C$7)*(YEAR('Bookings Log'!$A$6:$A$505)=$E$7)*('Bookings Log'!$B$6:$B$505=$C$6),ROW('Bookings Log'!$A$6:$A$505)-5),3),"")),"") | E16: =IFERROR(INDEX('Bookings Log'!$F$6:$F$505,IFERROR(SMALL(IF((MONTH('Bookings Log'!$A$6:$A$505)=$C$7)*(YEAR('Bookings Log'!$A$6:$A$505)=$E$7)*('Bookings Log'!$B$6:$B$505=$C$6),ROW('Bookings Log'!$A$6:$A$505)-5),3),""))-INDEX('Bookings Log'!$J$6:$J$505,IFERROR(SMALL(IF((MONTH('Bookings Log'!$A$6:$A$505)=$C$7)*(YEAR('Bookings Log'!$A$6:$A$505)=$E$7)*('Bookings Log'!$B$6:$B$505=$C$6),ROW('Bookings Log'!$A$6:$A$505)-5),3),"")),"") | F16: =IFERROR(INDEX('Bookings Log'!$J$6:$J$505,IFERROR(SMALL(IF((MONTH('Bookings Log'!$A$6:$A$505)=$C$7)*(YEAR('Bookings Log'!$A$6:$A$505)=$E$7)*('Bookings Log'!$B$6:$B$505=$C$6),ROW('Bookings Log'!$A$6:$A$505)-5),3),"")),"") | G16: =IFERROR(INDEX('Bookings Log'!$L$6:$L$505,IFERROR(SMALL(IF((MONTH('Bookings Log'!$A$6:$A$505)=$C$7)*(YEAR('Bookings Log'!$A$6:$A$505)=$E$7)*('Bookings Log'!$B$6:$B$505=$C$6),ROW('Bookings Log'!$A$6:$A$505)-5),3),"")),"")
B17: =IFERROR(INDEX('Bookings Log'!$A$6:$A$505,IFERROR(SMALL(IF((MONTH('Bookings Log'!$A$6:$A$505)=$C$7)*(YEAR('Bookings Log'!$A$6:$A$505)=$E$7)*('Bookings Log'!$B$6:$B$505=$C$6),ROW('Bookings Log'!$A$6:$A$505)-5),4),"")),"") | C17: =IFERROR(INDEX('Bookings Log'!$C$6:$C$505,IFERROR(SMALL(IF((MONTH('Bookings Log'!$A$6:$A$505)=$C$7)*(YEAR('Bookings Log'!$A$6:$A$505)=$E$7)*('Bookings Log'!$B$6:$B$505=$C$6),ROW('Bookings Log'!$A$6:$A$505)-5),4),"")),"") | D17: =IFERROR(INDEX('Bookings Log'!$F$6:$F$505,IFERROR(SMALL(IF((MONTH('Bookings Log'!$A$6:$A$505)=$C$7)*(YEAR('Bookings Log'!$A$6:$A$505)=$E$7)*('Bookings Log'!$B$6:$B$505=$C$6),ROW('Bookings Log'!$A$6:$A$505)-5),4),"")),"") | E17: =IFERROR(INDEX('Bookings Log'!$F$6:$F$505,IFERROR(SMALL(IF((MONTH('Bookings Log'!$A$6:$A$505)=$C$7)*(YEAR('Bookings Log'!$A$6:$A$505)=$E$7)*('Bookings Log'!$B$6:$B$505=$C$6),ROW('Bookings Log'!$A$6:$A$505)-5),4),""))-INDEX('Bookings Log'!$J$6:$J$505,IFERROR(SMALL(IF((MONTH('Bookings Log'!$A$6:$A$505)=$C$7)*(YEAR('Bookings Log'!$A$6:$A$505)=$E$7)*('Bookings Log'!$B$6:$B$505=$C$6),ROW('Bookings Log'!$A$6:$A$505)-5),4),"")),"") | F17: =IFERROR(INDEX('Bookings Log'!$J$6:$J$505,IFERROR(SMALL(IF((MONTH('Bookings Log'!$A$6:$A$505)=$C$7)*(YEAR('Bookings Log'!$A$6:$A$505)=$E$7)*('Bookings Log'!$B$6:$B$505=$C$6),ROW('Bookings Log'!$A$6:$A$505)-5),4),"")),"") | G17: =IFERROR(INDEX('Bookings Log'!$L$6:$L$505,IFERROR(SMALL(IF((MONTH('Bookings Log'!$A$6:$A$505)=$C$7)*(YEAR('Bookings Log'!$A$6:$A$505)=$E$7)*('Bookings Log'!$B$6:$B$505=$C$6),ROW('Bookings Log'!$A$6:$A$505)-5),4),"")),"")
B18: =IFERROR(INDEX('Bookings Log'!$A$6:$A$505,IFERROR(SMALL(IF((MONTH('Bookings Log'!$A$6:$A$505)=$C$7)*(YEAR('Bookings Log'!$A$6:$A$505)=$E$7)*('Bookings Log'!$B$6:$B$505=$C$6),ROW('Bookings Log'!$A$6:$A$505)-5),5),"")),"") | C18: =IFERROR(INDEX('Bookings Log'!$C$6:$C$505,IFERROR(SMALL(IF((MONTH('Bookings Log'!$A$6:$A$505)=$C$7)*(YEAR('Bookings Log'!$A$6:$A$505)=$E$7)*('Bookings Log'!$B$6:$B$505=$C$6),ROW('Bookings Log'!$A$6:$A$505)-5),5),"")),"") | D18: =IFERROR(INDEX('Bookings Log'!$F$6:$F$505,IFERROR(SMALL(IF((MONTH('Bookings Log'!$A$6:$A$505)=$C$7)*(YEAR('Bookings Log'!$A$6:$A$505)=$E$7)*('Bookings Log'!$B$6:$B$505=$C$6),ROW('Bookings Log'!$A$6:$A$505)-5),5),"")),"") | E18: =IFERROR(INDEX('Bookings Log'!$F$6:$F$505,IFERROR(SMALL(IF((MONTH('Bookings Log'!$A$6:$A$505)=$C$7)*(YEAR('Bookings Log'!$A$6:$A$505)=$E$7)*('Bookings Log'!$B$6:$B$505=$C$6),ROW('Bookings Log'!$A$6:$A$505)-5),5),""))-INDEX('Bookings Log'!$J$6:$J$505,IFERROR(SMALL(IF((MONTH('Bookings Log'!$A$6:$A$505)=$C$7)*(YEAR('Bookings Log'!$A$6:$A$505)=$E$7)*('Bookings Log'!$B$6:$B$505=$C$6),ROW('Bookings Log'!$A$6:$A$505)-5),5),"")),"") | F18: =IFERROR(INDEX('Bookings Log'!$J$6:$J$505,IFERROR(SMALL(IF((MONTH('Bookings Log'!$A$6:$A$505)=$C$7)*(YEAR('Bookings Log'!$A$6:$A$505)=$E$7)*('Bookings Log'!$B$6:$B$505=$C$6),ROW('Bookings Log'!$A$6:$A$505)-5),5),"")),"") | G18: =IFERROR(INDEX('Bookings Log'!$L$6:$L$505,IFERROR(SMALL(IF((MONTH('Bookings Log'!$A$6:$A$505)=$C$7)*(YEAR('Bookings Log'!$A$6:$A$505)=$E$7)*('Bookings Log'!$B$6:$B$505=$C$6),ROW('Bookings Log'!$A$6:$A$505)-5),5),"")),"")
B19: =IFERROR(INDEX('Bookings Log'!$A$6:$A$505,IFERROR(SMALL(IF((MONTH('Bookings Log'!$A$6:$A$505)=$C$7)*(YEAR('Bookings Log'!$A$6:$A$505)=$E$7)*('Bookings Log'!$B$6:$B$505=$C$6),ROW('Bookings Log'!$A$6:$A$505)-5),6),"")),"") | C19: =IFERROR(INDEX('Bookings Log'!$C$6:$C$505,IFERROR(SMALL(IF((MONTH('Bookings Log'!$A$6:$A$505)=$C$7)*(YEAR('Bookings Log'!$A$6:$A$505)=$E$7)*('Bookings Log'!$B$6:$B$505=$C$6),ROW('Bookings Log'!$A$6:$A$505)-5),6),"")),"") | D19: =IFERROR(INDEX('Bookings Log'!$F$6:$F$505,IFERROR(SMALL(IF((MONTH('Bookings Log'!$A$6:$A$505)=$C$7)*(YEAR('Bookings Log'!$A$6:$A$505)=$E$7)*('Bookings Log'!$B$6:$B$505=$C$6),ROW('Bookings Log'!$A$6:$A$505)-5),6),"")),"") | E19: =IFERROR(INDEX('Bookings Log'!$F$6:$F$505,IFERROR(SMALL(IF((MONTH('Bookings Log'!$A$6:$A$505)=$C$7)*(YEAR('Bookings Log'!$A$6:$A$505)=$E$7)*('Bookings Log'!$B$6:$B$505=$C$6),ROW('Bookings Log'!$A$6:$A$505)-5),6),""))-INDEX('Bookings Log'!$J$6:$J$505,IFERROR(SMALL(IF((MONTH('Bookings Log'!$A$6:$A$505)=$C$7)*(YEAR('Bookings Log'!$A$6:$A$505)=$E$7)*('Bookings Log'!$B$6:$B$505=$C$6),ROW('Bookings Log'!$A$6:$A$505)-5),6),"")),"") | F19: =IFERROR(INDEX('Bookings Log'!$J$6:$J$505,IFERROR(SMALL(IF((MONTH('Bookings Log'!$A$6:$A$505)=$C$7)*(YEAR('Bookings Log'!$A$6:$A$505)=$E$7)*('Bookings Log'!$B$6:$B$505=$C$6),ROW('Bookings Log'!$A$6:$A$505)-5),6),"")),"") | G19: =IFERROR(INDEX('Bookings Log'!$L$6:$L$505,IFERROR(SMALL(IF((MONTH('Bookings Log'!$A$6:$A$505)=$C$7)*(YEAR('Bookings Log'!$A$6:$A$505)=$E$7)*('Bookings Log'!$B$6:$B$505=$C$6),ROW('Bookings Log'!$A$6:$A$505)-5),6),"")),"")
B20: =IFERROR(INDEX('Bookings Log'!$A$6:$A$505,IFERROR(SMALL(IF((MONTH('Bookings Log'!$A$6:$A$505)=$C$7)*(YEAR('Bookings Log'!$A$6:$A$505)=$E$7)*('Bookings Log'!$B$6:$B$505=$C$6),ROW('Bookings Log'!$A$6:$A$505)-5),7),"")),"") | C20: =IFERROR(INDEX('Bookings Log'!$C$6:$C$505,IFERROR(SMALL(IF((MONTH('Bookings Log'!$A$6:$A$505)=$C$7)*(YEAR('Bookings Log'!$A$6:$A$505)=$E$7)*('Bookings Log'!$B$6:$B$505=$C$6),ROW('Bookings Log'!$A$6:$A$505)-5),7),"")),"") | D20: =IFERROR(INDEX('Bookings Log'!$F$6:$F$505,IFERROR(SMALL(IF((MONTH('Bookings Log'!$A$6:$A$505)=$C$7)*(YEAR('Bookings Log'!$A$6:$A$505)=$E$7)*('Bookings Log'!$B$6:$B$505=$C$6),ROW('Bookings Log'!$A$6:$A$505)-5),7),"")),"") | E20: =IFERROR(INDEX('Bookings Log'!$F$6:$F$505,IFERROR(SMALL(IF((MONTH('Bookings Log'!$A$6:$A$505)=$C$7)*(YEAR('Bookings Log'!$A$6:$A$505)=$E$7)*('Bookings Log'!$B$6:$B$505=$C$6),ROW('Bookings Log'!$A$6:$A$505)-5),7),""))-INDEX('Bookings Log'!$J$6:$J$505,IFERROR(SMALL(IF((MONTH('Bookings Log'!$A$6:$A$505)=$C$7)*(YEAR('Bookings Log'!$A$6:$A$505)=$E$7)*('Bookings Log'!$B$6:$B$505=$C$6),ROW('Bookings Log'!$A$6:$A$505)-5),7),"")),"") | F20: =IFERROR(INDEX('Bookings Log'!$J$6:$J$505,IFERROR(SMALL(IF((MONTH('Bookings Log'!$A$6:$A$505)=$C$7)*(YEAR('Bookings Log'!$A$6:$A$505)=$E$7)*('Bookings Log'!$B$6:$B$505=$C$6),ROW('Bookings Log'!$A$6:$A$505)-5),7),"")),"") | G20: =IFERROR(INDEX('Bookings Log'!$L$6:$L$505,IFERROR(SMALL(IF((MONTH('Bookings Log'!$A$6:$A$505)=$C$7)*(YEAR('Bookings Log'!$A$6:$A$505)=$E$7)*('Bookings Log'!$B$6:$B$505=$C$6),ROW('Bookings Log'!$A$6:$A$505)-5),7),"")),"")
B21: =IFERROR(INDEX('Bookings Log'!$A$6:$A$505,IFERROR(SMALL(IF((MONTH('Bookings Log'!$A$6:$A$505)=$C$7)*(YEAR('Bookings Log'!$A$6:$A$505)=$E$7)*('Bookings Log'!$B$6:$B$505=$C$6),ROW('Bookings Log'!$A$6:$A$505)-5),8),"")),"") | C21: =IFERROR(INDEX('Bookings Log'!$C$6:$C$505,IFERROR(SMALL(IF((MONTH('Bookings Log'!$A$6:$A$505)=$C$7)*(YEAR('Bookings Log'!$A$6:$A$505)=$E$7)*('Bookings Log'!$B$6:$B$505=$C$6),ROW('Bookings Log'!$A$6:$A$505)-5),8),"")),"") | D21: =IFERROR(INDEX('Bookings Log'!$F$6:$F$505,IFERROR(SMALL(IF((MONTH('Bookings Log'!$A$6:$A$505)=$C$7)*(YEAR('Bookings Log'!$A$6:$A$505)=$E$7)*('Bookings Log'!$B$6:$B$505=$C$6),ROW('Bookings Log'!$A$6:$A$505)-5),8),"")),"") | E21: =IFERROR(INDEX('Bookings Log'!$F$6:$F$505,IFERROR(SMALL(IF((MONTH('Bookings Log'!$A$6:$A$505)=$C$7)*(YEAR('Bookings Log'!$A$6:$A$505)=$E$7)*('Bookings Log'!$B$6:$B$505=$C$6),ROW('Bookings Log'!$A$6:$A$505)-5),8),""))-INDEX('Bookings Log'!$J$6:$J$505,IFERROR(SMALL(IF((MONTH('Bookings Log'!$A$6:$A$505)=$C$7)*(YEAR('Bookings Log'!$A$6:$A$505)=$E$7)*('Bookings Log'!$B$6:$B$505=$C$6),ROW('Bookings Log'!$A$6:$A$505)-5),8),"")),"") | F21: =IFERROR(INDEX('Bookings Log'!$J$6:$J$505,IFERROR(SMALL(IF((MONTH('Bookings Log'!$A$6:$A$505)=$C$7)*(YEAR('Bookings Log'!$A$6:$A$505)=$E$7)*('Bookings Log'!$B$6:$B$505=$C$6),ROW('Bookings Log'!$A$6:$A$505)-5),8),"")),"") | G21: =IFERROR(INDEX('Bookings Log'!$L$6:$L$505,IFERROR(SMALL(IF((MONTH('Bookings Log'!$A$6:$A$505)=$C$7)*(YEAR('Bookings Log'!$A$6:$A$505)=$E$7)*('Bookings Log'!$B$6:$B$505=$C$6),ROW('Bookings Log'!$A$6:$A$505)-5),8),"")),"")
B22: =IFERROR(INDEX('Bookings Log'!$A$6:$A$505,IFERROR(SMALL(IF((MONTH('Bookings Log'!$A$6:$A$505)=$C$7)*(YEAR('Bookings Log'!$A$6:$A$505)=$E$7)*('Bookings Log'!$B$6:$B$505=$C$6),ROW('Bookings Log'!$A$6:$A$505)-5),9),"")),"") | C22: =IFERROR(INDEX('Bookings Log'!$C$6:$C$505,IFERROR(SMALL(IF((MONTH('Bookings Log'!$A$6:$A$505)=$C$7)*(YEAR('Bookings Log'!$A$6:$A$505)=$E$7)*('Bookings Log'!$B$6:$B$505=$C$6),ROW('Bookings Log'!$A$6:$A$505)-5),9),"")),"") | D22: =IFERROR(INDEX('Bookings Log'!$F$6:$F$505,IFERROR(SMALL(IF((MONTH('Bookings Log'!$A$6:$A$505)=$C$7)*(YEAR('Bookings Log'!$A$6:$A$505)=$E$7)*('Bookings Log'!$B$6:$B$505=$C$6),ROW('Bookings Log'!$A$6:$A$505)-5),9),"")),"") | E22: =IFERROR(INDEX('Bookings Log'!$F$6:$F$505,IFERROR(SMALL(IF((MONTH('Bookings Log'!$A$6:$A$505)=$C$7)*(YEAR('Bookings Log'!$A$6:$A$505)=$E$7)*('Bookings Log'!$B$6:$B$505=$C$6),ROW('Bookings Log'!$A$6:$A$505)-5),9),""))-INDEX('Bookings Log'!$J$6:$J$505,IFERROR(SMALL(IF((MONTH('Bookings Log'!$A$6:$A$505)=$C$7)*(YEAR('Bookings Log'!$A$6:$A$505)=$E$7)*('Bookings Log'!$B$6:$B$505=$C$6),ROW('Bookings Log'!$A$6:$A$505)-5),9),"")),"") | F22: =IFERROR(INDEX('Bookings Log'!$J$6:$J$505,IFERROR(SMALL(IF((MONTH('Bookings Log'!$A$6:$A$505)=$C$7)*(YEAR('Bookings Log'!$A$6:$A$505)=$E$7)*('Bookings Log'!$B$6:$B$505=$C$6),ROW('Bookings Log'!$A$6:$A$505)-5),9),"")),"") | G22: =IFERROR(INDEX('Bookings Log'!$L$6:$L$505,IFERROR(SMALL(IF((MONTH('Bookings Log'!$A$6:$A$505)=$C$7)*(YEAR('Bookings Log'!$A$6:$A$505)=$E$7)*('Bookings Log'!$B$6:$B$505=$C$6),ROW('Bookings Log'!$A$6:$A$505)-5),9),"")),"")
B23: =IFERROR(INDEX('Bookings Log'!$A$6:$A$505,IFERROR(SMALL(IF((MONTH('Bookings Log'!$A$6:$A$505)=$C$7)*(YEAR('Bookings Log'!$A$6:$A$505)=$E$7)*('Bookings Log'!$B$6:$B$505=$C$6),ROW('Bookings Log'!$A$6:$A$505)-5),10),"")),"") | C23: =IFERROR(INDEX('Bookings Log'!$C$6:$C$505,IFERROR(SMALL(IF((MONTH('Bookings Log'!$A$6:$A$505)=$C$7)*(YEAR('Bookings Log'!$A$6:$A$505)=$E$7)*('Bookings Log'!$B$6:$B$505=$C$6),ROW('Bookings Log'!$A$6:$A$505)-5),10),"")),"") | D23: =IFERROR(INDEX('Bookings Log'!$F$6:$F$505,IFERROR(SMALL(IF((MONTH('Bookings Log'!$A$6:$A$505)=$C$7)*(YEAR('Bookings Log'!$A$6:$A$505)=$E$7)*('Bookings Log'!$B$6:$B$505=$C$6),ROW('Bookings Log'!$A$6:$A$505)-5),10),"")),"") | E23: =IFERROR(INDEX('Bookings Log'!$F$6:$F$505,IFERROR(SMALL(IF((MONTH('Bookings Log'!$A$6:$A$505)=$C$7)*(YEAR('Bookings Log'!$A$6:$A$505)=$E$7)*('Bookings Log'!$B$6:$B$505=$C$6),ROW('Bookings Log'!$A$6:$A$505)-5),10),""))-INDEX('Bookings Log'!$J$6:$J$505,IFERROR(SMALL(IF((MONTH('Bookings Log'!$A$6:$A$505)=$C$7)*(YEAR('Bookings Log'!$A$6:$A$505)=$E$7)*('Bookings Log'!$B$6:$B$505=$C$6),ROW('Bookings Log'!$A$6:$A$505)-5),10),"")),"") | F23: =IFERROR(INDEX('Bookings Log'!$J$6:$J$505,IFERROR(SMALL(IF((MONTH('Bookings Log'!$A$6:$A$505)=$C$7)*(YEAR('Bookings Log'!$A$6:$A$505)=$E$7)*('Bookings Log'!$B$6:$B$505=$C$6),ROW('Bookings Log'!$A$6:$A$505)-5),10),"")),"") | G23: =IFERROR(INDEX('Bookings Log'!$L$6:$L$505,IFERROR(SMALL(IF((MONTH('Bookings Log'!$A$6:$A$505)=$C$7)*(YEAR('Bookings Log'!$A$6:$A$505)=$E$7)*('Bookings Log'!$B$6:$B$505=$C$6),ROW('Bookings Log'!$A$6:$A$505)-5),10),"")),"")
B24: =IFERROR(INDEX('Bookings Log'!$A$6:$A$505,IFERROR(SMALL(IF((MONTH('Bookings Log'!$A$6:$A$505)=$C$7)*(YEAR('Bookings Log'!$A$6:$A$505)=$E$7)*('Bookings Log'!$B$6:$B$505=$C$6),ROW('Bookings Log'!$A$6:$A$505)-5),11),"")),"") | C24: =IFERROR(INDEX('Bookings Log'!$C$6:$C$505,IFERROR(SMALL(IF((MONTH('Bookings Log'!$A$6:$A$505)=$C$7)*(YEAR('Bookings Log'!$A$6:$A$505)=$E$7)*('Bookings Log'!$B$6:$B$505=$C$6),ROW('Bookings Log'!$A$6:$A$505)-5),11),"")),"") | D24: =IFERROR(INDEX('Bookings Log'!$F$6:$F$505,IFERROR(SMALL(IF((MONTH('Bookings Log'!$A$6:$A$505)=$C$7)*(YEAR('Bookings Log'!$A$6:$A$505)=$E$7)*('Bookings Log'!$B$6:$B$505=$C$6),ROW('Bookings Log'!$A$6:$A$505)-5),11),"")),"") | E24: =IFERROR(INDEX('Bookings Log'!$F$6:$F$505,IFERROR(SMALL(IF((MONTH('Bookings Log'!$A$6:$A$505)=$C$7)*(YEAR('Bookings Log'!$A$6:$A$505)=$E$7)*('Bookings Log'!$B$6:$B$505=$C$6),ROW('Bookings Log'!$A$6:$A$505)-5),11),""))-INDEX('Bookings Log'!$J$6:$J$505,IFERROR(SMALL(IF((MONTH('Bookings Log'!$A$6:$A$505)=$C$7)*(YEAR('Bookings Log'!$A$6:$A$505)=$E$7)*('Bookings Log'!$B$6:$B$505=$C$6),ROW('Bookings Log'!$A$6:$A$505)-5),11),"")),"") | F24: =IFERROR(INDEX('Bookings Log'!$J$6:$J$505,IFERROR(SMALL(IF((MONTH('Bookings Log'!$A$6:$A$505)=$C$7)*(YEAR('Bookings Log'!$A$6:$A$505)=$E$7)*('Bookings Log'!$B$6:$B$505=$C$6),ROW('Bookings Log'!$A$6:$A$505)-5),11),"")),"") | G24: =IFERROR(INDEX('Bookings Log'!$L$6:$L$505,IFERROR(SMALL(IF((MONTH('Bookings Log'!$A$6:$A$505)=$C$7)*(YEAR('Bookings Log'!$A$6:$A$505)=$E$7)*('Bookings Log'!$B$6:$B$505=$C$6),ROW('Bookings Log'!$A$6:$A$505)-5),11),"")),"")
B25: =IFERROR(INDEX('Bookings Log'!$A$6:$A$505,IFERROR(SMALL(IF((MONTH('Bookings Log'!$A$6:$A$505)=$C$7)*(YEAR('Bookings Log'!$A$6:$A$505)=$E$7)*('Bookings Log'!$B$6:$B$505=$C$6),ROW('Bookings Log'!$A$6:$A$505)-5),12),"")),"") | C25: =IFERROR(INDEX('Bookings Log'!$C$6:$C$505,IFERROR(SMALL(IF((MONTH('Bookings Log'!$A$6:$A$505)=$C$7)*(YEAR('Bookings Log'!$A$6:$A$505)=$E$7)*('Bookings Log'!$B$6:$B$505=$C$6),ROW('Bookings Log'!$A$6:$A$505)-5),12),"")),"") | D25: =IFERROR(INDEX('Bookings Log'!$F$6:$F$505,IFERROR(SMALL(IF((MONTH('Bookings Log'!$A$6:$A$505)=$C$7)*(YEAR('Bookings Log'!$A$6:$A$505)=$E$7)*('Bookings Log'!$B$6:$B$505=$C$6),ROW('Bookings Log'!$A$6:$A$505)-5),12),"")),"") | E25: =IFERROR(INDEX('Bookings Log'!$F$6:$F$505,IFERROR(SMALL(IF((MONTH('Bookings Log'!$A$6:$A$505)=$C$7)*(YEAR('Bookings Log'!$A$6:$A$505)=$E$7)*('Bookings Log'!$B$6:$B$505=$C$6),ROW('Bookings Log'!$A$6:$A$505)-5),12),""))-INDEX('Bookings Log'!$J$6:$J$505,IFERROR(SMALL(IF((MONTH('Bookings Log'!$A$6:$A$505)=$C$7)*(YEAR('Bookings Log'!$A$6:$A$505)=$E$7)*('Bookings Log'!$B$6:$B$505=$C$6),ROW('Bookings Log'!$A$6:$A$505)-5),12),"")),"") | F25: =IFERROR(INDEX('Bookings Log'!$J$6:$J$505,IFERROR(SMALL(IF((MONTH('Bookings Log'!$A$6:$A$505)=$C$7)*(YEAR('Bookings Log'!$A$6:$A$505)=$E$7)*('Bookings Log'!$B$6:$B$505=$C$6),ROW('Bookings Log'!$A$6:$A$505)-5),12),"")),"") | G25: =IFERROR(INDEX('Bookings Log'!$L$6:$L$505,IFERROR(SMALL(IF((MONTH('Bookings Log'!$A$6:$A$505)=$C$7)*(YEAR('Bookings Log'!$A$6:$A$505)=$E$7)*('Bookings Log'!$B$6:$B$505=$C$6),ROW('Bookings Log'!$A$6:$A$505)-5),12),"")),"")
B26: =IFERROR(INDEX('Bookings Log'!$A$6:$A$505,IFERROR(SMALL(IF((MONTH('Bookings Log'!$A$6:$A$505)=$C$7)*(YEAR('Bookings Log'!$A$6:$A$505)=$E$7)*('Bookings Log'!$B$6:$B$505=$C$6),ROW('Bookings Log'!$A$6:$A$505)-5),13),"")),"") | C26: =IFERROR(INDEX('Bookings Log'!$C$6:$C$505,IFERROR(SMALL(IF((MONTH('Bookings Log'!$A$6:$A$505)=$C$7)*(YEAR('Bookings Log'!$A$6:$A$505)=$E$7)*('Bookings Log'!$B$6:$B$505=$C$6),ROW('Bookings Log'!$A$6:$A$505)-5),13),"")),"") | D26: =IFERROR(INDEX('Bookings Log'!$F$6:$F$505,IFERROR(SMALL(IF((MONTH('Bookings Log'!$A$6:$A$505)=$C$7)*(YEAR('Bookings Log'!$A$6:$A$505)=$E$7)*('Bookings Log'!$B$6:$B$505=$C$6),ROW('Bookings Log'!$A$6:$A$505)-5),13),"")),"") | E26: =IFERROR(INDEX('Bookings Log'!$F$6:$F$505,IFERROR(SMALL(IF((MONTH('Bookings Log'!$A$6:$A$505)=$C$7)*(YEAR('Bookings Log'!$A$6:$A$505)=$E$7)*('Bookings Log'!$B$6:$B$505=$C$6),ROW('Bookings Log'!$A$6:$A$505)-5),13),""))-INDEX('Bookings Log'!$J$6:$J$505,IFERROR(SMALL(IF((MONTH('Bookings Log'!$A$6:$A$505)=$C$7)*(YEAR('Bookings Log'!$A$6:$A$505)=$E$7)*('Bookings Log'!$B$6:$B$505=$C$6),ROW('Bookings Log'!$A$6:$A$505)-5),13),"")),"") | F26: =IFERROR(INDEX('Bookings Log'!$J$6:$J$505,IFERROR(SMALL(IF((MONTH('Bookings Log'!$A$6:$A$505)=$C$7)*(YEAR('Bookings Log'!$A$6:$A$505)=$E$7)*('Bookings Log'!$B$6:$B$505=$C$6),ROW('Bookings Log'!$A$6:$A$505)-5),13),"")),"") | G26: =IFERROR(INDEX('Bookings Log'!$L$6:$L$505,IFERROR(SMALL(IF((MONTH('Bookings Log'!$A$6:$A$505)=$C$7)*(YEAR('Bookings Log'!$A$6:$A$505)=$E$7)*('Bookings Log'!$B$6:$B$505=$C$6),ROW('Bookings Log'!$A$6:$A$505)-5),13),"")),"")
B27: =IFERROR(INDEX('Bookings Log'!$A$6:$A$505,IFERROR(SMALL(IF((MONTH('Bookings Log'!$A$6:$A$505)=$C$7)*(YEAR('Bookings Log'!$A$6:$A$505)=$E$7)*('Bookings Log'!$B$6:$B$505=$C$6),ROW('Bookings Log'!$A$6:$A$505)-5),14),"")),"") | C27: =IFERROR(INDEX('Bookings Log'!$C$6:$C$505,IFERROR(SMALL(IF((MONTH('Bookings Log'!$A$6:$A$505)=$C$7)*(YEAR('Bookings Log'!$A$6:$A$505)=$E$7)*('Bookings Log'!$B$6:$B$505=$C$6),ROW('Bookings Log'!$A$6:$A$505)-5),14),"")),"") | D27: =IFERROR(INDEX('Bookings Log'!$F$6:$F$505,IFERROR(SMALL(IF((MONTH('Bookings Log'!$A$6:$A$505)=$C$7)*(YEAR('Bookings Log'!$A$6:$A$505)=$E$7)*('Bookings Log'!$B$6:$B$505=$C$6),ROW('Bookings Log'!$A$6:$A$505)-5),14),"")),"") | E27: =IFERROR(INDEX('Bookings Log'!$F$6:$F$505,IFERROR(SMALL(IF((MONTH('Bookings Log'!$A$6:$A$505)=$C$7)*(YEAR('Bookings Log'!$A$6:$A$505)=$E$7)*('Bookings Log'!$B$6:$B$505=$C$6),ROW('Bookings Log'!$A$6:$A$505)-5),14),""))-INDEX('Bookings Log'!$J$6:$J$505,IFERROR(SMALL(IF((MONTH('Bookings Log'!$A$6:$A$505)=$C$7)*(YEAR('Bookings Log'!$A$6:$A$505)=$E$7)*('Bookings Log'!$B$6:$B$505=$C$6),ROW('Bookings Log'!$A$6:$A$505)-5),14),"")),"") | F27: =IFERROR(INDEX('Bookings Log'!$J$6:$J$505,IFERROR(SMALL(IF((MONTH('Bookings Log'!$A$6:$A$505)=$C$7)*(YEAR('Bookings Log'!$A$6:$A$505)=$E$7)*('Bookings Log'!$B$6:$B$505=$C$6),ROW('Bookings Log'!$A$6:$A$505)-5),14),"")),"") | G27: =IFERROR(INDEX('Bookings Log'!$L$6:$L$505,IFERROR(SMALL(IF((MONTH('Bookings Log'!$A$6:$A$505)=$C$7)*(YEAR('Bookings Log'!$A$6:$A$505)=$E$7)*('Bookings Log'!$B$6:$B$505=$C$6),ROW('Bookings Log'!$A$6:$A$505)-5),14),"")),"")
B28: =IFERROR(INDEX('Bookings Log'!$A$6:$A$505,IFERROR(SMALL(IF((MONTH('Bookings Log'!$A$6:$A$505)=$C$7)*(YEAR('Bookings Log'!$A$6:$A$505)=$E$7)*('Bookings Log'!$B$6:$B$505=$C$6),ROW('Bookings Log'!$A$6:$A$505)-5),15),"")),"") | C28: =IFERROR(INDEX('Bookings Log'!$C$6:$C$505,IFERROR(SMALL(IF((MONTH('Bookings Log'!$A$6:$A$505)=$C$7)*(YEAR('Bookings Log'!$A$6:$A$505)=$E$7)*('Bookings Log'!$B$6:$B$505=$C$6),ROW('Bookings Log'!$A$6:$A$505)-5),15),"")),"") | D28: =IFERROR(INDEX('Bookings Log'!$F$6:$F$505,IFERROR(SMALL(IF((MONTH('Bookings Log'!$A$6:$A$505)=$C$7)*(YEAR('Bookings Log'!$A$6:$A$505)=$E$7)*('Bookings Log'!$B$6:$B$505=$C$6),ROW('Bookings Log'!$A$6:$A$505)-5),15),"")),"") | E28: =IFERROR(INDEX('Bookings Log'!$F$6:$F$505,IFERROR(SMALL(IF((MONTH('Bookings Log'!$A$6:$A$505)=$C$7)*(YEAR('Bookings Log'!$A$6:$A$505)=$E$7)*('Bookings Log'!$B$6:$B$505=$C$6),ROW('Bookings Log'!$A$6:$A$505)-5),15),""))-INDEX('Bookings Log'!$J$6:$J$505,IFERROR(SMALL(IF((MONTH('Bookings Log'!$A$6:$A$505)=$C$7)*(YEAR('Bookings Log'!$A$6:$A$505)=$E$7)*('Bookings Log'!$B$6:$B$505=$C$6),ROW('Bookings Log'!$A$6:$A$505)-5),15),"")),"") | F28: =IFERROR(INDEX('Bookings Log'!$J$6:$J$505,IFERROR(SMALL(IF((MONTH('Bookings Log'!$A$6:$A$505)=$C$7)*(YEAR('Bookings Log'!$A$6:$A$505)=$E$7)*('Bookings Log'!$B$6:$B$505=$C$6),ROW('Bookings Log'!$A$6:$A$505)-5),15),"")),"") | G28: =IFERROR(INDEX('Bookings Log'!$L$6:$L$505,IFERROR(SMALL(IF((MONTH('Bookings Log'!$A$6:$A$505)=$C$7)*(YEAR('Bookings Log'!$A$6:$A$505)=$E$7)*('Bookings Log'!$B$6:$B$505=$C$6),ROW('Bookings Log'!$A$6:$A$505)-5),15),"")),"")
B30: Subtotals: | D30: =SUMPRODUCT((MONTH('Bookings Log'!$A$6:$A$505)=$C$7)*(YEAR('Bookings Log'!$A$6:$A$505)=$E$7)*('Bookings Log'!$B$6:$B$505=$C$6)*'Bookings Log'!$F$6:$F$505) | E30: =D30-F30 | F30: =SUMPRODUCT((MONTH('Bookings Log'!$A$6:$A$505)=$C$7)*(YEAR('Bookings Log'!$A$6:$A$505)=$E$7)*('Bookings Log'!$B$6:$B$505=$C$6)*'Bookings Log'!$J$6:$J$505) | G30: =SUMPRODUCT((MONTH('Bookings Log'!$A$6:$A$505)=$C$7)*(YEAR('Bookings Log'!$A$6:$A$505)=$E$7)*('Bookings Log'!$B$6:$B$505=$C$6)*'Bookings Log'!$L$6:$L$505)
B32: COMMISSION DETAIL
B33: ="Per agreement: "&IFERROR(VLOOKUP($C$6,'Co-Host Agreements'!$A$6:$K$20,4,FALSE),"")&" | "&TEXT(IFERROR(VLOOKUP($C$6,'Co-Host Agreements'!$A$6:$K$20,5,FALSE),0),"0.0%")&" + $"&TEXT(IFERROR(VLOOKUP($C$6,'Co-Host Agreements'!$A$6:$K$20,6,FALSE),0),"0")&" flat per booking"
B36: TOTAL TO CO-HOST | G36: =G30
B37: TOTAL TO OWNER | G37: =F30-G30
B39: PAYMENT INSTRUCTIONS
B40: Please remit the TOTAL TO CO-HOST amount above via your preferred payment method by the 10th of the following month. Receipts and supporting documentation available on request.
B43: ="Generated "&TEXT(TODAY(),"mmmm d, yyyy")

Sheet Year-End Summary
A2: =HYPERLINK("#'Monthly Statements'!A1", "← BACK") | D2: YEAR-END SUMMARY | J2: =HYPERLINK("#'Settings'!A1", "NEXT →")
A4: Per-property totals for the active tax year (set on Settings B5). Properties at >= 1099 threshold flag for 1099-NEC issuance.
A5: Tax year (from Settings): | B5: =Settings!B5
A7: Property | B7: Owner | C7: Bookings | D7: Total gross | E7: Total deductions | F7: Total NET | G7: Commission paid | H7: 1099-NEC required?
A8: =IF('Co-Host Agreements'!A6="","",'Co-Host Agreements'!A6) | B8: =IF(A8="","",'Co-Host Agreements'!B6) | C8: =IF(A8="","",SUMPRODUCT((YEAR('Bookings Log'!$A$6:$A$505)=$B$5)*('Bookings Log'!$B$6:$B$505=A8)*1)) | D8: =IF(A8="","",SUMPRODUCT((YEAR('Bookings Log'!$A$6:$A$505)=$B$5)*('Bookings Log'!$B$6:$B$505=A8)*'Bookings Log'!$F$6:$F$505)) | E8: =IF(A8="","",D8-F8) | F8: =IF(A8="","",SUMPRODUCT((YEAR('Bookings Log'!$A$6:$A$505)=$B$5)*('Bookings Log'!$B$6:$B$505=A8)*'Bookings Log'!$J$6:$J$505)) | G8: =IF(A8="","",SUMPRODUCT((YEAR('Bookings Log'!$A$6:$A$505)=$B$5)*('Bookings Log'!$B$6:$B$505=A8)*'Bookings Log'!$L$6:$L$505)) | H8: =IF(A8="","",IF(G8>=Settings!$B$29,"Yes","No"))
A9: =IF('Co-Host Agreements'!A7="","",'Co-Host Agreements'!A7) | B9: =IF(A9="","",'Co-Host Agreements'!B7) | C9: =IF(A9="","",SUMPRODUCT((YEAR('Bookings Log'!$A$6:$A$505)=$B$5)*('Bookings Log'!$B$6:$B$505=A9)*1)) | D9: =IF(A9="","",SUMPRODUCT((YEAR('Bookings Log'!$A$6:$A$505)=$B$5)*('Bookings Log'!$B$6:$B$505=A9)*'Bookings Log'!$F$6:$F$505)) | E9: =IF(A9="","",D9-F9) | F9: =IF(A9="","",SUMPRODUCT((YEAR('Bookings Log'!$A$6:$A$505)=$B$5)*('Bookings Log'!$B$6:$B$505=A9)*'Bookings Log'!$J$6:$J$505)) | G9: =IF(A9="","",SUMPRODUCT((YEAR('Bookings Log'!$A$6:$A$505)=$B$5)*('Bookings Log'!$B$6:$B$505=A9)*'Bookings Log'!$L$6:$L$505)) | H9: =IF(A9="","",IF(G9>=Settings!$B$29,"Yes","No"))
A10: =IF('Co-Host Agreements'!A8="","",'Co-Host Agreements'!A8) | B10: =IF(A10="","",'Co-Host Agreements'!B8) | C10: =IF(A10="","",SUMPRODUCT((YEAR('Bookings Log'!$A$6:$A$505)=$B$5)*('Bookings Log'!$B$6:$B$505=A10)*1)) | D10: =IF(A10="","",SUMPRODUCT((YEAR('Bookings Log'!$A$6:$A$505)=$B$5)*('Bookings Log'!$B$6:$B$505=A10)*'Bookings Log'!$F$6:$F$505)) | E10: =IF(A10="","",D10-F10) | F10: =IF(A10="","",SUMPRODUCT((YEAR('Bookings Log'!$A$6:$A$505)=$B$5)*('Bookings Log'!$B$6:$B$505=A10)*'Bookings Log'!$J$6:$J$505)) | G10: =IF(A10="","",SUMPRODUCT((YEAR('Bookings Log'!$A$6:$A$505)=$B$5)*('Bookings Log'!$B$6:$B$505=A10)*'Bookings Log'!$L$6:$L$505)) | H10: =IF(A10="","",IF(G10>=Settings!$B$29,"Yes","No"))
A11: =IF('Co-Host Agreements'!A9="","",'Co-Host Agreements'!A9) | B11: =IF(A11="","",'Co-Host Agreements'!B9) | C11: =IF(A11="","",SUMPRODUCT((YEAR('Bookings Log'!$A$6:$A$505)=$B$5)*('Bookings Log'!$B$6:$B$505=A11)*1)) | D11: =IF(A11="","",SUMPRODUCT((YEAR('Bookings Log'!$A$6:$A$505)=$B$5)*('Bookings Log'!$B$6:$B$505=A11)*'Bookings Log'!$F$6:$F$505)) | E11: =IF(A11="","",D11-F11) | F11: =IF(A11="","",SUMPRODUCT((YEAR('Bookings Log'!$A$6:$A$505)=$B$5)*('Bookings Log'!$B$6:$B$505=A11)*'Bookings Log'!$J$6:$J$505)) | G11: =IF(A11="","",SUMPRODUCT((YEAR('Bookings Log'!$A$6:$A$505)=$B$5)*('Bookings Log'!$B$6:$B$505=A11)*'Bookings Log'!$L$6:$L$505)) | H11: =IF(A11="","",IF(G11>=Settings!$B$29,"Yes","No"))
