Workbook

Sheet Start
A2: The STR Ledger
A4: Dynamic Pricing Calculator
A5: Season, day, event — a suggested rate for every night.
A7: REV-002 · v1.0 · BLANK
A11: =IF(Settings!B5="","(set property on Settings tab)",Settings!B5)
A13: ="PRICING YEAR "&Settings!B7
A15: AVG NIGHTLY | D15: PEAK NIGHTLY | G15: LOW NIGHTLY | J15: REVPAR PROJ
A16: =IFERROR(AVERAGE('365-Day Calendar'!I6:I370),0) | D16: =IFERROR(MAX('365-Day Calendar'!I6:I370),0) | G16: =IFERROR(MIN('365-Day Calendar'!I6:I370),0) | J16: =IFERROR(AVERAGE('365-Day Calendar'!I6:I370)*Inputs!C13,0)
A20: RevPAR projection = average suggested nightly × occupancy assumption (set on Inputs).
A22: Re-run when base rate, peak season, or event calendar changes.
A25: =HYPERLINK("#'Inputs'!A1", "Inputs") | D25: =HYPERLINK("#'365-Day Calendar'!A1", "365-Day Calendar") | G25: =HYPERLINK("#'Monthly Summary'!A1", "Monthly Summary") | J25: =HYPERLINK("#'Settings'!A1", "Settings")
A30: Pricing across the portfolio? Get the Pricing Bundle at thestrledger.com/pricing — $97.
A33: Questions? hello@thestrledger.com
A34: REV-002 · v1.0 · BLANK · Free updates forever

Sheet Inputs
A2: =HYPERLINK("#'Settings'!A1", "← BACK") | D2: INPUTS | J2: =HYPERLINK("#'365-Day Calendar'!A1", "NEXT →")
A4: Base rate, four seasons, day-of-week multipliers, and twelve event slots. Suggested rate = Base × Season × DOW × Event.
A6: BASE RATE + OCCUPANCY ASSUMPTION
B7: Base nightly rate ($): | E7: The 'normal night' rate before any multiplier
B13: Annual occupancy assumption (%): | E13: Used for RevPAR projection on Start tab + Monthly Summary
A15: SEASON DEFINITIONS (4 seasons, edit dates / mult)
B16: Season | C16: Start date | D16: End date | E16: Multiplier | G16: Notes
F17: Slowest months — heat with discounts
F18: Wake-up demand — keep at neutral
F19: Highest demand window of the year
F20: Cooling demand but holds value
A22: DAY-OF-WEEK MULTIPLIERS (Weekday code matches WEEKDAY(date,2))
B23: Day | C23: Weekday code | D23: Multiplier
C24: 1
C25: 2
C26: 3
C27: 4
C28: 5
C29: 6
C30: 7
A32: EVENT LIFTS (12 slots — add holidays, festivals, concerts)
B33: Date | C33: Event name | D33: Multiplier | F33: Notes
A47: Note: events override season + DOW. If two events fall on the same date, the calendar uses the FIRST match in the list — order events by importance. Blank rows are ignored.
A52: Questions? hello@thestrledger.com
A53: REV-002 · Inputs

Sheet 365-Day Calendar
A2: =HYPERLINK("#'Inputs'!A1", "← BACK") | D2: 365-DAY CALENDAR | J2: =HYPERLINK("#'Monthly Summary'!A1", "NEXT →")
A4: One row per night. Edit the override column if you want to lock a rate; everything else recomputes from Inputs.
A5: Date | B5: Day | C5: Season | D5: Season× | E5: DOW× | F5: Event× | G5: Suggested | H5: Override | I5: Final rate
A6: =DATE(Settings!$B$7,1,1)+0 | B6: =TEXT(A6,"ddd") | C6: =IFERROR(INDEX(Inputs!$B$17:$B$20,MATCH(1,(A6>=Inputs!$C$17:$C$20)*(A6<=Inputs!$D$17:$D$20),0)),"") | D6: =IFERROR(INDEX(Inputs!$E$17:$E$20,MATCH(1,(A6>=Inputs!$C$17:$C$20)*(A6<=Inputs!$D$17:$D$20),0)),1) | E6: =INDEX(Inputs!$D$24:$D$30,WEEKDAY(A6,2)) | F6: =IFERROR(INDEX(Inputs!$D$34:$D$45,MATCH(A6,Inputs!$B$34:$B$45,0)),1) | G6: =Inputs!$C$7*D6*E6*F6 | I6: =IF(H6<>"",H6,G6)
A7: =DATE(Settings!$B$7,1,1)+1 | B7: =TEXT(A7,"ddd") | C7: =IFERROR(INDEX(Inputs!$B$17:$B$20,MATCH(1,(A7>=Inputs!$C$17:$C$20)*(A7<=Inputs!$D$17:$D$20),0)),"") | D7: =IFERROR(INDEX(Inputs!$E$17:$E$20,MATCH(1,(A7>=Inputs!$C$17:$C$20)*(A7<=Inputs!$D$17:$D$20),0)),1) | E7: =INDEX(Inputs!$D$24:$D$30,WEEKDAY(A7,2)) | F7: =IFERROR(INDEX(Inputs!$D$34:$D$45,MATCH(A7,Inputs!$B$34:$B$45,0)),1) | G7: =Inputs!$C$7*D7*E7*F7 | I7: =IF(H7<>"",H7,G7)
A8: =DATE(Settings!$B$7,1,1)+2 | B8: =TEXT(A8,"ddd") | C8: =IFERROR(INDEX(Inputs!$B$17:$B$20,MATCH(1,(A8>=Inputs!$C$17:$C$20)*(A8<=Inputs!$D$17:$D$20),0)),"") | D8: =IFERROR(INDEX(Inputs!$E$17:$E$20,MATCH(1,(A8>=Inputs!$C$17:$C$20)*(A8<=Inputs!$D$17:$D$20),0)),1) | E8: =INDEX(Inputs!$D$24:$D$30,WEEKDAY(A8,2)) | F8: =IFERROR(INDEX(Inputs!$D$34:$D$45,MATCH(A8,Inputs!$B$34:$B$45,0)),1) | G8: =Inputs!$C$7*D8*E8*F8 | I8: =IF(H8<>"",H8,G8)
A9: =DATE(Settings!$B$7,1,1)+3 | B9: =TEXT(A9,"ddd") | C9: =IFERROR(INDEX(Inputs!$B$17:$B$20,MATCH(1,(A9>=Inputs!$C$17:$C$20)*(A9<=Inputs!$D$17:$D$20),0)),"") | D9: =IFERROR(INDEX(Inputs!$E$17:$E$20,MATCH(1,(A9>=Inputs!$C$17:$C$20)*(A9<=Inputs!$D$17:$D$20),0)),1) | E9: =INDEX(Inputs!$D$24:$D$30,WEEKDAY(A9,2)) | F9: =IFERROR(INDEX(Inputs!$D$34:$D$45,MATCH(A9,Inputs!$B$34:$B$45,0)),1) | G9: =Inputs!$C$7*D9*E9*F9 | I9: =IF(H9<>"",H9,G9)
A10: =DATE(Settings!$B$7,1,1)+4 | B10: =TEXT(A10,"ddd") | C10: =IFERROR(INDEX(Inputs!$B$17:$B$20,MATCH(1,(A10>=Inputs!$C$17:$C$20)*(A10<=Inputs!$D$17:$D$20),0)),"") | D10: =IFERROR(INDEX(Inputs!$E$17:$E$20,MATCH(1,(A10>=Inputs!$C$17:$C$20)*(A10<=Inputs!$D$17:$D$20),0)),1) | E10: =INDEX(Inputs!$D$24:$D$30,WEEKDAY(A10,2)) | F10: =IFERROR(INDEX(Inputs!$D$34:$D$45,MATCH(A10,Inputs!$B$34:$B$45,0)),1) | G10: =Inputs!$C$7*D10*E10*F10 | I10: =IF(H10<>"",H10,G10)
A11: =DATE(Settings!$B$7,1,1)+5 | B11: =TEXT(A11,"ddd") | C11: =IFERROR(INDEX(Inputs!$B$17:$B$20,MATCH(1,(A11>=Inputs!$C$17:$C$20)*(A11<=Inputs!$D$17:$D$20),0)),"") | D11: =IFERROR(INDEX(Inputs!$E$17:$E$20,MATCH(1,(A11>=Inputs!$C$17:$C$20)*(A11<=Inputs!$D$17:$D$20),0)),1) | E11: =INDEX(Inputs!$D$24:$D$30,WEEKDAY(A11,2)) | F11: =IFERROR(INDEX(Inputs!$D$34:$D$45,MATCH(A11,Inputs!$B$34:$B$45,0)),1) | G11: =Inputs!$C$7*D11*E11*F11 | I11: =IF(H11<>"",H11,G11)
A12: =DATE(Settings!$B$7,1,1)+6 | B12: =TEXT(A12,"ddd") | C12: =IFERROR(INDEX(Inputs!$B$17:$B$20,MATCH(1,(A12>=Inputs!$C$17:$C$20)*(A12<=Inputs!$D$17:$D$20),0)),"") | D12: =IFERROR(INDEX(Inputs!$E$17:$E$20,MATCH(1,(A12>=Inputs!$C$17:$C$20)*(A12<=Inputs!$D$17:$D$20),0)),1) | E12: =INDEX(Inputs!$D$24:$D$30,WEEKDAY(A12,2)) | F12: =IFERROR(INDEX(Inputs!$D$34:$D$45,MATCH(A12,Inputs!$B$34:$B$45,0)),1) | G12: =Inputs!$C$7*D12*E12*F12 | I12: =IF(H12<>"",H12,G12)
A13: =DATE(Settings!$B$7,1,1)+7 | B13: =TEXT(A13,"ddd") | C13: =IFERROR(INDEX(Inputs!$B$17:$B$20,MATCH(1,(A13>=Inputs!$C$17:$C$20)*(A13<=Inputs!$D$17:$D$20),0)),"") | D13: =IFERROR(INDEX(Inputs!$E$17:$E$20,MATCH(1,(A13>=Inputs!$C$17:$C$20)*(A13<=Inputs!$D$17:$D$20),0)),1) | E13: =INDEX(Inputs!$D$24:$D$30,WEEKDAY(A13,2)) | F13: =IFERROR(INDEX(Inputs!$D$34:$D$45,MATCH(A13,Inputs!$B$34:$B$45,0)),1) | G13: =Inputs!$C$7*D13*E13*F13 | I13: =IF(H13<>"",H13,G13)
A14: =DATE(Settings!$B$7,1,1)+8 | B14: =TEXT(A14,"ddd") | C14: =IFERROR(INDEX(Inputs!$B$17:$B$20,MATCH(1,(A14>=Inputs!$C$17:$C$20)*(A14<=Inputs!$D$17:$D$20),0)),"") | D14: =IFERROR(INDEX(Inputs!$E$17:$E$20,MATCH(1,(A14>=Inputs!$C$17:$C$20)*(A14<=Inputs!$D$17:$D$20),0)),1) | E14: =INDEX(Inputs!$D$24:$D$30,WEEKDAY(A14,2)) | F14: =IFERROR(INDEX(Inputs!$D$34:$D$45,MATCH(A14,Inputs!$B$34:$B$45,0)),1) | G14: =Inputs!$C$7*D14*E14*F14 | I14: =IF(H14<>"",H14,G14)
A15: =DATE(Settings!$B$7,1,1)+9 | B15: =TEXT(A15,"ddd") | C15: =IFERROR(INDEX(Inputs!$B$17:$B$20,MATCH(1,(A15>=Inputs!$C$17:$C$20)*(A15<=Inputs!$D$17:$D$20),0)),"") | D15: =IFERROR(INDEX(Inputs!$E$17:$E$20,MATCH(1,(A15>=Inputs!$C$17:$C$20)*(A15<=Inputs!$D$17:$D$20),0)),1) | E15: =INDEX(Inputs!$D$24:$D$30,WEEKDAY(A15,2)) | F15: =IFERROR(INDEX(Inputs!$D$34:$D$45,MATCH(A15,Inputs!$B$34:$B$45,0)),1) | G15: =Inputs!$C$7*D15*E15*F15 | I15: =IF(H15<>"",H15,G15)
A16: =DATE(Settings!$B$7,1,1)+10 | B16: =TEXT(A16,"ddd") | C16: =IFERROR(INDEX(Inputs!$B$17:$B$20,MATCH(1,(A16>=Inputs!$C$17:$C$20)*(A16<=Inputs!$D$17:$D$20),0)),"") | D16: =IFERROR(INDEX(Inputs!$E$17:$E$20,MATCH(1,(A16>=Inputs!$C$17:$C$20)*(A16<=Inputs!$D$17:$D$20),0)),1) | E16: =INDEX(Inputs!$D$24:$D$30,WEEKDAY(A16,2)) | F16: =IFERROR(INDEX(Inputs!$D$34:$D$45,MATCH(A16,Inputs!$B$34:$B$45,0)),1) | G16: =Inputs!$C$7*D16*E16*F16 | I16: =IF(H16<>"",H16,G16)
A17: =DATE(Settings!$B$7,1,1)+11 | B17: =TEXT(A17,"ddd") | C17: =IFERROR(INDEX(Inputs!$B$17:$B$20,MATCH(1,(A17>=Inputs!$C$17:$C$20)*(A17<=Inputs!$D$17:$D$20),0)),"") | D17: =IFERROR(INDEX(Inputs!$E$17:$E$20,MATCH(1,(A17>=Inputs!$C$17:$C$20)*(A17<=Inputs!$D$17:$D$20),0)),1) | E17: =INDEX(Inputs!$D$24:$D$30,WEEKDAY(A17,2)) | F17: =IFERROR(INDEX(Inputs!$D$34:$D$45,MATCH(A17,Inputs!$B$34:$B$45,0)),1) | G17: =Inputs!$C$7*D17*E17*F17 | I17: =IF(H17<>"",H17,G17)
A18: =DATE(Settings!$B$7,1,1)+12 | B18: =TEXT(A18,"ddd") | C18: =IFERROR(INDEX(Inputs!$B$17:$B$20,MATCH(1,(A18>=Inputs!$C$17:$C$20)*(A18<=Inputs!$D$17:$D$20),0)),"") | D18: =IFERROR(INDEX(Inputs!$E$17:$E$20,MATCH(1,(A18>=Inputs!$C$17:$C$20)*(A18<=Inputs!$D$17:$D$20),0)),1) | E18: =INDEX(Inputs!$D$24:$D$30,WEEKDAY(A18,2)) | F18: =IFERROR(INDEX(Inputs!$D$34:$D$45,MATCH(A18,Inputs!$B$34:$B$45,0)),1) | G18: =Inputs!$C$7*D18*E18*F18 | I18: =IF(H18<>"",H18,G18)
A19: =DATE(Settings!$B$7,1,1)+13 | B19: =TEXT(A19,"ddd") | C19: =IFERROR(INDEX(Inputs!$B$17:$B$20,MATCH(1,(A19>=Inputs!$C$17:$C$20)*(A19<=Inputs!$D$17:$D$20),0)),"") | D19: =IFERROR(INDEX(Inputs!$E$17:$E$20,MATCH(1,(A19>=Inputs!$C$17:$C$20)*(A19<=Inputs!$D$17:$D$20),0)),1) | E19: =INDEX(Inputs!$D$24:$D$30,WEEKDAY(A19,2)) | F19: =IFERROR(INDEX(Inputs!$D$34:$D$45,MATCH(A19,Inputs!$B$34:$B$45,0)),1) | G19: =Inputs!$C$7*D19*E19*F19 | I19: =IF(H19<>"",H19,G19)
A20: =DATE(Settings!$B$7,1,1)+14 | B20: =TEXT(A20,"ddd") | C20: =IFERROR(INDEX(Inputs!$B$17:$B$20,MATCH(1,(A20>=Inputs!$C$17:$C$20)*(A20<=Inputs!$D$17:$D$20),0)),"") | D20: =IFERROR(INDEX(Inputs!$E$17:$E$20,MATCH(1,(A20>=Inputs!$C$17:$C$20)*(A20<=Inputs!$D$17:$D$20),0)),1) | E20: =INDEX(Inputs!$D$24:$D$30,WEEKDAY(A20,2)) | F20: =IFERROR(INDEX(Inputs!$D$34:$D$45,MATCH(A20,Inputs!$B$34:$B$45,0)),1) | G20: =Inputs!$C$7*D20*E20*F20 | I20: =IF(H20<>"",H20,G20)
A21: =DATE(Settings!$B$7,1,1)+15 | B21: =TEXT(A21,"ddd") | C21: =IFERROR(INDEX(Inputs!$B$17:$B$20,MATCH(1,(A21>=Inputs!$C$17:$C$20)*(A21<=Inputs!$D$17:$D$20),0)),"") | D21: =IFERROR(INDEX(Inputs!$E$17:$E$20,MATCH(1,(A21>=Inputs!$C$17:$C$20)*(A21<=Inputs!$D$17:$D$20),0)),1) | E21: =INDEX(Inputs!$D$24:$D$30,WEEKDAY(A21,2)) | F21: =IFERROR(INDEX(Inputs!$D$34:$D$45,MATCH(A21,Inputs!$B$34:$B$45,0)),1) | G21: =Inputs!$C$7*D21*E21*F21 | I21: =IF(H21<>"",H21,G21)
A22: =DATE(Settings!$B$7,1,1)+16 | B22: =TEXT(A22,"ddd") | C22: =IFERROR(INDEX(Inputs!$B$17:$B$20,MATCH(1,(A22>=Inputs!$C$17:$C$20)*(A22<=Inputs!$D$17:$D$20),0)),"") | D22: =IFERROR(INDEX(Inputs!$E$17:$E$20,MATCH(1,(A22>=Inputs!$C$17:$C$20)*(A22<=Inputs!$D$17:$D$20),0)),1) | E22: =INDEX(Inputs!$D$24:$D$30,WEEKDAY(A22,2)) | F22: =IFERROR(INDEX(Inputs!$D$34:$D$45,MATCH(A22,Inputs!$B$34:$B$45,0)),1) | G22: =Inputs!$C$7*D22*E22*F22 | I22: =IF(H22<>"",H22,G22)
A23: =DATE(Settings!$B$7,1,1)+17 | B23: =TEXT(A23,"ddd") | C23: =IFERROR(INDEX(Inputs!$B$17:$B$20,MATCH(1,(A23>=Inputs!$C$17:$C$20)*(A23<=Inputs!$D$17:$D$20),0)),"") | D23: =IFERROR(INDEX(Inputs!$E$17:$E$20,MATCH(1,(A23>=Inputs!$C$17:$C$20)*(A23<=Inputs!$D$17:$D$20),0)),1) | E23: =INDEX(Inputs!$D$24:$D$30,WEEKDAY(A23,2)) | F23: =IFERROR(INDEX(Inputs!$D$34:$D$45,MATCH(A23,Inputs!$B$34:$B$45,0)),1) | G23: =Inputs!$C$7*D23*E23*F23 | I23: =IF(H23<>"",H23,G23)
A24: =DATE(Settings!$B$7,1,1)+18 | B24: =TEXT(A24,"ddd") | C24: =IFERROR(INDEX(Inputs!$B$17:$B$20,MATCH(1,(A24>=Inputs!$C$17:$C$20)*(A24<=Inputs!$D$17:$D$20),0)),"") | D24: =IFERROR(INDEX(Inputs!$E$17:$E$20,MATCH(1,(A24>=Inputs!$C$17:$C$20)*(A24<=Inputs!$D$17:$D$20),0)),1) | E24: =INDEX(Inputs!$D$24:$D$30,WEEKDAY(A24,2)) | F24: =IFERROR(INDEX(Inputs!$D$34:$D$45,MATCH(A24,Inputs!$B$34:$B$45,0)),1) | G24: =Inputs!$C$7*D24*E24*F24 | I24: =IF(H24<>"",H24,G24)
A25: =DATE(Settings!$B$7,1,1)+19 | B25: =TEXT(A25,"ddd") | C25: =IFERROR(INDEX(Inputs!$B$17:$B$20,MATCH(1,(A25>=Inputs!$C$17:$C$20)*(A25<=Inputs!$D$17:$D$20),0)),"") | D25: =IFERROR(INDEX(Inputs!$E$17:$E$20,MATCH(1,(A25>=Inputs!$C$17:$C$20)*(A25<=Inputs!$D$17:$D$20),0)),1) | E25: =INDEX(Inputs!$D$24:$D$30,WEEKDAY(A25,2)) | F25: =IFERROR(INDEX(Inputs!$D$34:$D$45,MATCH(A25,Inputs!$B$34:$B$45,0)),1) | G25: =Inputs!$C$7*D25*E25*F25 | I25: =IF(H25<>"",H25,G25)
A26: =DATE(Settings!$B$7,1,1)+20 | B26: =TEXT(A26,"ddd") | C26: =IFERROR(INDEX(Inputs!$B$17:$B$20,MATCH(1,(A26>=Inputs!$C$17:$C$20)*(A26<=Inputs!$D$17:$D$20),0)),"") | D26: =IFERROR(INDEX(Inputs!$E$17:$E$20,MATCH(1,(A26>=Inputs!$C$17:$C$20)*(A26<=Inputs!$D$17:$D$20),0)),1) | E26: =INDEX(Inputs!$D$24:$D$30,WEEKDAY(A26,2)) | F26: =IFERROR(INDEX(Inputs!$D$34:$D$45,MATCH(A26,Inputs!$B$34:$B$45,0)),1) | G26: =Inputs!$C$7*D26*E26*F26 | I26: =IF(H26<>"",H26,G26)
A27: =DATE(Settings!$B$7,1,1)+21 | B27: =TEXT(A27,"ddd") | C27: =IFERROR(INDEX(Inputs!$B$17:$B$20,MATCH(1,(A27>=Inputs!$C$17:$C$20)*(A27<=Inputs!$D$17:$D$20),0)),"") | D27: =IFERROR(INDEX(Inputs!$E$17:$E$20,MATCH(1,(A27>=Inputs!$C$17:$C$20)*(A27<=Inputs!$D$17:$D$20),0)),1) | E27: =INDEX(Inputs!$D$24:$D$30,WEEKDAY(A27,2)) | F27: =IFERROR(INDEX(Inputs!$D$34:$D$45,MATCH(A27,Inputs!$B$34:$B$45,0)),1) | G27: =Inputs!$C$7*D27*E27*F27 | I27: =IF(H27<>"",H27,G27)
A28: =DATE(Settings!$B$7,1,1)+22 | B28: =TEXT(A28,"ddd") | C28: =IFERROR(INDEX(Inputs!$B$17:$B$20,MATCH(1,(A28>=Inputs!$C$17:$C$20)*(A28<=Inputs!$D$17:$D$20),0)),"") | D28: =IFERROR(INDEX(Inputs!$E$17:$E$20,MATCH(1,(A28>=Inputs!$C$17:$C$20)*(A28<=Inputs!$D$17:$D$20),0)),1) | E28: =INDEX(Inputs!$D$24:$D$30,WEEKDAY(A28,2)) | F28: =IFERROR(INDEX(Inputs!$D$34:$D$45,MATCH(A28,Inputs!$B$34:$B$45,0)),1) | G28: =Inputs!$C$7*D28*E28*F28 | I28: =IF(H28<>"",H28,G28)
A29: =DATE(Settings!$B$7,1,1)+23 | B29: =TEXT(A29,"ddd") | C29: =IFERROR(INDEX(Inputs!$B$17:$B$20,MATCH(1,(A29>=Inputs!$C$17:$C$20)*(A29<=Inputs!$D$17:$D$20),0)),"") | D29: =IFERROR(INDEX(Inputs!$E$17:$E$20,MATCH(1,(A29>=Inputs!$C$17:$C$20)*(A29<=Inputs!$D$17:$D$20),0)),1) | E29: =INDEX(Inputs!$D$24:$D$30,WEEKDAY(A29,2)) | F29: =IFERROR(INDEX(Inputs!$D$34:$D$45,MATCH(A29,Inputs!$B$34:$B$45,0)),1) | G29: =Inputs!$C$7*D29*E29*F29 | I29: =IF(H29<>"",H29,G29)
A30: =DATE(Settings!$B$7,1,1)+24 | B30: =TEXT(A30,"ddd") | C30: =IFERROR(INDEX(Inputs!$B$17:$B$20,MATCH(1,(A30>=Inputs!$C$17:$C$20)*(A30<=Inputs!$D$17:$D$20),0)),"") | D30: =IFERROR(INDEX(Inputs!$E$17:$E$20,MATCH(1,(A30>=Inputs!$C$17:$C$20)*(A30<=Inputs!$D$17:$D$20),0)),1) | E30: =INDEX(Inputs!$D$24:$D$30,WEEKDAY(A30,2)) | F30: =IFERROR(INDEX(Inputs!$D$34:$D$45,MATCH(A30,Inputs!$B$34:$B$45,0)),1) | G30: =Inputs!$C$7*D30*E30*F30 | I30: =IF(H30<>"",H30,G30)
A31: =DATE(Settings!$B$7,1,1)+25 | B31: =TEXT(A31,"ddd") | C31: =IFERROR(INDEX(Inputs!$B$17:$B$20,MATCH(1,(A31>=Inputs!$C$17:$C$20)*(A31<=Inputs!$D$17:$D$20),0)),"") | D31: =IFERROR(INDEX(Inputs!$E$17:$E$20,MATCH(1,(A31>=Inputs!$C$17:$C$20)*(A31<=Inputs!$D$17:$D$20),0)),1) | E31: =INDEX(Inputs!$D$24:$D$30,WEEKDAY(A31,2)) | F31: =IFERROR(INDEX(Inputs!$D$34:$D$45,MATCH(A31,Inputs!$B$34:$B$45,0)),1) | G31: =Inputs!$C$7*D31*E31*F31 | I31: =IF(H31<>"",H31,G31)
A32: =DATE(Settings!$B$7,1,1)+26 | B32: =TEXT(A32,"ddd") | C32: =IFERROR(INDEX(Inputs!$B$17:$B$20,MATCH(1,(A32>=Inputs!$C$17:$C$20)*(A32<=Inputs!$D$17:$D$20),0)),"") | D32: =IFERROR(INDEX(Inputs!$E$17:$E$20,MATCH(1,(A32>=Inputs!$C$17:$C$20)*(A32<=Inputs!$D$17:$D$20),0)),1) | E32: =INDEX(Inputs!$D$24:$D$30,WEEKDAY(A32,2)) | F32: =IFERROR(INDEX(Inputs!$D$34:$D$45,MATCH(A32,Inputs!$B$34:$B$45,0)),1) | G32: =Inputs!$C$7*D32*E32*F32 | I32: =IF(H32<>"",H32,G32)
A33: =DATE(Settings!$B$7,1,1)+27 | B33: =TEXT(A33,"ddd") | C33: =IFERROR(INDEX(Inputs!$B$17:$B$20,MATCH(1,(A33>=Inputs!$C$17:$C$20)*(A33<=Inputs!$D$17:$D$20),0)),"") | D33: =IFERROR(INDEX(Inputs!$E$17:$E$20,MATCH(1,(A33>=Inputs!$C$17:$C$20)*(A33<=Inputs!$D$17:$D$20),0)),1) | E33: =INDEX(Inputs!$D$24:$D$30,WEEKDAY(A33,2)) | F33: =IFERROR(INDEX(Inputs!$D$34:$D$45,MATCH(A33,Inputs!$B$34:$B$45,0)),1) | G33: =Inputs!$C$7*D33*E33*F33 | I33: =IF(H33<>"",H33,G33)
A34: =DATE(Settings!$B$7,1,1)+28 | B34: =TEXT(A34,"ddd") | C34: =IFERROR(INDEX(Inputs!$B$17:$B$20,MATCH(1,(A34>=Inputs!$C$17:$C$20)*(A34<=Inputs!$D$17:$D$20),0)),"") | D34: =IFERROR(INDEX(Inputs!$E$17:$E$20,MATCH(1,(A34>=Inputs!$C$17:$C$20)*(A34<=Inputs!$D$17:$D$20),0)),1) | E34: =INDEX(Inputs!$D$24:$D$30,WEEKDAY(A34,2)) | F34: =IFERROR(INDEX(Inputs!$D$34:$D$45,MATCH(A34,Inputs!$B$34:$B$45,0)),1) | G34: =Inputs!$C$7*D34*E34*F34 | I34: =IF(H34<>"",H34,G34)
A35: =DATE(Settings!$B$7,1,1)+29 | B35: =TEXT(A35,"ddd") | C35: =IFERROR(INDEX(Inputs!$B$17:$B$20,MATCH(1,(A35>=Inputs!$C$17:$C$20)*(A35<=Inputs!$D$17:$D$20),0)),"") | D35: =IFERROR(INDEX(Inputs!$E$17:$E$20,MATCH(1,(A35>=Inputs!$C$17:$C$20)*(A35<=Inputs!$D$17:$D$20),0)),1) | E35: =INDEX(Inputs!$D$24:$D$30,WEEKDAY(A35,2)) | F35: =IFERROR(INDEX(Inputs!$D$34:$D$45,MATCH(A35,Inputs!$B$34:$B$45,0)),1) | G35: =Inputs!$C$7*D35*E35*F35 | I35: =IF(H35<>"",H35,G35)
A36: =DATE(Settings!$B$7,1,1)+30 | B36: =TEXT(A36,"ddd") | C36: =IFERROR(INDEX(Inputs!$B$17:$B$20,MATCH(1,(A36>=Inputs!$C$17:$C$20)*(A36<=Inputs!$D$17:$D$20),0)),"") | D36: =IFERROR(INDEX(Inputs!$E$17:$E$20,MATCH(1,(A36>=Inputs!$C$17:$C$20)*(A36<=Inputs!$D$17:$D$20),0)),1) | E36: =INDEX(Inputs!$D$24:$D$30,WEEKDAY(A36,2)) | F36: =IFERROR(INDEX(Inputs!$D$34:$D$45,MATCH(A36,Inputs!$B$34:$B$45,0)),1) | G36: =Inputs!$C$7*D36*E36*F36 | I36: =IF(H36<>"",H36,G36)
A37: =DATE(Settings!$B$7,1,1)+31 | B37: =TEXT(A37,"ddd") | C37: =IFERROR(INDEX(Inputs!$B$17:$B$20,MATCH(1,(A37>=Inputs!$C$17:$C$20)*(A37<=Inputs!$D$17:$D$20),0)),"") | D37: =IFERROR(INDEX(Inputs!$E$17:$E$20,MATCH(1,(A37>=Inputs!$C$17:$C$20)*(A37<=Inputs!$D$17:$D$20),0)),1) | E37: =INDEX(Inputs!$D$24:$D$30,WEEKDAY(A37,2)) | F37: =IFERROR(INDEX(Inputs!$D$34:$D$45,MATCH(A37,Inputs!$B$34:$B$45,0)),1) | G37: =Inputs!$C$7*D37*E37*F37 | I37: =IF(H37<>"",H37,G37)
A38: =DATE(Settings!$B$7,1,1)+32 | B38: =TEXT(A38,"ddd") | C38: =IFERROR(INDEX(Inputs!$B$17:$B$20,MATCH(1,(A38>=Inputs!$C$17:$C$20)*(A38<=Inputs!$D$17:$D$20),0)),"") | D38: =IFERROR(INDEX(Inputs!$E$17:$E$20,MATCH(1,(A38>=Inputs!$C$17:$C$20)*(A38<=Inputs!$D$17:$D$20),0)),1) | E38: =INDEX(Inputs!$D$24:$D$30,WEEKDAY(A38,2)) | F38: =IFERROR(INDEX(Inputs!$D$34:$D$45,MATCH(A38,Inputs!$B$34:$B$45,0)),1) | G38: =Inputs!$C$7*D38*E38*F38 | I38: =IF(H38<>"",H38,G38)
A39: =DATE(Settings!$B$7,1,1)+33 | B39: =TEXT(A39,"ddd") | C39: =IFERROR(INDEX(Inputs!$B$17:$B$20,MATCH(1,(A39>=Inputs!$C$17:$C$20)*(A39<=Inputs!$D$17:$D$20),0)),"") | D39: =IFERROR(INDEX(Inputs!$E$17:$E$20,MATCH(1,(A39>=Inputs!$C$17:$C$20)*(A39<=Inputs!$D$17:$D$20),0)),1) | E39: =INDEX(Inputs!$D$24:$D$30,WEEKDAY(A39,2)) | F39: =IFERROR(INDEX(Inputs!$D$34:$D$45,MATCH(A39,Inputs!$B$34:$B$45,0)),1) | G39: =Inputs!$C$7*D39*E39*F39 | I39: =IF(H39<>"",H39,G39)
A40: =DATE(Settings!$B$7,1,1)+34 | B40: =TEXT(A40,"ddd") | C40: =IFERROR(INDEX(Inputs!$B$17:$B$20,MATCH(1,(A40>=Inputs!$C$17:$C$20)*(A40<=Inputs!$D$17:$D$20),0)),"") | D40: =IFERROR(INDEX(Inputs!$E$17:$E$20,MATCH(1,(A40>=Inputs!$C$17:$C$20)*(A40<=Inputs!$D$17:$D$20),0)),1) | E40: =INDEX(Inputs!$D$24:$D$30,WEEKDAY(A40,2)) | F40: =IFERROR(INDEX(Inputs!$D$34:$D$45,MATCH(A40,Inputs!$B$34:$B$45,0)),1) | G40: =Inputs!$C$7*D40*E40*F40 | I40: =IF(H40<>"",H40,G40)
A41: =DATE(Settings!$B$7,1,1)+35 | B41: =TEXT(A41,"ddd") | C41: =IFERROR(INDEX(Inputs!$B$17:$B$20,MATCH(1,(A41>=Inputs!$C$17:$C$20)*(A41<=Inputs!$D$17:$D$20),0)),"") | D41: =IFERROR(INDEX(Inputs!$E$17:$E$20,MATCH(1,(A41>=Inputs!$C$17:$C$20)*(A41<=Inputs!$D$17:$D$20),0)),1) | E41: =INDEX(Inputs!$D$24:$D$30,WEEKDAY(A41,2)) | F41: =IFERROR(INDEX(Inputs!$D$34:$D$45,MATCH(A41,Inputs!$B$34:$B$45,0)),1) | G41: =Inputs!$C$7*D41*E41*F41 | I41: =IF(H41<>"",H41,G41)
A42: =DATE(Settings!$B$7,1,1)+36 | B42: =TEXT(A42,"ddd") | C42: =IFERROR(INDEX(Inputs!$B$17:$B$20,MATCH(1,(A42>=Inputs!$C$17:$C$20)*(A42<=Inputs!$D$17:$D$20),0)),"") | D42: =IFERROR(INDEX(Inputs!$E$17:$E$20,MATCH(1,(A42>=Inputs!$C$17:$C$20)*(A42<=Inputs!$D$17:$D$20),0)),1) | E42: =INDEX(Inputs!$D$24:$D$30,WEEKDAY(A42,2)) | F42: =IFERROR(INDEX(Inputs!$D$34:$D$45,MATCH(A42,Inputs!$B$34:$B$45,0)),1) | G42: =Inputs!$C$7*D42*E42*F42 | I42: =IF(H42<>"",H42,G42)
...

Sheet Monthly Summary
A2: =HYPERLINK("#'365-Day Calendar'!A1", "← BACK") | D2: MONTHLY SUMMARY | J2: =HYPERLINK("#'Settings'!A1", "NEXT →")
A4: Twelve months at a glance. Edit the occupancy column to project revenue per month — these flow into the chart.
B6: Month | C6: Avg rate | D6: Min rate | E6: Max rate | F6: Occupancy % | G6: Projected revenue
B7: January | C7: =IFERROR(AVERAGEIFS('365-Day Calendar'!$I$6:$I$370,'365-Day Calendar'!$A$6:$A$370,">="&DATE(Settings!$B$7,1,1),'365-Day Calendar'!$A$6:$A$370,"<"&DATE(Settings!$B$7,2,1)),0) | D7: =IFERROR(MINIFS('365-Day Calendar'!$I$6:$I$370,'365-Day Calendar'!$A$6:$A$370,">="&DATE(Settings!$B$7,1,1),'365-Day Calendar'!$A$6:$A$370,"<"&DATE(Settings!$B$7,2,1)),0) | E7: =IFERROR(MAXIFS('365-Day Calendar'!$I$6:$I$370,'365-Day Calendar'!$A$6:$A$370,">="&DATE(Settings!$B$7,1,1),'365-Day Calendar'!$A$6:$A$370,"<"&DATE(Settings!$B$7,2,1)),0) | G7: =C7*DAY(EOMONTH(DATE(Settings!$B$7,1,1),0))*F7
B8: February | C8: =IFERROR(AVERAGEIFS('365-Day Calendar'!$I$6:$I$370,'365-Day Calendar'!$A$6:$A$370,">="&DATE(Settings!$B$7,2,1),'365-Day Calendar'!$A$6:$A$370,"<"&DATE(Settings!$B$7,3,1)),0) | D8: =IFERROR(MINIFS('365-Day Calendar'!$I$6:$I$370,'365-Day Calendar'!$A$6:$A$370,">="&DATE(Settings!$B$7,2,1),'365-Day Calendar'!$A$6:$A$370,"<"&DATE(Settings!$B$7,3,1)),0) | E8: =IFERROR(MAXIFS('365-Day Calendar'!$I$6:$I$370,'365-Day Calendar'!$A$6:$A$370,">="&DATE(Settings!$B$7,2,1),'365-Day Calendar'!$A$6:$A$370,"<"&DATE(Settings!$B$7,3,1)),0) | G8: =C8*DAY(EOMONTH(DATE(Settings!$B$7,2,1),0))*F8
B9: March | C9: =IFERROR(AVERAGEIFS('365-Day Calendar'!$I$6:$I$370,'365-Day Calendar'!$A$6:$A$370,">="&DATE(Settings!$B$7,3,1),'365-Day Calendar'!$A$6:$A$370,"<"&DATE(Settings!$B$7,4,1)),0) | D9: =IFERROR(MINIFS('365-Day Calendar'!$I$6:$I$370,'365-Day Calendar'!$A$6:$A$370,">="&DATE(Settings!$B$7,3,1),'365-Day Calendar'!$A$6:$A$370,"<"&DATE(Settings!$B$7,4,1)),0) | E9: =IFERROR(MAXIFS('365-Day Calendar'!$I$6:$I$370,'365-Day Calendar'!$A$6:$A$370,">="&DATE(Settings!$B$7,3,1),'365-Day Calendar'!$A$6:$A$370,"<"&DATE(Settings!$B$7,4,1)),0) | G9: =C9*DAY(EOMONTH(DATE(Settings!$B$7,3,1),0))*F9
B10: April | C10: =IFERROR(AVERAGEIFS('365-Day Calendar'!$I$6:$I$370,'365-Day Calendar'!$A$6:$A$370,">="&DATE(Settings!$B$7,4,1),'365-Day Calendar'!$A$6:$A$370,"<"&DATE(Settings!$B$7,5,1)),0) | D10: =IFERROR(MINIFS('365-Day Calendar'!$I$6:$I$370,'365-Day Calendar'!$A$6:$A$370,">="&DATE(Settings!$B$7,4,1),'365-Day Calendar'!$A$6:$A$370,"<"&DATE(Settings!$B$7,5,1)),0) | E10: =IFERROR(MAXIFS('365-Day Calendar'!$I$6:$I$370,'365-Day Calendar'!$A$6:$A$370,">="&DATE(Settings!$B$7,4,1),'365-Day Calendar'!$A$6:$A$370,"<"&DATE(Settings!$B$7,5,1)),0) | G10: =C10*DAY(EOMONTH(DATE(Settings!$B$7,4,1),0))*F10
B11: May | C11: =IFERROR(AVERAGEIFS('365-Day Calendar'!$I$6:$I$370,'365-Day Calendar'!$A$6:$A$370,">="&DATE(Settings!$B$7,5,1),'365-Day Calendar'!$A$6:$A$370,"<"&DATE(Settings!$B$7,6,1)),0) | D11: =IFERROR(MINIFS('365-Day Calendar'!$I$6:$I$370,'365-Day Calendar'!$A$6:$A$370,">="&DATE(Settings!$B$7,5,1),'365-Day Calendar'!$A$6:$A$370,"<"&DATE(Settings!$B$7,6,1)),0) | E11: =IFERROR(MAXIFS('365-Day Calendar'!$I$6:$I$370,'365-Day Calendar'!$A$6:$A$370,">="&DATE(Settings!$B$7,5,1),'365-Day Calendar'!$A$6:$A$370,"<"&DATE(Settings!$B$7,6,1)),0) | G11: =C11*DAY(EOMONTH(DATE(Settings!$B$7,5,1),0))*F11
B12: June | C12: =IFERROR(AVERAGEIFS('365-Day Calendar'!$I$6:$I$370,'365-Day Calendar'!$A$6:$A$370,">="&DATE(Settings!$B$7,6,1),'365-Day Calendar'!$A$6:$A$370,"<"&DATE(Settings!$B$7,7,1)),0) | D12: =IFERROR(MINIFS('365-Day Calendar'!$I$6:$I$370,'365-Day Calendar'!$A$6:$A$370,">="&DATE(Settings!$B$7,6,1),'365-Day Calendar'!$A$6:$A$370,"<"&DATE(Settings!$B$7,7,1)),0) | E12: =IFERROR(MAXIFS('365-Day Calendar'!$I$6:$I$370,'365-Day Calendar'!$A$6:$A$370,">="&DATE(Settings!$B$7,6,1),'365-Day Calendar'!$A$6:$A$370,"<"&DATE(Settings!$B$7,7,1)),0) | G12: =C12*DAY(EOMONTH(DATE(Settings!$B$7,6,1),0))*F12
B13: July | C13: =IFERROR(AVERAGEIFS('365-Day Calendar'!$I$6:$I$370,'365-Day Calendar'!$A$6:$A$370,">="&DATE(Settings!$B$7,7,1),'365-Day Calendar'!$A$6:$A$370,"<"&DATE(Settings!$B$7,8,1)),0) | D13: =IFERROR(MINIFS('365-Day Calendar'!$I$6:$I$370,'365-Day Calendar'!$A$6:$A$370,">="&DATE(Settings!$B$7,7,1),'365-Day Calendar'!$A$6:$A$370,"<"&DATE(Settings!$B$7,8,1)),0) | E13: =IFERROR(MAXIFS('365-Day Calendar'!$I$6:$I$370,'365-Day Calendar'!$A$6:$A$370,">="&DATE(Settings!$B$7,7,1),'365-Day Calendar'!$A$6:$A$370,"<"&DATE(Settings!$B$7,8,1)),0) | G13: =C13*DAY(EOMONTH(DATE(Settings!$B$7,7,1),0))*F13
B14: August | C14: =IFERROR(AVERAGEIFS('365-Day Calendar'!$I$6:$I$370,'365-Day Calendar'!$A$6:$A$370,">="&DATE(Settings!$B$7,8,1),'365-Day Calendar'!$A$6:$A$370,"<"&DATE(Settings!$B$7,9,1)),0) | D14: =IFERROR(MINIFS('365-Day Calendar'!$I$6:$I$370,'365-Day Calendar'!$A$6:$A$370,">="&DATE(Settings!$B$7,8,1),'365-Day Calendar'!$A$6:$A$370,"<"&DATE(Settings!$B$7,9,1)),0) | E14: =IFERROR(MAXIFS('365-Day Calendar'!$I$6:$I$370,'365-Day Calendar'!$A$6:$A$370,">="&DATE(Settings!$B$7,8,1),'365-Day Calendar'!$A$6:$A$370,"<"&DATE(Settings!$B$7,9,1)),0) | G14: =C14*DAY(EOMONTH(DATE(Settings!$B$7,8,1),0))*F14
B15: September | C15: =IFERROR(AVERAGEIFS('365-Day Calendar'!$I$6:$I$370,'365-Day Calendar'!$A$6:$A$370,">="&DATE(Settings!$B$7,9,1),'365-Day Calendar'!$A$6:$A$370,"<"&DATE(Settings!$B$7,10,1)),0) | D15: =IFERROR(MINIFS('365-Day Calendar'!$I$6:$I$370,'365-Day Calendar'!$A$6:$A$370,">="&DATE(Settings!$B$7,9,1),'365-Day Calendar'!$A$6:$A$370,"<"&DATE(Settings!$B$7,10,1)),0) | E15: =IFERROR(MAXIFS('365-Day Calendar'!$I$6:$I$370,'365-Day Calendar'!$A$6:$A$370,">="&DATE(Settings!$B$7,9,1),'365-Day Calendar'!$A$6:$A$370,"<"&DATE(Settings!$B$7,10,1)),0) | G15: =C15*DAY(EOMONTH(DATE(Settings!$B$7,9,1),0))*F15
B16: October | C16: =IFERROR(AVERAGEIFS('365-Day Calendar'!$I$6:$I$370,'365-Day Calendar'!$A$6:$A$370,">="&DATE(Settings!$B$7,10,1),'365-Day Calendar'!$A$6:$A$370,"<"&DATE(Settings!$B$7,11,1)),0) | D16: =IFERROR(MINIFS('365-Day Calendar'!$I$6:$I$370,'365-Day Calendar'!$A$6:$A$370,">="&DATE(Settings!$B$7,10,1),'365-Day Calendar'!$A$6:$A$370,"<"&DATE(Settings!$B$7,11,1)),0) | E16: =IFERROR(MAXIFS('365-Day Calendar'!$I$6:$I$370,'365-Day Calendar'!$A$6:$A$370,">="&DATE(Settings!$B$7,10,1),'365-Day Calendar'!$A$6:$A$370,"<"&DATE(Settings!$B$7,11,1)),0) | G16: =C16*DAY(EOMONTH(DATE(Settings!$B$7,10,1),0))*F16
B17: November | C17: =IFERROR(AVERAGEIFS('365-Day Calendar'!$I$6:$I$370,'365-Day Calendar'!$A$6:$A$370,">="&DATE(Settings!$B$7,11,1),'365-Day Calendar'!$A$6:$A$370,"<"&DATE(Settings!$B$7,12,1)),0) | D17: =IFERROR(MINIFS('365-Day Calendar'!$I$6:$I$370,'365-Day Calendar'!$A$6:$A$370,">="&DATE(Settings!$B$7,11,1),'365-Day Calendar'!$A$6:$A$370,"<"&DATE(Settings!$B$7,12,1)),0) | E17: =IFERROR(MAXIFS('365-Day Calendar'!$I$6:$I$370,'365-Day Calendar'!$A$6:$A$370,">="&DATE(Settings!$B$7,11,1),'365-Day Calendar'!$A$6:$A$370,"<"&DATE(Settings!$B$7,12,1)),0) | G17: =C17*DAY(EOMONTH(DATE(Settings!$B$7,11,1),0))*F17
B18: December | C18: =IFERROR(AVERAGEIFS('365-Day Calendar'!$I$6:$I$370,'365-Day Calendar'!$A$6:$A$370,">="&DATE(Settings!$B$7,12,1),'365-Day Calendar'!$A$6:$A$370,"<="&DATE(Settings!$B$7,12,31)),0) | D18: =IFERROR(MINIFS('365-Day Calendar'!$I$6:$I$370,'365-Day Calendar'!$A$6:$A$370,">="&DATE(Settings!$B$7,12,1),'365-Day Calendar'!$A$6:$A$370,"<="&DATE(Settings!$B$7,12,31)),0) | E18: =IFERROR(MAXIFS('365-Day Calendar'!$I$6:$I$370,'365-Day Calendar'!$A$6:$A$370,">="&DATE(Settings!$B$7,12,1),'365-Day Calendar'!$A$6:$A$370,"<="&DATE(Settings!$B$7,12,31)),0) | G18: =C18*DAY(EOMONTH(DATE(Settings!$B$7,12,1),0))*F18
B19: ANNUAL TOTAL | C19: =AVERAGE(C7:C18) | D19: =MIN(D7:D18) | E19: =MAX(E7:E18) | F19: =AVERAGE(F7:F18) | G19: =SUM(G7:G18)
A22: Why month-level matters: occupancy assumptions vary by season — use the per-month % to get a more realistic revenue projection than a flat annual rate. Cross-check with PriceLabs or your booking history.
A27: Questions? hello@thestrledger.com
A28: REV-002 · Monthly Summary

Sheet Settings
A2: =HYPERLINK("#'Start'!A1", "← BACK") | D2: SETTINGS | J2: =HYPERLINK("#'Inputs'!A1", "NEXT →")
A4: Property + active year. The 365-day calendar regenerates from the year cell — change it once, the whole workbook follows.
C5: ← property name
C7: ← active year (drives the calendar)
A9: SEASON NAME LIST
C10: Season 1
C11: Season 2
C12: Season 3
C13: Season 4
A16: Tip: when you roll into a new year, just update the active year above. The calendar dates rebuild and your season cutoffs (set on Inputs) follow. Event dates stay literal — re-enter them per year since holidays move.
A22: Questions? hello@thestrledger.com
A23: REV-002 · Settings
