Workbook

Sheet Start
A2: The STR Ledger
A4: Holiday + Event Pricing Calendar
A5: Bump rates before the calendar bumps you.
A7: REV-005 · v1.0 · DEMO
A10: EVENTS NEXT 30 DAYS | E10: EVENTS NEXT 60 DAYS | I10: AVG LIFT % NEXT 90 DAYS
A11: =COUNTIFS(Events!A7:A206,">="&TODAY(),Events!A7:A206,"<="&TODAY()+30) | E11: =COUNTIFS(Events!A7:A206,">="&TODAY(),Events!A7:A206,"<="&TODAY()+60) | I11: =IFERROR(AVERAGEIFS(Events!F7:F206,Events!A7:A206,">="&TODAY(),Events!A7:A206,"<="&TODAY()+90)/100,0)
A14: high-rate dates inside 30 days — set rates now | E14: events on the 60-day horizon | I14: average demand lift on the 90-day horizon
A17: WHAT THIS DOES
A18: Tracks the 12 federal holidays, regional school breaks, and local high-demand events for your market. Each event has a demand-lift % that drives a suggested nightly rate from your base. Open the Upcoming List before peaks; verify rates are bumped on Airbnb/VRBO before guests book at flat pricing.
A23: HOW TO USE
A24: 1. Set base rate + active year on Settings. 2. Customize Events: keep federal holidays, swap school breaks for your region, add your local festivals/concerts/games. 3. Each Friday, open Upcoming List — red rows are < 14 days out with rates not yet updated. Bump them, mark Status = Y.
A29: =HYPERLINK("#'Events'!A1", "Events") | D29: =HYPERLINK("#'Year-View Calendar'!A1", "Year-View Calendar") | G29: =HYPERLINK("#'Upcoming List'!A1", "Upcoming List") | J29: =HYPERLINK("#'Settings'!A1", "Settings")
A33: Need full revenue coverage? Add the Revenue Bundle at thestrledger.com/revenue — RevPAR, cleaning fee optimizer, break-even occupancy, holiday pricing.
A36: Questions? hello@thestrledger.com
A37: REV-005 · v1.0 · DEMO · Free updates forever

Sheet Events
A2: =HYPERLINK("#'Start'!A1", "← BACK") | D2: EVENTS | J2: =HYPERLINK("#'Year-View Calendar'!A1", "NEXT →")
A4: Master register of high-demand dates. Suggested rate auto-calcs from base rate (Settings B7) × (1 + Lift%/100). Capacity 200 rows.
A6: Date | B6: End date | C6: Event name | D6: Type | E6: Region | F6: Lift % | G6: Suggested rate | H6: Min-night Y/N | I6: Notes / source URL
A7: 46023 | B7: 46023 | C7: New Year's Day | D7: Federal Holiday | E7: All | F7: 25 | G7: =IF(F7="","",Settings!$B$7*(1+F7/100)) | H7: N | I7: Federal holiday — moderate demand, family travel.
A8: 46041 | B8: 46041 | C8: Martin Luther King Jr. Day | D8: Federal Holiday | E8: All | F8: 20 | G8: =IF(F8="","",Settings!$B$7*(1+F8/100)) | H8: Y | I8: 3-day weekend; require 3-night minimum.
A9: 46069 | B9: 46069 | C9: Presidents' Day | D9: Federal Holiday | E9: All | F9: 25 | G9: =IF(F9="","",Settings!$B$7*(1+F9/100)) | H9: Y | I9: Long weekend, ski markets peak; 3-night minimum.
A10: 46167 | B10: 46167 | C10: Memorial Day | D10: Federal Holiday | E10: All | F10: 45 | G10: =IF(F10="","",Settings!$B$7*(1+F10/100)) | H10: Y | I10: Unofficial start of summer — strong demand, 3-night min.
A11: 46207 | B11: 46207 | C11: Independence Day | D11: Federal Holiday | E11: All | F11: 65 | G11: =IF(F11="","",Settings!$B$7*(1+F11/100)) | H11: Y | I11: Peak summer holiday; require 3-night minimum.
A12: 46272 | B12: 46272 | C12: Labor Day | D12: Federal Holiday | E12: All | F12: 80 | G12: =IF(F12="","",Settings!$B$7*(1+F12/100)) | H12: Y | I12: Last big summer weekend; max lift, 3-night minimum.
A13: 46307 | B13: 46307 | C13: Columbus Day / Indigenous Peoples Day | D13: Federal Holiday | E13: All | F13: 30 | G13: =IF(F13="","",Settings!$B$7*(1+F13/100)) | H13: N | I13: Fall foliage in mountain markets — moderate lift.
A14: 46337 | B14: 46337 | C14: Veterans Day | D14: Federal Holiday | E14: All | F14: 20 | G14: =IF(F14="","",Settings!$B$7*(1+F14/100)) | H14: N | I14: Mid-week observance; light lift.
A15: 46352 | B15: 46352 | C15: Thanksgiving Day | D15: Federal Holiday | E15: All | F15: 55 | G15: =IF(F15="","",Settings!$B$7*(1+F15/100)) | H15: Y | I15: Family travel peak; 3-night minimum recommended.
A16: 46381 | B16: 46381 | C16: Christmas Day | D16: Federal Holiday | E16: All | F16: 60 | G16: =IF(F16="","",Settings!$B$7*(1+F16/100)) | H16: Y | I16: Holiday week peak; consider 4-night minimum.
A17: 46387 | B17: 46387 | C17: New Year's Eve | D17: Federal Holiday | E17: All | F17: 80 | G17: =IF(F17="","",Settings!$B$7*(1+F17/100)) | H17: Y | I17: Top demand night of year; max lift + 3-night min.
A18: 46117 | B18: 46117 | C18: Easter Sunday | D18: Federal Holiday | E18: All | F18: 40 | G18: =IF(F18="","",Settings!$B$7*(1+F18/100)) | H18: Y | I18: Spring family travel; school break overlap.
... A28: 46240 | B28: 46243 | C28: Gatlinburg Craftsmen's Fair | D28: Festival | E28: Southeast | F28: 40 | G28: =IF(F28="","",Settings!$B$7*(1+F28/100)) | H28: Y | I28: Long-running summer arts festival; strong weekend lift.
G29: =IF(F29="","",Settings!$B$7*(1+F29/100))
G30: =IF(F30="","",Settings!$B$7*(1+F30/100))
G31: =IF(F31="","",Settings!$B$7*(1+F31/100))
G32: =IF(F32="","",Settings!$B$7*(1+F32/100))
G33: =IF(F33="","",Settings!$B$7*(1+F33/100))
G34: =IF(F34="","",Settings!$B$7*(1+F34/100))
G35: =IF(F35="","",Settings!$B$7*(1+F35/100))
G36: =IF(F36="","",Settings!$B$7*(1+F36/100))
G37: =IF(F37="","",Settings!$B$7*(1+F37/100))
G38: =IF(F38="","",Settings!$B$7*(1+F38/100))
G39: =IF(F39="","",Settings!$B$7*(1+F39/100))
G40: =IF(F40="","",Settings!$B$7*(1+F40/100))
... G206: =IF(F206="","",Settings!$B$7*(1+F206/100))

Sheet Year-View Calendar
A2: =HYPERLINK("#'Events'!A1", "← BACK") | D2: YEAR-VIEW CALENDAR | J2: =HYPERLINK("#'Upcoming List'!A1", "NEXT →")
A4: 12-month grid for the active year (Settings B5). Days that fall on a registered event are gold-soft. Legend below lists each highlighted date with its event.
A6: January 2026 | H6: February 2026 | O6: March 2026
A7: S | B7: M | C7: T | D7: W | E7: T | F7: F | G7: S | H7: S | I7: M | J7: T | K7: W | L7: T | M7: F | N7: S | O7: S | P7: M | Q7: T | R7: W | S7: T | T7: F | U7: S
E8: 1 | F8: 2 | G8: 3 | H8: 1 | I8: 2 | J8: 3 | K8: 4 | L8: 5 | M8: 6 | N8: 7 | O8: 1 | P8: 2 | Q8: 3 | R8: 4 | S8: 5 | T8: 6 | U8: 7
A9: 4 | B9: 5 | C9: 6 | D9: 7 | E9: 8 | F9: 9 | G9: 10 | H9: 8 | I9: 9 | J9: 10 | K9: 11 | L9: 12 | M9: 13 | N9: 14 | O9: 8 | P9: 9 | Q9: 10 | R9: 11 | S9: 12 | T9: 13 | U9: 14
A10: 11 | B10: 12 | C10: 13 | D10: 14 | E10: 15 | F10: 16 | G10: 17 | H10: 15 | I10: 16 | J10: 17 | K10: 18 | L10: 19 | M10: 20 | N10: 21 | O10: 15 | P10: 16 | Q10: 17 | R10: 18 | S10: 19 | T10: 20 | U10: 21
A11: 18 | B11: 19 | C11: 20 | D11: 21 | E11: 22 | F11: 23 | G11: 24 | H11: 22 | I11: 23 | J11: 24 | K11: 25 | L11: 26 | M11: 27 | N11: 28 | O11: 22 | P11: 23 | Q11: 24 | R11: 25 | S11: 26 | T11: 27 | U11: 28
A12: 25 | B12: 26 | C12: 27 | D12: 28 | E12: 29 | F12: 30 | G12: 31 | O12: 29 | P12: 30 | Q12: 31
A16: April 2026 | H16: May 2026 | O16: June 2026
A17: S | B17: M | C17: T | D17: W | E17: T | F17: F | G17: S | H17: S | I17: M | J17: T | K17: W | L17: T | M17: F | N17: S | O17: S | P17: M | Q17: T | R17: W | S17: T | T17: F | U17: S
D18: 1 | E18: 2 | F18: 3 | G18: 4 | M18: 1 | N18: 2 | P18: 1 | Q18: 2 | R18: 3 | S18: 4 | T18: 5 | U18: 6
A19: 5 | B19: 6 | C19: 7 | D19: 8 | E19: 9 | F19: 10 | G19: 11 | H19: 3 | I19: 4 | J19: 5 | K19: 6 | L19: 7 | M19: 8 | N19: 9 | O19: 7 | P19: 8 | Q19: 9 | R19: 10 | S19: 11 | T19: 12 | U19: 13
A20: 12 | B20: 13 | C20: 14 | D20: 15 | E20: 16 | F20: 17 | G20: 18 | H20: 10 | I20: 11 | J20: 12 | K20: 13 | L20: 14 | M20: 15 | N20: 16 | O20: 14 | P20: 15 | Q20: 16 | R20: 17 | S20: 18 | T20: 19 | U20: 20
A21: 19 | B21: 20 | C21: 21 | D21: 22 | E21: 23 | F21: 24 | G21: 25 | H21: 17 | I21: 18 | J21: 19 | K21: 20 | L21: 21 | M21: 22 | N21: 23 | O21: 21 | P21: 22 | Q21: 23 | R21: 24 | S21: 25 | T21: 26 | U21: 27
A22: 26 | B22: 27 | C22: 28 | D22: 29 | E22: 30 | H22: 24 | I22: 25 | J22: 26 | K22: 27 | L22: 28 | M22: 29 | N22: 30 | O22: 28 | P22: 29 | Q22: 30
H23: 31
A26: July 2026 | H26: August 2026 | O26: September 2026
A27: S | B27: M | C27: T | D27: W | E27: T | F27: F | G27: S | H27: S | I27: M | J27: T | K27: W | L27: T | M27: F | N27: S | O27: S | P27: M | Q27: T | R27: W | S27: T | T27: F | U27: S
D28: 1 | E28: 2 | F28: 3 | G28: 4 | N28: 1 | Q28: 1 | R28: 2 | S28: 3 | T28: 4 | U28: 5
A29: 5 | B29: 6 | C29: 7 | D29: 8 | E29: 9 | F29: 10 | G29: 11 | H29: 2 | I29: 3 | J29: 4 | K29: 5 | L29: 6 | M29: 7 | N29: 8 | O29: 6 | P29: 7 | Q29: 8 | R29: 9 | S29: 10 | T29: 11 | U29: 12
A30: 12 | B30: 13 | C30: 14 | D30: 15 | E30: 16 | F30: 17 | G30: 18 | H30: 9 | I30: 10 | J30: 11 | K30: 12 | L30: 13 | M30: 14 | N30: 15 | O30: 13 | P30: 14 | Q30: 15 | R30: 16 | S30: 17 | T30: 18 | U30: 19
A31: 19 | B31: 20 | C31: 21 | D31: 22 | E31: 23 | F31: 24 | G31: 25 | H31: 16 | I31: 17 | J31: 18 | K31: 19 | L31: 20 | M31: 21 | N31: 22 | O31: 20 | P31: 21 | Q31: 22 | R31: 23 | S31: 24 | T31: 25 | U31: 26
A32: 26 | B32: 27 | C32: 28 | D32: 29 | E32: 30 | F32: 31 | H32: 23 | I32: 24 | J32: 25 | K32: 26 | L32: 27 | M32: 28 | N32: 29 | O32: 27 | P32: 28 | Q32: 29 | R32: 30
H33: 30 | I33: 31
A36: October 2026 | H36: November 2026 | O36: December 2026
A37: S | B37: M | C37: T | D37: W | E37: T | F37: F | G37: S | H37: S | I37: M | J37: T | K37: W | L37: T | M37: F | N37: S | O37: S | P37: M | Q37: T | R37: W | S37: T | T37: F | U37: S
E38: 1 | F38: 2 | G38: 3 | H38: 1 | I38: 2 | J38: 3 | K38: 4 | L38: 5 | M38: 6 | N38: 7 | Q38: 1 | R38: 2 | S38: 3 | T38: 4 | U38: 5
A39: 4 | B39: 5 | C39: 6 | D39: 7 | E39: 8 | F39: 9 | G39: 10 | H39: 8 | I39: 9 | J39: 10 | K39: 11 | L39: 12 | M39: 13 | N39: 14 | O39: 6 | P39: 7 | Q39: 8 | R39: 9 | S39: 10 | T39: 11 | U39: 12
A40: 11 | B40: 12 | C40: 13 | D40: 14 | E40: 15 | F40: 16 | G40: 17 | H40: 15 | I40: 16 | J40: 17 | K40: 18 | L40: 19 | M40: 20 | N40: 21 | O40: 13 | P40: 14 | Q40: 15 | R40: 16 | S40: 17 | T40: 18 | U40: 19
A41: 18 | B41: 19 | C41: 20 | D41: 21 | E41: 22 | F41: 23 | G41: 24 | H41: 22 | I41: 23 | J41: 24 | K41: 25 | L41: 26 | M41: 27 | N41: 28 | O41: 20 | P41: 21 | Q41: 22 | R41: 23 | S41: 24 | T41: 25 | U41: 26
A42: 25 | B42: 26 | C42: 27 | D42: 28 | E42: 29 | F42: 30 | G42: 31 | H42: 29 | I42: 30 | O42: 27 | P42: 28 | Q42: 29 | R42: 30 | S42: 31
A47: EVENT LEGEND — highlighted dates above
A48: 46023 | D48: New Year's Day
A49: 46041 | D49: Martin Luther King Jr. Day
A50: 46069 | D50: Presidents' Day
A51: 46095 | D51: Dollywood Season Opening
A52: 46097 | D52: Spring Break — Southeast Schools
A53: 46098 | D53: Spring Break — Southeast Schools
A54: 46099 | D54: Spring Break — Southeast Schools
...

Sheet Upcoming List
A2: =HYPERLINK("#'Year-View Calendar'!A1", "← BACK") | D2: UPCOMING LIST | J2: =HYPERLINK("#'Settings'!A1", "NEXT →")
A4: Next 30 events sorted by date. Red rows = ≤ 14 days out AND Status = N — set the rate now before guests book at flat pricing.
A6: Date | B6: Days away | C6: Event | D6: Lift % | E6: Suggested rate | F6: Status | G6: Notes
A7: 46167 | B7: =IF(A7<>"",A7-TODAY(),"") | C7: Memorial Day | D7: 45 | E7: =IF(D7="","",Settings!$B$7*(1+D7/100)) | F7: N | G7: Unofficial start of summer — strong demand, 3-night min.
A8: 46181 | B8: =IF(A8<>"",A8-TODAY(),"") | C8: Summer Break — Southeast Schools | D8: 35 | E8: =IF(D8="","",Settings!$B$7*(1+D8/100)) | F8: N | G8: Sustained baseline lift through summer.
A9: 46207 | B9: =IF(A9<>"",A9-TODAY(),"") | C9: Independence Day | D9: 65 | E9: =IF(D9="","",Settings!$B$7*(1+D9/100)) | F9: N | G9: Peak summer holiday; require 3-night minimum.
A10: 46240 | B10: =IF(A10<>"",A10-TODAY(),"") | C10: Gatlinburg Craftsmen's Fair | D10: 40 | E10: =IF(D10="","",Settings!$B$7*(1+D10/100)) | F10: N | G10: Long-running summer arts festival; strong weekend lift.
A11: 46272 | B11: =IF(A11<>"",A11-TODAY(),"") | C11: Labor Day | D11: 80 | E11: =IF(D11="","",Settings!$B$7*(1+D11/100)) | F11: N | G11: Last big summer weekend; max lift, 3-night minimum.
A12: 46282 | B12: =IF(A12<>"",A12-TODAY(),"") | C12: Fall Rod Run — Pigeon Forge | D12: 70 | E12: =IF(D12="","",Settings!$B$7*(1+D12/100)) | F12: N | G12: Larger of the two Rod Runs; peak demand.
A13: 46300 | B13: =IF(A13<>"",A13-TODAY(),"") | C13: Fall Break — Southeast Schools | D13: 40 | E13: =IF(D13="","",Settings!$B$7*(1+D13/100)) | F13: N | G13: Fall break + foliage overlap; strong demand.
A14: 46307 | B14: =IF(A14<>"",A14-TODAY(),"") | C14: Columbus Day / Indigenous Peoples Day | D14: 30 | E14: =IF(D14="","",Settings!$B$7*(1+D14/100)) | F14: N | G14: Fall foliage in mountain markets — moderate lift.
A15: 46333 | B15: =IF(A15<>"",A15-TODAY(),"") | C15: Smoky Mountain Marathon | D15: 45 | E15: =IF(D15="","",Settings!$B$7*(1+D15/100)) | F15: N | G15: Runners + spectators fill Sevierville/Pigeon Forge.
A16: 46337 | B16: =IF(A16<>"",A16-TODAY(),"") | C16: Veterans Day | D16: 20 | E16: =IF(D16="","",Settings!$B$7*(1+D16/100)) | F16: N | G16: Mid-week observance; light lift.
A17: 46339 | B17: =IF(A17<>"",A17-TODAY(),"") | C17: Smoky Mountain Christmas — Dollywood | D17: 50 | E17: =IF(D17="","",Settings!$B$7*(1+D17/100)) | F17: N | G17: Multi-week Christmas event drives sustained lift.
A18: 46352 | B18: =IF(A18<>"",A18-TODAY(),"") | C18: Thanksgiving Day | D18: 55 | E18: =IF(D18="","",Settings!$B$7*(1+D18/100)) | F18: N | G18: Family travel peak; 3-night minimum recommended.
... A21: 46387 | B21: =IF(A21<>"",A21-TODAY(),"") | C21: New Year's Eve | D21: 80 | E21: =IF(D21="","",Settings!$B$7*(1+D21/100)) | F21: N | G21: Top demand night of year; max lift + 3-night min.
B22: =IF(A22<>"",A22-TODAY(),"") | E22: =IF(D22="","",Settings!$B$7*(1+D22/100))
B23: =IF(A23<>"",A23-TODAY(),"") | E23: =IF(D23="","",Settings!$B$7*(1+D23/100))
B24: =IF(A24<>"",A24-TODAY(),"") | E24: =IF(D24="","",Settings!$B$7*(1+D24/100))
B25: =IF(A25<>"",A25-TODAY(),"") | E25: =IF(D25="","",Settings!$B$7*(1+D25/100))
B26: =IF(A26<>"",A26-TODAY(),"") | E26: =IF(D26="","",Settings!$B$7*(1+D26/100))
B27: =IF(A27<>"",A27-TODAY(),"") | E27: =IF(D27="","",Settings!$B$7*(1+D27/100))
B28: =IF(A28<>"",A28-TODAY(),"") | E28: =IF(D28="","",Settings!$B$7*(1+D28/100))
B29: =IF(A29<>"",A29-TODAY(),"") | E29: =IF(D29="","",Settings!$B$7*(1+D29/100))
B30: =IF(A30<>"",A30-TODAY(),"") | E30: =IF(D30="","",Settings!$B$7*(1+D30/100))
B31: =IF(A31<>"",A31-TODAY(),"") | E31: =IF(D31="","",Settings!$B$7*(1+D31/100))
B32: =IF(A32<>"",A32-TODAY(),"") | E32: =IF(D32="","",Settings!$B$7*(1+D32/100))
B33: =IF(A33<>"",A33-TODAY(),"") | E33: =IF(D33="","",Settings!$B$7*(1+D33/100))
... B36: =IF(A36<>"",A36-TODAY(),"") | E36: =IF(D36="","",Settings!$B$7*(1+D36/100))

Sheet Settings
A2: =HYPERLINK("#'Upcoming List'!A1", "← BACK") | D2: SETTINGS
A4: Active year, base rate, and dropdown lists for Events. Edit to match your portfolio.
B5: 2026 | D5: Active year — drives Year-View Calendar and Upcoming List | F5: Active year — drives Year-View Calendar and Upcoming List
D6: Federal Holiday | E6: All
B7: 185 | D7: School Break | E7: Northeast | F7: Base nightly rate — Suggested rate = Base × (1 + Lift%)
D8: Sporting | E8: Southeast
B9: Southeast | D9: Concert | E9: Midwest | F9: Region — drives default school break dates
D10: Festival | E10: Southwest
D11: Convention | E11: West Coast
A12: DROPDOWN LISTS — edit to match your portfolio | D12: Other | E12: Mountain
D13: Event types | E13: Regions
A18: YEAR-END ARCHIVE — fill in Jan, then clear Events for the new year
A19: Year | B19: Events tracked | C19: Avg lift % | D19: Total $ lift captured
A20: 2026
A21: 2027
A22: 2028
A23: 2029
A24: 2030
A25: 2031
A28: Tip: each January, copy your YTD totals from Events into the row above for last year, then clear Events to repopulate with the new year's holidays + festivals.
