Workbook

Sheet Start
A2: The STR Ledger
A4: Glamping / Unique-Stay P&L
A5: Built for yurts, domes, A-frames, treehouses, and the off-grid life.
A6: =IF(Income!N7=0,"📊 Log a month of revenue to see your seasonality verdict.","✓ YTD Revenue = "&TEXT(Income!N7,"$#,##0")&" · YTD NOI = "&TEXT(Income!N7-Expenses!N25,"$#,##0"))
A7: SPC-001 · v2.2 · DEMO
A10: YTD REVENUE | D10: PEAK SHARE | G10: YTD EXPENSES | J10: ALT REV %
A11: =Income!N7 | D11: =IF(Income!N7=0,0,('Seasonality Dashboard'!B7)/Income!N7) | G11: =Expenses!N25 | J11: =IF(Income!N7=0,0,SUM(Income!N10:N13)/Income!N7)
A14: lodging + alt | D14: of total revenue | G14: all categories | J14: firewood + gear + experiences
A17: =HYPERLINK("#'Income'!A1", "→ OPEN INCOME MATRIX")
A22: =HYPERLINK("#'Expenses'!A1", "Expenses") | D22: =HYPERLINK("#'Seasonality Dashboard'!A1", "Seasonality") | G22: =HYPERLINK("#'Off-Grid Utilities'!A1", "Off-Grid Utilities") | J22: =HYPERLINK("#'Settings'!A1", "Settings")
A25: =HYPERLINK("#'Alt Revenue'!A1", "Alt Revenue") | G25: =HYPERLINK("#'Expenses'!A1", "📄 Print Year-End P&L")
A28: 📅 SEASONALITY: glamping commonly loses money Off-Season — track Peak NOI carefully. Most operators earn ~70% of annual NOI in Peak alone.
A30: 💡 Upgrade to the Full version at thestrledger.com/upgrade — multi-property, depreciation, multi-LLC support.
A33: Questions? hello@thestrledger.com
A34: SPC-001 · v2.2 · Free updates forever

Sheet Income
A2: =HYPERLINK("#'Start'!A1", "← BACK") | D2: INCOME | J2: =HYPERLINK("#'Expenses'!A1", "NEXT →")
A4: Monthly revenue rollup — lodging + alt-revenue lines
A5: Line | B5: Jan | C5: Feb | D5: Mar | E5: Apr | F5: May | G5: Jun | H5: Jul | I5: Aug | J5: Sep | K5: Oct | L5: Nov | M5: Dec | N5: YTD
A7: TOTAL REVENUE | B7: =SUM(B8:B14) | C7: =SUM(C8:C14) | D7: =SUM(D8:D14) | E7: =SUM(E8:E14) | F7: =SUM(F8:F14) | G7: =SUM(G8:G14) | H7: =SUM(H8:H14) | I7: =SUM(I8:I14) | ... N7: =SUM(N8:N14)
A8: Lodging revenue (nightly rate × nights) | B8: 1100 | C8: 1000 | D8: 3200 | E8: 3500 | F8: 9800 | G8: 13200 | H8: 14500 | I8: 14200 | J8: 12800 | K8: 11500 | L8: 4300 | M8: 1300 | N8: =SUM(B8:M8)
A9: Cleaning fee revenue | B9: 150 | C9: 130 | D9: 320 | E9: 360 | F9: 980 | G9: 1200 | H9: 1320 | I9: 1280 | J9: 1180 | K9: 1080 | L9: 430 | M9: 170 | N9: =SUM(B9:M9)
A10: Firewood sales | B10: 20 | C10: 20 | D10: 60 | E10: 80 | F10: 240 | G10: 340 | H10: 380 | I10: 360 | J10: 280 | K10: 200 | L10: 60 | M10: 20 | N10: =SUM(B10:M10)
A11: Gear rentals (kayak / fire pit / e-bike) | B11: 0 | C11: 0 | D11: 60 | E11: 120 | F11: 380 | G11: 540 | H11: 620 | I11: 600 | J11: 480 | K11: 240 | L11: 0 | M11: 0 | N11: =SUM(B11:M11)
A12: On-site experiences (guided / hosted) | B12: 0 | C12: 0 | D12: 0 | E12: 50 | F12: 150 | G12: 220 | H12: 260 | I12: 240 | J12: 180 | K12: 80 | L12: 20 | M12: 0 | N12: =SUM(B12:M12)
A13: Photo-shoot fees | B13: 0 | C13: 0 | D13: 50 | E13: 100 | F13: 250 | G13: 350 | H13: 400 | I13: 400 | J13: 250 | K13: 150 | L13: 50 | M13: 0 | N13: =SUM(B13:M13)
A14: Pet fee revenue | B14: 50 | C14: 50 | D14: 100 | E14: 100 | F14: 250 | G14: 350 | H14: 400 | I14: 400 | J14: 350 | K14: 300 | L14: 100 | M14: 50 | N14: =SUM(B14:M14)

Sheet Expenses
A2: =HYPERLINK("#'Income'!A1", "← BACK") | D2: EXPENSES | J2: =HYPERLINK("#'Seasonality Dashboard'!A1", "NEXT →")
A4: Monthly expense rollup — glamping-specific categories
A5: Category | B5: Jan | C5: Feb | D5: Mar | E5: Apr | F5: May | G5: Jun | H5: Jul | I5: Aug | J5: Sep | K5: Oct | L5: Nov | M5: Dec | N5: YTD
A7: Propane (refills + tank rental) | B7: 220 | C7: 220 | D7: 280 | E7: 320 | F7: 480 | G7: 540 | H7: 560 | I7: 540 | J7: 500 | K7: 420 | L7: 380 | M7: 340 | N7: =SUM(B7:M7)
A8: Generator fuel + maintenance | B8: 30 | C8: 30 | D8: 60 | E8: 80 | F8: 140 | G8: 180 | H8: 200 | I8: 180 | J8: 160 | K8: 100 | L8: 30 | M8: 10 | N8: =SUM(B8:M8)
A9: Water (delivery / well pump electrical) | B9: 80 | C9: 80 | D9: 100 | E9: 120 | F9: 200 | G9: 240 | H9: 260 | I9: 240 | J9: 220 | K9: 160 | L9: 100 | M9: 80 | N9: =SUM(B9:M9)
A10: Septic / port-a-potty pumping | B10: 0 | C10: 0 | D10: 120 | E10: 120 | F10: 240 | G10: 240 | H10: 240 | I10: 240 | J10: 240 | K10: 240 | L10: 120 | M10: 0 | N10: =SUM(B10:M10)
A11: Linens (replaced more frequently) | B11: 120 | C11: 120 | D11: 200 | E11: 240 | F11: 420 | G11: 480 | H11: 500 | I11: 480 | J11: 440 | K11: 380 | L11: 180 | M11: 120 | N11: =SUM(B11:M11)
A12: Weather damage repairs | B12: 200 | C12: 0 | D12: 400 | E12: 0 | F12: 200 | G12: 0 | H12: 0 | I12: 0 | J12: 200 | K12: 200 | L12: 400 | M12: 200 | N12: =SUM(B12:M12)
A13: Pest control | B13: 0 | C13: 60 | D13: 0 | E13: 60 | F13: 0 | G13: 60 | H13: 0 | I13: 60 | J13: 0 | K13: 60 | L13: 0 | M13: 60 | N13: =SUM(B13:M13)
A14: Composting / waste management | B14: 40 | C14: 40 | D14: 60 | E14: 60 | F14: 100 | G14: 120 | H14: 140 | I14: 120 | J14: 100 | K14: 80 | L14: 60 | M14: 40 | N14: =SUM(B14:M14)
A15: Decor refresh (Insta inventory) | B15: 0 | C15: 0 | D15: 200 | E15: 0 | F15: 300 | G15: 0 | H15: 200 | I15: 0 | J15: 200 | K15: 0 | L15: 0 | M15: 0 | N15: =SUM(B15:M15)
A16: Listing photo refresh | B16: 0 | C16: 0 | D16: 400 | E16: 0 | F16: 0 | G16: 0 | H16: 400 | I16: 0 | J16: 0 | K16: 0 | L16: 400 | M16: 0 | N16: =SUM(B16:M16)
A17: Insurance (specialty glamping policy) | B17: 180 | C17: 180 | D17: 180 | E17: 180 | F17: 180 | G17: 180 | H17: 180 | I17: 180 | J17: 180 | K17: 180 | L17: 180 | M17: 180 | N17: =SUM(B17:M17)
A18: Property taxes | B18: 0 | C18: 0 | D18: 0 | E18: 0 | F18: 0 | G18: 0 | H18: 0 | I18: 0 | J18: 0 | K18: 0 | L18: 1800 | M18: 0 | N18: =SUM(B18:M18)
... A23: Other — Misc | B23: 40 | C23: 40 | D23: 60 | E23: 60 | F23: 100 | G23: 120 | H23: 140 | I23: 120 | J23: 100 | K23: 80 | L23: 60 | M23: 40 | N23: =SUM(B23:M23)
A25: TOTAL EXPENSES | B25: =SUM(B7:B23) | C25: =SUM(C7:C23) | D25: =SUM(D7:D23) | E25: =SUM(E7:E23) | F25: =SUM(F7:F23) | G25: =SUM(G7:G23) | H25: =SUM(H7:H23) | I25: =SUM(I7:I23) | ... N25: =SUM(N7:N23)
A27: NET OPERATING INCOME | B27: =Income!B7-B25 | C27: =Income!C7-C25 | D27: =Income!D7-D25 | E27: =Income!E7-E25 | F27: =Income!F7-F25 | G27: =Income!G7-G25 | H27: =Income!H7-H25 | I27: =Income!I7-I25 | ... N27: =Income!N7-N25

Sheet Seasonality Dashboard
A2: =HYPERLINK("#'Expenses'!A1", "← BACK") | D2: SEASONALITY DASHBOARD | J2: =HYPERLINK("#'Off-Grid Utilities'!A1", "NEXT →")
A4: Per-season breakdown — set season month ranges on Settings
A5: Metric | B5: Peak (May-Oct) | C5: Shoulder (Mar-Apr, Nov) | D5: Off (Dec-Feb)
A7: Revenue total | B7: =Income!F7+Income!G7+Income!H7+Income!I7+Income!J7+Income!K7 | C7: =Income!D7+Income!E7+Income!L7 | D7: =Income!B7+Income!C7+Income!M7
A8: Expenses total | B8: =Expenses!F25+Expenses!G25+Expenses!H25+Expenses!I25+Expenses!J25+Expenses!K25 | C8: =Expenses!D25+Expenses!E25+Expenses!L25 | D8: =Expenses!B25+Expenses!C25+Expenses!M25
A9: NOI | B9: =B7-B8 | C9: =C7-C8 | D9: =D7-D8
A11: Months in season | B11: May, Jun, Jul, Aug, Sep, Oct | C11: Mar, Apr, Nov | D11: Dec, Jan, Feb
A12: Avg occupancy % | B12: 0.78 | C12: 0.45 | D12: 0.18
A13: Avg ADR | B13: 245 | C13: 185 | D13: 145
A15: Peak share of NOI: | B15: =IF(SUM(B9:D9)=0,0,B9/SUM(B9:D9))

Sheet Off-Grid Utilities
A2: =HYPERLINK("#'Seasonality Dashboard'!A1", "← BACK") | D2: OFF-GRID UTILITIES | J2: =HYPERLINK("#'Alt Revenue'!A1", "NEXT →")
A4: Three stacked registers — propane refills, generator hours, water-haul
A6: PROPANE REFILL LOG
A7: Date | B7: Property | C7: Refill (gal) | D7: Cost ($) | E7: Vendor | F7: Tank % at refill | G7: Notes
A8: 46034 | B8: Smokies Yurt | C8: 100 | D8: 320 | E8: Suburban Propane | F8: 20%
A9: 46068 | B9: Smokies Yurt | C9: 100 | D9: 315 | E9: Suburban Propane | F9: 25%
A10: 46101 | B10: Smokies Yurt | C10: 120 | D10: 380 | E10: AmeriGas | F10: 15%
A11: 46134 | B11: Smokies Yurt | C11: 120 | D11: 385 | E11: AmeriGas | F11: 20%
A12: 46160 | B12: Smokies Yurt | C12: 150 | D12: 470 | E12: Suburban Propane | F12: 10%
A13: 46188 | B13: Smokies Yurt | C13: 150 | D13: 475 | E13: Suburban Propane | F13: 10%
A14: 46215 | B14: Smokies Yurt | C14: 150 | D14: 480 | E14: AmeriGas | F14: 15%
A15: 46244 | B15: Smokies Yurt | C15: 150 | D15: 470 | E15: AmeriGas | F15: 10%
A16: 46280 | B16: Smokies Yurt | C16: 140 | D16: 440 | E16: Suburban Propane | F16: 15%
A17: 46315 | B17: Smokies Yurt | C17: 130 | D17: 410 | E17: Suburban Propane | F17: 20%
A18: 46348 | B18: Smokies Yurt | C18: 120 | D18: 380 | E18: AmeriGas | F18: 20%
A19: 46374 | B19: Smokies Yurt | C19: 110 | D19: 350 | E19: AmeriGas | F19: 25%
A58: TOTALS | C58: =SUM(C8:C57) | D58: =SUM(D8:D57)
A60: GENERATOR HOURS LOG
A61: Date | B61: Hours run | C61: Fuel added (gal) | D61: Service notes
A62: 46037 | B62: 4 | C62: 2 | D62: Cold-snap backup
A63: 46073 | B63: 3 | C63: 2 | D63: Storm outage
A64: 46099 | B64: 6 | C64: 3 | D64: Routine
A65: 46134 | B65: 8 | C65: 4 | D65: Routine + oil change
A66: 46157 | B66: 14 | C66: 6 | D66: Peak season starts
A67: 46185 | B67: 22 | C67: 10 | D67: Peak operations
A68: 46213 | B68: 28 | C68: 12 | D68: Peak — heatwave AC
A69: 46228 | B69: 24 | C69: 12 | D69: Peak — continued
A70: 46249 | B70: 26 | C70: 12 | D70: Peak — service due
A71: 46277 | B71: 18 | C71: 8 | D71: Shoulder taper
A72: 46310 | B72: 12 | C72: 6 | D72: Shoulder taper
A73: 46346 | B73: 4 | C73: 2 | D73: Off-season check
A112: TOTALS | B112: =SUM(B62:B111) | C112: =SUM(C62:C111)
A114: WATER-HAUL LOG
A115: Date | B115: Gallons delivered | C115: Cost ($) | D115: Vendor
A116: 46096 | B116: 500 | C116: 120 | D116: AquaHaul TN
A117: 46130 | B117: 500 | C117: 120 | D117: AquaHaul TN
A118: 46157 | B118: 750 | C118: 180 | D118: AquaHaul TN
A119: 46183 | B119: 750 | C119: 180 | D119: Mountain Water Co
A120: 46211 | B120: 1000 | C120: 240 | D120: Mountain Water Co
A121: 46225 | B121: 1000 | C121: 240 | D121: AquaHaul TN
...

Sheet Alt Revenue
A2: =HYPERLINK("#'Off-Grid Utilities'!A1", "← BACK") | D2: ALT REVENUE | J2: =HYPERLINK("#'Settings'!A1", "NEXT →")
A4: Alt-revenue mix — pulls from Income tab rows 10-13
A5: Alt-Revenue Line | B5: Jan | C5: Feb | D5: Mar | E5: Apr | F5: May | G5: Jun | H5: Jul | I5: Aug | J5: Sep | K5: Oct | L5: Nov | M5: Dec | N5: YTD
A7: Firewood sales | B7: =Income!B10 | C7: =Income!C10 | D7: =Income!D10 | E7: =Income!E10 | F7: =Income!F10 | G7: =Income!G10 | H7: =Income!H10 | I7: =Income!I10 | ... M7: =Income!M10 | N7: =SUM(B7:M7)
A8: Gear rentals (kayak / fire pit / e-bike) | B8: =Income!B11 | C8: =Income!C11 | D8: =Income!D11 | E8: =Income!E11 | F8: =Income!F11 | G8: =Income!G11 | H8: =Income!H11 | I8: =Income!I11 | ... M8: =Income!M11 | N8: =SUM(B8:M8)
A9: On-site experiences (guided / hosted) | B9: =Income!B12 | C9: =Income!C12 | D9: =Income!D12 | E9: =Income!E12 | F9: =Income!F12 | G9: =Income!G12 | H9: =Income!H12 | I9: =Income!I12 | ... M9: =Income!M12 | N9: =SUM(B9:M9)
A10: Photo-shoot fees | B10: =Income!B13 | C10: =Income!C13 | D10: =Income!D13 | E10: =Income!E13 | F10: =Income!F13 | G10: =Income!G13 | H10: =Income!H13 | I10: =Income!I13 | ... M10: =Income!M13 | N10: =SUM(B10:M10)
A12: TOTAL ALT REVENUE | B12: =SUM(B7:B10) | C12: =SUM(C7:C10) | D12: =SUM(D7:D10) | E12: =SUM(E7:E10) | F12: =SUM(F7:F10) | G12: =SUM(G7:G10) | H12: =SUM(H7:H10) | I12: =SUM(I7:I10) | ... N12: =SUM(N7:N10)

Sheet Settings
A2: =HYPERLINK("#'Alt Revenue'!A1", "← BACK") | D2: SETTINGS
A4: Property name · active year · season cutoffs · off-grid toggle
A5: Property name: | B5: Smokies Yurt
A6: Property type: | B6: Yurt + dome combo (10 acres)
A7: Active year: | B7: 2026
A9: Peak season start date: | B9: 46143
A10: Shoulder start date: | B10: 46082
A11: Off-season start date: | B11: 46357
A13: Off-grid? (Y/N): | B13: Y
A14: Number of units: | B14: 2
A15: Avg unit capacity (sqft): | B15: 320
A17: Active year drives every monthly aggregate. Bump it each January. Season cutoff dates are reference markers — Seasonality Dashboard uses fixed Peak (May-Oct) / Shoulder (Mar-Apr, Nov) / Off (Dec-Feb) windows.
A21: Questions? hello@thestrledger.com
A22: SPC-001 · v2.2
